Workbook

Sheet Summary
A1: Chaldale Moorage Audit | Administrator and Board Review
A2: Prepared 2026-08-01 | Queue scope 2023-01-01 through 2026-07-31 | Positive billing variance means expected revenue exceeds the supplied export
A4: Queue and Appeal Risk | D4: Billing Reconciliation | H4: Aging and Collections
A5: Dated skips tested | B5: =COUNTIF('Queue Exceptions'!$A:$A,"SKIP") -> 309 | D5: Occupied slips | E5: =COUNTIF('Billing Reconciliations'!$D:$D,"WL-*") -> 1086 | H5: Ledger accounts supplied | I5: =COUNTIF(Aging!$A:$A,"AC-*") -> 260
A6: Skips lacking proof | B6: =COUNTIFS('Queue Exceptions'!$A:$A,"SKIP",'Queue Exceptions'!$Q:$Q,"EXCEPTION") -> 19 | D6: Expected July base | E6: =SUM('Billing Reconciliations'!$P:$P) -> 439918.3 | H6: Active accounts absent | I6: =E5-I5 -> 826
A7: LOA amendments tested | B7: =COUNTIF('Queue Exceptions'!$A:$A,"LOA AMENDMENT") -> 176 | D7: Exported July base | E7: =SUM('Billing Reconciliations'!$U:$U) -> 319760.05 | H7: >90-day accounts | I7: =COUNTIF(Aging!$Q:$Q,"DELINQUENT >90") -> 6
A8: Unsupported LOA entries | B8: =COUNTIFS('Queue Exceptions'!$A:$A,"LOA AMENDMENT",'Queue Exceptions'!$Q:$Q,"EXCEPTION") -> 11 | D8: Monthly exposure | E8: =SUM('Billing Reconciliations'!$V:$V) -> 120158.25 | H8: >90-day balance | I8: =SUMIF(Aging!$Q:$Q,"DELINQUENT >90",Aging!$P:$P) -> 4368
A9: Unresolved LOA-use cases | B9: =COUNTIFS('Queue Exceptions'!$A:$A,"LOA AMENDMENT",'Queue Exceptions'!$P:$P,"UNRESOLVED USE") -> 2 | D9: Annualized exposure | E9: =SUM('Billing Reconciliations'!$W:$W) -> 1441899 | H9: Aging bucket total | I9: =SUM(Aging!$M:$M) -> 147836
A10: Undated omitted leads | B10: =COUNTIF('Queue Exceptions'!$A:$A,"UNDATED LEAD") -> 2 | D10: Missing export lines | E10: =COUNTIF('Billing Reconciliations'!$X:$X,"MISSING FROM EXPORT") -> 317 | H10: total_due control gap | I10: =SUM(Aging!$O:$O) -> 17108
A11: Priority 1 items | B11: =COUNTIF('Queue Exceptions'!$R:$R,"PRIORITY 1*") -> 7 | D11: Potential commercial uplift | E11: =SUM('Billing Reconciliations'!$Y:$Y) -> 12281.34 | H11: Rows with total_due errors | I11: =COUNTIF(Aging!$O:$O,">0.004")+COUNTIF(Aging!$O:$O,"<-0.004") -> 39
D12: Covered placements >40 ft | E12: =COUNTIF('Billing Reconciliations'!$AA:$AA,"COVERED >40 FT") -> 228
A15: Board Decision Framing
A16: ="Billing export exposure is "&TEXT(E8,"$#,##0.00")&" per month and "&TEXT(E9,"$#,##0.00")&" annualized. Treat it as exposure, not confirmed GL loss, until the complete July subledger and batch-control report are reconciled." -> Billing export exposure is $120,158.25 per month and $1,441,899.00 annualized. Treat it as exposure, not confirmed GL loss, until the complete July subledger and batch-control report are reconciled.
A17: ="Appeal risk: "&TEXT(B6,"#,##0")&" proven same-day proof failures, "&TEXT(B9,"#,##0")&" unresolved LOA-use cases, and "&TEXT(B10,"#,##0")&" undated omitted leads. Appeal 2018-3 places the burden on the District and bars later-created support from curing a skip." -> Appeal risk: 19 proven same-day proof failures, 2 unresolved LOA-use cases, and 2 undated omitted leads. Appeal 2018-3 places the burden on the District and bars later-created support from curing a skip.
A18: ="Collections: "&TEXT(I7,"#,##0")&" active holders carry "&TEXT(I8,"$#,##0.00")&" more than 90 days past due, but the supplied aging covers only "&TEXT(I5,"#,##0")&" of "&TEXT(E5,"#,##0")&" occupied accounts." -> Collections: 6 active holders carry $4,368.00 more than 90 days past due, but the supplied aging covers only 260 of 1,086 occupied accounts.
A20: Categories With No Identified Exception
A21: Exported billed-line rate and length arithmetic | D21: =IF(COUNTIFS('Billing Reconciliations'!$D:$D,"WL-*",'Billing Reconciliations'!$Q:$Q,"<>",'Billing Reconciliations'!$X:$X,"<>CLEAR")=0,"No exceptions identified among exported billed lines","Exceptions identified - see Billing Reconciliations") -> No exceptions identified among exported billed lines
A22: Overbilling | D22: =IF(COUNTIF('Billing Reconciliations'!$X:$X,"OVERBILLING")=0,"No exceptions identified","Overbilling exceptions identified") -> No exceptions identified
A23: Conclusive use of an unsupported LOA | D23: =IF(COUNTIF('Queue Exceptions'!$P:$P,"CONFIRMED USE")=0,"No conclusive use established; two cases remain unresolved","Confirmed use identified") -> No conclusive use established; two cases remain unresolved
A24: Aging accounts without >90-day balances | D24: ="No >90-day exception on "&TEXT(COUNTIFS(Aging!$A:$A,"AC-*",Aging!$Q:$Q,"CLEAR"),"#,##0")&" supplied accounts" -> No >90-day exception on 254 supplied accounts
A27: Basis, Authority, and Limitations
A28: Queue test | C28: skip_events_2022_2026.csv and five in-scope skip PDFs; Standing Order 15-3 sections 3.2-3.3; Appeal 2018-3 p.2. A cover sheet or later review is not proof.
A29: LOA test | C29: amendment_log_2022_2026.csv; Resolution 2022-06 p.2 section 4.3 and p.3 section 6.2. The resolution controls prior rules under section 7.2.
A30: Billing basis | C30: slip_inventory_2026-08.csv, applicant_register_2026-08.csv, and billing_transactions_2022_2026.csv. Billable feet = greater of rounded-up recorded LOA or nominal slip length.
A31: Rate basis | C31: Resolution 2022-06 p.1 sections 1.1-1.3: $10.40 covered and $7.55 open per foot-month from 2022-08-01. Commercial multiplier remains 1.35 under Tariff Resolution 2019-14 section 2.3.
A32: Aging basis | C32: ar_aging_2026-07-31.xlsx, AR_Aging rows 3-262. Its Summary sheet labels days_90 as 91-120, so more than 90 days = days_90 + days_120_plus.
A33: Extract limits | C33: Billing ends after GW-0501 and aging omits 826 active accounts. Complete July customer subledger, posting-batch control, GL detail, full aging, current agreements, and check-in measurement blocks are required to confirm district-wide loss.
A34: Scope assumption | C34: August OCCUPIED inventory is assumed active on 2026-07-31. Base reconciliation excludes tax, electricity, late fees, liveaboard charges, and unverified commercial uplift.

Sheet Queue Exceptions
A1: Queue Exceptions | Skip and LOA Control Testing
A2: Audit period: 2023-01-01 through 2026-07-31 inclusive
A3: Population: every dated skip in the skip export and every dated LOA amendment in the amendment log. Two undated leads are displayed but excluded from the dated population.
A4: Evidence Flag Y ordinarily reflects the source export/log, not a paper-file inspection. Only five in-scope skip PDFs were supplied; filter Exception Status and Appeal Priority for action.
A5: Record Type | B5: Event Date | C5: Record ID | D5: Offer ID | E5: Applicant ID | F5: Applicant Name | G5: Rank | H5: Slip ID | I5: Basin | J5: Reason / Field | K5: Old LOA | L5: New LOA | M5: Evidence Flag | N5: Evidence Reference | O5: Required Standard | P5: Use Assessment | Q5: Exception Status | R5: Appeal Priority | S5: Key Facts | T5: Source Records | U5: Governing Authority
A6: SKIP | B6: 44934 | C6: SKP-2023-0095 | D6: OFR-2023-0323 | E6: WL-03099 | F6: Ryan Robertson / Robertson Marine LLC | G6: 2099 | H6: LP-0317 | I6: Ledgport | J6: vessel-fit | M6: Y | N6: OTHER_SUPPORT; skip export flag=Y | O6: Vessel particulars of record relied upon | P6: NOT APPLICABLE | Q6: =IF(A6="UNDATED LEAD","UNRESOLVED",IF(M6="N","EXCEPTION",IF(A6="SKIP",IF(ISNUMBER(SEARCH("_skip_justification.pdf",N6)),"CLEAR - FILE VERIFIED","CLEAR ON EXPORT"),"CLEAR ON LOG"))) -> CLEAR ON EXPORT | R6: =IF(Q6="UNRESOLVED","PRIORITY 1 - OBTAIN FILE",IF(Q6<>"EXCEPTION","NONE",IF(OR(AND(A6="LOA AMENDMENT",P6="UNRESOLVED USE"),AND(A6="SKIP",OR(E6="WL-02618",E6="WL-03044",E6="WL-03390"))),"PRIORITY 1",IF(A6="SKIP","PRIORITY 2","PRIORITY 3")))) -> NONE | T6: skip_events_2022_2026.csv row 96; offer_events_2022_2026.csv row 324 | U6: Standing Order 15-3 sections 3.2-3.3; Appeal 2018-3 p.2 sections III-A and IV-A
A7: SKIP | B7: 44934 | C7: SKP-2023-0096 | D7: OFR-2023-0324 | E7: WL-02685 | F7: Stephanie Hill | G7: 1685 | H7: LP-0906 | I7: Ledgport | J7: vessel-fit | M7: Y | N7: INSURANCE_DECL; skip export flag=Y | O7: Vessel particulars of record relied upon | P7: NOT APPLICABLE | Q7: =IF(A7="UNDATED LEAD","UNRESOLVED",IF(M7="N","EXCEPTION",IF(A7="SKIP",IF(ISNUMBER(SEARCH("_skip_justification.pdf",N7)),"CLEAR - FILE VERIFIED","CLEAR ON EXPORT"),"CLEAR ON LOG"))) -> CLEAR ON EXPORT | R7: =IF(Q7="UNRESOLVED","PRIORITY 1 - OBTAIN FILE",IF(Q7<>"EXCEPTION","NONE",IF(OR(AND(A7="LOA AMENDMENT",P7="UNRESOLVED USE"),AND(A7="SKIP",OR(E7="WL-02618",E7="WL-03044",E7="WL-03390"))),"PRIORITY 1",IF(A7="SKIP","PRIORITY 2","PRIORITY 3")))) -> NONE | T7: skip_events_2022_2026.csv row 97; offer_events_2022_2026.csv row 325 | U7: Standing Order 15-3 sections 3.2-3.3; Appeal 2018-3 p.2 sections III-A and IV-A
A8: SKIP | B8: 44934 | C8: SKP-2023-0098 | D8: OFR-2023-0334 | E8: WL-01959 | F8: Jonathan Moore | G8: 959 | H8: VB-1023 | I8: Vessbank | J8: not-current | M8: Y | N8: WRITTEN_STATEMENT; skip export flag=Y | O8: Ledger or register extract showing the deficiency | P8: NOT APPLICABLE | Q8: =IF(A8="UNDATED LEAD","UNRESOLVED",IF(M8="N","EXCEPTION",IF(A8="SKIP",IF(ISNUMBER(SEARCH("_skip_justification.pdf",N8)),"CLEAR - FILE VERIFIED","CLEAR ON EXPORT"),"CLEAR ON LOG"))) -> CLEAR ON EXPORT | R8: =IF(Q8="UNRESOLVED","PRIORITY 1 - OBTAIN FILE",IF(Q8<>"EXCEPTION","NONE",IF(OR(AND(A8="LOA AMENDMENT",P8="UNRESOLVED USE"),AND(A8="SKIP",OR(E8="WL-02618",E8="WL-03044",E8="WL-03390"))),"PRIORITY 1",IF(A8="SKIP","PRIORITY 2","PRIORITY 3")))) -> NONE | T8: skip_events_2022_2026.csv row 99; offer_events_2022_2026.csv row 335 | U8: Standing Order 15-3 sections 3.2-3.3; Appeal 2018-3 p.2 sections III-A and IV-A
A9: SKIP | B9: 44936 | C9: SKP-2023-0099 | D9: OFR-2023-0338 | E9: WL-01695 | F9: Antonio Leach | G9: 695 | H9: EW-0203 | I9: Eastwey | J9: vessel-fit | M9: N | N9: INSURANCE_DECL; skip export flag=N | O9: Vessel particulars of record relied upon | P9: NOT APPLICABLE | Q9: =IF(A9="UNDATED LEAD","UNRESOLVED",IF(M9="N","EXCEPTION",IF(A9="SKIP",IF(ISNUMBER(SEARCH("_skip_justification.pdf",N9)),"CLEAR - FILE VERIFIED","CLEAR ON EXPORT"),"CLEAR ON LOG"))) -> EXCEPTION | R9: =IF(Q9="UNRESOLVED","PRIORITY 1 - OBTAIN FILE",IF(Q9<>"EXCEPTION","NONE",IF(OR(AND(A9="LOA AMENDMENT",P9="UNRESOLVED USE"),AND(A9="SKIP",OR(E9="WL-02618",E9="WL-03044",E9="WL-03390"))),"PRIORITY 1",IF(A9="SKIP","PRIORITY 2","PRIORITY 3")))) -> PRIORITY 2 | S9: No supporting record attached. Later disposition=SUSTAINED; review=GF on 2023-01-13; later review cannot cure the missing same-day record. | T9: skip_events_2022_2026.csv row 100; offer_events_2022_2026.csv row 339 | U9: Standing Order 15-3 sections 3.2-3.3; Appeal 2018-3 p.2 sections III-A and IV-A
A10: SKIP | B10: 44952 | C10: SKP-2023-0097 | D10: OFR-2023-0326 | E10: WL-01298 | F10: Jason Boyd / Boyd Marine LLC | G10: 298 | H10: GW-0708 | I10: Gullwing | J10: vessel-fit | M10: Y | N10: OTHER_SUPPORT; skip export flag=Y | O10: Vessel particulars of record relied upon | P10: NOT APPLICABLE | Q10: =IF(A10="UNDATED LEAD","UNRESOLVED",IF(M10="N","EXCEPTION",IF(A10="SKIP",IF(ISNUMBER(SEARCH("_skip_justification.pdf",N10)),"CLEAR - FILE VERIFIED","CLEAR ON EXPORT"),"CLEAR ON LOG"))) -> CLEAR ON EXPORT | R10: =IF(Q10="UNRESOLVED","PRIORITY 1 - OBTAIN FILE",IF(Q10<>"EXCEPTION","NONE",IF(OR(AND(A10="LOA AMENDMENT",P10="UNRESOLVED USE"),AND(A10="SKIP",OR(E10="WL-02618",E10="WL-03044",E10="WL-03390"))),"PRIORITY 1",IF(A10="SKIP","PRIORITY 2","PRIORITY 3")))) -> NONE | T10: skip_events_2022_2026.csv row 98; offer_events_2022_2026.csv row 327 | U10: Standing Order 15-3 sections 3.2-3.3; Appeal 2018-3 p.2 sections III-A and IV-A
A11: SKIP | B11: 44967 | C11: SKP-2023-0102 | D11: OFR-2023-0346 | E11: WL-03582 | F11: Melissa Jones / Jones Holdings LLC | G11: 2582 | H11: GW-0615 | I11: Gullwing | J11: not-current | M11: Y | N11: INSURANCE_DECL; skip export flag=Y | O11: Ledger or register extract showing the deficiency | P11: NOT APPLICABLE | Q11: =IF(A11="UNDATED LEAD","UNRESOLVED",IF(M11="N","EXCEPTION",IF(A11="SKIP",IF(ISNUMBER(SEARCH("_skip_justification.pdf",N11)),"CLEAR - FILE VERIFIED","CLEAR ON EXPORT"),"CLEAR ON LOG"))) -> CLEAR ON EXPORT | R11: =IF(Q11="UNRESOLVED","PRIORITY 1 - OBTAIN FILE",IF(Q11<>"EXCEPTION","NONE",IF(OR(AND(A11="LOA AMENDMENT",P11="UNRESOLVED USE"),AND(A11="SKIP",OR(E11="WL-02618",E11="WL-03044",E11="WL-03390"))),"PRIORITY 1",IF(A11="SKIP","PRIORITY 2","PRIORITY 3")))) -> NONE | T11: skip_events_2022_2026.csv row 103; offer_events_2022_2026.csv row 347 | U11: Standing Order 15-3 sections 3.2-3.3; Appeal 2018-3 p.2 sections III-A and IV-A
A12: SKIP | B12: 44974 | C12: SKP-2023-0103 | D12: OFR-2023-0350 | E12: WL-02918 | F12: Kara Aguilar / Aguilar Ventures LLC | G12: 1918 | H12: LP-1116 | I12: Ledgport | J12: declined-prior-offer | M12: Y | N12: OTHER_SUPPORT; skip export flag=Y | O12: Prior offer identified by date and slip | P12: NOT APPLICABLE | Q12: =IF(A12="UNDATED LEAD","UNRESOLVED",IF(M12="N","EXCEPTION",IF(A12="SKIP",IF(ISNUMBER(SEARCH("_skip_justification.pdf",N12)),"CLEAR - FILE VERIFIED","CLEAR ON EXPORT"),"CLEAR ON LOG"))) -> CLEAR ON EXPORT | R12: =IF(Q12="UNRESOLVED","PRIORITY 1 - OBTAIN FILE",IF(Q12<>"EXCEPTION","NONE",IF(OR(AND(A12="LOA AMENDMENT",P12="UNRESOLVED USE"),AND(A12="SKIP",OR(E12="WL-02618",E12="WL-03044",E12="WL-03390"))),"PRIORITY 1",IF(A12="SKIP","PRIORITY 2","PRIORITY 3")))) -> NONE | T12: skip_events_2022_2026.csv row 104; offer_events_2022_2026.csv row 351 | U12: Standing Order 15-3 sections 3.2-3.3; Appeal 2018-3 p.2 sections III-A and IV-A
A13: SKIP | B13: 44975 | C13: SKP-2023-0100 | D13: OFR-2023-0343 | E13: WL-02565 | F13: Christina Smith | G13: 1565 | H13: GW-0116 | I13: Gullwing | J13: vessel-fit | M13: Y | N13: REPAIR_ESTIMATE; skip export flag=Y | O13: Vessel particulars of record relied upon | P13: NOT APPLICABLE | Q13: =IF(A13="UNDATED LEAD","UNRESOLVED",IF(M13="N","EXCEPTION",IF(A13="SKIP",IF(ISNUMBER(SEARCH("_skip_justification.pdf",N13)),"CLEAR - FILE VERIFIED","CLEAR ON EXPORT"),"CLEAR ON LOG"))) -> CLEAR ON EXPORT | R13: =IF(Q13="UNRESOLVED","PRIORITY 1 - OBTAIN FILE",IF(Q13<>"EXCEPTION","NONE",IF(OR(AND(A13="LOA AMENDMENT",P13="UNRESOLVED USE"),AND(A13="SKIP",OR(E13="WL-02618",E13="WL-03044",E13="WL-03390"))),"PRIORITY 1",IF(A13="SKIP","PRIORITY 2","PRIORITY 3")))) -> NONE | T13: skip_events_2022_2026.csv row 101; offer_events_2022_2026.csv row 344 | U13: Standing Order 15-3 sections 3.2-3.3; Appeal 2018-3 p.2 sections III-A and IV-A
A14: SKIP | B14: 44976 | C14: SKP-2023-0101 | D14: OFR-2023-0345 | E14: WL-02664 | F14: Mark Smith / Smith Marine LLC | G14: 1664 | H14: GW-0220 | I14: Gullwing | J14: preference-mismatch | M14: Y | N14: WRITTEN_STATEMENT; skip export flag=Y | O14: Recorded preference sheet | P14: NOT APPLICABLE | Q14: =IF(A14="UNDATED LEAD","UNRESOLVED",IF(M14="N","EXCEPTION",IF(A14="SKIP",IF(ISNUMBER(SEARCH("_skip_justification.pdf",N14)),"CLEAR - FILE VERIFIED","CLEAR ON EXPORT"),"CLEAR ON LOG"))) -> CLEAR ON EXPORT | R14: =IF(Q14="UNRESOLVED","PRIORITY 1 - OBTAIN FILE",IF(Q14<>"EXCEPTION","NONE",IF(OR(AND(A14="LOA AMENDMENT",P14="UNRESOLVED USE"),AND(A14="SKIP",OR(E14="WL-02618",E14="WL-03044",E14="WL-03390"))),"PRIORITY 1",IF(A14="SKIP","PRIORITY 2","PRIORITY 3")))) -> NONE | T14: skip_events_2022_2026.csv row 102; offer_events_2022_2026.csv row 346 | U14: Standing Order 15-3 sections 3.2-3.3; Appeal 2018-3 p.2 sections III-A and IV-A
A15: SKIP | B15: 44991 | C15: SKP-2023-0105 | D15: OFR-2023-0361 | E15: WL-02366 | F15: Megan Hoffman / Hoffman Marine LLC | G15: 1366 | H15: LP-1116 | I15: Ledgport | J15: vessel-fit | M15: Y | N15: WRITTEN_STATEMENT; skip export flag=Y | O15: Vessel particulars of record relied upon | P15: NOT APPLICABLE | Q15: =IF(A15="UNDATED LEAD","UNRESOLVED",IF(M15="N","EXCEPTION",IF(A15="SKIP",IF(ISNUMBER(SEARCH("_skip_justification.pdf",N15)),"CLEAR - FILE VERIFIED","CLEAR ON EXPORT"),"CLEAR ON LOG"))) -> CLEAR ON EXPORT | R15: =IF(Q15="UNRESOLVED","PRIORITY 1 - OBTAIN FILE",IF(Q15<>"EXCEPTION","NONE",IF(OR(AND(A15="LOA AMENDMENT",P15="UNRESOLVED USE"),AND(A15="SKIP",OR(E15="WL-02618",E15="WL-03044",E15="WL-03390"))),"PRIORITY 1",IF(A15="SKIP","PRIORITY 2","PRIORITY 3")))) -> NONE | T15: skip_events_2022_2026.csv row 106; offer_events_2022_2026.csv row 362 | U15: Standing Order 15-3 sections 3.2-3.3; Appeal 2018-3 p.2 sections III-A and IV-A
A16: SKIP | B16: 44995 | C16: SKP-2023-0107 | D16: OFR-2023-0368 | E16: WL-01984 | F16: Vanessa Jackson / Jackson Holdings LLC | G16: 984 | H16: GW-0606 | I16: Gullwing | J16: declined-prior-offer | M16: Y | N16: WRITTEN_STATEMENT; skip export flag=Y | O16: Prior offer identified by date and slip | P16: NOT APPLICABLE | Q16: =IF(A16="UNDATED LEAD","UNRESOLVED",IF(M16="N","EXCEPTION",IF(A16="SKIP",IF(ISNUMBER(SEARCH("_skip_justification.pdf",N16)),"CLEAR - FILE VERIFIED","CLEAR ON EXPORT"),"CLEAR ON LOG"))) -> CLEAR ON EXPORT | R16: =IF(Q16="UNRESOLVED","PRIORITY 1 - OBTAIN FILE",IF(Q16<>"EXCEPTION","NONE",IF(OR(AND(A16="LOA AMENDMENT",P16="UNRESOLVED USE"),AND(A16="SKIP",OR(E16="WL-02618",E16="WL-03044",E16="WL-03390"))),"PRIORITY 1",IF(A16="SKIP","PRIORITY 2","PRIORITY 3")))) -> NONE | T16: skip_events_2022_2026.csv row 108; offer_events_2022_2026.csv row 369 | U16: Standing Order 15-3 sections 3.2-3.3; Appeal 2018-3 p.2 sections III-A and IV-A
A17: SKIP | B17: 45000 | C17: SKP-2023-0104 | D17: OFR-2023-0360 | E17: WL-03523 | F17: Darlene Glover | G17: 2523 | H17: SB-0210 | I17: Salmonberry | J17: vessel-fit | M17: N | N17: WRITTEN_STATEMENT; skip export flag=N | O17: Vessel particulars of record relied upon | P17: NOT APPLICABLE | Q17: =IF(A17="UNDATED LEAD","UNRESOLVED",IF(M17="N","EXCEPTION",IF(A17="SKIP",IF(ISNUMBER(SEARCH("_skip_justification.pdf",N17)),"CLEAR - FILE VERIFIED","CLEAR ON EXPORT"),"CLEAR ON LOG"))) -> EXCEPTION | R17: =IF(Q17="UNRESOLVED","PRIORITY 1 - OBTAIN FILE",IF(Q17<>"EXCEPTION","NONE",IF(OR(AND(A17="LOA AMENDMENT",P17="UNRESOLVED USE"),AND(A17="SKIP",OR(E17="WL-02618",E17="WL-03044",E17="WL-03390"))),"PRIORITY 1",IF(A17="SKIP","PRIORITY 2","PRIORITY 3")))) -> PRIORITY 2 | S17: No supporting record attached. Later disposition=SUSTAINED; review=NO on 2023-03-18; later review cannot cure the missing same-day record. | T17: skip_events_2022_2026.csv row 105; offer_events_2022_2026.csv row 361 | U17: Standing Order 15-3 sections 3.2-3.3; Appeal 2018-3 p.2 sections III-A and IV-A
A18: SKIP | B18: 45006 | C18: SKP-2023-0108 | D18: OFR-2023-0370 | E18: WL-01649 | F18: Amy Krueger / Krueger Charters Inc | G18: 649 | H18: VB-0717 | I18: Vessbank | J18: vessel-fit | M18: Y | N18: REPAIR_ESTIMATE; skip export flag=Y | O18: Vessel particulars of record relied upon | P18: NOT APPLICABLE | Q18: =IF(A18="UNDATED LEAD","UNRESOLVED",IF(M18="N","EXCEPTION",IF(A18="SKIP",IF(ISNUMBER(SEARCH("_skip_justification.pdf",N18)),"CLEAR - FILE VERIFIED","CLEAR ON EXPORT"),"CLEAR ON LOG"))) -> CLEAR ON EXPORT | R18: =IF(Q18="UNRESOLVED","PRIORITY 1 - OBTAIN FILE",IF(Q18<>"EXCEPTION","NONE",IF(OR(AND(A18="LOA AMENDMENT",P18="UNRESOLVED USE"),AND(A18="SKIP",OR(E18="WL-02618",E18="WL-03044",E18="WL-03390"))),"PRIORITY 1",IF(A18="SKIP","PRIORITY 2","PRIORITY 3")))) -> NONE | T18: skip_events_2022_2026.csv row 109; offer_events_2022_2026.csv row 371 | U18: Standing Order 15-3 sections 3.2-3.3; Appeal 2018-3 p.2 sections III-A and IV-A
A19: SKIP | B19: 45010 | C19: SKP-2023-0109 | D19: OFR-2023-0371 | E19: WL-03535 | F19: Allison Castro / Castro Marine LLC | G19: 2535 | H19: GW-0101 | I19: Gullwing | J19: vessel-fit | M19: Y | N19: OTHER_SUPPORT; skip export flag=Y | O19: Vessel particulars of record relied upon | P19: NOT APPLICABLE | Q19: =IF(A19="UNDATED LEAD","UNRESOLVED",IF(M19="N","EXCEPTION",IF(A19="SKIP",IF(ISNUMBER(SEARCH("_skip_justification.pdf",N19)),"CLEAR - FILE VERIFIED","CLEAR ON EXPORT"),"CLEAR ON LOG"))) -> CLEAR ON EXPORT | R19: =IF(Q19="UNRESOLVED","PRIORITY 1 - OBTAIN FILE",IF(Q19<>"EXCEPTION","NONE",IF(OR(AND(A19="LOA AMENDMENT",P19="UNRESOLVED USE"),AND(A19="SKIP",OR(E19="WL-02618",E19="WL-03044",E19="WL-03390"))),"PRIORITY 1",IF(A19="SKIP","PRIORITY 2","PRIORITY 3")))) -> NONE | T19: skip_events_2022_2026.csv row 110; offer_events_2022_2026.csv row 372 | U19: Standing Order 15-3 sections 3.2-3.3; Appeal 2018-3 p.2 sections III-A and IV-A
A20: SKIP | B20: 45012 | C20: SKP-2023-0106 | D20: OFR-2023-0364 | E20: WL-01388 | F20: Sharon Young | G20: 388 | H20: SB-0617 | I20: Salmonberry | J20: vessel-fit | M20: Y | N20: REPAIR_ESTIMATE; skip export flag=Y | O20: Vessel particulars of record relied upon | P20: NOT APPLICABLE | Q20: =IF(A20="UNDATED LEAD","UNRESOLVED",IF(M20="N","EXCEPTION",IF(A20="SKIP",IF(ISNUMBER(SEARCH("_skip_justification.pdf",N20)),"CLEAR - FILE VERIFIED","CLEAR ON EXPORT"),"CLEAR ON LOG"))) -> CLEAR ON EXPORT | R20: =IF(Q20="UNRESOLVED","PRIORITY 1 - OBTAIN FILE",IF(Q20<>"EXCEPTION","NONE",IF(OR(AND(A20="LOA AMENDMENT",P20="UNRESOLVED USE"),AND(A20="SKIP",OR(E20="WL-02618",E20="WL-03044",E20="WL-03390"))),"PRIORITY 1",IF(A20="SKIP","PRIORITY 2","PRIORITY 3")))) -> NONE | T20: skip_events_2022_2026.csv row 107; offer_events_2022_2026.csv row 365 | U20: Standing Order 15-3 sections 3.2-3.3; Appeal 2018-3 p.2 sections III-A and IV-A
A21: SKIP | B21: 45018 | C21: SKP-2023-0117 | D21: OFR-2023-0409 | E21: WL-01089 | F21: Erin Holmes | G21: 89 | H21: GW-0306 | I21: Gullwing | J21: declined-prior-offer | M21: Y | N21: REPAIR_ESTIMATE; skip export flag=Y | O21: Prior offer identified by date and slip | P21: NOT APPLICABLE | Q21: =IF(A21="UNDATED LEAD","UNRESOLVED",IF(M21="N","EXCEPTION",IF(A21="SKIP",IF(ISNUMBER(SEARCH("_skip_justification.pdf",N21)),"CLEAR - FILE VERIFIED","CLEAR ON EXPORT"),"CLEAR ON LOG"))) -> CLEAR ON EXPORT | R21: =IF(Q21="UNRESOLVED","PRIORITY 1 - OBTAIN FILE",IF(Q21<>"EXCEPTION","NONE",IF(OR(AND(A21="LOA AMENDMENT",P21="UNRESOLVED USE"),AND(A21="SKIP",OR(E21="WL-02618",E21="WL-03044",E21="WL-03390"))),"PRIORITY 1",IF(A21="SKIP","PRIORITY 2","PRIORITY 3")))) -> NONE | T21: skip_events_2022_2026.csv row 118; offer_events_2022_2026.csv row 410 | U21: Standing Order 15-3 sections 3.2-3.3; Appeal 2018-3 p.2 sections III-A and IV-A
A22: SKIP | B22: 45019 | C22: SKP-2023-0112 | D22: OFR-2023-0387 | E22: WL-03014 | F22: Daniel Mitchell / Mitchell Holdings LLC | G22: 2014 | H22: LP-0204 | I22: Ledgport | J22: vessel-fit | M22: Y | N22: WRITTEN_STATEMENT; skip export flag=Y | O22: Vessel particulars of record relied upon | P22: NOT APPLICABLE | Q22: =IF(A22="UNDATED LEAD","UNRESOLVED",IF(M22="N","EXCEPTION",IF(A22="SKIP",IF(ISNUMBER(SEARCH("_skip_justification.pdf",N22)),"CLEAR - FILE VERIFIED","CLEAR ON EXPORT"),"CLEAR ON LOG"))) -> CLEAR ON EXPORT | R22: =IF(Q22="UNRESOLVED","PRIORITY 1 - OBTAIN FILE",IF(Q22<>"EXCEPTION","NONE",IF(OR(AND(A22="LOA AMENDMENT",P22="UNRESOLVED USE"),AND(A22="SKIP",OR(E22="WL-02618",E22="WL-03044",E22="WL-03390"))),"PRIORITY 1",IF(A22="SKIP","PRIORITY 2","PRIORITY 3")))) -> NONE | T22: skip_events_2022_2026.csv row 113; offer_events_2022_2026.csv row 388 | U22: Standing Order 15-3 sections 3.2-3.3; Appeal 2018-3 p.2 sections III-A and IV-A
A23: SKIP | B23: 45024 | C23: SKP-2023-0115 | D23: OFR-2023-0401 | E23: WL-01145 | F23: Francisco Weaver | G23: 145 | H23: EW-0304 | I23: Eastwey | J23: not-current | M23: Y | N23: INSURANCE_DECL; skip export flag=Y | O23: Ledger or register extract showing the deficiency | P23: NOT APPLICABLE | Q23: =IF(A23="UNDATED LEAD","UNRESOLVED",IF(M23="N","EXCEPTION",IF(A23="SKIP",IF(ISNUMBER(SEARCH("_skip_justification.pdf",N23)),"CLEAR - FILE VERIFIED","CLEAR ON EXPORT"),"CLEAR ON LOG"))) -> CLEAR ON EXPORT | R23: =IF(Q23="UNRESOLVED","PRIORITY 1 - OBTAIN FILE",IF(Q23<>"EXCEPTION","NONE",IF(OR(AND(A23="LOA AMENDMENT",P23="UNRESOLVED USE"),AND(A23="SKIP",OR(E23="WL-02618",E23="WL-03044",E23="WL-03390"))),"PRIORITY 1",IF(A23="SKIP","PRIORITY 2","PRIORITY 3")))) -> NONE | T23: skip_events_2022_2026.csv row 116; offer_events_2022_2026.csv row 402 | U23: Standing Order 15-3 sections 3.2-3.3; Appeal 2018-3 p.2 sections III-A and IV-A
A24: SKIP | B24: 45025 | C24: SKP-2023-0113 | D24: OFR-2023-0392 | E24: WL-01886 | F24: Kenneth Riley | G24: 886 | H24: GW-0116 | I24: Gullwing | J24: not-current | M24: Y | N24: WRITTEN_STATEMENT; skip export flag=Y | O24: Ledger or register extract showing the deficiency | P24: NOT APPLICABLE | Q24: =IF(A24="UNDATED LEAD","UNRESOLVED",IF(M24="N","EXCEPTION",IF(A24="SKIP",IF(ISNUMBER(SEARCH("_skip_justification.pdf",N24)),"CLEAR - FILE VERIFIED","CLEAR ON EXPORT"),"CLEAR ON LOG"))) -> CLEAR ON EXPORT | R24: =IF(Q24="UNRESOLVED","PRIORITY 1 - OBTAIN FILE",IF(Q24<>"EXCEPTION","NONE",IF(OR(AND(A24="LOA AMENDMENT",P24="UNRESOLVED USE"),AND(A24="SKIP",OR(E24="WL-02618",E24="WL-03044",E24="WL-03390"))),"PRIORITY 1",IF(A24="SKIP","PRIORITY 2","PRIORITY 3")))) -> NONE | T24: skip_events_2022_2026.csv row 114; offer_events_2022_2026.csv row 393 | U24: Standing Order 15-3 sections 3.2-3.3; Appeal 2018-3 p.2 sections III-A and IV-A
A25: SKIP | B25: 45027 | C25: SKP-2023-0114 | D25: OFR-2023-0395 | E25: WL-02074 | F25: Erika Martin | G25: 1074 | H25: EW-1007 | I25: Eastwey | J25: vessel-fit | M25: Y | N25: REPAIR_ESTIMATE; skip export flag=Y | O25: Vessel particulars of record relied upon | P25: NOT APPLICABLE | Q25: =IF(A25="UNDATED LEAD","UNRESOLVED",IF(M25="N","EXCEPTION",IF(A25="SKIP",IF(ISNUMBER(SEARCH("_skip_justification.pdf",N25)),"CLEAR - FILE VERIFIED","CLEAR ON EXPORT"),"CLEAR ON LOG"))) -> CLEAR ON EXPORT | R25: =IF(Q25="UNRESOLVED","PRIORITY 1 - OBTAIN FILE",IF(Q25<>"EXCEPTION","NONE",IF(OR(AND(A25="LOA AMENDMENT",P25="UNRESOLVED USE"),AND(A25="SKIP",OR(E25="WL-02618",E25="WL-03044",E25="WL-03390"))),"PRIORITY 1",IF(A25="SKIP","PRIORITY 2","PRIORITY 3")))) -> NONE | T25: skip_events_2022_2026.csv row 115; offer_events_2022_2026.csv row 396 | U25: Standing Order 15-3 sections 3.2-3.3; Appeal 2018-3 p.2 sections III-A and IV-A
A26: SKIP | B26: 45036 | C26: SKP-2023-0110 | D26: OFR-2023-0374 | E26: WL-01473 | F26: Ian Parrish / Parrish Charters Inc | G26: 473 | H26: SB-0623 | I26: Salmonberry | J26: vessel-fit | M26: Y | N26: INSURANCE_DECL; skip export flag=Y | O26: Vessel particulars of record relied upon | P26: NOT APPLICABLE | Q26: =IF(A26="UNDATED LEAD","UNRESOLVED",IF(M26="N","EXCEPTION",IF(A26="SKIP",IF(ISNUMBER(SEARCH("_skip_justification.pdf",N26)),"CLEAR - FILE VERIFIED","CLEAR ON EXPORT"),"CLEAR ON LOG"))) -> CLEAR ON EXPORT | R26: =IF(Q26="UNRESOLVED","PRIORITY 1 - OBTAIN FILE",IF(Q26<>"EXCEPTION","NONE",IF(OR(AND(A26="LOA AMENDMENT",P26="UNRESOLVED USE"),AND(A26="SKIP",OR(E26="WL-02618",E26="WL-03044",E26="WL-03390"))),"PRIORITY 1",IF(A26="SKIP","PRIORITY 2","PRIORITY 3")))) -> NONE | T26: skip_events_2022_2026.csv row 111; offer_events_2022_2026.csv row 375 | U26: Standing Order 15-3 sections 3.2-3.3; Appeal 2018-3 p.2 sections III-A and IV-A
A27: SKIP | B27: 45036 | C27: SKP-2023-0111 | D27: OFR-2023-0375 | E27: WL-02941 | F27: Jose Benson | G27: 1941 | H27: SB-0109 | I27: Salmonberry | J27: vessel-fit | M27: Y | N27: OTHER_SUPPORT; skip export flag=Y | O27: Vessel particulars of record relied upon | P27: NOT APPLICABLE | Q27: =IF(A27="UNDATED LEAD","UNRESOLVED",IF(M27="N","EXCEPTION",IF(A27="SKIP",IF(ISNUMBER(SEARCH("_skip_justification.pdf",N27)),"CLEAR - FILE VERIFIED","CLEAR ON EXPORT"),"CLEAR ON LOG"))) -> CLEAR ON EXPORT | R27: =IF(Q27="UNRESOLVED","PRIORITY 1 - OBTAIN FILE",IF(Q27<>"EXCEPTION","NONE",IF(OR(AND(A27="LOA AMENDMENT",P27="UNRESOLVED USE"),AND(A27="SKIP",OR(E27="WL-02618",E27="WL-03044",E27="WL-03390"))),"PRIORITY 1",IF(A27="SKIP","PRIORITY 2","PRIORITY 3")))) -> NONE | T27: skip_events_2022_2026.csv row 112; offer_events_2022_2026.csv row 376 | U27: Standing Order 15-3 sections 3.2-3.3; Appeal 2018-3 p.2 sections III-A and IV-A
A28: SKIP | B28: 45044 | C28: SKP-2023-0116 | D28: OFR-2023-0403 | E28: WL-01274 | F28: Lisa Campbell / Campbell Ventures LLC | G28: 274 | H28: GW-0905 | I28: Gullwing | J28: vessel-fit | M28: Y | N28: WRITTEN_STATEMENT; skip export flag=Y | O28: Vessel particulars of record relied upon | P28: NOT APPLICABLE | Q28: =IF(A28="UNDATED LEAD","UNRESOLVED",IF(M28="N","EXCEPTION",IF(A28="SKIP",IF(ISNUMBER(SEARCH("_skip_justification.pdf",N28)),"CLEAR - FILE VERIFIED","CLEAR ON EXPORT"),"CLEAR ON LOG"))) -> CLEAR ON EXPORT | R28: =IF(Q28="UNRESOLVED","PRIORITY 1 - OBTAIN FILE",IF(Q28<>"EXCEPTION","NONE",IF(OR(AND(A28="LOA AMENDMENT",P28="UNRESOLVED USE"),AND(A28="SKIP",OR(E28="WL-02618",E28="WL-03044",E28="WL-03390"))),"PRIORITY 1",IF(A28="SKIP","PRIORITY 2","PRIORITY 3")))) -> NONE | T28: skip_events_2022_2026.csv row 117; offer_events_2022_2026.csv row 404 | U28: Standing Order 15-3 sections 3.2-3.3; Appeal 2018-3 p.2 sections III-A and IV-A
A29: SKIP | B29: 45048 | C29: SKP-2023-0120 | D29: OFR-2023-0417 | E29: WL-01469 | F29: John Lynch / Lynch Charters Inc | G29: 469 | H29: LP-1104 | I29: Ledgport | J29: vessel-fit | M29: Y | N29: OTHER_SUPPORT; skip export flag=Y | O29: Vessel particulars of record relied upon | P29: NOT APPLICABLE | Q29: =IF(A29="UNDATED LEAD","UNRESOLVED",IF(M29="N","EXCEPTION",IF(A29="SKIP",IF(ISNUMBER(SEARCH("_skip_justification.pdf",N29)),"CLEAR - FILE VERIFIED","CLEAR ON EXPORT"),"CLEAR ON LOG"))) -> CLEAR ON EXPORT | R29: =IF(Q29="UNRESOLVED","PRIORITY 1 - OBTAIN FILE",IF(Q29<>"EXCEPTION","NONE",IF(OR(AND(A29="LOA AMENDMENT",P29="UNRESOLVED USE"),AND(A29="SKIP",OR(E29="WL-02618",E29="WL-03044",E29="WL-03390"))),"PRIORITY 1",IF(A29="SKIP","PRIORITY 2","PRIORITY 3")))) -> NONE | T29: skip_events_2022_2026.csv row 121; offer_events_2022_2026.csv row 418 | U29: Standing Order 15-3 sections 3.2-3.3; Appeal 2018-3 p.2 sections III-A and IV-A
A30: SKIP | B30: 45048 | C30: SKP-2023-0129 | D30: OFR-2023-0440 | E30: WL-03178 | F30: Kristen Schneider / Schneider Charters Inc | G30: 2178 | H30: VB-0810 | I30: Vessbank | J30: vessel-fit | M30: Y | N30: REPAIR_ESTIMATE; skip export flag=Y | O30: Vessel particulars of record relied upon | P30: NOT APPLICABLE | Q30: =IF(A30="UNDATED LEAD","UNRESOLVED",IF(M30="N","EXCEPTION",IF(A30="SKIP",IF(ISNUMBER(SEARCH("_skip_justification.pdf",N30)),"CLEAR - FILE VERIFIED","CLEAR ON EXPORT"),"CLEAR ON LOG"))) -> CLEAR ON EXPORT | R30: =IF(Q30="UNRESOLVED","PRIORITY 1 - OBTAIN FILE",IF(Q30<>"EXCEPTION","NONE",IF(OR(AND(A30="LOA AMENDMENT",P30="UNRESOLVED USE"),AND(A30="SKIP",OR(E30="WL-02618",E30="WL-03044",E30="WL-03390"))),"PRIORITY 1",IF(A30="SKIP","PRIORITY 2","PRIORITY 3")))) -> NONE | T30: skip_events_2022_2026.csv row 130; offer_events_2022_2026.csv row 441 | U30: Standing Order 15-3 sections 3.2-3.3; Appeal 2018-3 p.2 sections III-A and IV-A
A31: SKIP | B31: 45048 | C31: SKP-2023-0408 | D31: OFR-2023-1487 | E31: WL-02618 | F31: Gary Tomlinson | G31: 1618 | H31: GW-0610 | I31: Gullwing | J31: vessel-fit | M31: N | N31: WL-02618_skip_justification.pdf p.1 - support expressly not attached | O31: Vessel particulars of record relied upon | P31: NOT APPLICABLE | Q31: =IF(A31="UNDATED LEAD","UNRESOLVED",IF(M31="N","EXCEPTION",IF(A31="SKIP",IF(ISNUMBER(SEARCH("_skip_justification.pdf",N31)),"CLEAR - FILE VERIFIED","CLEAR ON EXPORT"),"CLEAR ON LOG"))) -> EXCEPTION | R31: =IF(Q31="UNRESOLVED","PRIORITY 1 - OBTAIN FILE",IF(Q31<>"EXCEPTION","NONE",IF(OR(AND(A31="LOA AMENDMENT",P31="UNRESOLVED USE"),AND(A31="SKIP",OR(E31="WL-02618",E31="WL-03044",E31="WL-03390"))),"PRIORITY 1",IF(A31="SKIP","PRIORITY 2","PRIORITY 3")))) -> PRIORITY 1 | S31: PDF says EW-0414; skip export says GW-0610. File ends at cover sheet. | T31: skip_events_2022_2026.csv row 409; no matching offer-export row; WL-02618_skip_justification.pdf | U31: Standing Order 15-3 sections 3.2-3.3; Appeal 2018-3 p.2 sections III-A and IV-A
A32: SKIP | B32: 45050 | C32: SKP-2023-0128 | D32: OFR-2023-0436 | E32: WL-03537 | F32: Angel Wheeler | G32: 2537 | H32: GW-0709 | I32: Gullwing | J32: not-current | M32: Y | N32: OTHER_SUPPORT; skip export flag=Y | O32: Ledger or register extract showing the deficiency | P32: NOT APPLICABLE | Q32: =IF(A32="UNDATED LEAD","UNRESOLVED",IF(M32="N","EXCEPTION",IF(A32="SKIP",IF(ISNUMBER(SEARCH("_skip_justification.pdf",N32)),"CLEAR - FILE VERIFIED","CLEAR ON EXPORT"),"CLEAR ON LOG"))) -> CLEAR ON EXPORT | R32: =IF(Q32="UNRESOLVED","PRIORITY 1 - OBTAIN FILE",IF(Q32<>"EXCEPTION","NONE",IF(OR(AND(A32="LOA AMENDMENT",P32="UNRESOLVED USE"),AND(A32="SKIP",OR(E32="WL-02618",E32="WL-03044",E32="WL-03390"))),"PRIORITY 1",IF(A32="SKIP","PRIORITY 2","PRIORITY 3")))) -> NONE | T32: skip_events_2022_2026.csv row 129; offer_events_2022_2026.csv row 437 | U32: Standing Order 15-3 sections 3.2-3.3; Appeal 2018-3 p.2 sections III-A and IV-A
A33: SKIP | B33: 45051 | C33: SKP-2023-0119 | D33: OFR-2023-0412 | E33: WL-03151 | F33: Elizabeth King / King Marine LLC | G33: 2151 | H33: VB-0220 | I33: Vessbank | J33: declined-prior-offer | M33: Y | N33: REPAIR_ESTIMATE; skip export flag=Y | O33: Prior offer identified by date and slip | P33: NOT APPLICABLE | Q33: =IF(A33="UNDATED LEAD","UNRESOLVED",IF(M33="N","EXCEPTION",IF(A33="SKIP",IF(ISNUMBER(SEARCH("_skip_justification.pdf",N33)),"CLEAR - FILE VERIFIED","CLEAR ON EXPORT"),"CLEAR ON LOG"))) -> CLEAR ON EXPORT | R33: =IF(Q33="UNRESOLVED","PRIORITY 1 - OBTAIN FILE",IF(Q33<>"EXCEPTION","NONE",IF(OR(AND(A33="LOA AMENDMENT",P33="UNRESOLVED USE"),AND(A33="SKIP",OR(E33="WL-02618",E33="WL-03044",E33="WL-03390"))),"PRIORITY 1",IF(A33="SKIP","PRIORITY 2","PRIORITY 3")))) -> NONE | T33: skip_events_2022_2026.csv row 120; offer_events_2022_2026.csv row 413 | U33: Standing Order 15-3 sections 3.2-3.3; Appeal 2018-3 p.2 sections III-A and IV-A
A34: SKIP | B34: 45056 | C34: SKP-2023-0126 | D34: OFR-2023-0432 | E34: WL-02134 | F34: James Martin | G34: 1134 | H34: EW-0320 | I34: Eastwey | J34: not-current | M34: Y | N34: INSURANCE_DECL; skip export flag=Y | O34: Ledger or register extract showing the deficiency | P34: NOT APPLICABLE | Q34: =IF(A34="UNDATED LEAD","UNRESOLVED",IF(M34="N","EXCEPTION",IF(A34="SKIP",IF(ISNUMBER(SEARCH("_skip_justification.pdf",N34)),"CLEAR - FILE VERIFIED","CLEAR ON EXPORT"),"CLEAR ON LOG"))) -> CLEAR ON EXPORT | R34: =IF(Q34="UNRESOLVED","PRIORITY 1 - OBTAIN FILE",IF(Q34<>"EXCEPTION","NONE",IF(OR(AND(A34="LOA AMENDMENT",P34="UNRESOLVED USE"),AND(A34="SKIP",OR(E34="WL-02618",E34="WL-03044",E34="WL-03390"))),"PRIORITY 1",IF(A34="SKIP","PRIORITY 2","PRIORITY 3")))) -> NONE | T34: skip_events_2022_2026.csv row 127; offer_events_2022_2026.csv row 433 | U34: Standing Order 15-3 sections 3.2-3.3; Appeal 2018-3 p.2 sections III-A and IV-A
A35: SKIP | B35: 45058 | C35: SKP-2023-0121 | D35: OFR-2023-0418 | E35: WL-03181 | F35: Annette Collins / Collins Ventures LLC | G35: 2181 | H35: SB-0903 | I35: Salmonberry | J35: vessel-fit | M35: Y | N35: OTHER_SUPPORT; skip export flag=Y | O35: Vessel particulars of record relied upon | P35: NOT APPLICABLE | Q35: =IF(A35="UNDATED LEAD","UNRESOLVED",IF(M35="N","EXCEPTION",IF(A35="SKIP",IF(ISNUMBER(SEARCH("_skip_justification.pdf",N35)),"CLEAR - FILE VERIFIED","CLEAR ON EXPORT"),"CLEAR ON LOG"))) -> CLEAR ON EXPORT | R35: =IF(Q35="UNRESOLVED","PRIORITY 1 - OBTAIN FILE",IF(Q35<>"EXCEPTION","NONE",IF(OR(AND(A35="LOA AMENDMENT",P35="UNRESOLVED USE"),AND(A35="SKIP",OR(E35="WL-02618",E35="WL-03044",E35="WL-03390"))),"PRIORITY 1",IF(A35="SKIP","PRIORITY 2","PRIORITY 3")))) -> NONE | T35: skip_events_2022_2026.csv row 122; offer_events_2022_2026.csv row 419 | U35: Standing Order 15-3 sections 3.2-3.3; Appeal 2018-3 p.2 sections III-A and IV-A
A36: SKIP | B36: 45059 | C36: SKP-2023-0118 | D36: OFR-2023-0411 | E36: WL-02485 | F36: Matthew Dickerson | G36: 1485 | H36: VB-0521 | I36: Vessbank | J36: not-current | M36: Y | N36: INSURANCE_DECL; skip export flag=Y | O36: Ledger or register extract showing the deficiency | P36: NOT APPLICABLE | Q36: =IF(A36="UNDATED LEAD","UNRESOLVED",IF(M36="N","EXCEPTION",IF(A36="SKIP",IF(ISNUMBER(SEARCH("_skip_justification.pdf",N36)),"CLEAR - FILE VERIFIED","CLEAR ON EXPORT"),"CLEAR ON LOG"))) -> CLEAR ON EXPORT | R36: =IF(Q36="UNRESOLVED","PRIORITY 1 - OBTAIN FILE",IF(Q36<>"EXCEPTION","NONE",IF(OR(AND(A36="LOA AMENDMENT",P36="UNRESOLVED USE"),AND(A36="SKIP",OR(E36="WL-02618",E36="WL-03044",E36="WL-03390"))),"PRIORITY 1",IF(A36="SKIP","PRIORITY 2","PRIORITY 3")))) -> NONE | T36: skip_events_2022_2026.csv row 119; offer_events_2022_2026.csv row 412 | U36: Standing Order 15-3 sections 3.2-3.3; Appeal 2018-3 p.2 sections III-A and IV-A
A37: SKIP | B37: 45065 | C37: SKP-2023-0124 | D37: OFR-2023-0422 | E37: WL-02100 | F37: Michelle Pena / Pena Charters Inc | G37: 1100 | H37: VB-0504 | I37: Vessbank | J37: preference-mismatch | M37: Y | N37: INSURANCE_DECL; skip export flag=Y | O37: Recorded preference sheet | P37: NOT APPLICABLE | Q37: =IF(A37="UNDATED LEAD","UNRESOLVED",IF(M37="N","EXCEPTION",IF(A37="SKIP",IF(ISNUMBER(SEARCH("_skip_justification.pdf",N37)),"CLEAR - FILE VERIFIED","CLEAR ON EXPORT"),"CLEAR ON LOG"))) -> CLEAR ON EXPORT | R37: =IF(Q37="UNRESOLVED","PRIORITY 1 - OBTAIN FILE",IF(Q37<>"EXCEPTION","NONE",IF(OR(AND(A37="LOA AMENDMENT",P37="UNRESOLVED USE"),AND(A37="SKIP",OR(E37="WL-02618",E37="WL-03044",E37="WL-03390"))),"PRIORITY 1",IF(A37="SKIP","PRIORITY 2","PRIORITY 3")))) -> NONE | T37: skip_events_2022_2026.csv row 125; offer_events_2022_2026.csv row 423 | U37: Standing Order 15-3 sections 3.2-3.3; Appeal 2018-3 p.2 sections III-A and IV-A
A38: SKIP | B38: 45066 | C38: SKP-2023-0122 | D38: OFR-2023-0419 | E38: WL-03816 | F38: Brittany Lopez / Lopez Marine LLC | G38: 2816 | H38: VB-0113 | I38: Vessbank | J38: preference-mismatch | M38: Y | N38: OTHER_SUPPORT; skip export flag=Y | O38: Recorded preference sheet | P38: NOT APPLICABLE | Q38: =IF(A38="UNDATED LEAD","UNRESOLVED",IF(M38="N","EXCEPTION",IF(A38="SKIP",IF(ISNUMBER(SEARCH("_skip_justification.pdf",N38)),"CLEAR - FILE VERIFIED","CLEAR ON EXPORT"),"CLEAR ON LOG"))) -> CLEAR ON EXPORT | R38: =IF(Q38="UNRESOLVED","PRIORITY 1 - OBTAIN FILE",IF(Q38<>"EXCEPTION","NONE",IF(OR(AND(A38="LOA AMENDMENT",P38="UNRESOLVED USE"),AND(A38="SKIP",OR(E38="WL-02618",E38="WL-03044",E38="WL-03390"))),"PRIORITY 1",IF(A38="SKIP","PRIORITY 2","PRIORITY 3")))) -> NONE | T38: skip_events_2022_2026.csv row 123; offer_events_2022_2026.csv row 420 | U38: Standing Order 15-3 sections 3.2-3.3; Appeal 2018-3 p.2 sections III-A and IV-A
A39: SKIP | B39: 45067 | C39: SKP-2023-0123 | D39: OFR-2023-0421 | E39: WL-03712 | F39: Charles Graham / Graham Holdings LLC | G39: 2712 | H39: LP-0113 | I39: Ledgport | J39: declined-prior-offer | M39: Y | N39: INSURANCE_DECL; skip export flag=Y | O39: Prior offer identified by date and slip | P39: NOT APPLICABLE | Q39: =IF(A39="UNDATED LEAD","UNRESOLVED",IF(M39="N","EXCEPTION",IF(A39="SKIP",IF(ISNUMBER(SEARCH("_skip_justification.pdf",N39)),"CLEAR - FILE VERIFIED","CLEAR ON EXPORT"),"CLEAR ON LOG"))) -> CLEAR ON EXPORT | R39: =IF(Q39="UNRESOLVED","PRIORITY 1 - OBTAIN FILE",IF(Q39<>"EXCEPTION","NONE",IF(OR(AND(A39="LOA AMENDMENT",P39="UNRESOLVED USE"),AND(A39="SKIP",OR(E39="WL-02618",E39="WL-03044",E39="WL-03390"))),"PRIORITY 1",IF(A39="SKIP","PRIORITY 2","PRIORITY 3")))) -> NONE | T39: skip_events_2022_2026.csv row 124; offer_events_2022_2026.csv row 422 | U39: Standing Order 15-3 sections 3.2-3.3; Appeal 2018-3 p.2 sections III-A and IV-A
A40: SKIP | B40: 45067 | C40: SKP-2023-0125 | D40: OFR-2023-0429 | E40: WL-02777 | F40: Carolyn Johnson | G40: 1777 | H40: LP-0402 | I40: Ledgport | J40: vessel-fit | M40: Y | N40: OTHER_SUPPORT; skip export flag=Y | O40: Vessel particulars of record relied upon | P40: NOT APPLICABLE | Q40: =IF(A40="UNDATED LEAD","UNRESOLVED",IF(M40="N","EXCEPTION",IF(A40="SKIP",IF(ISNUMBER(SEARCH("_skip_justification.pdf",N40)),"CLEAR - FILE VERIFIED","CLEAR ON EXPORT"),"CLEAR ON LOG"))) -> CLEAR ON EXPORT | R40: =IF(Q40="UNRESOLVED","PRIORITY 1 - OBTAIN FILE",IF(Q40<>"EXCEPTION","NONE",IF(OR(AND(A40="LOA AMENDMENT",P40="UNRESOLVED USE"),AND(A40="SKIP",OR(E40="WL-02618",E40="WL-03044",E40="WL-03390"))),"PRIORITY 1",IF(A40="SKIP","PRIORITY 2","PRIORITY 3")))) -> NONE | T40: skip_events_2022_2026.csv row 126; offer_events_2022_2026.csv row 430 | U40: Standing Order 15-3 sections 3.2-3.3; Appeal 2018-3 p.2 sections III-A and IV-A
...

Sheet Billing Reconciliations
A1: Billing Reconciliations | Active Slip Population
A2: July 2026 base moorage against August 2026 occupied-slip inventory
A3: Formula: billable feet = MAX(slip size, ROUNDUP(recorded LOA,0)); expected base = billable feet x covered/open base rate. Positive variance means expected revenue exceeds the supplied billing export.
A4: All active LOAs match the August applicant register, but paper check-in measurement blocks were not supplied. August OCCUPIED status is assumed to apply at 2026-07-31; commercial status remains subject to signed-agreement review.
A5: Slip ID | B5: Basin | C5: Basin Type | D5: Tenant ID | E5: Holder | F5: Applicant Type | G5: Agreement ID | H5: Inventory LOA | I5: Register LOA | J5: LOA Variance | K5: Measurement Evidence | L5: Slip Size | M5: Rounded LOA | N5: Billable Feet | O5: Base Rate / Foot-Month | P5: Expected Base Moorage | Q5: July Txn ID | R5: Txn Rate Class | S5: Actual Length Billed | T5: Actual Rate | U5: Actual Base Amount | V5: Monthly Variance | W5: Annualized Variance | X5: Billing Result | Y5: Potential Commercial Uplift | Z5: Rate Class Review | AA5: Placement Flag | AB5: Billing Source | AC5: Measurement Source | AD5: Governing Authority
A6: EW-0101 | B6: Eastwey | C6: open | D6: WL-01414 | E6: Phillip Massey | F6: CORPORATION | G6: MA-2024-0101 | H6: 29.3 | I6: 29.3 | J6: =H6-I6 -> 0 | K6: =IF(ABS(J6)<0.001,"MATCH - PAPER CHECK-IN NOT SUPPLIED","DATA MISMATCH") -> MATCH - PAPER CHECK-IN NOT SUPPLIED | L6: 80 | M6: =ROUNDUP(H6,0) -> 30 | N6: =MAX(L6,M6) -> 80 | O6: 7.55 | P6: =N6*O6 -> 604 | Q6: TXN-202607-028683 | R6: NON_COMM_MONTHLY | S6: 80 | T6: 7.55 | U6: 604 | V6: =P6-U6 -> 0 | W6: =V6*12 -> 0 | X6: =IF(Q6="","MISSING FROM EXPORT",IF(ABS(V6)<0.005,"CLEAR",IF(V6>0,"UNDERBILLING","OVERBILLING"))) -> CLEAR | Y6: =IF(F6="COMMERCIAL",ROUND(P6*0.35,2),0) -> 0 | Z6: =IF(F6="COMMERCIAL","VERIFY SIGNED AGREEMENT","NO EXCEPTION") -> NO EXCEPTION | AA6: =IF(AND(C6="covered",N6>40),"COVERED >40 FT","") | AB6: billing_transactions_2022_2026.csv row 45265 | AC6: slip_inventory_2026-08.csv row 502; applicant_register_2026-08.csv row 415 | AD6: Tariff Resolution 2019-14 p.1 definition 4 and pp.2-3 sections 2.4/7.3; Resolution 2022-06 p.1 sections 1.1-1.3
A7: EW-0102 | B7: Eastwey | C7: open | D7: WL-03666 | E7: Andrea Franco | F7: PARTNERSHIP | G7: MA-2024-0102 | H7: 55.3 | I7: 55.3 | J7: =H7-I7 -> 0 | K7: =IF(ABS(J7)<0.001,"MATCH - PAPER CHECK-IN NOT SUPPLIED","DATA MISMATCH") -> MATCH - PAPER CHECK-IN NOT SUPPLIED | L7: 24 | M7: =ROUNDUP(H7,0) -> 56 | N7: =MAX(L7,M7) -> 56 | O7: 7.55 | P7: =N7*O7 -> 422.8 | Q7: TXN-202607-028766 | R7: NON_COMM_MONTHLY | S7: 56 | T7: 7.55 | U7: 422.8 | V7: =P7-U7 -> 0 | W7: =V7*12 -> 0 | X7: =IF(Q7="","MISSING FROM EXPORT",IF(ABS(V7)<0.005,"CLEAR",IF(V7>0,"UNDERBILLING","OVERBILLING"))) -> CLEAR | Y7: =IF(F7="COMMERCIAL",ROUND(P7*0.35,2),0) -> 0 | Z7: =IF(F7="COMMERCIAL","VERIFY SIGNED AGREEMENT","NO EXCEPTION") -> NO EXCEPTION | AA7: =IF(AND(C7="covered",N7>40),"COVERED >40 FT","") | AB7: billing_transactions_2022_2026.csv row 45266 | AC7: slip_inventory_2026-08.csv row 503; applicant_register_2026-08.csv row 2667 | AD7: Tariff Resolution 2019-14 p.1 definition 4 and pp.2-3 sections 2.4/7.3; Resolution 2022-06 p.1 sections 1.1-1.3
A8: EW-0103 | B8: Eastwey | C8: open | D8: WL-01149 | E8: David Hoffman | F8: LLC | G8: MA-2024-0103 | H8: 42.6 | I8: 42.6 | J8: =H8-I8 -> 0 | K8: =IF(ABS(J8)<0.001,"MATCH - PAPER CHECK-IN NOT SUPPLIED","DATA MISMATCH") -> MATCH - PAPER CHECK-IN NOT SUPPLIED | L8: 36 | M8: =ROUNDUP(H8,0) -> 43 | N8: =MAX(L8,M8) -> 43 | O8: 7.55 | P8: =N8*O8 -> 324.65 | Q8: TXN-202607-028830 | R8: NON_COMM_MONTHLY | S8: 43 | T8: 7.55 | U8: 324.65 | V8: =P8-U8 -> 0 | W8: =V8*12 -> 0 | X8: =IF(Q8="","MISSING FROM EXPORT",IF(ABS(V8)<0.005,"CLEAR",IF(V8>0,"UNDERBILLING","OVERBILLING"))) -> CLEAR | Y8: =IF(F8="COMMERCIAL",ROUND(P8*0.35,2),0) -> 0 | Z8: =IF(F8="COMMERCIAL","VERIFY SIGNED AGREEMENT","NO EXCEPTION") -> NO EXCEPTION | AA8: =IF(AND(C8="covered",N8>40),"COVERED >40 FT","") | AB8: billing_transactions_2022_2026.csv row 45267 | AC8: slip_inventory_2026-08.csv row 504; applicant_register_2026-08.csv row 150 | AD8: Tariff Resolution 2019-14 p.1 definition 4 and pp.2-3 sections 2.4/7.3; Resolution 2022-06 p.1 sections 1.1-1.3
A9: EW-0105 | B9: Eastwey | C9: open | D9: WL-03242 | E9: Micheal Navarro | F9: PARTNERSHIP | G9: MA-2024-0105 | H9: 60.2 | I9: 60.2 | J9: =H9-I9 -> 0 | K9: =IF(ABS(J9)<0.001,"MATCH - PAPER CHECK-IN NOT SUPPLIED","DATA MISMATCH") -> MATCH - PAPER CHECK-IN NOT SUPPLIED | L9: 36 | M9: =ROUNDUP(H9,0) -> 61 | N9: =MAX(L9,M9) -> 61 | O9: 7.55 | P9: =N9*O9 -> 460.55 | Q9: TXN-202607-028896 | R9: NON_COMM_MONTHLY | S9: 61 | T9: 7.55 | U9: 460.55 | V9: =P9-U9 -> 0 | W9: =V9*12 -> 0 | X9: =IF(Q9="","MISSING FROM EXPORT",IF(ABS(V9)<0.005,"CLEAR",IF(V9>0,"UNDERBILLING","OVERBILLING"))) -> CLEAR | Y9: =IF(F9="COMMERCIAL",ROUND(P9*0.35,2),0) -> 0 | Z9: =IF(F9="COMMERCIAL","VERIFY SIGNED AGREEMENT","NO EXCEPTION") -> NO EXCEPTION | AA9: =IF(AND(C9="covered",N9>40),"COVERED >40 FT","") | AB9: billing_transactions_2022_2026.csv row 45268 | AC9: slip_inventory_2026-08.csv row 506; applicant_register_2026-08.csv row 2243 | AD9: Tariff Resolution 2019-14 p.1 definition 4 and pp.2-3 sections 2.4/7.3; Resolution 2022-06 p.1 sections 1.1-1.3
A10: EW-0106 | B10: Eastwey | C10: open | D10: WL-03380 | E10: Charles Snyder | F10: INDIVIDUAL | G10: MA-2024-0106 | H10: 47.5 | I10: 47.5 | J10: =H10-I10 -> 0 | K10: =IF(ABS(J10)<0.001,"MATCH - PAPER CHECK-IN NOT SUPPLIED","DATA MISMATCH") -> MATCH - PAPER CHECK-IN NOT SUPPLIED | L10: 45 | M10: =ROUNDUP(H10,0) -> 48 | N10: =MAX(L10,M10) -> 48 | O10: 7.55 | P10: =N10*O10 -> 362.4 | Q10: TXN-202607-028972 | R10: NON_COMM_MONTHLY | S10: 48 | T10: 7.55 | U10: 362.4 | V10: =P10-U10 -> 0 | W10: =V10*12 -> 0 | X10: =IF(Q10="","MISSING FROM EXPORT",IF(ABS(V10)<0.005,"CLEAR",IF(V10>0,"UNDERBILLING","OVERBILLING"))) -> CLEAR | Y10: =IF(F10="COMMERCIAL",ROUND(P10*0.35,2),0) -> 0 | Z10: =IF(F10="COMMERCIAL","VERIFY SIGNED AGREEMENT","NO EXCEPTION") -> NO EXCEPTION | AA10: =IF(AND(C10="covered",N10>40),"COVERED >40 FT","") | AB10: billing_transactions_2022_2026.csv row 45269 | AC10: slip_inventory_2026-08.csv row 507; applicant_register_2026-08.csv row 2381 | AD10: Tariff Resolution 2019-14 p.1 definition 4 and pp.2-3 sections 2.4/7.3; Resolution 2022-06 p.1 sections 1.1-1.3
A11: EW-0107 | B11: Eastwey | C11: open | D11: WL-01368 | E11: Justin Turner | F11: INDIVIDUAL | G11: MA-2024-0107 | H11: 23.7 | I11: 23.7 | J11: =H11-I11 -> 0 | K11: =IF(ABS(J11)<0.001,"MATCH - PAPER CHECK-IN NOT SUPPLIED","DATA MISMATCH") -> MATCH - PAPER CHECK-IN NOT SUPPLIED | L11: 28 | M11: =ROUNDUP(H11,0) -> 24 | N11: =MAX(L11,M11) -> 28 | O11: 7.55 | P11: =N11*O11 -> 211.4 | Q11: TXN-202607-029047 | R11: NON_COMM_MONTHLY | S11: 28 | T11: 7.55 | U11: 211.4 | V11: =P11-U11 -> 0 | W11: =V11*12 -> 0 | X11: =IF(Q11="","MISSING FROM EXPORT",IF(ABS(V11)<0.005,"CLEAR",IF(V11>0,"UNDERBILLING","OVERBILLING"))) -> CLEAR | Y11: =IF(F11="COMMERCIAL",ROUND(P11*0.35,2),0) -> 0 | Z11: =IF(F11="COMMERCIAL","VERIFY SIGNED AGREEMENT","NO EXCEPTION") -> NO EXCEPTION | AA11: =IF(AND(C11="covered",N11>40),"COVERED >40 FT","") | AB11: billing_transactions_2022_2026.csv row 45270 | AC11: slip_inventory_2026-08.csv row 508; applicant_register_2026-08.csv row 369 | AD11: Tariff Resolution 2019-14 p.1 definition 4 and pp.2-3 sections 2.4/7.3; Resolution 2022-06 p.1 sections 1.1-1.3
A12: EW-0108 | B12: Eastwey | C12: open | D12: WL-02070 | E12: Leslie Thomas | F12: INDIVIDUAL | G12: MA-2024-0108 | H12: 59.3 | I12: 59.3 | J12: =H12-I12 -> 0 | K12: =IF(ABS(J12)<0.001,"MATCH - PAPER CHECK-IN NOT SUPPLIED","DATA MISMATCH") -> MATCH - PAPER CHECK-IN NOT SUPPLIED | L12: 40 | M12: =ROUNDUP(H12,0) -> 60 | N12: =MAX(L12,M12) -> 60 | O12: 7.55 | P12: =N12*O12 -> 453 | Q12: TXN-202607-029118 | R12: NON_COMM_MONTHLY | S12: 60 | T12: 7.55 | U12: 453 | V12: =P12-U12 -> 0 | W12: =V12*12 -> 0 | X12: =IF(Q12="","MISSING FROM EXPORT",IF(ABS(V12)<0.005,"CLEAR",IF(V12>0,"UNDERBILLING","OVERBILLING"))) -> CLEAR | Y12: =IF(F12="COMMERCIAL",ROUND(P12*0.35,2),0) -> 0 | Z12: =IF(F12="COMMERCIAL","VERIFY SIGNED AGREEMENT","NO EXCEPTION") -> NO EXCEPTION | AA12: =IF(AND(C12="covered",N12>40),"COVERED >40 FT","") | AB12: billing_transactions_2022_2026.csv row 45271 | AC12: slip_inventory_2026-08.csv row 509; applicant_register_2026-08.csv row 1071 | AD12: Tariff Resolution 2019-14 p.1 definition 4 and pp.2-3 sections 2.4/7.3; Resolution 2022-06 p.1 sections 1.1-1.3
A13: EW-0109 | B13: Eastwey | C13: open | D13: WL-03624 | E13: Robert Rodriguez | F13: INDIVIDUAL | G13: MA-2024-0109 | H13: 30.9 | I13: 30.9 | J13: =H13-I13 -> 0 | K13: =IF(ABS(J13)<0.001,"MATCH - PAPER CHECK-IN NOT SUPPLIED","DATA MISMATCH") -> MATCH - PAPER CHECK-IN NOT SUPPLIED | L13: 60 | M13: =ROUNDUP(H13,0) -> 31 | N13: =MAX(L13,M13) -> 60 | O13: 7.55 | P13: =N13*O13 -> 453 | Q13: TXN-202607-029184 | R13: NON_COMM_MONTHLY | S13: 60 | T13: 7.55 | U13: 453 | V13: =P13-U13 -> 0 | W13: =V13*12 -> 0 | X13: =IF(Q13="","MISSING FROM EXPORT",IF(ABS(V13)<0.005,"CLEAR",IF(V13>0,"UNDERBILLING","OVERBILLING"))) -> CLEAR | Y13: =IF(F13="COMMERCIAL",ROUND(P13*0.35,2),0) -> 0 | Z13: =IF(F13="COMMERCIAL","VERIFY SIGNED AGREEMENT","NO EXCEPTION") -> NO EXCEPTION | AA13: =IF(AND(C13="covered",N13>40),"COVERED >40 FT","") | AB13: billing_transactions_2022_2026.csv row 45273 | AC13: slip_inventory_2026-08.csv row 510; applicant_register_2026-08.csv row 2625 | AD13: Tariff Resolution 2019-14 p.1 definition 4 and pp.2-3 sections 2.4/7.3; Resolution 2022-06 p.1 sections 1.1-1.3
A14: EW-0110 | B14: Eastwey | C14: open | D14: WL-01831 | E14: Angela Andersen | F14: JOINT | G14: MA-2024-0110 | H14: 36.3 | I14: 36.3 | J14: =H14-I14 -> 0 | K14: =IF(ABS(J14)<0.001,"MATCH - PAPER CHECK-IN NOT SUPPLIED","DATA MISMATCH") -> MATCH - PAPER CHECK-IN NOT SUPPLIED | L14: 28 | M14: =ROUNDUP(H14,0) -> 37 | N14: =MAX(L14,M14) -> 37 | O14: 7.55 | P14: =N14*O14 -> 279.35 | Q14: TXN-202607-029245 | R14: NON_COMM_MONTHLY | S14: 37 | T14: 7.55 | U14: 279.35 | V14: =P14-U14 -> 0 | W14: =V14*12 -> 0 | X14: =IF(Q14="","MISSING FROM EXPORT",IF(ABS(V14)<0.005,"CLEAR",IF(V14>0,"UNDERBILLING","OVERBILLING"))) -> CLEAR | Y14: =IF(F14="COMMERCIAL",ROUND(P14*0.35,2),0) -> 0 | Z14: =IF(F14="COMMERCIAL","VERIFY SIGNED AGREEMENT","NO EXCEPTION") -> NO EXCEPTION | AA14: =IF(AND(C14="covered",N14>40),"COVERED >40 FT","") | AB14: billing_transactions_2022_2026.csv row 45275 | AC14: slip_inventory_2026-08.csv row 511; applicant_register_2026-08.csv row 832 | AD14: Tariff Resolution 2019-14 p.1 definition 4 and pp.2-3 sections 2.4/7.3; Resolution 2022-06 p.1 sections 1.1-1.3
A15: EW-0111 | B15: Eastwey | C15: open | D15: WL-01617 | E15: James Ferguson | F15: JOINT | G15: MA-2024-0111 | H15: 43.9 | I15: 43.9 | J15: =H15-I15 -> 0 | K15: =IF(ABS(J15)<0.001,"MATCH - PAPER CHECK-IN NOT SUPPLIED","DATA MISMATCH") -> MATCH - PAPER CHECK-IN NOT SUPPLIED | L15: 28 | M15: =ROUNDUP(H15,0) -> 44 | N15: =MAX(L15,M15) -> 44 | O15: 7.55 | P15: =N15*O15 -> 332.2 | Q15: TXN-202607-029327 | R15: NON_COMM_MONTHLY | S15: 44 | T15: 7.55 | U15: 332.2 | V15: =P15-U15 -> 0 | W15: =V15*12 -> 0 | X15: =IF(Q15="","MISSING FROM EXPORT",IF(ABS(V15)<0.005,"CLEAR",IF(V15>0,"UNDERBILLING","OVERBILLING"))) -> CLEAR | Y15: =IF(F15="COMMERCIAL",ROUND(P15*0.35,2),0) -> 0 | Z15: =IF(F15="COMMERCIAL","VERIFY SIGNED AGREEMENT","NO EXCEPTION") -> NO EXCEPTION | AA15: =IF(AND(C15="covered",N15>40),"COVERED >40 FT","") | AB15: billing_transactions_2022_2026.csv row 45276 | AC15: slip_inventory_2026-08.csv row 512; applicant_register_2026-08.csv row 618 | AD15: Tariff Resolution 2019-14 p.1 definition 4 and pp.2-3 sections 2.4/7.3; Resolution 2022-06 p.1 sections 1.1-1.3
A16: EW-0112 | B16: Eastwey | C16: open | D16: WL-01533 | E16: Beth Cooper | F16: NONPROFIT | G16: MA-2024-0112 | H16: 38.7 | I16: 38.7 | J16: =H16-I16 -> 0 | K16: =IF(ABS(J16)<0.001,"MATCH - PAPER CHECK-IN NOT SUPPLIED","DATA MISMATCH") -> MATCH - PAPER CHECK-IN NOT SUPPLIED | L16: 70 | M16: =ROUNDUP(H16,0) -> 39 | N16: =MAX(L16,M16) -> 70 | O16: 7.55 | P16: =N16*O16 -> 528.5 | Q16: TXN-202607-029413 | R16: NON_COMM_MONTHLY | S16: 70 | T16: 7.55 | U16: 528.5 | V16: =P16-U16 -> 0 | W16: =V16*12 -> 0 | X16: =IF(Q16="","MISSING FROM EXPORT",IF(ABS(V16)<0.005,"CLEAR",IF(V16>0,"UNDERBILLING","OVERBILLING"))) -> CLEAR | Y16: =IF(F16="COMMERCIAL",ROUND(P16*0.35,2),0) -> 0 | Z16: =IF(F16="COMMERCIAL","VERIFY SIGNED AGREEMENT","NO EXCEPTION") -> NO EXCEPTION | AA16: =IF(AND(C16="covered",N16>40),"COVERED >40 FT","") | AB16: billing_transactions_2022_2026.csv row 45278 | AC16: slip_inventory_2026-08.csv row 513; applicant_register_2026-08.csv row 534 | AD16: Tariff Resolution 2019-14 p.1 definition 4 and pp.2-3 sections 2.4/7.3; Resolution 2022-06 p.1 sections 1.1-1.3
A17: EW-0113 | B17: Eastwey | C17: open | D17: WL-01482 | E17: Brandon Boyer | F17: CORPORATION | G17: MA-2024-0113 | H17: 61.3 | I17: 61.3 | J17: =H17-I17 -> 0 | K17: =IF(ABS(J17)<0.001,"MATCH - PAPER CHECK-IN NOT SUPPLIED","DATA MISMATCH") -> MATCH - PAPER CHECK-IN NOT SUPPLIED | L17: 45 | M17: =ROUNDUP(H17,0) -> 62 | N17: =MAX(L17,M17) -> 62 | O17: 7.55 | P17: =N17*O17 -> 468.1 | Q17: TXN-202607-029473 | R17: NON_COMM_MONTHLY | S17: 62 | T17: 7.55 | U17: 468.1 | V17: =P17-U17 -> 0 | W17: =V17*12 -> 0 | X17: =IF(Q17="","MISSING FROM EXPORT",IF(ABS(V17)<0.005,"CLEAR",IF(V17>0,"UNDERBILLING","OVERBILLING"))) -> CLEAR | Y17: =IF(F17="COMMERCIAL",ROUND(P17*0.35,2),0) -> 0 | Z17: =IF(F17="COMMERCIAL","VERIFY SIGNED AGREEMENT","NO EXCEPTION") -> NO EXCEPTION | AA17: =IF(AND(C17="covered",N17>40),"COVERED >40 FT","") | AB17: billing_transactions_2022_2026.csv row 45280 | AC17: slip_inventory_2026-08.csv row 514; applicant_register_2026-08.csv row 483 | AD17: Tariff Resolution 2019-14 p.1 definition 4 and pp.2-3 sections 2.4/7.3; Resolution 2022-06 p.1 sections 1.1-1.3
... A306: GW-0501 | B306: Gullwing | C306: open | D306: WL-01450 | E306: Joel Barnes | F306: PARTNERSHIP | G306: MA-2024-0501 | H306: 22.6 | I306: 22.6 | J306: =H306-I306 -> 0 | K306: =IF(ABS(J306)<0.001,"MATCH - PAPER CHECK-IN NOT SUPPLIED","DATA MISMATCH") -> MATCH - PAPER CHECK-IN NOT SUPPLIED | L306: 40 | M306: =ROUNDUP(H306,0) -> 23 | N306: =MAX(L306,M306) -> 40 | O306: 7.55 | P306: =N306*O306 -> 302 | Q306: TXN-202607-046796 | R306: NON_COMM_MONTHLY | S306: 40 | T306: 7.55 | U306: 302 | V306: =P306-U306 -> 0 | W306: =V306*12 -> 0 | X306: =IF(Q306="","MISSING FROM EXPORT",IF(ABS(V306)<0.005,"CLEAR",IF(V306>0,"UNDERBILLING","OVERBILLING"))) -> CLEAR | Y306: =IF(F306="COMMERCIAL",ROUND(P306*0.35,2),0) -> 0 | Z306: =IF(F306="COMMERCIAL","VERIFY SIGNED AGREEMENT","NO EXCEPTION") -> NO EXCEPTION | AA306: =IF(AND(C306="covered",N306>40),"COVERED >40 FT","") | AB306: billing_transactions_2022_2026.csv row 45693 | AC306: slip_inventory_2026-08.csv row 834; applicant_register_2026-08.csv row 451 | AD306: Tariff Resolution 2019-14 p.1 definition 4 and pp.2-3 sections 2.4/7.3; Resolution 2022-06 p.1 sections 1.1-1.3
A307: GW-0502 | B307: Gullwing | C307: open | D307: WL-03559 | E307: David Sanders | F307: INDIVIDUAL | G307: MA-2024-0502 | H307: 36.5 | I307: 36.5 | J307: =H307-I307 -> 0 | K307: =IF(ABS(J307)<0.001,"MATCH - PAPER CHECK-IN NOT SUPPLIED","DATA MISMATCH") -> MATCH - PAPER CHECK-IN NOT SUPPLIED | L307: 60 | M307: =ROUNDUP(H307,0) -> 37 | N307: =MAX(L307,M307) -> 60 | O307: 7.55 | P307: =N307*O307 -> 453 | U307: 0 | V307: =P307-U307 -> 453 | W307: =V307*12 -> 5436 | X307: =IF(Q307="","MISSING FROM EXPORT",IF(ABS(V307)<0.005,"CLEAR",IF(V307>0,"UNDERBILLING","OVERBILLING"))) -> MISSING FROM EXPORT | Y307: =IF(F307="COMMERCIAL",ROUND(P307*0.35,2),0) -> 0 | Z307: =IF(F307="COMMERCIAL","VERIFY SIGNED AGREEMENT","NO EXCEPTION") -> NO EXCEPTION | AA307: =IF(AND(C307="covered",N307>40),"COVERED >40 FT","") | AB307: No July 2026 monthly-moorage line in supplied export | AC307: slip_inventory_2026-08.csv row 835; applicant_register_2026-08.csv row 2560 | AD307: Tariff Resolution 2019-14 p.1 definition 4 and pp.2-3 sections 2.4/7.3; Resolution 2022-06 p.1 sections 1.1-1.3
A308: GW-0503 | B308: Gullwing | C308: open | D308: WL-01494 | E308: Ashley Park | F308: CORPORATION | G308: MA-2024-0503 | H308: 43.9 | I308: 43.9 | J308: =H308-I308 -> 0 | K308: =IF(ABS(J308)<0.001,"MATCH - PAPER CHECK-IN NOT SUPPLIED","DATA MISMATCH") -> MATCH - PAPER CHECK-IN NOT SUPPLIED | L308: 32 | M308: =ROUNDUP(H308,0) -> 44 | N308: =MAX(L308,M308) -> 44 | O308: 7.55 | P308: =N308*O308 -> 332.2 | U308: 0 | V308: =P308-U308 -> 332.2 | W308: =V308*12 -> 3986.4 | X308: =IF(Q308="","MISSING FROM EXPORT",IF(ABS(V308)<0.005,"CLEAR",IF(V308>0,"UNDERBILLING","OVERBILLING"))) -> MISSING FROM EXPORT | Y308: =IF(F308="COMMERCIAL",ROUND(P308*0.35,2),0) -> 0 | Z308: =IF(F308="COMMERCIAL","VERIFY SIGNED AGREEMENT","NO EXCEPTION") -> NO EXCEPTION | AA308: =IF(AND(C308="covered",N308>40),"COVERED >40 FT","") | AB308: No July 2026 monthly-moorage line in supplied export | AC308: slip_inventory_2026-08.csv row 836; applicant_register_2026-08.csv row 495 | AD308: Tariff Resolution 2019-14 p.1 definition 4 and pp.2-3 sections 2.4/7.3; Resolution 2022-06 p.1 sections 1.1-1.3
A309: GW-0504 | B309: Gullwing | C309: open | D309: WL-01500 | E309: Patricia Marquez | F309: COMMERCIAL | G309: MA-2024-0504 | H309: 25.2 | I309: 25.2 | J309: =H309-I309 -> 0 | K309: =IF(ABS(J309)<0.001,"MATCH - PAPER CHECK-IN NOT SUPPLIED","DATA MISMATCH") -> MATCH - PAPER CHECK-IN NOT SUPPLIED | L309: 50 | M309: =ROUNDUP(H309,0) -> 26 | N309: =MAX(L309,M309) -> 50 | O309: 7.55 | P309: =N309*O309 -> 377.5 | U309: 0 | V309: =P309-U309 -> 377.5 | W309: =V309*12 -> 4530 | X309: =IF(Q309="","MISSING FROM EXPORT",IF(ABS(V309)<0.005,"CLEAR",IF(V309>0,"UNDERBILLING","OVERBILLING"))) -> MISSING FROM EXPORT | Y309: =IF(F309="COMMERCIAL",ROUND(P309*0.35,2),0) -> 132.13 | Z309: =IF(F309="COMMERCIAL","VERIFY SIGNED AGREEMENT","NO EXCEPTION") -> VERIFY SIGNED AGREEMENT | AA309: =IF(AND(C309="covered",N309>40),"COVERED >40 FT","") | AB309: No July 2026 monthly-moorage line in supplied export | AC309: slip_inventory_2026-08.csv row 837; applicant_register_2026-08.csv row 501 | AD309: Tariff Resolution 2019-14 p.1 definition 4 and pp.2-3 sections 2.4/7.3; Resolution 2022-06 p.1 sections 1.1-1.3
A310: GW-0505 | B310: Gullwing | C310: open | D310: WL-01089 | E310: Erin Holmes | F310: INDIVIDUAL | G310: MA-2024-0505 | H310: 54.3 | I310: 54.3 | J310: =H310-I310 -> 0 | K310: =IF(ABS(J310)<0.001,"MATCH - PAPER CHECK-IN NOT SUPPLIED","DATA MISMATCH") -> MATCH - PAPER CHECK-IN NOT SUPPLIED | L310: 60 | M310: =ROUNDUP(H310,0) -> 55 | N310: =MAX(L310,M310) -> 60 | O310: 7.55 | P310: =N310*O310 -> 453 | U310: 0 | V310: =P310-U310 -> 453 | W310: =V310*12 -> 5436 | X310: =IF(Q310="","MISSING FROM EXPORT",IF(ABS(V310)<0.005,"CLEAR",IF(V310>0,"UNDERBILLING","OVERBILLING"))) -> MISSING FROM EXPORT | Y310: =IF(F310="COMMERCIAL",ROUND(P310*0.35,2),0) -> 0 | Z310: =IF(F310="COMMERCIAL","VERIFY SIGNED AGREEMENT","NO EXCEPTION") -> NO EXCEPTION | AA310: =IF(AND(C310="covered",N310>40),"COVERED >40 FT","") | AB310: No July 2026 monthly-moorage line in supplied export | AC310: slip_inventory_2026-08.csv row 838; applicant_register_2026-08.csv row 90 | AD310: Tariff Resolution 2019-14 p.1 definition 4 and pp.2-3 sections 2.4/7.3; Resolution 2022-06 p.1 sections 1.1-1.3
