Workbook

Sheet Summary of Findings
A1: Chaldale Moorage Audit - Summary of Findings
A2: Board decision view | as of August 1, 2026 | all displayed metrics are formulas tied to detailed/source sheets.
A4: AUGUST BILLING | E4: AUGUST BILLING | I4: CORRECTIVE BILLING
A5: Expected base moorage | E5: Recorded base moorage | I5: Missing postings
A6: ='Billing Reconciliation'!C11 -> 439918.3 | E6: ='Billing Reconciliation'!D11 -> 319760.05 | I6: ='Billing Reconciliation'!F11 -> 317
A8: CORRECTIVE BILLING | E8: COLLECT NOW | I8: COLLECT NOW
A9: Unbilled base charges | E9: Overdue excl. current | I9: Aged 91+
A10: =-'Billing Reconciliation'!E11 -> 120158.25 | E10: ='Aging Report'!B5 -> 10233.6 | I10: ='Aging Report'!B6 -> 4368
A12: Formula findings and required Board attention
A13: Area | B13: Formula Metric | C13: Result | D13: Interpretation / Action
A14: Billing | B14: Occupied slips | C14: =COUNTIF('Billing Reconciliation'!$D$15:$D$1194,"OCCUPIED") -> 1086 | D14: All occupied slips are tested against the August 1 posting.
A15: Billing | B15: Missing August bills | C15: =COUNTIF('Billing Reconciliation'!$R$15:$R$1194,"MISSING AUGUST BILL") -> 317 | D15: Issue corrective base-moorage bills before treating the balance as delinquent.
A16: Collections | B16: Occupied 91+ accounts | C16: ='Aging Report'!B4 -> 6 | D16: Collect the overdue portion now; current bucket remains separate.
A17: Queue | B17: In-scope Board reviews | C17: =COUNTIFS('Queue Exceptions'!$R$7:$R$13,"IN SCOPE",'Queue Exceptions'!$T$7:$T$13,"BOARD REVIEW") -> 6 | D17: Retrieve exact contemporaneous files; if absent, use prospective first-offer remedy.
A18: LOA amendments | B18: In-scope amendments | C18: =COUNTA('Amendment Audit'!$A$6:$A$205) -> 200 | D18: After 2022-08-01 through 2026-07-31.
A19: LOA amendments | B19: No qualifying source reference | C19: =COUNTIF('Amendment Audit'!$H$6:$H$205,"No qualifying reference") -> 12 | D19: Do not use these LOA changes until section 4.3 support is filed.
A20: LOA amendments | B20: Matching supplied certificate unsigned | C20: =COUNTIFS('Amendment Audit'!$I$6:$I$205,"YES",'Amendment Audit'!$J$6:$J$205,"N") -> 1 | D20: The matching certificate does not meet the strict signature requirement.
A21: LOA amendments | B21: Reference only - verify file | C21: =COUNTIF('Amendment Audit'!$N$6:$N$205,"REFERENCE ONLY - VERIFY FILE") -> 187 | D21: The log names a qualifying-looking document, but the underlying file is not in this packet.
A24: Decision sequencing
A25: 1 | B25: Collect overdue receivables | C25: ="Authorize collection on the "&TEXT('Aging Report'!B4,"0")&" occupied accounts in Aging Report for $"&TEXT('Aging Report'!B5,"#,##0.00")&" overdue, while keeping $"&TEXT('Aging Report'!B7-'Aging Report'!B5,"#,##0.00")&" current separate." -> Authorize collection on the 6 occupied accounts in Aging Report for $10,233.60 overdue, while keeping $2,932.80 current separate.
A26: 2 | B26: Correct August billing | C26: ="Issue and validate "&TEXT('Billing Reconciliation'!F11,"0")&" missing August base-moorage postings totaling $"&TEXT(-'Billing Reconciliation'!E11,"#,##0.00")&"." -> Issue and validate 317 missing August base-moorage postings totaling $120,158.25.
A27: 3 | B27: Protect queue integrity | C27: ="Do not rely on the "&TEXT(COUNTIFS('Queue Exceptions'!$R$7:$R$13,"IN SCOPE",'Queue Exceptions'!$T$7:$T$13,"BOARD REVIEW"),"0")&" in-scope targeted skips until exact offer and supporting records are produced; apply prospective relief if proof is absent." -> Do not rely on the 6 in-scope targeted skips until exact offer and supporting records are produced; apply prospective relief if proof is absent.
A28: 4 | B28: Validate LOA amendments | C28: ="Suspend use of "&TEXT(COUNTIF('Amendment Audit'!$H$6:$H$205,"No qualifying reference"),"0")&" no-source LOA changes and "&TEXT(COUNTIFS('Amendment Audit'!$I$6:$I$205,"YES",'Amendment Audit'!$J$6:$J$205,"N"),"0")&" unsigned linked certificate; retrieve the "&TEXT(COUNTIF('Amendment Audit'!$N$6:$N$205,"REFERENCE ONLY - VERIFY FILE"),"0")&" reference-only files." -> Suspend use of 12 no-source LOA changes and 1 unsigned linked certificate; retrieve the 187 reference-only files.
A31: Sources: resolution_2022-06.pdf; tariff_resolution_2019-14.pdf; standing_order_15-3.pdf; appeal_2018-3_decision.pdf; listed data files and evidence PDFs. See Sources & Rules for sections and scope.

Sheet Sources & Rules
A1: Sources and Governing Rules
A2: Authority, cutoffs, rate basis, and source traceability used throughout the workbook.
A4: Audit as of | B4: 46235 | C4: Task date; events after this date are not used.
A5: Billing posting tested | B5: 46235 | C5: August 1 monthly moorage postings only.
A6: Skip review start | B6: 44927 | C6: Requested period begins January 1, 2023.
A7: Skip review end | B7: 46234 | C7: Requested period ends July 31, 2026.
A8: Covered rate per foot-month | B8: 10.4 | C8: Resolution 2022-06 sections 1.1 and 2.1.
A9: Open rate per foot-month | B9: 7.55 | C9: Resolution 2022-06 sections 1.2 and 2.1.
A10: Variance sign | B10: Actual minus expected | C10: Negative means underbilled or missing; base moorage excludes tax/electricity.
A13: Controlling rules
A14: Authority | B14: Section | C14: Rule applied | D14: Why it governs | E14: Applied in | F14: Source file
A15: Resolution 2022-06 | B15: 1.1-1.2, 2.1 | C15: Covered $10.40 and open $7.55 per foot-month for periods beginning on/after 2022-08-01. | D15: Later amendment controls; section 7.2 resolves conflicts. | E15: Billing Reconciliation | F15: resolution_2022-06.pdf
A16: Tariff Resolution 2019-14 | B16: 1 definition 4; 2.4; 7.3 | C16: Billable length is greater of rounded-up check-in LOA or nominal slip length. | D16: Retained except where amended by Resolution 2022-06. | E16: Billing Reconciliation | F16: tariff_resolution_2019-14.pdf
A17: Standing Order 15-3 | B17: 3.2-3.3 | C17: Skip file must be assembled that day and contain the reason-specific supporting record; cover alone fails. | D17: Operative counter procedure for skips. | E17: Queue Exceptions | F17: standing_order_15-3.pdf
A18: Appeal 2018-3 | B18: III-A; IV-A; V.4 | C18: District bears burden; later-created proof cannot cure; completed assignment is not displaced, remedy is prospective. | D18: Board precedent interpreting contemporaneous proof. | E18: Queue Exceptions | F18: appeal_2018-3_decision.pdf
A19: Resolution 2022-06 | B19: 4.3; 6.1-6.2 | C19: Post-adoption LOA amendment requires signed measurement certificate or yard haul-out measurement sheet, filed and cross-referenced at entry. | D19: Specific later rule for LOA amendments. | E19: Amendment Audit | F19: resolution_2022-06.pdf
A22: Data sources and scope
A23: Source file | B23: Sheet / rows or filter | C23: Use | D23: Authority notes | E23: Records loaded | F23: Path
A24: slip_inventory_2026-08.csv | B24: rows 2-1181 | C24: Occupied status, slip class, tenant, LOA | D24: Current inventory as of 2026-08 | E24: =COUNTA('Source - Inventory'!$A$5:$A$1184) -> 1180 | F24: /home/agent/workspace/facilities_and_slips/exports/slip_inventory_2026-08.csv
A25: billing_transactions_2022_2026.csv | B25: post_date 2026-08-01; MONTHLY_MOORAGE | C25: Actual August base moorage | D25: Tax and electricity excluded | E25: =COUNTA('Source - Billing Aug26'!$A$5:$A$773) -> 769 | F25: /home/agent/workspace/finance_and_billing/exports/billing_transactions_2022_2026.csv
A26: ar_aging_2026-07-31.xlsx | B26: AR_Aging rows 3-262 | C26: Aging and collection status | D26: 91-120 is source column days_90 | E26: =COUNTA('Source - AR Aging'!$A$5:$A$264) -> 260 | F26: /home/agent/workspace/finance_and_billing/aging/ar_aging_2026-07-31.xlsx
A27: skip_events_2022_2026.csv | B27: all rows; targeted event detail | C27: Skip-event cross-check | D27: Date filter applied by formula | E27: =COUNTA('Source - Skip Events'!$A$5:$A$416) -> 412 | F27: /home/agent/workspace/waiting_list_administration/exports/skip_events_2022_2026.csv
A28: offer_events_2022_2026.csv | B28: all rows | C28: Offer existence and event cross-check | D28: Offer IDs tested by formula | E28: =COUNTA('Source - Offer Events'!$A$5:$A$1490) -> 1486 | F28: /home/agent/workspace/waiting_list_administration/exports/offer_events_2022_2026.csv
A29: applicant_register_2026-08.csv | B29: all rows | C29: Application chronology and current status | D29: Current register snapshot | E29: =COUNTA('Source - Applicants'!$A$5:$A$2914) -> 2910 | F29: /home/agent/workspace/waiting_list_administration/exports/applicant_register_2026-08.csv
A30: amendment_log_2022_2026.csv | B30: LOA after 2022-08-01 through 2026-07-31 | C30: LOA support and downstream skip check | D30: Post-adoption period and audit cutoff applied in Amendment Audit. | E30: =COUNTA('Amendment Audit'!$A$6:$A$205) -> 200 | F30: /home/agent/workspace/waiting_list_administration/exports/amendment_log_2022_2026.csv

Sheet Source - Applicants
A1: Source - Applicants
A2: /home/agent/workspace/waiting_list_administration/exports/applicant_register_2026-08.csv
A4: applicant_id | B4: rank | C4: last_name | D4: first_name | E4: applicant_type | F4: entity_name | G4: application_date | H4: status | I4: vessel_name | J4: vessel_type | K4: loa_ft | L4: beam_ft | M4: preference_basin | N4: preference_slip_size | O4: phone | P4: email | Q4: city | R4: state | S4: zip | T4: last_renewal_date | U4: renewal_cycle_current | V4: notes
A5: WL-01001 | B5: 1 | C5: Jones | D5: Valerie | E5: PARTNERSHIP | F5: Jones Holdings LLC | G5: 44574 | H5: EXPIRED | I5: MURRE WEATHER | J5: CRUISER | K5: 51.6 | L5: 17.7 | M5: Vessbank | N5: 45 | O5: (360) 555-1979 | P5: valerie_jones@quillayute.org | Q5: Aberdeen | R5: WA | S5: 98520 | U5: 2023
A6: WL-01002 | B6: 2 | C6: Ramirez | D6: Virginia | E6: PARTNERSHIP | F6: Ramirez Holdings LLC | G6: 44577 | H6: ACTIVE_WAITLIST | I6: HERON MIST | J6: CRUISER | K6: 38.2 | L6: 12.1 | M6: ANY | N6: 50 | O6: (541) 555-3938 | P6: virginia.ramirez@gmail.example.com | Q6: Coos Bay | R6: OR | S6: 97420 | T6: 46012 | U6: 2026
A7: WL-01003 | B7: 3 | C7: Phillips | D7: Shannon | E7: INDIVIDUAL | G7: 44579 | H7: ACTIVE_WAITLIST | I7: HALIBUT REACH | J7: CRUISER | K7: 55 | L7: 19.6 | M7: ANY | N7: 50 | O7: (360) 555-8152 | P7: shannon_phillips@gmail.example.com | Q7: Aberdeen | R7: WA | S7: 98520 | T7: 45994 | U7: 2026
A8: WL-01004 | B8: 4 | C8: Lopez | D8: Joseph | E8: CORPORATION | F8: Lopez Charters Inc | G8: 44580 | H8: ACTIVE_WAITLIST | I8: OTTER HARBOR | J8: SAIL_MONO | K8: 61.6 | L8: 20 | M8: OPEN_ONLY | N8: 28 | O8: (360) 555-2544 | P8: joseph_lopez@quillayute.org | Q8: Bremerton | R8: WA | S8: 98337 | T8: 46017 | U8: 2026
A9: WL-01005 | B9: 5 | C9: Sharp | D9: Joseph | E9: JOINT | G9: 44583 | H9: ACTIVE_WAITLIST | I9: POINT ROSE | J9: POWER_INBOARD | K9: 49.9 | L9: 17.3 | M9: COVERED_ONLY | N9: 32 | O9: (360) 555-3393 | P9: josephsharp@quillayute.org | Q9: Chaldale | R9: WA | S9: 98554 | T9: 46000 | U9: 2026
A10: WL-01006 | B10: 6 | C10: Hammond | D10: Gregory | E10: JOINT | G10: 44585 | H10: ACTIVE_WAITLIST | I10: FOUL ROSE | J10: HOUSEBOAT | K10: 34.4 | L10: 9.9 | M10: COVERED_ONLY | N10: 40 | O10: (541) 555-2767 | P10: gregoryhammond@gmail.example.com | Q10: Newport | R10: OR | S10: 97365 | T10: 46014 | U10: 2026
A11: WL-01007 | B11: 7 | C11: Henderson | D11: Victoria | E11: COMMERCIAL | F11: Henderson Ventures LLC | G11: 44593 | H11: ACTIVE_WAITLIST | I11: HERON QUEEN | J11: COMMERCIAL_FISH | K11: 47.6 | L11: 14.3 | M11: Vessbank | N11: 24 | O11: (503) 555-6028 | P11: victoriahenderson@harbormail.net | Q11: Astoria | R11: OR | S11: 97103 | T11: 46009 | U11: 2026
A12: WL-01008 | B12: 8 | C12: Houston | D12: Thomas | E12: JOINT | G12: 44594 | H12: ACTIVE_WAITLIST | I12: KESTREL REACH | J12: HOUSEBOAT | K12: 52.8 | L12: 16 | M12: ANY | N12: 28 | O12: (206) 555-4373 | P12: thomashouston@salishnet.net | Q12: Seattle | R12: WA | S12: 98101 | T12: 46015 | U12: 2026
A13: WL-01009 | B13: 9 | C13: Moon | D13: Mark | E13: TRUST | F13: Moon Charters Inc | G13: 44595 | H13: ACTIVE_WAITLIST | I13: KESTREL HRABOR | J13: SAIL_MULTI | K13: 22.2 | L13: 7.4 | M13: Salmonberry | N13: 24 | O13: (360) 555-1937 | P13: markmoon@quillayute.org | Q13: Olympia | R13: WA | S13: 98501 | T13: 46019 | U13: 2026
A14: WL-01010 | B14: 10 | C14: Hanson | D14: Steven | E14: TRUST | F14: Hanson Marine LLC | G14: 44596 | H14: ACTIVE_WAITLIST | I14: SANDERLING WEATHER | J14: POWER_OUTBOARD | K14: 26.5 | L14: 8.7 | M14: ANY | N14: 24 | O14: (253) 555-3212 | P14: stevenhanson@gmail.example.com | Q14: Tacoma | R14: WA | S14: 98402 | T14: 46010 | U14: 2026
A15: WL-01011 | B15: 11 | C15: Hughes | D15: Kristen | E15: NONPROFIT | F15: Hughes Holdings LLC | G15: 44597 | H15: ACTIVE_WAITLIST | I15: TIDE BAY | J15: SPORTFISH | K15: 60.3 | L15: 17.5 | M15: COVERED_ONLY | N15: 36 | O15: (541) 555-7463 | P15: kristenhughes@harbormail.net | Q15: Coos Bay | R15: OR | S15: 97420 | T15: 46001 | U15: 2026
A16: WL-01012 | B16: 12 | C16: Jones | D16: Janet | E16: COMMERCIAL | F16: Jones Holdings LLC | G16: 44599 | H16: ACTIVE_WAITLIST | I16: SALISH REACH | J16: POWER_INBOARD | K16: 23 | L16: 6.6 | M16: Ledgport | N16: 36 | O16: (360) 555-5884 | P16: janetjones@harbormail.net | Q16: Bremerton | R16: WA | S16: 98337 | T16: 46000 | U16: 2026
A17: WL-01013 | B17: 13 | C17: Booker | D17: Brian | E17: INDIVIDUAL | G17: 44600 | H17: ACTIVE_WAITLIST | I17: TIDE WIND | J17: SAIL_MONO | K17: 52.5 | L17: 18 | M17: Vessbank | N17: 50 | O17: (253) 555-0180 | P17: brianbooker@salishnet.net | Q17: Tacoma | R17: WA | S17: 98402 | T17: 46002 | U17: 2026
A18: WL-01014 | B18: 14 | C18: Johnson | D18: Maria | E18: JOINT | G18: 44605 | H18: ACTIVE_WAITLIST | I18: SPINDRIFT ROSE | J18: CRUISER | K18: 43.6 | L18: 13.6 | M18: COVERED_ONLY | N18: 45 | O18: (360) 555-9658 | P18: mariajohnson@harbormail.net | Q18: Chaldale | R18: WA | S18: 98554 | T18: 46000 | U18: 2026
A19: WL-01015 | B19: 15 | C19: Miller | D19: Danielle | E19: PARTNERSHIP | F19: Miller Charters Inc | G19: 44607 | H19: RETAINER | I19: ANCHOR GLIDE | J19: COMMERCIAL_FISH | K19: 18.2 | L19: 6.4 | M19: ANY | N19: 28 | O19: (425) 555-8363 | P19: danielle.miller@harbormail.net | Q19: Everett | R19: WA | S19: 98201 | T19: 46014 | U19: 2026
A20: WL-01016 | B20: 16 | C20: Mosley | D20: Jared | E20: NONPROFIT | F20: Mosley Marine LLC | G20: 44609 | H20: ACTIVE_WAITLIST | I20: OSPREY DNACER | J20: SAIL_MONO | K20: 43.6 | L20: 13.2 | M20: ANY | N20: 40 | O20: (541) 555-0842 | P20: jared_mosley@quillayute.org | Q20: Newport | R20: OR | S20: 97365 | T20: 45996 | U20: 2026
A21: WL-01017 | B21: 17 | C21: Sawyer | D21: Darren | E21: LLC | F21: Sawyer Holdings LLC | G21: 44613 | H21: RETAINER | I21: CORMORANT ROSE | J21: POWER_INBOARD | K21: 44.5 | L21: 14.7 | M21: Eastwey | N21: 36 | O21: (541) 555-4149 | P21: darren_sawyer@gmail.example.com | Q21: Newport | R21: OR | S21: 97365 | T21: 46009 | U21: 2026
A22: WL-01018 | B22: 18 | C22: Gutierrez | D22: Hector | E22: LLC | F22: Gutierrez Holdings LLC | G22: 44613 | H22: ACTIVE_WAITLIST | I22: SALISH ANN | J22: POWER_STERNDRIVE | K22: 53 | L22: 18.3 | M22: COVERED_ONLY | N22: 32 | O22: (360) 555-4074 | P22: hectorgutierrez@salishnet.net | Q22: Chaldale | R22: WA | S22: 98554 | T22: 46004 | U22: 2026
A23: WL-01019 | B23: 19 | C23: Charles | D23: Danielle | E23: INDIVIDUAL | G23: 44617 | H23: ACTIVE_WAITLIST | I23: BRANT STAR | J23: POWER_INBOARD | K23: 48.2 | L23: 13.9 | M23: OPEN_ONLY | N23: 28 | O23: (360) 555-7310 | P23: danielle.charles@salishnet.net | Q23: Longview | R23: WA | S23: 98632 | T23: 46007 | U23: 2026
A24: WL-01020 | B24: 20 | C24: Williams | D24: Patricia | E24: JOINT | G24: 44621 | H24: EXPIRED | I24: GRAY HARBOR | J24: POWER_INBOARD | K24: 22.2 | L24: 7.1 | M24: Ledgport | N24: 24 | O24: (360) 555-8231 | P24: patricia.williams@outlook.example.com | Q24: Port Angeles | R24: WA | S24: 98362 | U24: 2022
A25: WL-01021 | B25: 21 | C25: Freeman | D25: Deborah | E25: COMMERCIAL | F25: Freeman Holdings LLC | G25: 44621 | H25: ACTIVE_WAITLIST | I25: DRIFT MIST | J25: TRAWLER | K25: 24.1 | L25: 7.5 | M25: ANY | N25: 45 | O25: (541) 555-2489 | P25: deborah.freeman@outlook.example.com | Q25: Newport | R25: OR | S25: 97365 | T25: 46008 | U25: 2026
A26: WL-01022 | B26: 22 | C26: Cooley | D26: Brett | E26: JOINT | G26: 44623 | H26: ACTIVE_WAITLIST | I26: HALIBUT ANN | J26: SAIL_MONO | K26: 43.9 | L26: 14.7 | M26: COVERED_ONLY | N26: 40 | O26: (425) 555-0104 | P26: brettcooley@gmail.example.com | Q26: Everett | R26: WA | S26: 98201 | T26: 46007 | U26: 2026
A27: WL-01023 | B27: 23 | C27: Stone | D27: Emily | E27: INDIVIDUAL | G27: 44629 | H27: ACTIVE_WAITLIST | I27: OSPREY LIGHT | J27: SPORTFISH | K27: 33.9 | L27: 11.7 | M27: ANY | N27: 36 | O27: (503) 555-0387 | P27: emily.stone@harbormail.net | Q27: Astoria | R27: OR | S27: 97103 | T27: 46006 | U27: 2026
A28: WL-01024 | B28: 24 | C28: Henson | D28: Jennifer | E28: COMMERCIAL | F28: Henson Charters Inc | G28: 44630 | H28: ACTIVE_WAITLIST | I28: OTTER WIND | J28: POWER_INBOARD | K28: 48.1 | L28: 13.9 | M28: OPEN_ONLY | N28: 40 | O28: (360) 555-6567 | P28: jenniferhenson@outlook.example.com | Q28: Port Angeles | R28: WA | S28: 98362 | T28: 45992 | U28: 2026
A29: WL-01025 | B29: 25 | C29: Peters | D29: Joanna | E29: INDIVIDUAL | G29: 44630 | H29: ACTIVE_WAITLIST | I29: SALISH SONG | J29: HOUSEBOAT | K29: 48.6 | L29: 16.4 | M29: Vessbank | N29: 32 | O29: (360) 555-3010 | P29: joanna.peters@outlook.example.com | Q29: Aberdeen | R29: WA | S29: 98520 | T29: 45994 | U29: 2026
A30: WL-01026 | B30: 26 | C30: Jacobs | D30: Dawn | E30: NONPROFIT | F30: Jacobs Marine LLC | G30: 44633 | H30: ACTIVE_WAITLIST | I30: GRAY WEATHER | J30: POWER_STERNDRIVE | K30: 53.1 | L30: 15.1 | M30: ANY | N30: 40 | O30: (541) 555-9190 | P30: dawn.jacobs@quillayute.org | Q30: Coos Bay | R30: OR | S30: 97420 | T30: 45996 | U30: 2026
A31: WL-01027 | B31: 27 | C31: Jones | D31: Rachel | E31: JOINT | G31: 44635 | H31: ACTIVE_WAITLIST | I31: SEAL ANN | J31: ELECTRIC | K31: 53.9 | L31: 15.5 | M31: ANY | N31: 32 | O31: (360) 555-5808 | P31: racheljones@gmail.example.com | Q31: Longview | R31: WA | S31: 98632 | T31: 45998 | U31: 2026
A32: WL-01028 | B32: 28 | C32: Benson | D32: Brittany | E32: INDIVIDUAL | G32: 44635 | H32: ACTIVE_WAITLIST | I32: CORMORANT WAKE | J32: SAIL_MONO | K32: 53.7 | L32: 17.9 | M32: COVERED_ONLY | N32: 50 | O32: (541) 555-4453 | P32: brittanybenson@pugetpost.com | Q32: Newport | R32: OR | S32: 97365 | T32: 45995 | U32: 2026
A33: WL-01029 | B33: 29 | C33: Wang | D33: John | E33: INDIVIDUAL | G33: 44638 | H33: ACTIVE_WAITLIST | I33: MURRE HARBOR | J33: POWER_STERNDRIVE | K33: 44.6 | L33: 13.4 | M33: Salmonberry | N33: 28 | O33: (541) 555-8388 | P33: johnwang@quillayute.org | Q33: Newport | R33: OR | S33: 97365 | T33: 46006 | U33: 2026
A34: WL-01030 | B34: 30 | C34: Carr | D34: Elizabeth | E34: INDIVIDUAL | G34: 44640 | H34: ACTIVE_WAITLIST | I34: ANCHOR CREST | J34: CRUISER | K34: 37 | L34: 12.6 | M34: COVERED_ONLY | N34: 36 | O34: (206) 555-8297 | P34: elizabeth.carr@salishnet.net | Q34: Seattle | R34: WA | S34: 98101 | T34: 46006 | U34: 2026
A35: WL-01031 | B35: 31 | C35: Garza | D35: John | E35: CORPORATION | F35: Garza Holdings LLC | G35: 44641 | H35: ACTIVE_WAITLIST | I35: PINTAIL VEER | J35: SPORTFISH | K35: 21.9 | L35: 7.7 | M35: Vessbank | N35: 50 | O35: (360) 555-0933 | P35: john.garza@salishnet.net | Q35: Longview | R35: WA | S35: 98632 | T35: 45998 | U35: 2026
A36: WL-01032 | B36: 32 | C36: Yoder | D36: Ryan | E36: INDIVIDUAL | G36: 44641 | H36: RETAINER | I36: PETREL SONG | J36: POWER_STERNDRIVE | K36: 41.4 | L36: 11.9 | M36: Vessbank | N36: 32 | O36: (425) 555-4079 | P36: ryanyoder@salishnet.net | Q36: Everett | R36: WA | S36: 98201 | T36: 46018 | U36: 2026
A37: WL-01033 | B37: 33 | C37: Gonzalez | D37: Jodi | E37: JOINT | G37: 44643 | H37: ACTIVE_WAITLIST | I37: PETREL QUEEN | J37: POWER_OUTBOARD | K37: 29 | L37: 9.2 | M37: ANY | N37: 24 | O37: (360) 555-3596 | P37: jodi_gonzalez@quillayute.org | Q37: Aberdeen | R37: WA | S37: 98520 | T37: 45997 | U37: 2026
A38: WL-01034 | B38: 34 | C38: Gill | D38: Keith | E38: INDIVIDUAL | G38: 44644 | H38: ACTIVE_WAITLIST | I38: SCOTER ROCK | J38: ELECTRIC | K38: 47.4 | L38: 14.7 | M38: Vessbank | N38: 32 | O38: (503) 555-2375 | P38: keithgill@pugetpost.com | Q38: Astoria | R38: OR | S38: 97103 | T38: 46016 | U38: 2026
A39: WL-01035 | B39: 35 | C39: Webster | D39: Ivan | E39: LLC | F39: Webster Marine LLC | G39: 44644 | H39: ACTIVE_WAITLIST | I39: SALISH DANCER | J39: HOUSEBOAT | K39: 58.9 | L39: 17.8 | M39: ANY | N39: 45 | O39: (541) 555-5558 | P39: ivanwebster@quillayute.org | Q39: Newport | R39: OR | S39: 97365 | T39: 46016 | U39: 2026
A40: WL-01036 | B40: 36 | C40: Rogers | D40: Brandy | E40: JOINT | G40: 44645 | H40: ACTIVE_WAITLIST | I40: HERON LINE | J40: POWER_OUTBOARD | K40: 23.3 | L40: 7.1 | M40: Vessbank | N40: 50 | O40: (541) 555-5122 | P40: brandy_rogers@outlook.example.com | Q40: Newport | R40: OR | S40: 97365 | T40: 45999 | U40: 2026
A41: WL-01037 | B41: 37 | C41: Hunter | D41: Karen | E41: INDIVIDUAL | G41: 44646 | H41: EXPIRED | I41: GRAY MIST | J41: ELECTRIC | K41: 19.1 | L41: 5.8 | M41: ANY | N41: 32 | O41: (425) 555-4490 | P41: karen.hunter@salishnet.net | Q41: Everett | R41: WA | S41: 98201 | U41: 2023
...

Sheet Source - Offer Events
A1: Source - Offer Events
A2: /home/agent/workspace/waiting_list_administration/exports/offer_events_2022_2026.csv
A4: offer_id | B4: offer_date | C4: applicant_id | D4: rank_at_offer | E4: slip_id | F4: basin | G4: slip_size_ft | H4: covered | I4: rate_class | J4: monthly_rate | K4: offer_seq | L4: outcome | M4: response_due_date | N4: response_date | O4: days_to_respond | P4: skip_reason_code | Q4: agreement_id | R4: notes
A5: OFR-2022-0001 | B5: 44582 | C5: WL-02136 | D5: 1136 | E5: GW-0701 | F5: Gullwing | G5: 80 | H5: OPEN | I5: NON_COMM_MONTHLY | J5: 7.55 | K5: 1 | L5: SKIPPED | M5: 44596 | P5: vessel-fit
A6: OFR-2022-0002 | B6: 44569 | C6: WL-02400 | D6: 1400 | E6: VB-0907 | F6: Vessbank | G6: 28 | H6: COVERED | I6: NON_COMM_MONTHLY | J6: 10.4 | K6: 1 | L6: ACCEPTED | M6: 44579 | N6: 44581 | O6: 12 | Q6: MA-2022-0907
A7: OFR-2022-0003 | B7: 44575 | C7: WL-02494 | D7: 1494 | E7: GW-0710 | F7: Gullwing | G7: 36 | H7: OPEN | I7: NON_COMM_MONTHLY | J7: 7.55 | K7: 1 | L7: DECLINED_RETAINER | M7: 44589 | N7: 44588 | O7: 13
A8: OFR-2022-0004 | B8: 44584 | C8: WL-01104 | D8: 104 | E8: LP-0414 | F8: Ledgport | G8: 40 | H8: COVERED | I8: NON_COMM_MONTHLY | J8: 10.4 | K8: 1 | L8: EXPIRED | M8: 44594 | N8: 44588 | O8: 4
A9: OFR-2022-0005 | B9: 44577 | C9: WL-02683 | D9: 1683 | E9: LP-0804 | F9: Ledgport | G9: 32 | H9: COVERED | I9: NON_COMM_MONTHLY | J9: 10.4 | K9: 1 | L9: ACCEPTED | M9: 44587 | N9: 44587 | O9: 10 | Q9: MA-2022-0804
A10: OFR-2022-0006 | B10: 44570 | C10: WL-03173 | D10: 2173 | E10: SB-0812 | F10: Salmonberry | G10: 32 | H10: OPEN | I10: NON_COMM_MONTHLY | J10: 7.55 | K10: 2 | L10: PENDING | M10: 44584
A11: OFR-2022-0007 | B11: 44562 | C11: WL-01369 | D11: 369 | E11: EW-0818 | F11: Eastwey | G11: 32 | H11: OPEN | I11: NON_COMM_MONTHLY | J11: 7.55 | K11: 2 | L11: EXPIRED | M11: 44576 | N11: 44569 | O11: 7
A12: OFR-2022-0008 | B12: 44563 | C12: WL-02883 | D12: 1883 | E12: SB-0209 | F12: Salmonberry | G12: 24 | H12: OPEN | I12: NON_COMM_MONTHLY | J12: 7.55 | K12: 1 | L12: EXPIRED | M12: 44577 | N12: 44577 | O12: 14
A13: OFR-2022-0009 | B13: 44581 | C13: WL-02049 | D13: 1049 | E13: LP-0707 | F13: Ledgport | G13: 28 | H13: COVERED | I13: NON_COMM_MONTHLY | J13: 10.4 | K13: 1 | L13: DECLINED_RETAINER | M13: 44591 | N13: 44591 | O13: 10
A14: OFR-2022-0010 | B14: 44582 | C14: WL-01004 | D14: 4 | E14: GW-0411 | F14: Gullwing | G14: 32 | H14: OPEN | I14: NON_COMM_MONTHLY | J14: 7.55 | K14: 1 | L14: SKIPPED | M14: 44596 | P14: not-current
A15: OFR-2022-0011 | B15: 44571 | C15: WL-03553 | D15: 2553 | E15: VB-0820 | F15: Vessbank | G15: 36 | H15: COVERED | I15: NON_COMM_MONTHLY | J15: 10.4 | K15: 1 | L15: ACCEPTED | M15: 44581 | N15: 44584 | O15: 13 | Q15: MA-2022-0820
A16: OFR-2022-0012 | B16: 44568 | C16: WL-03449 | D16: 2449 | E16: LP-0313 | F16: Ledgport | G16: 32 | H16: COVERED | I16: NON_COMM_MONTHLY | J16: 10.4 | K16: 1 | L16: DECLINED_RETAINER | M16: 44578 | N16: 44581 | O16: 13
A17: OFR-2022-0013 | B17: 44585 | C17: WL-03735 | D17: 2735 | E17: LP-0612 | F17: Ledgport | G17: 32 | H17: COVERED | I17: NON_COMM_MONTHLY | J17: 10.4 | K17: 2 | L17: ACCEPTED | M17: 44595 | N17: 44595 | O17: 10 | Q17: MA-2022-0612
A18: OFR-2022-0014 | B18: 44568 | C18: WL-03826 | D18: 2826 | E18: LP-0216 | F18: Ledgport | G18: 32 | H18: COVERED | I18: NON_COMM_MONTHLY | J18: 10.4 | K18: 1 | L18: DECLINED_RETAINER | M18: 44578 | N18: 44573 | O18: 5
A19: OFR-2022-0015 | B19: 44574 | C19: WL-01817 | D19: 817 | E19: SB-0307 | F19: Salmonberry | G19: 32 | H19: OPEN | I19: NON_COMM_MONTHLY | J19: 7.55 | K19: 1 | L19: DECLINED_RETAINER | M19: 44588 | N19: 44578 | O19: 4
A20: OFR-2022-0016 | B20: 44577 | C20: WL-01468 | D20: 468 | E20: LP-1003 | F20: Ledgport | G20: 28 | H20: COVERED | I20: NON_COMM_MONTHLY | J20: 10.4 | K20: 1 | L20: ACCEPTED | M20: 44587 | N20: 44581 | O20: 4 | Q20: MA-2022-1003
A21: OFR-2022-0017 | B21: 44576 | C21: WL-02851 | D21: 1851 | E21: SB-0315 | F21: Salmonberry | G21: 24 | H21: OPEN | I21: NON_COMM_MONTHLY | J21: 7.55 | K21: 1 | L21: DECLINED | M21: 44590 | N21: 44588 | O21: 12
A22: OFR-2022-0018 | B22: 44575 | C22: WL-01364 | D22: 364 | E22: GW-0811 | F22: Gullwing | G22: 45 | H22: OPEN | I22: NON_COMM_MONTHLY | J22: 7.55 | K22: 1 | L22: SKIPPED | M22: 44589 | P22: declined-prior-offer
A23: OFR-2022-0019 | B23: 44578 | C23: WL-01700 | D23: 700 | E23: LP-1019 | F23: Ledgport | G23: 32 | H23: COVERED | I23: NON_COMM_MONTHLY | J23: 10.4 | K23: 1 | L23: SKIPPED | M23: 44588 | P23: vessel-fit
A24: OFR-2022-0020 | B24: 44573 | C24: WL-01605 | D24: 605 | E24: LP-0111 | F24: Ledgport | G24: 40 | H24: COVERED | I24: NON_COMM_MONTHLY | J24: 10.4 | K24: 1 | L24: DECLINED | M24: 44583 | N24: 44586 | O24: 13
A25: OFR-2022-0021 | B25: 44579 | C25: WL-03516 | D25: 2516 | E25: GW-0419 | F25: Gullwing | G25: 32 | H25: OPEN | I25: NON_COMM_MONTHLY | J25: 7.55 | K25: 1 | L25: EXPIRED | M25: 44593 | N25: 44592 | O25: 13
A26: OFR-2022-0022 | B26: 44564 | C26: WL-01553 | D26: 553 | E26: EW-0408 | F26: Eastwey | G26: 28 | H26: OPEN | I26: NON_COMM_MONTHLY | J26: 7.55 | K26: 1 | L26: DECLINED | M26: 44578 | N26: 44578 | O26: 14
A27: OFR-2022-0023 | B27: 44585 | C27: WL-01399 | D27: 399 | E27: LP-0320 | F27: Ledgport | G27: 24 | H27: COVERED | I27: NON_COMM_MONTHLY | J27: 10.4 | K27: 1 | L27: SKIPPED | M27: 44595 | P27: preference-mismatch
A28: OFR-2022-0024 | B28: 44603 | C28: WL-03158 | D28: 2158 | E28: EW-0911 | F28: Eastwey | G28: 60 | H28: OPEN | I28: NON_COMM_MONTHLY | J28: 7.55 | K28: 1 | L28: ACCEPTED | M28: 44617 | N28: 44617 | O28: 14 | Q28: MA-2022-0911
A29: OFR-2022-0025 | B29: 44614 | C29: WL-03852 | D29: 2852 | E29: EW-0313 | F29: Eastwey | G29: 50 | H29: OPEN | I29: NON_COMM_MONTHLY | J29: 7.55 | K29: 2 | L29: SKIPPED | M29: 44628 | P29: declined-prior-offer
A30: OFR-2022-0026 | B30: 44605 | C30: WL-03346 | D30: 2346 | E30: GW-0406 | F30: Gullwing | G30: 28 | H30: OPEN | I30: NON_COMM_MONTHLY | J30: 7.55 | K30: 1 | L30: SKIPPED | M30: 44619 | P30: vessel-fit
A31: OFR-2022-0027 | B31: 44611 | C31: WL-02299 | D31: 1299 | E31: GW-0918 | F31: Gullwing | G31: 50 | H31: OPEN | I31: NON_COMM_MONTHLY | J31: 7.55 | K31: 2 | L31: DECLINED_RETAINER | M31: 44625 | N31: 44621 | O31: 10
A32: OFR-2022-0028 | B32: 44600 | C32: WL-02722 | D32: 1722 | E32: GW-0813 | F32: Gullwing | G32: 28 | H32: OPEN | I32: NON_COMM_MONTHLY | J32: 7.55 | K32: 2 | L32: ACCEPTED | M32: 44614 | N32: 44617 | O32: 17 | Q32: MA-2022-0813
A33: OFR-2022-0029 | B33: 44604 | C33: WL-02580 | D33: 1580 | E33: VB-1017 | F33: Vessbank | G33: 24 | H33: COVERED | I33: NON_COMM_MONTHLY | J33: 10.4 | K33: 1 | L33: EXPIRED | M33: 44614 | N33: 44616 | O33: 12
A34: OFR-2022-0030 | B34: 44600 | C34: WL-01051 | D34: 51 | E34: SB-0224 | F34: Salmonberry | G34: 32 | H34: OPEN | I34: NON_COMM_MONTHLY | J34: 7.55 | K34: 2 | L34: ACCEPTED | M34: 44614 | N34: 44617 | O34: 17 | Q34: MA-2022-0224
A35: OFR-2022-0031 | B35: 44596 | C35: WL-03579 | D35: 2579 | E35: GW-1012 | F35: Gullwing | G35: 80 | H35: OPEN | I35: NON_COMM_MONTHLY | J35: 7.55 | K35: 1 | L35: SKIPPED | M35: 44610 | P35: vessel-fit
A36: OFR-2022-0032 | B36: 44619 | C36: WL-01600 | D36: 600 | E36: EW-0317 | F36: Eastwey | G36: 36 | H36: OPEN | I36: NON_COMM_MONTHLY | J36: 7.55 | K36: 1 | L36: DECLINED | M36: 44633 | N36: 44621 | O36: 2
A37: OFR-2022-0033 | B37: 44609 | C37: WL-02224 | D37: 1224 | E37: LP-0121 | F37: Ledgport | G37: 32 | H37: COVERED | I37: NON_COMM_MONTHLY | J37: 10.4 | K37: 1 | L37: SKIPPED | M37: 44619 | P37: preference-mismatch
A38: OFR-2022-0034 | B38: 44604 | C38: WL-01971 | D38: 971 | E38: GW-0213 | F38: Gullwing | G38: 28 | H38: OPEN | I38: NON_COMM_MONTHLY | J38: 7.55 | K38: 2 | L38: DECLINED | M38: 44618 | N38: 44613 | O38: 9
A39: OFR-2022-0035 | B39: 44620 | C39: WL-02063 | D39: 1063 | E39: VB-0220 | F39: Vessbank | G39: 28 | H39: COVERED | I39: NON_COMM_MONTHLY | J39: 10.4 | K39: 2 | L39: SKIPPED | M39: 44630 | P39: declined-prior-offer
A40: OFR-2022-0036 | B40: 44595 | C40: WL-01307 | D40: 307 | E40: GW-0511 | F40: Gullwing | G40: 70 | H40: OPEN | I40: NON_COMM_MONTHLY | J40: 7.55 | K40: 1 | L40: EXPIRED | M40: 44609 | N40: 44604 | O40: 9
A41: OFR-2022-0037 | B41: 44640 | C41: WL-01140 | D41: 140 | E41: SB-0510 | F41: Salmonberry | G41: 32 | H41: OPEN | I41: NON_COMM_MONTHLY | J41: 7.55 | K41: 1 | L41: SKIPPED | M41: 44654 | P41: preference-mismatch
...

Sheet Source - Skip Events
A1: Source - Skip Events
A2: /home/agent/workspace/waiting_list_administration/exports/skip_events_2022_2026.csv
A4: skip_id | B4: offer_id | C4: skip_date | D4: applicant_id | E4: rank_at_offer | F4: slip_id | G4: basin | H4: slip_size_ft | I4: reason_code | J4: justification_category | K4: documentation_attached | L4: documentation_type | M4: reviewed_by | N4: review_date | O4: disposition | P4: notes
A5: SKP-2022-0001 | B5: OFR-2022-0001 | C5: 44582 | D5: WL-02136 | E5: 1136 | F5: GW-0701 | G5: Gullwing | H5: 80 | I5: vessel-fit | J5: SLIP_SIZE_MISMATCH | K5: Y | L5: INSURANCE_DECL | M5: MT | N5: 44584 | O5: SUSTAINED
A6: SKP-2022-0002 | B6: OFR-2022-0010 | C6: 44582 | D6: WL-01004 | E6: 4 | F6: GW-0411 | G6: Gullwing | H6: 32 | I6: not-current | J6: INSURANCE_LAPSE | K6: Y | L6: WRITTEN_STATEMENT | M6: EK | N6: 44587 | O6: SUSTAINED
A7: SKP-2022-0003 | B7: OFR-2022-0018 | C7: 44575 | D7: WL-01364 | E7: 364 | F7: GW-0811 | G7: Gullwing | H7: 45 | I7: declined-prior-offer | J7: OTHER | K7: Y | L7: INSURANCE_DECL | M7: MT | N7: 44580 | O7: SUSTAINED
A8: SKP-2022-0004 | B8: OFR-2022-0019 | C8: 44578 | D8: WL-01700 | E8: 700 | F8: LP-1019 | G8: Ledgport | H8: 32 | I8: vessel-fit | J8: SLIP_SIZE_MISMATCH | K8: Y | L8: REPAIR_ESTIMATE | M8: NO | N8: 44578 | O8: SUSTAINED
A9: SKP-2022-0005 | B9: OFR-2022-0023 | C9: 44585 | D9: WL-01399 | E9: 399 | F9: LP-0320 | G9: Ledgport | H9: 24 | I9: preference-mismatch | J9: LOCATION_PREF | K9: Y | L9: REPAIR_ESTIMATE | M9: RD | N9: 44587 | O9: SUSTAINED
A10: SKP-2022-0006 | B10: OFR-2022-0025 | C10: 44614 | D10: WL-03852 | E10: 2852 | F10: EW-0313 | G10: Eastwey | H10: 50 | I10: declined-prior-offer | J10: OTHER | K10: Y | L10: WRITTEN_STATEMENT | M10: PC | N10: 44615 | O10: SUSTAINED
A11: SKP-2022-0007 | B11: OFR-2022-0026 | C11: 44605 | D11: WL-03346 | E11: 2346 | F11: GW-0406 | G11: Gullwing | H11: 28 | I11: vessel-fit | J11: SLIP_SIZE_MISMATCH | K11: Y | L11: OTHER_SUPPORT | M11: PC | N11: 44607 | O11: SUSTAINED
A12: SKP-2022-0008 | B12: OFR-2022-0031 | C12: 44596 | D12: WL-03579 | E12: 2579 | F12: GW-1012 | G12: Gullwing | H12: 80 | I12: vessel-fit | J12: SLIP_SIZE_MISMATCH | K12: Y | L12: REPAIR_ESTIMATE | M12: PC | N12: 44600 | O12: SUSTAINED
A13: SKP-2022-0009 | B13: OFR-2022-0033 | C13: 44609 | D13: WL-02224 | E13: 1224 | F13: LP-0121 | G13: Ledgport | H13: 32 | I13: preference-mismatch | J13: LOCATION_PREF | K13: Y | L13: OTHER_SUPPORT | M13: TY | N13: 44610 | O13: SUSTAINED
A14: SKP-2022-0010 | B14: OFR-2022-0035 | C14: 44620 | D14: WL-02063 | E14: 1063 | F14: VB-0220 | G14: Vessbank | H14: 28 | I14: declined-prior-offer | J14: OTHER | K14: Y | L14: INSURANCE_DECL | M14: BH | N14: 44621 | O14: SUSTAINED
A15: SKP-2022-0011 | B15: OFR-2022-0037 | C15: 44640 | D15: WL-01140 | E15: 140 | F15: SB-0510 | G15: Salmonberry | H15: 32 | I15: preference-mismatch | J15: LOCATION_PREF | K15: Y | L15: REPAIR_ESTIMATE | M15: PC | N15: 44643 | O15: SUSTAINED
A16: SKP-2022-0012 | B16: OFR-2022-0039 | C16: 44634 | D16: WL-01929 | E16: 929 | F16: EW-0119 | G16: Eastwey | H16: 32 | I16: not-current | J16: INSURANCE_LAPSE | K16: Y | L16: OTHER_SUPPORT | M16: DR | N16: 44637 | O16: SUSTAINED
... A410: SKP-2026-0406 | B410: OFR-2026-1479 | C410: 46238 | D410: WL-01517 | E410: 517 | F410: SB-0623 | G410: Salmonberry | H410: 28 | I410: vessel-fit | J410: SLIP_SIZE_MISMATCH | K410: Y | L410: INSURANCE_DECL | M410: TY | N410: 46243 | O410: SUSTAINED
A411: SKP-2022-0407 | B411: OFR-2022-1487 | C411: 44818 | D411: WL-02211 | E411: 1211 | F411: GW-0417 | G411: Gullwing | H411: 32 | I411: not-current | J411: INSURANCE_LAPSE | K411: N | M411: BH | N411: 44820 | O411: SUSTAINED | P411: Cover sheet only - supporting record not attached
A412: SKP-2023-0408 | B412: OFR-2023-1487 | C412: 45048 | D412: WL-02618 | E412: 1618 | F412: GW-0610 | G412: Gullwing | H412: 32 | I412: vessel-fit | J412: SLIP_SIZE_MISMATCH | K412: N | M412: BH | N412: 45050 | O412: SUSTAINED | P412: Cover sheet only - supporting record not attached
A413: SKP-2024-0409 | B413: OFR-2024-1487 | C413: 45342 | D413: WL-03044 | E413: 2044 | F413: VB-0904 | G413: Vessbank | H413: 28 | I413: preference-mismatch | J413: LOCATION_PREF | K413: N | M413: PC | N413: 45344 | O413: SUSTAINED | P413: Cover sheet only - supporting record not attached
A414: SKP-2024-0410 | B414: OFR-2024-1487 | C414: 45601 | D414: WL-03390 | E414: 2390 | F414: SB-0120 | G414: Salmonberry | H414: 40 | I414: declined-prior-offer | J414: OTHER | K414: N | M414: GF | N414: 45603 | O414: SUSTAINED | P414: Cover sheet only - supporting record not attached
A415: SKP-2024-0411 | B415: OFR-2024-1487 | C415: 45370 | D415: WL-02877 | E415: 1877 | F415: GW-1012 | G415: Gullwing | H415: 80 | I415: vessel-fit | J415: SLIP_SIZE_MISMATCH | K415: Y | L415: REPAIR_ESTIMATE | M415: BH | N415: 45372 | O415: SUSTAINED
A416: SKP-2025-0412 | B416: OFR-2025-1487 | C416: 45909 | D416: WL-03102 | E416: 2102 | F416: LP-0806 | G416: Ledgport | H416: 36 | I416: preference-mismatch | J416: LOCATION_PREF | K416: Y | L416: OTHER_SUPPORT | M416: DR | N416: 45911 | O416: SUSTAINED

Sheet Source - Amendments
A1: Source - Amendments
A2: /home/agent/workspace/waiting_list_administration/exports/amendment_log_2022_2026.csv
A4: amendment_id | B4: amendment_ts | C4: applicant_id | D4: field_code | E4: field_label | F4: old_value | G4: new_value | H4: workstation_id | I4: source_document | J4: requires_cert | K4: counter_log_ref | L4: notes
A5: AMD-000001 | B5: 44565 | C5: WL-01912 | D5: VESSEL_NAME | E5: Vessel Name | F5: SALISH MOON | G5: SEAL ANN | H5: HB-COUNTER-2 | J5: N | K5: day log 2022-01-04
A6: AMD-000002 | B6: 44565 | C6: WL-02451 | D6: LOA | E6: Length Overall (LOA) | F6: 26.6 | G6: 23.7 | H6: HB-COUNTER-2 | J6: Y | K6: day log 2022-01-04
A7: AMD-000003 | B7: 44565 | C7: WL-02532 | D7: OFFICIAL_NUM | E7: Official Number / Registration | F7: 583536 | G7: 912469 | H7: HB-COUNTER-2 | I7: driver's license | J7: N | K7: day log 2022-01-04
A8: AMD-000004 | B8: 44565 | C8: WL-03719 | D8: LOA | E8: Length Overall (LOA) | F8: 52.4 | G8: 52.7 | H8: HB-COUNTER-2 | J8: Y | K8: day log 2022-01-04
A9: AMD-000005 | B9: 44566 | C9: WL-01030 | D9: BEAM | E9: Beam (Width) | F9: 10.2 | G9: 9.5 | H9: HB-COUNTER-2 | I9: check-in measurement 2022-01-05 | J9: Y | K9: day log 2022-01-05
A10: AMD-000006 | B10: 44566 | C10: WL-01279 | D10: HIN | E10: Hull Identification Number | F10: CHD93697R987 | G10: CHD31514J530 | H10: HB-COUNTER-2 | J10: N | K10: day log 2022-01-05
A11: AMD-000007 | B11: 44566 | C11: WL-01327 | D11: YEAR_BUILT | E11: Year Built | F11: 1970 | G11: 1970 | H11: HB-COUNTER-2 | I11: owner declaration at counter | J11: N | K11: day log 2022-01-05
A12: AMD-000008 | B12: 44567 | C12: WL-02766 | D12: VESSEL_NAME | E12: Vessel Name | F12: HALIBUT SONG | G12: BRANT DANCER | H12: HB-COUNTER-2 | J12: N | K12: day log 2022-01-06
A13: AMD-000009 | B13: 44567 | C13: WL-03069 | D13: OWNER_NAME | E13: Owner Name | F13: POWER_STERNDRIVE | G13: ALUMINUM | H13: HB-COUNTER-2 | I13: insurance decl page | J13: N | K13: day log 2022-01-06
A14: AMD-000010 | B14: 44569 | C14: WL-02223 | D14: VESSEL_NAME | E14: Vessel Name | F14: PINTAIL HARBOR | G14: SCOTER ANN | H14: HB-COUNTER-2 | I14: insurance decl page | J14: N | K14: day log 2022-01-08
A15: AMD-000011 | B15: 44570 | C15: WL-02658 | D15: OFFICIAL_NUM | E15: Official Number / Registration | F15: 600626 | G15: 775543 | H15: HB-COUNTER-2 | I15: owner declaration at counter | J15: N | K15: day log 2022-01-09
A16: AMD-000012 | B16: 44570 | C16: WL-02515 | D16: YEAR_BUILT | E16: Year Built | F16: 2019 | G16: 2019 | H16: HB-COUNTER-2 | J16: N | K16: day log 2022-01-09
A17: AMD-000013 | B17: 44572 | C17: WL-02159 | D17: LOA | E17: Length Overall (LOA) | F17: 36.4 | G17: 35.8 | H17: HB-COUNTER-2 | J17: Y | K17: day log 2022-01-11
A18: AMD-000014 | B18: 44572 | C18: WL-03620 | D18: ENGINE_HP | E18: Engine Horsepower | F18: 250 | G18: 210 | H18: HB-COUNTER-2 | I18: registration | J18: N | K18: day log 2022-01-11
A19: AMD-000015 | B19: 44573 | C19: WL-03233 | D19: OFFICIAL_NUM | E19: Official Number / Registration | F19: 444197 | G19: 531542 | H19: HB-COUNTER-2 | I19: insurance decl page | J19: N | K19: day log 2022-01-12
A20: AMD-000016 | B20: 44574 | C20: WL-02963 | D20: PROPULSION_TYPE | E20: Propulsion Type | F20: SPORTFISH | G20: CRUISER | H20: HB-COUNTER-2 | I20: insurance decl page | J20: N | K20: day log 2022-01-13
A21: AMD-000017 | B21: 44575 | C21: WL-03558 | D21: HULL_MATERIAL | E21: Hull Material | F21: CA | G21: WOOD | H21: HB-COUNTER-2 | I21: registration | J21: N | K21: day log 2022-01-14
A22: AMD-000018 | B22: 44577 | C22: WL-03728 | D22: BUILD_LOCATION | E22: Build Location / Yard | F22: US | G22: SPORTFISH | H22: HB-COUNTER-2 | I22: bill of sale | J22: N | K22: day log 2022-01-16
A23: AMD-000019 | B23: 44578 | C23: WL-03478 | D23: ENGINE_HP | E23: Engine Horsepower | F23: 150 | G23: 85 | H23: HB-COUNTER-2 | I23: driver's license | J23: N | K23: day log 2022-01-17
A24: AMD-000020 | B24: 44580 | C24: WL-02811 | D24: LOA | E24: Length Overall (LOA) | F24: 54.2 | G24: 51.3 | H24: HB-COUNTER-2 | J24: Y | K24: day log 2022-01-19
A25: AMD-000021 | B25: 44580 | C25: WL-02251 | D25: NET_TONNAGE | E25: Net Tonnage (NT) | F25: 12.7 | G25: 12.8 | H25: HB-COUNTER-2 | J25: Y | K25: day log 2022-01-19
A26: AMD-000022 | B26: 44581 | C26: WL-01279 | D26: PROPULSION_TYPE | E26: Propulsion Type | F26: SPORTFISH | G26: US | H26: HB-COUNTER-2 | J26: N | K26: day log 2022-01-20
A27: AMD-000023 | B27: 44581 | C27: WL-01770 | D27: ENGINE_HP | E27: Engine Horsepower | F27: 330 | G27: 330 | H27: HB-COUNTER-2 | J27: N | K27: day log 2022-01-20
A28: AMD-000024 | B28: 44581 | C28: WL-02211 | D28: OWNER_NAME | E28: Owner Name | F28: POWER_STERNDRIVE | G28: CRUISER | H28: HB-COUNTER-2 | I28: registration | J28: N | K28: day log 2022-01-20
A29: AMD-000025 | B29: 44582 | C29: WL-02564 | D29: OWNER_ADDRESS | E29: Owner Address | F29: 7770 Zachary Ville, Aberdeen, WA | G29: 8994 Roman Burgs, Aberdeen, WA | H29: HB-COUNTER-2 | I29: insurance decl page | J29: N | K29: day log 2022-01-21
A30: AMD-000026 | B30: 44582 | C30: WL-03090 | D30: HIN | E30: Hull Identification Number | F30: CHD81847K911 | G30: CHD99753P758 | H30: HB-COUNTER-2 | I30: driver's license | J30: N | K30: day log 2022-01-21
A31: AMD-000027 | B31: 44584 | C31: WL-03837 | D31: FLAG | E31: Flag State | F31: ELECTRIC | G31: POWER_INBOARD | H31: HB-COUNTER-2 | I31: driver's license | J31: N | K31: day log 2022-01-23
A32: AMD-000028 | B32: 44585 | C32: WL-03847 | D32: OWNER_NAME | E32: Owner Name | F32: WOOD | G32: US | H32: HB-COUNTER-2 | I32: bill of sale | J32: N | K32: day log 2022-01-24
A33: AMD-000029 | B33: 44586 | C33: WL-02050 | D33: LOA | E33: Length Overall (LOA) | F33: 45.4 | G33: 42.5 | H33: HB-COUNTER-2 | J33: Y | K33: day log 2022-01-25
A34: AMD-000030 | B34: 44586 | C34: WL-03720 | D34: ENGINE_HP | E34: Engine Horsepower | F34: 375 | G34: 210 | H34: HB-COUNTER-2 | I34: owner declaration at counter | J34: N | K34: day log 2022-01-25
A35: AMD-000031 | B35: 44587 | C35: WL-03436 | D35: ENGINE_MAKE | E35: Engine Make / Model | F35: SAIL_MONO | G35: SAIL_MULTI | H35: HB-COUNTER-2 | I35: registration | J35: N | K35: day log 2022-01-26
A36: AMD-000032 | B36: 44587 | C36: WL-01762 | D36: YEAR_BUILT | E36: Year Built | F36: 1971 | G36: 1971 | H36: HB-COUNTER-2 | J36: N | K36: day log 2022-01-26
A37: AMD-000033 | B37: 44587 | C37: WL-01737 | D37: VESSEL_NAME | E37: Vessel Name | F37: OTTER REACH | G37: HALIBUT REACH | H37: HB-COUNTER-2 | J37: N | K37: day log 2022-01-26
A38: AMD-000034 | B38: 44588 | C38: WL-01169 | D38: OWNER_NAME | E38: Owner Name | F38: POWER_INBOARD | G38: SAIL_MULTI | H38: HB-COUNTER-2 | I38: insurance decl page | J38: N | K38: day log 2022-01-27
A39: AMD-000035 | B39: 44589 | C39: WL-02302 | D39: BUILD_LOCATION | E39: Build Location / Yard | F39: FOAM_CORE | G39: POWER_OUTBOARD | H39: HB-COUNTER-2 | I39: owner declaration at counter | J39: N | K39: day log 2022-01-28
A40: AMD-000036 | B40: 44589 | C40: WL-01515 | D40: HULL_MATERIAL | E40: Hull Material | F40: POWER_OUTBOARD | G40: FIBERGLASS | H40: HB-COUNTER-2 | I40: driver's license | J40: N | K40: day log 2022-01-28
A41: AMD-000037 | B41: 44589 | C41: WL-01863 | D41: GROSS_TONNAGE | E41: Gross Tonnage (GT) | F41: 27.4 | G41: 27.8 | H41: HB-COUNTER-2 | J41: Y | K41: day log 2022-01-28
...

Sheet Source - Inventory
A1: Source - Inventory
A2: /home/agent/workspace/facilities_and_slips/exports/slip_inventory_2026-08.csv
A4: slip_id | B4: basin | C4: basin_type | D4: dock_row | E4: slip_size_ft | F4: slip_class | G4: covered | H4: beam_max_ft | I4: amenities | J4: status | K4: current_agreement_id | L4: tenant_id | M4: tenant_name | N4: vessel_name | O4: vessel_loa_ft | P4: monthly_rate | Q4: last_inspection_date | R4: notes
A5: LP-0101 | B5: Ledgport | C5: covered | D5: A | E5: 24 | F5: Small | G5: COVERED | H5: 9 | I5: Water, 30A/50A Power | J5: OCCUPIED | K5: MA-2024-0101 | L5: WL-02442 | M5: Elizabeth Burns | N5: SABLE REACH | O5: 51 | P5: 10.4 | Q5: 46014
A6: LP-0102 | B6: Ledgport | C6: covered | D6: A | E6: 40 | F6: Medium | G6: COVERED | H6: 14 | I6: Water, 50A Power | J6: OCCUPIED | K6: MA-2024-0102 | L6: WL-02413 | M6: Damon Phillips | N6: SEAL ROCK | O6: 21.9 | P6: 10.4 | Q6: 46136
A7: LP-0103 | B7: Ledgport | C7: covered | D7: A | E7: 28 | F7: Small | G7: COVERED | H7: 10 | I7: Water, 30A/50A Power | J7: OCCUPIED | K7: MA-2024-0103 | L7: WL-01449 | M7: Charles Hudson | N7: HALIBUT HARBOR | O7: 32.7 | P7: 10.4 | Q7: 45636
A8: LP-0104 | B8: Ledgport | C8: covered | D8: A | E8: 24 | F8: Small | G8: COVERED | H8: 9 | I8: Water, 30A/50A Power | J8: OCCUPIED | K8: MA-2024-0104 | L8: WL-03625 | M8: Vincent Johnson | N8: ANCHOR DANCER | O8: 42.8 | P8: 10.4 | Q8: 45813
A9: LP-0105 | B9: Ledgport | C9: covered | D9: A | E9: 36 | F9: Medium | G9: COVERED | H9: 13 | I9: Water, 50A Power | J9: OCCUPIED | K9: MA-2024-0105 | L9: WL-03876 | M9: John Heath | N9: CORMORANT GLIDE | O9: 39 | P9: 10.4 | Q9: 45674
A10: LP-0106 | B10: Ledgport | C10: covered | D10: A | E10: 24 | F10: Small | G10: COVERED | H10: 9 | I10: Water, 30A/50A Power | J10: OCCUPIED | K10: MA-2024-0106 | L10: WL-02316 | M10: Cheryl Elliott | N10: POINT ROSE | O10: 39 | P10: 10.4 | Q10: 46044
A11: LP-0107 | B11: Ledgport | C11: covered | D11: A | E11: 24 | F11: Small | G11: COVERED | H11: 9 | I11: Water, 30A/50A Power | J11: OCCUPIED | K11: MA-2024-0107 | L11: WL-02607 | M11: Sean Charles | N11: KESTREL REACH | O11: 30.4 | P11: 10.4 | Q11: 45836
A12: LP-0108 | B12: Ledgport | C12: covered | D12: A | E12: 32 | F12: Medium | G12: COVERED | H12: 12 | I12: Water, 30A/50A Power | J12: OCCUPIED | K12: MA-2024-0108 | L12: WL-01567 | M12: Alan Thomas | N12: PETREL HARBOR | O12: 23.4 | P12: 10.4 | Q12: 45664
A13: LP-0109 | B13: Ledgport | C13: covered | D13: A | E13: 32 | F13: Medium | G13: COVERED | H13: 12 | I13: Water, 30A/50A Power | J13: OCCUPIED | K13: MA-2024-0109 | L13: WL-02768 | M13: Sandra Sweeney | N13: CORMORANT REACH | O13: 20.8 | P13: 10.4 | Q13: 46089
A14: LP-0110 | B14: Ledgport | C14: covered | D14: A | E14: 28 | F14: Small | G14: COVERED | H14: 10 | I14: Water, 30A/50A Power | J14: OCCUPIED | K14: MA-2024-0110 | L14: WL-03140 | M14: Jason Martinez | N14: PINTAIL STAR | O14: 26 | P14: 10.4 | Q14: 45893
A15: LP-0111 | B15: Ledgport | C15: covered | D15: A | E15: 40 | F15: Medium | G15: COVERED | H15: 14 | I15: Water, 50A Power | J15: OCCUPIED | K15: MA-2024-0111 | L15: WL-03621 | M15: Denise Powers | N15: SALISH WAKE | O15: 53.5 | P15: 10.4 | Q15: 46052
A16: LP-0112 | B16: Ledgport | C16: covered | D16: A | E16: 32 | F16: Medium | G16: COVERED | H16: 12 | I16: Water, 30A/50A Power | J16: GUEST | P16: 10.4 | Q16: 45766
A17: LP-0113 | B17: Ledgport | C17: covered | D17: A | E17: 36 | F17: Medium | G17: COVERED | H17: 13 | I17: Water, 50A Power | J17: OCCUPIED | K17: MA-2024-0113 | L17: WL-02762 | M17: Elizabeth Williams | N17: MURRE WAKE | O17: 26 | P17: 10.4 | Q17: 46169
A18: LP-0114 | B18: Ledgport | C18: covered | D18: A | E18: 24 | F18: Small | G18: COVERED | H18: 9 | I18: Water, 30A/50A Power | J18: OCCUPIED | K18: MA-2024-0114 | L18: WL-02237 | M18: William Powell | N18: SCOTER WEATHER | O18: 28.2 | P18: 10.4 | Q18: 46038
A19: LP-0115 | B19: Ledgport | C19: covered | D19: A | E19: 28 | F19: Small | G19: COVERED | H19: 10 | I19: Water, 30A/50A Power | J19: OCCUPIED | K19: MA-2024-0115 | L19: WL-02943 | M19: Matthew Thomas | N19: PINTAIL CREST | O19: 18.8 | P19: 10.4 | Q19: 45786
A20: LP-0116 | B20: Ledgport | C20: covered | D20: A | E20: 28 | F20: Small | G20: COVERED | H20: 10 | I20: Water, 30A/50A Power | J20: OCCUPIED | K20: MA-2024-0116 | L20: WL-02031 | M20: Joseph Bishop | N20: ANCHOR LIGHT | O20: 19.2 | P20: 10.4 | Q20: 45958
A21: LP-0117 | B21: Ledgport | C21: covered | D21: A | E21: 32 | F21: Medium | G21: COVERED | H21: 12 | I21: Water, 30A/50A Power | J21: OCCUPIED | K21: MA-2024-0117 | L21: WL-01361 | M21: Benjamin Willis | N21: COHO BAY | O21: 28.7 | P21: 10.4 | Q21: 45736
A22: LP-0118 | B22: Ledgport | C22: covered | D22: A | E22: 24 | F22: Small | G22: COVERED | H22: 9 | I22: Water, 30A/50A Power | J22: OCCUPIED | K22: MA-2024-0118 | L22: WL-03633 | M22: Keith Powell | N22: PINTAIL RUNNER | O22: 22.1 | P22: 10.4 | Q22: 45598
A23: LP-0119 | B23: Ledgport | C23: covered | D23: A | E23: 24 | F23: Small | G23: COVERED | H23: 9 | I23: Water, 30A/50A Power | J23: OCCUPIED | K23: MA-2024-0119 | L23: WL-01880 | M23: Walter Torres | N23: CORMORANT WEATHER | O23: 43.5 | P23: 10.4 | Q23: 46187
A24: LP-0120 | B24: Ledgport | C24: covered | D24: A | E24: 32 | F24: Medium | G24: COVERED | H24: 12 | I24: Water, 30A/50A Power | J24: OCCUPIED | K24: MA-2024-0120 | L24: WL-03128 | M24: Kayla Johnson | N24: FOUL SONG | O24: 30.8 | P24: 10.4 | Q24: 46056
A25: LP-0121 | B25: Ledgport | C25: covered | D25: A | E25: 32 | F25: Medium | G25: COVERED | H25: 12 | I25: Water, 30A/50A Power | J25: OCCUPIED | K25: MA-2024-0121 | L25: WL-03477 | M25: Darryl Garcia | N25: TIDE SHORE | O25: 51.3 | P25: 10.4 | Q25: 45730
A26: LP-0122 | B26: Ledgport | C26: covered | D26: A | E26: 36 | F26: Medium | G26: COVERED | H26: 13 | I26: Water, 50A Power | J26: OCCUPIED | K26: MA-2024-0122 | L26: WL-01974 | M26: Paula Arroyo | N26: OTTER SOUND | O26: 48.2 | P26: 10.4 | Q26: 45574
A27: LP-0123 | B27: Ledgport | C27: covered | D27: A | E27: 32 | F27: Medium | G27: COVERED | H27: 12 | I27: Water, 30A/50A Power | J27: OCCUPIED | K27: MA-2024-0123 | L27: WL-03479 | M27: Brittney Daugherty | N27: SALISH GLIDE | O27: 25.3 | P27: 10.4 | Q27: 46096
A28: LP-0124 | B28: Ledgport | C28: covered | D28: A | E28: 28 | F28: Small | G28: COVERED | H28: 10 | I28: Water, 30A/50A Power | J28: OCCUPIED | K28: MA-2024-0124 | L28: WL-02080 | M28: Audrey Le | N28: GRAY MIST | O28: 38.8 | P28: 10.4 | Q28: 45680
... A34: LP-0206 | B34: Ledgport | C34: covered | D34: B | E34: 24 | F34: Small | G34: COVERED | H34: 9 | I34: Water, 30A/50A Power | J34: OCCUPIED | K34: MA-2024-0206 | L34: WL-03079 | M34: Crystal Glover | N34: TIDE STAR | O34: 41.4 | P34: 10.4 | Q34: 46051
A35: LP-0207 | B35: Ledgport | C35: covered | D35: B | E35: 40 | F35: Medium | G35: COVERED | H35: 14 | I35: Water, 50A Power | J35: VACANT | P35: 10.4 | Q35: 45926
A36: LP-0208 | B36: Ledgport | C36: covered | D36: B | E36: 32 | F36: Medium | G36: COVERED | H36: 12 | I36: Water, 30A/50A Power | J36: OCCUPIED | K36: MA-2024-0208 | L36: WL-02432 | M36: James Olson | N36: SALISH SONG | O36: 35.9 | P36: 10.4 | Q36: 46062
A37: LP-0209 | B37: Ledgport | C37: covered | D37: B | E37: 32 | F37: Medium | G37: COVERED | H37: 12 | I37: Water, 30A/50A Power | J37: OCCUPIED | K37: MA-2024-0209 | L37: WL-01517 | M37: Manuel Abbott | N37: ANCHOR MIST | O37: 19.8 | P37: 10.4 | Q37: 46016
A38: LP-0210 | B38: Ledgport | C38: covered | D38: B | E38: 40 | F38: Medium | G38: COVERED | H38: 14 | I38: Water, 50A Power | J38: OCCUPIED | K38: MA-2024-0210 | L38: WL-02178 | M38: Thomas Stone | N38: COHO SHORE | O38: 24.8 | P38: 10.4 | Q38: 46029
A39: LP-0211 | B39: Ledgport | C39: covered | D39: B | E39: 24 | F39: Small | G39: COVERED | H39: 9 | I39: Water, 30A/50A Power | J39: VACANT | P39: 10.4 | Q39: 45973
A40: LP-0212 | B40: Ledgport | C40: covered | D40: B | E40: 24 | F40: Small | G40: COVERED | H40: 9 | I40: Water, 30A/50A Power | J40: OCCUPIED | K40: MA-2024-0212 | L40: WL-03348 | M40: Sandra Jackson | N40: HERON RUNNER | O40: 57.4 | P40: 10.4 | Q40: 46111
A41: LP-0213 | B41: Ledgport | C41: covered | D41: B | E41: 40 | F41: Medium | G41: COVERED | H41: 14 | I41: Water, 50A Power | J41: OCCUPIED | K41: MA-2024-0213 | L41: WL-02388 | M41: Gregory Brady | N41: DRIFT SOUND | O41: 49.7 | P41: 10.4 | Q41: 45885
A42: LP-0214 | B42: Ledgport | C42: covered | D42: B | E42: 28 | F42: Small | G42: COVERED | H42: 10 | I42: Water, 30A/50A Power | J42: OCCUPIED | K42: MA-2024-0214 | L42: WL-01816 | M42: Jeanne Bennett | N42: BRANT WIND | O42: 31 | P42: 10.4 | Q42: 45756
A43: LP-0215 | B43: Ledgport | C43: covered | D43: B | E43: 28 | F43: Small | G43: COVERED | H43: 10 | I43: Water, 30A/50A Power | J43: OCCUPIED | K43: MA-2024-0215 | L43: WL-01337 | M43: Anna Wright | N43: WIDGEON LIGHT | O43: 26.3 | P43: 10.4 | Q43: 45670
A44: LP-0216 | B44: Ledgport | C44: covered | D44: B | E44: 32 | F44: Medium | G44: COVERED | H44: 12 | I44: Water, 30A/50A Power | J44: OCCUPIED | K44: MA-2024-0216 | L44: WL-01428 | M44: Audrey Taylor | N44: SCOTER CREST | O44: 57 | P44: 10.4 | Q44: 45762
A45: LP-0217 | B45: Ledgport | C45: covered | D45: B | E45: 40 | F45: Medium | G45: COVERED | H45: 14 | I45: Water, 50A Power | J45: OCCUPIED | K45: MA-2024-0217 | L45: WL-01497 | M45: Aaron Ellis | N45: SANDERLING STAR | O45: 58.7 | P45: 10.4 | Q45: 45777
A46: LP-0218 | B46: Ledgport | C46: covered | D46: B | E46: 24 | F46: Small | G46: COVERED | H46: 9 | I46: Water, 30A/50A Power | J46: OCCUPIED | K46: MA-2024-0218 | L46: WL-01177 | M46: Sydney Moore | N46: SCOTER STAR | O46: 41.6 | P46: 10.4 | Q46: 45657
...

Sheet Source - Billing Aug26
A1: Source - Billing Aug26
A2: /home/agent/workspace/finance_and_billing/exports/billing_transactions_2022_2026.csv
A3: ="Filtered from the source file to post_date 2026-08-01 and txn_type MONTHLY_MOORAGE; "&TEXT(COUNTA(A5:A773),"0")&" source transactions." -> Filtered from the source file to post_date 2026-08-01 and txn_type MONTHLY_MOORAGE; 769 source transactions.
A4: txn_id | B4: post_date | C4: account_id | D4: applicant_id | E4: slip_id | F4: basin | G4: rate_class | H4: txn_type | I4: length_ft_billed | J4: months_billed | K4: foot_months | L4: rate_per_foot_month | M4: amount | N4: tax_amount | O4: total_amount | P4: payment_status | Q4: due_date | R4: paid_date | S4: notes
A5: TXN-202608-000064 | B5: 46235 | C5: AC-LP-0101 | D5: WL-02442 | E5: LP-0101 | F5: Ledgport | G5: NON_COMM_MONTHLY | H5: MONTHLY_MOORAGE | I5: 51 | J5: 1 | K5: 51 | L5: 10.4 | M5: 530.4 | N5: 68.1 | O5: 598.5 | P5: PAID | Q5: 46249 | R5: 46244
A6: TXN-202608-000108 | B6: 46235 | C6: AC-LP-0102 | D6: WL-02413 | E6: LP-0102 | F6: Ledgport | G6: NON_COMM_MONTHLY | H6: MONTHLY_MOORAGE | I6: 40 | J6: 1 | K6: 40 | L6: 10.4 | M6: 416 | N6: 53.41 | O6: 469.41 | P6: LATE | Q6: 46249
A7: TXN-202608-000171 | B7: 46235 | C7: AC-LP-0103 | D7: WL-01449 | E7: LP-0103 | F7: Ledgport | G7: NON_COMM_MONTHLY | H7: MONTHLY_MOORAGE | I7: 33 | J7: 1 | K7: 33 | L7: 10.4 | M7: 343.2 | N7: 44.07 | O7: 387.27 | P7: PAID | Q7: 46249 | R7: 46242
A8: TXN-202608-000239 | B8: 46235 | C8: AC-LP-0104 | D8: WL-03625 | E8: LP-0104 | F8: Ledgport | G8: NON_COMM_MONTHLY | H8: MONTHLY_MOORAGE | I8: 43 | J8: 1 | K8: 43 | L8: 10.4 | M8: 447.2 | N8: 57.42 | O8: 504.62 | P8: PAID | Q8: 46249 | R8: 46245
A9: TXN-202608-000299 | B9: 46235 | C9: AC-LP-0105 | D9: WL-03876 | E9: LP-0105 | F9: Ledgport | G9: NON_COMM_MONTHLY | H9: MONTHLY_MOORAGE | I9: 39 | J9: 1 | K9: 39 | L9: 10.4 | M9: 405.6 | N9: 52.08 | O9: 457.68 | P9: PAID | Q9: 46249 | R9: 46239
A10: TXN-202608-000338 | B10: 46235 | C10: AC-LP-0106 | D10: WL-02316 | E10: LP-0106 | F10: Ledgport | G10: NON_COMM_MONTHLY | H10: MONTHLY_MOORAGE | I10: 39 | J10: 1 | K10: 39 | L10: 10.4 | M10: 405.6 | N10: 52.08 | O10: 457.68 | P10: PAID | Q10: 46249 | R10: 46249
A11: TXN-202608-000413 | B11: 46235 | C11: AC-LP-0107 | D11: WL-02607 | E11: LP-0107 | F11: Ledgport | G11: NON_COMM_MONTHLY | H11: MONTHLY_MOORAGE | I11: 31 | J11: 1 | K11: 31 | L11: 10.4 | M11: 322.4 | N11: 41.4 | O11: 363.8 | P11: PAID | Q11: 46249 | R11: 46239
A12: TXN-202608-000483 | B12: 46235 | C12: AC-LP-0108 | D12: WL-01567 | E12: LP-0108 | F12: Ledgport | G12: NON_COMM_MONTHLY | H12: MONTHLY_MOORAGE | I12: 32 | J12: 1 | K12: 32 | L12: 10.4 | M12: 332.8 | N12: 42.73 | O12: 375.53 | P12: PAID | Q12: 46249 | R12: 46242
A13: TXN-202608-000533 | B13: 46235 | C13: AC-LP-0109 | D13: WL-02768 | E13: LP-0109 | F13: Ledgport | G13: NON_COMM_MONTHLY | H13: MONTHLY_MOORAGE | I13: 32 | J13: 1 | K13: 32 | L13: 10.4 | M13: 332.8 | N13: 42.73 | O13: 375.53 | P13: PAID | Q13: 46249 | R13: 46241
A14: TXN-202608-000581 | B14: 46235 | C14: AC-LP-0110 | D14: WL-03140 | E14: LP-0110 | F14: Ledgport | G14: NON_COMM_MONTHLY | H14: MONTHLY_MOORAGE | I14: 28 | J14: 1 | K14: 28 | L14: 10.4 | M14: 291.2 | N14: 37.39 | O14: 328.59 | P14: OPEN | Q14: 46249
A15: TXN-202608-000628 | B15: 46235 | C15: AC-LP-0111 | D15: WL-03621 | E15: LP-0111 | F15: Ledgport | G15: NON_COMM_MONTHLY | H15: MONTHLY_MOORAGE | I15: 54 | J15: 1 | K15: 54 | L15: 10.4 | M15: 561.6 | N15: 72.11 | O15: 633.71 | P15: PAID | Q15: 46249 | R15: 46242
A16: TXN-202608-000674 | B16: 46235 | C16: AC-LP-0113 | D16: WL-02762 | E16: LP-0113 | F16: Ledgport | G16: NON_COMM_MONTHLY | H16: MONTHLY_MOORAGE | I16: 36 | J16: 1 | K16: 36 | L16: 10.4 | M16: 374.4 | N16: 48.07 | O16: 422.47 | P16: PAID | Q16: 46249 | R16: 46247
A17: TXN-202608-000728 | B17: 46235 | C17: AC-LP-0114 | D17: WL-02237 | E17: LP-0114 | F17: Ledgport | G17: NON_COMM_MONTHLY | H17: MONTHLY_MOORAGE | I17: 29 | J17: 1 | K17: 29 | L17: 10.4 | M17: 301.6 | N17: 38.73 | O17: 340.33 | P17: PAID | Q17: 46249 | R17: 46249
A18: TXN-202608-000802 | B18: 46235 | C18: AC-LP-0115 | D18: WL-02943 | E18: LP-0115 | F18: Ledgport | G18: NON_COMM_MONTHLY | H18: MONTHLY_MOORAGE | I18: 28 | J18: 1 | K18: 28 | L18: 10.4 | M18: 291.2 | N18: 37.39 | O18: 328.59 | P18: PAID | Q18: 46249 | R18: 46249
A19: TXN-202608-000869 | B19: 46235 | C19: AC-LP-0116 | D19: WL-02031 | E19: LP-0116 | F19: Ledgport | G19: NON_COMM_MONTHLY | H19: MONTHLY_MOORAGE | I19: 28 | J19: 1 | K19: 28 | L19: 10.4 | M19: 291.2 | N19: 37.39 | O19: 328.59 | P19: PAID | Q19: 46249 | R19: 46248
A20: TXN-202608-000938 | B20: 46235 | C20: AC-LP-0117 | D20: WL-01361 | E20: LP-0117 | F20: Ledgport | G20: NON_COMM_MONTHLY | H20: MONTHLY_MOORAGE | I20: 32 | J20: 1 | K20: 32 | L20: 10.4 | M20: 332.8 | N20: 42.73 | O20: 375.53 | P20: PAID | Q20: 46249 | R20: 46247
A21: TXN-202608-000989 | B21: 46235 | C21: AC-LP-0118 | D21: WL-03633 | E21: LP-0118 | F21: Ledgport | G21: NON_COMM_MONTHLY | H21: MONTHLY_MOORAGE | I21: 24 | J21: 1 | K21: 24 | L21: 10.4 | M21: 249.6 | N21: 32.05 | O21: 281.65 | P21: PAID | Q21: 46249 | R21: 46246
A22: TXN-202608-001067 | B22: 46235 | C22: AC-LP-0119 | D22: WL-01880 | E22: LP-0119 | F22: Ledgport | G22: NON_COMM_MONTHLY | H22: MONTHLY_MOORAGE | I22: 44 | J22: 1 | K22: 44 | L22: 10.4 | M22: 457.6 | N22: 58.76 | O22: 516.36 | P22: LATE | Q22: 46249
A23: TXN-202608-001137 | B23: 46235 | C23: AC-LP-0120 | D23: WL-03128 | E23: LP-0120 | F23: Ledgport | G23: NON_COMM_MONTHLY | H23: MONTHLY_MOORAGE | I23: 32 | J23: 1 | K23: 32 | L23: 10.4 | M23: 332.8 | N23: 42.73 | O23: 375.53 | P23: PAID | Q23: 46249 | R23: 46249
A24: TXN-202608-001182 | B24: 46235 | C24: AC-LP-0121 | D24: WL-03477 | E24: LP-0121 | F24: Ledgport | G24: NON_COMM_MONTHLY | H24: MONTHLY_MOORAGE | I24: 52 | J24: 1 | K24: 52 | L24: 10.4 | M24: 540.8 | N24: 69.44 | O24: 610.24 | P24: LATE | Q24: 46249
A25: TXN-202608-001251 | B25: 46235 | C25: AC-LP-0122 | D25: WL-01974 | E25: LP-0122 | F25: Ledgport | G25: NON_COMM_MONTHLY | H25: MONTHLY_MOORAGE | I25: 49 | J25: 1 | K25: 49 | L25: 10.4 | M25: 509.6 | N25: 65.43 | O25: 575.03 | P25: PAID | Q25: 46249 | R25: 46237
A26: TXN-202608-001319 | B26: 46235 | C26: AC-LP-0123 | D26: WL-03479 | E26: LP-0123 | F26: Ledgport | G26: NON_COMM_MONTHLY | H26: MONTHLY_MOORAGE | I26: 32 | J26: 1 | K26: 32 | L26: 10.4 | M26: 332.8 | N26: 42.73 | O26: 375.53 | P26: PAID | Q26: 46249 | R26: 46246
A27: TXN-202608-001394 | B27: 46235 | C27: AC-LP-0124 | D27: WL-02080 | E27: LP-0124 | F27: Ledgport | G27: NON_COMM_MONTHLY | H27: MONTHLY_MOORAGE | I27: 39 | J27: 1 | K27: 39 | L27: 10.4 | M27: 405.6 | N27: 52.08 | O27: 457.68 | P27: PAID | Q27: 46249 | R27: 46249
A28: TXN-202608-001459 | B28: 46235 | C28: AC-LP-0201 | D28: WL-03657 | E28: LP-0201 | F28: Ledgport | G28: NON_COMM_MONTHLY | H28: MONTHLY_MOORAGE | I28: 52 | J28: 1 | K28: 52 | L28: 10.4 | M28: 540.8 | N28: 69.44 | O28: 610.24 | P28: PAID | Q28: 46249 | R28: 46246
A29: TXN-202608-001533 | B29: 46235 | C29: AC-LP-0202 | D29: WL-02964 | E29: LP-0202 | F29: Ledgport | G29: NON_COMM_MONTHLY | H29: MONTHLY_MOORAGE | I29: 38 | J29: 1 | K29: 38 | L29: 10.4 | M29: 395.2 | N29: 50.74 | O29: 445.94 | P29: PAID | Q29: 46249 | R29: 46240
A30: TXN-202608-001590 | B30: 46235 | C30: AC-LP-0203 | D30: WL-01820 | E30: LP-0203 | F30: Ledgport | G30: NON_COMM_MONTHLY | H30: MONTHLY_MOORAGE | I30: 29 | J30: 1 | K30: 29 | L30: 10.4 | M30: 301.6 | N30: 38.73 | O30: 340.33 | P30: PAID | Q30: 46249 | R30: 46245
A31: TXN-202608-001651 | B31: 46235 | C31: AC-LP-0204 | D31: WL-01587 | E31: LP-0204 | F31: Ledgport | G31: NON_COMM_MONTHLY | H31: MONTHLY_MOORAGE | I31: 36 | J31: 1 | K31: 36 | L31: 10.4 | M31: 374.4 | N31: 48.07 | O31: 422.47 | P31: PAID | Q31: 46249 | R31: 46242
A32: TXN-202608-001727 | B32: 46235 | C32: AC-LP-0205 | D32: WL-01514 | E32: LP-0205 | F32: Ledgport | G32: NON_COMM_MONTHLY | H32: MONTHLY_MOORAGE | I32: 40 | J32: 1 | K32: 40 | L32: 10.4 | M32: 416 | N32: 53.41 | O32: 469.41 | P32: PAID | Q32: 46249 | R32: 46237
A33: TXN-202608-001771 | B33: 46235 | C33: AC-LP-0206 | D33: WL-03079 | E33: LP-0206 | F33: Ledgport | G33: NON_COMM_MONTHLY | H33: MONTHLY_MOORAGE | I33: 42 | J33: 1 | K33: 42 | L33: 10.4 | M33: 436.8 | N33: 56.09 | O33: 492.89 | P33: PAID | Q33: 46249 | R33: 46249
