Workbook

Sheet Summary
A1: CHALDALE MOORAGE AUDIT
A2: Administrator review | Audit date 1 August 2026 | Queue period 1 January 2023 - 31 July 2026
A4: DECISION SNAPSHOT
B5: Clear queue exceptions | E5: Occupied slips | H5: Supplied active bills | K5: Active accounts >90 days
B6: =COUNTIF('Queue Exceptions'!$P$11:$P$29,"EXCEPTION") -> 19 | E6: =COUNTA('Billing Reconciliations'!$A$26:$A$1111) -> 1086 | H6: =COUNTIF('Billing Reconciliations'!$L$26:$L$1111,"<>") -> 769 | K6: =COUNTIF(Aging!$M$11:$M$16,">0") -> 6
B9: Observed posting variance | E9: Missing bill count | H9: Provisional completeness variance | K9: Amount >90 days
B10: =SUMIFS('Billing Reconciliations'!$S$26:$S$1111,'Billing Reconciliations'!$L$26:$L$1111,"<>") -> 0 | E10: =COUNTIF('Billing Reconciliations'!$T$26:$T$1111,"NO BILL*") -> 317 | H10: =SUM('Billing Reconciliations'!$S$26:$S$1111) -> -120158.25 | K10: =SUM(Aging!$M$11:$M$16) -> 4368
A13: FINDINGS AND BASIS
A15: Queue documentation | D15: 19 of 309 in-period skip-register rows state documentation_attached=N. Each is a clear Standing Order 15-3 ss.3.2-3.3 exception. Two supplied Y-file samples (WL-02877 and WL-03102) were verified compliant; 288 other Y rows were not supported by paper files in the supplied record.
A18: Length amendments | D18: No exception found. The latest pre-skip post-effective LOA amendments for 15 in-period events all cite an MC-number or yard haul-out sheet in amendment_log_2022_2026.csv. WL-03102 is additionally supported by the signed Foldview yard sheet dated 2025-06-29.
A21: Billing accuracy | D21: All 769 supplied 2026-08-01 monthly postings use $10.40/foot-month covered or $7.55/foot-month open; billed length equals max(nominal slip, inventory LOA rounded up), and posted amount variance is $0.00 before tax.
A24: Billing completeness | D24: 317 of 1,086 occupied slips have no August posting in the supplied transaction export: 127 Gullwing and 190 Salmonberry. The formula-driven $120,158.25 indicated shortfall uses current inventory LOA/slip fields and is provisional, not a receivable, pending the complete export and current check-in measurement blocks.
A27: Delinquency | D27: Six active slips carry balances older than 90 days in ar_aging_2026-07-31.xlsx. Their formula-computed >90 balance is $4,368.00; total balance across all age buckets is $13,166.40.
A30: Board priority | D30: Apply rank order using rank_at_offer, subject to historical identity/status validation. Appeal 2018-3 supports prospective first-matching-vacancy relief and leaving existing assignments undisturbed.
A33: Authority: Standing Order 15-3 ss.1.1, 3.2-3.3; Resolution 2022-06 ss.1-2, 4.3, 8.1; Tariff Resolution 2019-14 ss.1(4), 2.4, Schedule C; Appeal 2018-3 pp.2-3. Detailed source rows are identified on each audit tab.

Sheet Queue Exceptions
A1: QUEUE EXCEPTIONS | BOARD PRIORITY
A2: Clear exceptions sorted by rank at offer; period 2023-01-01 through 2026-07-31
A4: CONTROL TOTALS
A5: In-period skip rows | B5: =309 -> 309 | C5: Clear exceptions | D5: =COUNTIF($P$11:$P$29,"EXCEPTION") -> 19 | E5: Vessel-fit | F5: =COUNTIF($K$11:$K$29,"vessel-fit") -> 12 | G5: Not-current | H5: =COUNTIF($K$11:$K$29,"not-current") -> 2 | I5: Declined prior | J5: =COUNTIF($K$11:$K$29,"declined-prior-offer") -> 3 | K5: Preference | L5: =COUNTIF($K$11:$K$29,"preference-mismatch") -> 2 | M5: Unsupported LOA | N5: =COUNTIF($N$11:$N$29,"EXCEPTION*") -> 0 | O5: No unsupported length-amendment exceptions found.
A7: Evidence rule: a cover sheet alone is insufficient. The District bears the burden for departures from rank order, and later reconstruction cannot cure a deficient contemporaneous file. Current applicant records postdate 10 events; historical identity/rank must be validated before relief.
A10: Priority | B10: Skip ID | C10: Applicant ID | D10: Rank at Offer | E10: Applicant | F10: Current Status | G10: Vessel | H10: Skip Date | I10: Register Slip | J10: File Slip | K10: Reason Code | L10: Register Evidence | M10: File Evidence | N10: Length Amendment Test | O10: Source Conflict | P10: Conclusion | Q10: Recommended Action
A11: =RANK.EQ(D11,$D$11:$D$29,1)+COUNTIF($D$11:D11,D11)-1 -> 1 | B11: SKP-2025-0328 | C11: WL-01089 | D11: 89 | E11: Erin Holmes | F11: ACTIVE_WAITLIST | G11: CORMORANT WIND | H11: 45941 | I11: SB-0115 | K11: vessel-fit | L11: documentation_attached=N; type=REPAIR_ESTIMATE | M11: No paper justification file supplied; register states no attachment. | N11: PASS - no unsupported prior post-2022 LOA amendment located | O11: None identified from supplied fields | P11: EXCEPTION | Q11: Validate historical identity, status, preferences and day log; if confirmed, grant first future matching offer in rank order. Do not disturb current assignment.
A12: =RANK.EQ(D12,$D$11:$D$29,1)+COUNTIF($D$11:D12,D12)-1 -> 2 | B12: SKP-2024-0219 | C12: WL-01144 | D12: 144 | E12: James Lopez | F12: ACTIVE_WAITLIST | G12: PETREL CREST | H12: 45448 | I12: LP-0216 | K12: vessel-fit | L12: documentation_attached=N; type=WRITTEN_STATEMENT | M12: No paper justification file supplied; register states no attachment. | N12: PASS - no unsupported prior post-2022 LOA amendment located | O12: None identified from supplied fields | P12: EXCEPTION | Q12: Validate historical identity, status, preferences and day log; if confirmed, grant first future matching offer in rank order. Do not disturb current assignment.
A13: =RANK.EQ(D13,$D$11:$D$29,1)+COUNTIF($D$11:D13,D13)-1 -> 3 | B13: SKP-2023-0099 | C13: WL-01695 | D13: 695 | E13: Antonio Leach | F13: ACTIVE_WAITLIST | G13: SPINDRIFT VEER | H13: 44936 | I13: EW-0203 | K13: vessel-fit | L13: documentation_attached=N; type=INSURANCE_DECL | M13: No paper justification file supplied; register states no attachment. | N13: PASS - no unsupported prior post-2022 LOA amendment located | O13: Current register application 2023-07-03 postdates skip | P13: EXCEPTION | Q13: Validate historical identity, status, preferences and day log; if confirmed, grant first future matching offer in rank order. Do not disturb current assignment.
A14: =RANK.EQ(D14,$D$11:$D$29,1)+COUNTIF($D$11:D14,D14)-1 -> 4 | B14: SKP-2023-0131 | C14: WL-01781 | D14: 781 | E14: Crystal Parrish | F14: EXPIRED | G14: SPINDRIFT STAR | H14: 45092 | I14: LP-0220 | K14: preference-mismatch | L14: documentation_attached=N; type=OTHER_SUPPORT | M14: No paper justification file supplied; register states no attachment. | N14: PASS - no unsupported prior post-2022 LOA amendment located | O14: Current register application 2023-08-22 postdates skip | P14: EXCEPTION | Q14: Validate historical identity, status, preferences and day log; if confirmed, grant first future matching offer in rank order. Do not disturb current assignment.
A15: =RANK.EQ(D15,$D$11:$D$29,1)+COUNTIF($D$11:D15,D15)-1 -> 5 | B15: SKP-2026-0384 | C15: WL-01936 | D15: 936 | E15: Deanna Livingston | F15: ACTIVE_WAITLIST | G15: WIDGEON MIST | H15: 46195 | I15: VB-0507 | K15: not-current | L15: documentation_attached=N; type=WRITTEN_STATEMENT | M15: No paper justification file supplied; register states no attachment. | N15: PASS - no unsupported prior post-2022 LOA amendment located | O15: None identified from supplied fields | P15: EXCEPTION | Q15: Validate historical identity, status, preferences and day log; if confirmed, grant first future matching offer in rank order. Do not disturb current assignment.
A16: =RANK.EQ(D16,$D$11:$D$29,1)+COUNTIF($D$11:D16,D16)-1 -> 6 | B16: SKP-2024-0204 | C16: WL-01950 | D16: 950 | E16: Mathew Trujillo | F16: ACTIVE_WAITLIST | G16: TIDE WIND | H16: 45384 | I16: EW-0608 | K16: vessel-fit | L16: documentation_attached=N; type=OTHER_SUPPORT | M16: No paper justification file supplied; register states no attachment. | N16: PASS - no unsupported prior post-2022 LOA amendment located | O16: None identified from supplied fields | P16: EXCEPTION | Q16: Validate historical identity, status, preferences and day log; if confirmed, grant first future matching offer in rank order. Do not disturb current assignment.
A17: =RANK.EQ(D17,$D$11:$D$29,1)+COUNTIF($D$11:D17,D17)-1 -> 7 | B17: SKP-2023-0174 | C17: WL-02285 | D17: 1285 | E17: Brian Scott | F17: ACTIVE_WAITLIST | G17: PINTAIL VEER | H17: 45180 | I17: EW-0107 | K17: declined-prior-offer | L17: documentation_attached=N; type=WRITTEN_STATEMENT | M17: No paper justification file supplied; register states no attachment. | N17: PASS - no unsupported prior post-2022 LOA amendment located | O17: Current register application 2024-04-22 postdates skip | P17: EXCEPTION | Q17: Validate historical identity, status, preferences and day log; if confirmed, grant first future matching offer in rank order. Do not disturb current assignment.
A18: =RANK.EQ(D18,$D$11:$D$29,1)+COUNTIF($D$11:D18,D18)-1 -> 8 | B18: SKP-2025-0292 | C18: WL-02298 | D18: 1298 | E18: Ronald Simpson | F18: ACTIVE_WAITLIST | G18: COHO STAR | H18: 45844 | I18: GW-1017 | K18: vessel-fit | L18: documentation_attached=N; type=REPAIR_ESTIMATE | M18: No paper justification file supplied; register states no attachment. | N18: PASS - no unsupported prior post-2022 LOA amendment located | O18: None identified from supplied fields | P18: EXCEPTION | Q18: Validate historical identity, status, preferences and day log; if confirmed, grant first future matching offer in rank order. Do not disturb current assignment.
A19: =RANK.EQ(D19,$D$11:$D$29,1)+COUNTIF($D$11:D19,D19)-1 -> 9 | B19: SKP-2024-0249 | C19: WL-02598 | D19: 1598 | E19: Nicole Rubio | F19: ACTIVE_WAITLIST | G19: POINT WEATHER | H19: 45613 | I19: GW-0902 | K19: vessel-fit | L19: documentation_attached=N; type=INSURANCE_DECL | M19: No paper justification file supplied; register states no attachment. | N19: PASS - no unsupported prior post-2022 LOA amendment located | O19: None identified from supplied fields | P19: EXCEPTION | Q19: Validate historical identity, status, preferences and day log; if confirmed, grant first future matching offer in rank order. Do not disturb current assignment.
A20: =RANK.EQ(D20,$D$11:$D$29,1)+COUNTIF($D$11:D20,D20)-1 -> 10 | B20: SKP-2023-0408 | C20: WL-02618 | D20: 1618 | E20: Gary Tomlinson | F20: RETAINER | G20: SECOND WIND | H20: 45048 | I20: GW-0610 | J20: EW-0414 | K20: vessel-fit | L20: documentation_attached=N | M20: PDF p.1: cover only; supporting vessel particulars NOT ATTACHED. | N20: PASS - no unsupported prior post-2022 LOA amendment located | O20: Current register application 2024-09-17 postdates skip; register/file slip mismatch | P20: EXCEPTION | Q20: Validate historical identity, status, preferences and day log; if confirmed, grant first future matching offer in rank order. Do not disturb current assignment.
A21: =RANK.EQ(D21,$D$11:$D$29,1)+COUNTIF($D$11:D21,D21)-1 -> 11 | B21: SKP-2025-0309 | C21: WL-02838 | D21: 1838 | E21: Kimberly Griffin | F21: ACTIVE_WAITLIST | G21: MURRE SHORE | H21: 45897 | I21: LP-0413 | K21: declined-prior-offer | L21: documentation_attached=N; type=WRITTEN_STATEMENT | M21: No paper justification file supplied; register states no attachment. | N21: PASS - no unsupported prior post-2022 LOA amendment located | O21: None identified from supplied fields | P21: EXCEPTION | Q21: Validate historical identity, status, preferences and day log; if confirmed, grant first future matching offer in rank order. Do not disturb current assignment.
A22: =RANK.EQ(D22,$D$11:$D$29,1)+COUNTIF($D$11:D22,D22)-1 -> 12 | B22: SKP-2024-0207 | C22: WL-02948 | D22: 1948 | E22: Michael Salinas | F22: ACTIVE_WAITLIST | G22: KESTREL GLIDE | H22: 45403 | I22: GW-1013 | K22: vessel-fit | L22: documentation_attached=N; type=INSURANCE_DECL | M22: No paper justification file supplied; register states no attachment. | N22: PASS - no unsupported prior post-2022 LOA amendment located | O22: Current register application 2025-02-01 postdates skip | P22: EXCEPTION | Q22: Validate historical identity, status, preferences and day log; if confirmed, grant first future matching offer in rank order. Do not disturb current assignment.
A23: =RANK.EQ(D23,$D$11:$D$29,1)+COUNTIF($D$11:D23,D23)-1 -> 13 | B23: SKP-2024-0409 | C23: WL-03044 | D23: 2044 | E23: Iris Quan | F23: ACTIVE_WAITLIST | G23: LITTLE AUK | H23: 45342 | I23: VB-0904 | J23: EW-0603 | K23: preference-mismatch | L23: documentation_attached=N | M23: PDF p.1: cover only; recorded preference sheet NOT ATTACHED. | N23: PASS - no unsupported prior post-2022 LOA amendment located | O23: Current register application 2025-03-14 postdates skip; register/file slip mismatch | P23: EXCEPTION | Q23: Validate historical identity, status, preferences and day log; if confirmed, grant first future matching offer in rank order. Do not disturb current assignment.
A24: =RANK.EQ(D24,$D$11:$D$29,1)+COUNTIF($D$11:D24,D24)-1 -> 14 | B24: SKP-2026-0343 | C24: WL-03054 | D24: 2054 | E24: Amanda Schmidt | F24: ACTIVE_WAITLIST | G24: GRAY ROSE | H24: 46023 | I24: VB-0224 | K24: vessel-fit | L24: documentation_attached=N; type=OTHER_SUPPORT | M24: No paper justification file supplied; register states no attachment. | N24: PASS - no unsupported prior post-2022 LOA amendment located | O24: None identified from supplied fields | P24: EXCEPTION | Q24: Validate historical identity, status, preferences and day log; if confirmed, grant first future matching offer in rank order. Do not disturb current assignment.
A25: =RANK.EQ(D25,$D$11:$D$29,1)+COUNTIF($D$11:D25,D25)-1 -> 15 | B25: SKP-2025-0297 | C25: WL-03094 | D25: 2094 | E25: Christine Cook | F25: ACTIVE_WAITLIST | G25: PETREL SOUND | H25: 45866 | I25: GW-0103 | K25: not-current | L25: documentation_attached=N; type=REPAIR_ESTIMATE | M25: No paper justification file supplied; register states no attachment. | N25: PASS - no unsupported prior post-2022 LOA amendment located | O25: None identified from supplied fields | P25: EXCEPTION | Q25: Validate historical identity, status, preferences and day log; if confirmed, grant first future matching offer in rank order. Do not disturb current assignment.
A26: =RANK.EQ(D26,$D$11:$D$29,1)+COUNTIF($D$11:D26,D26)-1 -> 16 | B26: SKP-2024-0410 | C26: WL-03390 | D26: 2390 | E26: Phillip Ard | F26: RETAINER | G26: MOSSBACK | H26: 45601 | I26: SB-0120 | J26: VB-0144 | K26: declined-prior-offer | L26: documentation_attached=N | M26: PDF p.1: cover only; prior offer date/slip NOT ATTACHED; OFR-2024-0402 absent from offer export. | N26: PASS - no unsupported prior post-2022 LOA amendment located | O26: Current register application 2025-08-19 postdates skip; register/file slip mismatch | P26: EXCEPTION | Q26: Validate historical identity, status, preferences and day log; if confirmed, grant first future matching offer in rank order. Do not disturb current assignment.
A27: =RANK.EQ(D27,$D$11:$D$29,1)+COUNTIF($D$11:D27,D27)-1 -> 17 | B27: SKP-2023-0104 | C27: WL-03523 | D27: 2523 | E27: Darlene Glover | F27: ACTIVE_WAITLIST | G27: HERON SOUND | H27: 45000 | I27: SB-0210 | K27: vessel-fit | L27: documentation_attached=N; type=WRITTEN_STATEMENT | M27: No paper justification file supplied; register states no attachment. | N27: PASS - no unsupported prior post-2022 LOA amendment located | O27: Current register application 2025-11-02 postdates skip | P27: EXCEPTION | Q27: Validate historical identity, status, preferences and day log; if confirmed, grant first future matching offer in rank order. Do not disturb current assignment.
A28: =RANK.EQ(D28,$D$11:$D$29,1)+COUNTIF($D$11:D28,D28)-1 -> 18 | B28: SKP-2023-0166 | C28: WL-03844 | D28: 2844 | E28: Janet Medina | F28: RETAINER | G28: TIDE SOUND | H28: 45185 | I28: EW-0109 | K28: vessel-fit | L28: documentation_attached=N; type=OTHER_SUPPORT | M28: No paper justification file supplied; register states no attachment. | N28: PASS - no unsupported prior post-2022 LOA amendment located | O28: Current register application 2026-05-17 postdates skip | P28: EXCEPTION | Q28: Validate historical identity, status, preferences and day log; if confirmed, grant first future matching offer in rank order. Do not disturb current assignment.
A29: =RANK.EQ(D29,$D$11:$D$29,1)+COUNTIF($D$11:D29,D29)-1 -> 19 | B29: SKP-2026-0371 | C29: WL-03896 | D29: 2896 | E29: Stephen Hammond | F29: ACTIVE_WAITLIST | G29: CORMORANT WIND | H29: 46150 | I29: LP-0220 | K29: vessel-fit | L29: documentation_attached=N; type=WRITTEN_STATEMENT | M29: No paper justification file supplied; register states no attachment. | N29: PASS - no unsupported prior post-2022 LOA amendment located | O29: Current register application 2026-07-05 postdates skip | P29: EXCEPTION | Q29: Validate historical identity, status, preferences and day log; if confirmed, grant first future matching offer in rank order. Do not disturb current assignment.
A31: Sources: skip_events_2022_2026.csv rows 100, 105, 132, 167, 175, 205, 208, 220, 250, 293, 298, 310, 329, 344, 372, 385, 409-411; applicant_register_2026-08.csv; specified skip PDFs; amendment_log_2022_2026.csv. Board authority: Appeal 2018-3 pp.2-3.

Sheet Billing Reconciliations
A1: ACTIVE BILLING RECONCILIATION
A2: Occupied-slip register vs. 2026-08-01 monthly postings | Variance = posted amount minus formula-expected amount | Before tax
A4: RECONCILIATION BY BASIN
A6: Basin | B6: Occupied | C6: Bills Supplied | D6: Count Variance | E6: Posted Amount | F6: Expected Amount | G6: Amount Variance
A7: Ledgport | B7: =COUNTIF($B$26:$B$1111,A7) -> 241 | C7: =COUNTIFS($B$26:$B$1111,A7,$L$26:$L$1111,"<>") -> 241 | D7: =C7-B7 -> 0 | E7: =SUMIF($B$26:$B$1111,A7,$O$26:$O$1111) -> 106340 | F7: =SUMIF($B$26:$B$1111,A7,$P$26:$P$1111) -> 106340 | G7: =SUMIF($B$26:$B$1111,A7,$S$26:$S$1111) -> 0
A8: Vessbank | B8: =COUNTIF($B$26:$B$1111,A8) -> 227 | C8: =COUNTIFS($B$26:$B$1111,A8,$L$26:$L$1111,"<>") -> 227 | D8: =C8-B8 -> 0 | E8: =SUMIF($B$26:$B$1111,A8,$O$26:$O$1111) -> 101264.8 | F8: =SUMIF($B$26:$B$1111,A8,$P$26:$P$1111) -> 101264.8 | G8: =SUMIF($B$26:$B$1111,A8,$S$26:$S$1111) -> 0
A9: Eastwey | B9: =COUNTIF($B$26:$B$1111,A9) -> 215 | C9: =COUNTIFS($B$26:$B$1111,A9,$L$26:$L$1111,"<>") -> 215 | D9: =C9-B9 -> 0 | E9: =SUMIF($B$26:$B$1111,A9,$O$26:$O$1111) -> 79569.45 | F9: =SUMIF($B$26:$B$1111,A9,$P$26:$P$1111) -> 79569.45 | G9: =SUMIF($B$26:$B$1111,A9,$S$26:$S$1111) -> 0
A10: Gullwing | B10: =COUNTIF($B$26:$B$1111,A10) -> 213 | C10: =COUNTIFS($B$26:$B$1111,A10,$L$26:$L$1111,"<>") -> 86 | D10: =C10-B10 -> -127 | E10: =SUMIF($B$26:$B$1111,A10,$O$26:$O$1111) -> 32585.8 | F10: =SUMIF($B$26:$B$1111,A10,$P$26:$P$1111) -> 82347.85 | G10: =SUMIF($B$26:$B$1111,A10,$S$26:$S$1111) -> -49762.05
A11: Salmonberry | B11: =COUNTIF($B$26:$B$1111,A11) -> 190 | C11: =COUNTIFS($B$26:$B$1111,A11,$L$26:$L$1111,"<>") -> 0 | D11: =C11-B11 -> -190 | E11: =SUMIF($B$26:$B$1111,A11,$O$26:$O$1111) -> 0 | F11: =SUMIF($B$26:$B$1111,A11,$P$26:$P$1111) -> 70396.2 | G11: =SUMIF($B$26:$B$1111,A11,$S$26:$S$1111) -> -70396.2
A12: TOTAL | B12: =SUM(B7:B11) -> 1086 | C12: =SUM(C7:C11) -> 769 | D12: =C12-B12 -> -317 | E12: =SUM(E7:E11) -> 319760.05 | F12: =SUM(F7:F11) -> 439918.3 | G12: =SUM(G7:G11) -> -120158.25
A14: EVIDENCE LIMITS AND CERTIFICATE DISPOSITION
A15: All 769 supplied postings reconcile exactly to adopted rates and current inventory length fields. The 317 missing postings generate a formula-based indicated variance, but current agreement/check-in measurement blocks and possible annual or semi-annual prepayments were not supplied. Do not book the indicated difference until the export and measurement file are completed.
A17: Certificate | C17: Certified Basis | D17: Audit Disposition
A18: MC-2024-0062 / WL-01893 | C18: 31.4 ft -> 32 ft | D18: No current active billing for WL-01893. Certificate is applicant-specific and does not govern current VB-0208 occupant WL-03499; no billing variance assigned.
A19: MC-2024-0091 / WL-02401 | C19: 31.7 ft -> 32 ft | D19: Supports amendment_log rows 1289-1290. Applicant register marks WL-02401 EXPIRED; no active billing and no variance.
A20: Authority: Resolution 2022-06 ss.1.1-1.3 and 2.1 applies $10.40 covered / $7.55 open to periods beginning 2022-08-01. Tariff Resolution 2019-14 s.1(4) makes billable length the greater of nominal slip length or check-in LOA rounded up. Tax is excluded from variance because the adopted rates are pre-tax foot-month rates. All totals and variances are formulas. Sources: slip_inventory_2026-08.csv rows 2-1181 and billing_transactions_2022_2026.csv. The transaction export ends at GW-0501 and contains no Salmonberry rows.
A25: Slip ID | B25: Basin | C25: Basin Type | D25: Status | E25: Tenant / Applicant ID | F25: Tenant | G25: Vessel | H25: Slip Size ft | I25: Inventory LOA ft | J25: Expected Billable ft | K25: Required Rate | L25: Txn ID | M25: Billed Length | N25: Posted Rate | O25: Posted Amount | P25: Expected Amount | Q25: Rate Variance | R25: Length Variance | S25: Amount Variance | T25: Reconciliation | U25: Evidence / Source
A26: EW-0101 | B26: Eastwey | C26: open | D26: OCCUPIED | E26: WL-01414 | F26: Phillip Massey | G26: POINT SHORE | H26: 80 | I26: 29.3 | J26: =MAX(H26,ROUNDUP(I26,0)) -> 80 | K26: =IF(C26="covered",10.4,7.55) -> 7.55 | L26: TXN-202608-028684 | M26: 80 | N26: 7.55 | O26: 604 | P26: =J26*K26 -> 604 | Q26: =IF(L26="","",N26-K26) -> 0 | R26: =IF(L26="","",M26-J26) -> 0 | S26: =IF(L26="",-P26,O26-P26) -> 0 | T26: =IF(L26="","NO BILL IN SUPPLIED EXPORT",IF(ABS(Q26)>0.001,"RATE EXCEPTION",IF(ABS(R26)>0.001,"LENGTH EXCEPTION",IF(ABS(S26)>0.01,"AMOUNT EXCEPTION","OK")))) -> OK | U26: slip_inventory_2026-08.csv row 502; billing_transactions_2022_2026.csv row 46365
A27: EW-0102 | B27: Eastwey | C27: open | D27: OCCUPIED | E27: WL-03666 | F27: Andrea Franco | G27: GRAY SONG | H27: 24 | I27: 55.3 | J27: =MAX(H27,ROUNDUP(I27,0)) -> 56 | K27: =IF(C27="covered",10.4,7.55) -> 7.55 | L27: TXN-202608-028767 | M27: 56 | N27: 7.55 | O27: 422.8 | P27: =J27*K27 -> 422.8 | Q27: =IF(L27="","",N27-K27) -> 0 | R27: =IF(L27="","",M27-J27) -> 0 | S27: =IF(L27="",-P27,O27-P27) -> 0 | T27: =IF(L27="","NO BILL IN SUPPLIED EXPORT",IF(ABS(Q27)>0.001,"RATE EXCEPTION",IF(ABS(R27)>0.001,"LENGTH EXCEPTION",IF(ABS(S27)>0.01,"AMOUNT EXCEPTION","OK")))) -> OK | U27: slip_inventory_2026-08.csv row 503; billing_transactions_2022_2026.csv row 46367
A28: EW-0103 | B28: Eastwey | C28: open | D28: OCCUPIED | E28: WL-01149 | F28: David Hoffman | G28: MURRE RUNNER | H28: 36 | I28: 42.6 | J28: =MAX(H28,ROUNDUP(I28,0)) -> 43 | K28: =IF(C28="covered",10.4,7.55) -> 7.55 | L28: TXN-202608-028831 | M28: 43 | N28: 7.55 | O28: 324.65 | P28: =J28*K28 -> 324.65 | Q28: =IF(L28="","",N28-K28) -> 0 | R28: =IF(L28="","",M28-J28) -> 0 | S28: =IF(L28="",-P28,O28-P28) -> 0 | T28: =IF(L28="","NO BILL IN SUPPLIED EXPORT",IF(ABS(Q28)>0.001,"RATE EXCEPTION",IF(ABS(R28)>0.001,"LENGTH EXCEPTION",IF(ABS(S28)>0.01,"AMOUNT EXCEPTION","OK")))) -> OK | U28: slip_inventory_2026-08.csv row 504; billing_transactions_2022_2026.csv row 46369
A29: EW-0105 | B29: Eastwey | C29: open | D29: OCCUPIED | E29: WL-03242 | F29: Micheal Navarro | G29: SABLE MOON | H29: 36 | I29: 60.2 | J29: =MAX(H29,ROUNDUP(I29,0)) -> 61 | K29: =IF(C29="covered",10.4,7.55) -> 7.55 | L29: TXN-202608-028897 | M29: 61 | N29: 7.55 | O29: 460.55 | P29: =J29*K29 -> 460.55 | Q29: =IF(L29="","",N29-K29) -> 0 | R29: =IF(L29="","",M29-J29) -> 0 | S29: =IF(L29="",-P29,O29-P29) -> 0 | T29: =IF(L29="","NO BILL IN SUPPLIED EXPORT",IF(ABS(Q29)>0.001,"RATE EXCEPTION",IF(ABS(R29)>0.001,"LENGTH EXCEPTION",IF(ABS(S29)>0.01,"AMOUNT EXCEPTION","OK")))) -> OK | U29: slip_inventory_2026-08.csv row 506; billing_transactions_2022_2026.csv row 46371
A30: EW-0106 | B30: Eastwey | C30: open | D30: OCCUPIED | E30: WL-03380 | F30: Charles Snyder | G30: PETREL STAR | H30: 45 | I30: 47.5 | J30: =MAX(H30,ROUNDUP(I30,0)) -> 48 | K30: =IF(C30="covered",10.4,7.55) -> 7.55 | L30: TXN-202608-028973 | M30: 48 | N30: 7.55 | O30: 362.4 | P30: =J30*K30 -> 362.4 | Q30: =IF(L30="","",N30-K30) -> 0 | R30: =IF(L30="","",M30-J30) -> 0 | S30: =IF(L30="",-P30,O30-P30) -> 0 | T30: =IF(L30="","NO BILL IN SUPPLIED EXPORT",IF(ABS(Q30)>0.001,"RATE EXCEPTION",IF(ABS(R30)>0.001,"LENGTH EXCEPTION",IF(ABS(S30)>0.01,"AMOUNT EXCEPTION","OK")))) -> OK | U30: slip_inventory_2026-08.csv row 507; billing_transactions_2022_2026.csv row 46372
A31: EW-0107 | B31: Eastwey | C31: open | D31: OCCUPIED | E31: WL-01368 | F31: Justin Turner | G31: SABLE WIND | H31: 28 | I31: 23.7 | J31: =MAX(H31,ROUNDUP(I31,0)) -> 28 | K31: =IF(C31="covered",10.4,7.55) -> 7.55 | L31: TXN-202608-029048 | M31: 28 | N31: 7.55 | O31: 211.4 | P31: =J31*K31 -> 211.4 | Q31: =IF(L31="","",N31-K31) -> 0 | R31: =IF(L31="","",M31-J31) -> 0 | S31: =IF(L31="",-P31,O31-P31) -> 0 | T31: =IF(L31="","NO BILL IN SUPPLIED EXPORT",IF(ABS(Q31)>0.001,"RATE EXCEPTION",IF(ABS(R31)>0.001,"LENGTH EXCEPTION",IF(ABS(S31)>0.01,"AMOUNT EXCEPTION","OK")))) -> OK | U31: slip_inventory_2026-08.csv row 508; billing_transactions_2022_2026.csv row 46373
A32: EW-0108 | B32: Eastwey | C32: open | D32: OCCUPIED | E32: WL-02070 | F32: Leslie Thomas | G32: FOUL ROCK | H32: 40 | I32: 59.3 | J32: =MAX(H32,ROUNDUP(I32,0)) -> 60 | K32: =IF(C32="covered",10.4,7.55) -> 7.55 | L32: TXN-202608-029120 | M32: 60 | N32: 7.55 | O32: 453 | P32: =J32*K32 -> 453 | Q32: =IF(L32="","",N32-K32) -> 0 | R32: =IF(L32="","",M32-J32) -> 0 | S32: =IF(L32="",-P32,O32-P32) -> 0 | T32: =IF(L32="","NO BILL IN SUPPLIED EXPORT",IF(ABS(Q32)>0.001,"RATE EXCEPTION",IF(ABS(R32)>0.001,"LENGTH EXCEPTION",IF(ABS(S32)>0.01,"AMOUNT EXCEPTION","OK")))) -> OK | U32: slip_inventory_2026-08.csv row 509; billing_transactions_2022_2026.csv row 46374
A33: EW-0109 | B33: Eastwey | C33: open | D33: OCCUPIED | E33: WL-03624 | F33: Robert Rodriguez | G33: COHO ANN | H33: 60 | I33: 30.9 | J33: =MAX(H33,ROUNDUP(I33,0)) -> 60 | K33: =IF(C33="covered",10.4,7.55) -> 7.55 | L33: TXN-202608-029186 | M33: 60 | N33: 7.55 | O33: 453 | P33: =J33*K33 -> 453 | Q33: =IF(L33="","",N33-K33) -> 0 | R33: =IF(L33="","",M33-J33) -> 0 | S33: =IF(L33="",-P33,O33-P33) -> 0 | T33: =IF(L33="","NO BILL IN SUPPLIED EXPORT",IF(ABS(Q33)>0.001,"RATE EXCEPTION",IF(ABS(R33)>0.001,"LENGTH EXCEPTION",IF(ABS(S33)>0.01,"AMOUNT EXCEPTION","OK")))) -> OK | U33: slip_inventory_2026-08.csv row 510; billing_transactions_2022_2026.csv row 46375
A34: EW-0110 | B34: Eastwey | C34: open | D34: OCCUPIED | E34: WL-01831 | F34: Angela Andersen | G34: BRANT WAKE | H34: 28 | I34: 36.3 | J34: =MAX(H34,ROUNDUP(I34,0)) -> 37 | K34: =IF(C34="covered",10.4,7.55) -> 7.55 | L34: TXN-202608-029246 | M34: 37 | N34: 7.55 | O34: 279.35 | P34: =J34*K34 -> 279.35 | Q34: =IF(L34="","",N34-K34) -> 0 | R34: =IF(L34="","",M34-J34) -> 0 | S34: =IF(L34="",-P34,O34-P34) -> 5.6843419e-14 | T34: =IF(L34="","NO BILL IN SUPPLIED EXPORT",IF(ABS(Q34)>0.001,"RATE EXCEPTION",IF(ABS(R34)>0.001,"LENGTH EXCEPTION",IF(ABS(S34)>0.01,"AMOUNT EXCEPTION","OK")))) -> OK | U34: slip_inventory_2026-08.csv row 511; billing_transactions_2022_2026.csv row 46377
A35: EW-0111 | B35: Eastwey | C35: open | D35: OCCUPIED | E35: WL-01617 | F35: James Ferguson | G35: POINT DANCER | H35: 28 | I35: 43.9 | J35: =MAX(H35,ROUNDUP(I35,0)) -> 44 | K35: =IF(C35="covered",10.4,7.55) -> 7.55 | L35: TXN-202608-029329 | M35: 44 | N35: 7.55 | O35: 332.2 | P35: =J35*K35 -> 332.2 | Q35: =IF(L35="","",N35-K35) -> 0 | R35: =IF(L35="","",M35-J35) -> 0 | S35: =IF(L35="",-P35,O35-P35) -> 0 | T35: =IF(L35="","NO BILL IN SUPPLIED EXPORT",IF(ABS(Q35)>0.001,"RATE EXCEPTION",IF(ABS(R35)>0.001,"LENGTH EXCEPTION",IF(ABS(S35)>0.01,"AMOUNT EXCEPTION","OK")))) -> OK | U35: slip_inventory_2026-08.csv row 512; billing_transactions_2022_2026.csv row 46378
A36: EW-0112 | B36: Eastwey | C36: open | D36: OCCUPIED | E36: WL-01533 | F36: Beth Cooper | G36: SPINDRIFT WIND | H36: 70 | I36: 38.7 | J36: =MAX(H36,ROUNDUP(I36,0)) -> 70 | K36: =IF(C36="covered",10.4,7.55) -> 7.55 | L36: TXN-202608-029415 | M36: 70 | N36: 7.55 | O36: 528.5 | P36: =J36*K36 -> 528.5 | Q36: =IF(L36="","",N36-K36) -> 0 | R36: =IF(L36="","",M36-J36) -> 0 | S36: =IF(L36="",-P36,O36-P36) -> 0 | T36: =IF(L36="","NO BILL IN SUPPLIED EXPORT",IF(ABS(Q36)>0.001,"RATE EXCEPTION",IF(ABS(R36)>0.001,"LENGTH EXCEPTION",IF(ABS(S36)>0.01,"AMOUNT EXCEPTION","OK")))) -> OK | U36: slip_inventory_2026-08.csv row 513; billing_transactions_2022_2026.csv row 46380
A37: EW-0113 | B37: Eastwey | C37: open | D37: OCCUPIED | E37: WL-01482 | F37: Brandon Boyer | G37: TIDE MOON | H37: 45 | I37: 61.3 | J37: =MAX(H37,ROUNDUP(I37,0)) -> 62 | K37: =IF(C37="covered",10.4,7.55) -> 7.55 | L37: TXN-202608-029475 | M37: 62 | N37: 7.55 | O37: 468.1 | P37: =J37*K37 -> 468.1 | Q37: =IF(L37="","",N37-K37) -> 0 | R37: =IF(L37="","",M37-J37) -> 0 | S37: =IF(L37="",-P37,O37-P37) -> 5.6843419e-14 | T37: =IF(L37="","NO BILL IN SUPPLIED EXPORT",IF(ABS(Q37)>0.001,"RATE EXCEPTION",IF(ABS(R37)>0.001,"LENGTH EXCEPTION",IF(ABS(S37)>0.01,"AMOUNT EXCEPTION","OK")))) -> OK | U37: slip_inventory_2026-08.csv row 514; billing_transactions_2022_2026.csv row 46381
... A326: GW-0501 | B326: Gullwing | C326: open | D326: OCCUPIED | E326: WL-01450 | F326: Joel Barnes | G326: DRIFT WIND | H326: 40 | I326: 22.6 | J326: =MAX(H326,ROUNDUP(I326,0)) -> 40 | K326: =IF(C326="covered",10.4,7.55) -> 7.55 | L326: TXN-202608-046797 | M326: 40 | N326: 7.55 | O326: 302 | P326: =J326*K326 -> 302 | Q326: =IF(L326="","",N326-K326) -> 0 | R326: =IF(L326="","",M326-J326) -> 0 | S326: =IF(L326="",-P326,O326-P326) -> 0 | T326: =IF(L326="","NO BILL IN SUPPLIED EXPORT",IF(ABS(Q326)>0.001,"RATE EXCEPTION",IF(ABS(R326)>0.001,"LENGTH EXCEPTION",IF(ABS(S326)>0.01,"AMOUNT EXCEPTION","OK")))) -> OK | U326: slip_inventory_2026-08.csv row 834; billing_transactions_2022_2026.csv row 46801
A327: GW-0502 | B327: Gullwing | C327: open | D327: OCCUPIED | E327: WL-03559 | F327: David Sanders | G327: KESTREL VEER | H327: 60 | I327: 36.5 | J327: =MAX(H327,ROUNDUP(I327,0)) -> 60 | K327: =IF(C327="covered",10.4,7.55) -> 7.55 | P327: =J327*K327 -> 453 | Q327: =IF(L327="","",N327-K327) | R327: =IF(L327="","",M327-J327) | S327: =IF(L327="",-P327,O327-P327) -> -453 | T327: =IF(L327="","NO BILL IN SUPPLIED EXPORT",IF(ABS(Q327)>0.001,"RATE EXCEPTION",IF(ABS(R327)>0.001,"LENGTH EXCEPTION",IF(ABS(S327)>0.01,"AMOUNT EXCEPTION","OK")))) -> NO BILL IN SUPPLIED EXPORT | U327: slip_inventory_2026-08.csv row 835; no matching 2026-08-01 monthly posting in supplied export
A328: GW-0503 | B328: Gullwing | C328: open | D328: OCCUPIED | E328: WL-01494 | F328: Ashley Park | G328: COHO WEATHER | H328: 32 | I328: 43.9 | J328: =MAX(H328,ROUNDUP(I328,0)) -> 44 | K328: =IF(C328="covered",10.4,7.55) -> 7.55 | P328: =J328*K328 -> 332.2 | Q328: =IF(L328="","",N328-K328) | R328: =IF(L328="","",M328-J328) | S328: =IF(L328="",-P328,O328-P328) -> -332.2 | T328: =IF(L328="","NO BILL IN SUPPLIED EXPORT",IF(ABS(Q328)>0.001,"RATE EXCEPTION",IF(ABS(R328)>0.001,"LENGTH EXCEPTION",IF(ABS(S328)>0.01,"AMOUNT EXCEPTION","OK")))) -> NO BILL IN SUPPLIED EXPORT | U328: slip_inventory_2026-08.csv row 836; no matching 2026-08-01 monthly posting in supplied export
A329: GW-0504 | B329: Gullwing | C329: open | D329: OCCUPIED | E329: WL-01500 | F329: Patricia Marquez | G329: OSPREY GLIDE | H329: 50 | I329: 25.2 | J329: =MAX(H329,ROUNDUP(I329,0)) -> 50 | K329: =IF(C329="covered",10.4,7.55) -> 7.55 | P329: =J329*K329 -> 377.5 | Q329: =IF(L329="","",N329-K329) | R329: =IF(L329="","",M329-J329) | S329: =IF(L329="",-P329,O329-P329) -> -377.5 | T329: =IF(L329="","NO BILL IN SUPPLIED EXPORT",IF(ABS(Q329)>0.001,"RATE EXCEPTION",IF(ABS(R329)>0.001,"LENGTH EXCEPTION",IF(ABS(S329)>0.01,"AMOUNT EXCEPTION","OK")))) -> NO BILL IN SUPPLIED EXPORT | U329: slip_inventory_2026-08.csv row 837; no matching 2026-08-01 monthly posting in supplied export
A330: GW-0505 | B330: Gullwing | C330: open | D330: OCCUPIED | E330: WL-01089 | F330: Erin Holmes | G330: CORMORANT WIND | H330: 60 | I330: 54.3 | J330: =MAX(H330,ROUNDUP(I330,0)) -> 60 | K330: =IF(C330="covered",10.4,7.55) -> 7.55 | P330: =J330*K330 -> 453 | Q330: =IF(L330="","",N330-K330) | R330: =IF(L330="","",M330-J330) | S330: =IF(L330="",-P330,O330-P330) -> -453 | T330: =IF(L330="","NO BILL IN SUPPLIED EXPORT",IF(ABS(Q330)>0.001,"RATE EXCEPTION",IF(ABS(R330)>0.001,"LENGTH EXCEPTION",IF(ABS(S330)>0.01,"AMOUNT EXCEPTION","OK")))) -> NO BILL IN SUPPLIED EXPORT | U330: slip_inventory_2026-08.csv row 838; no matching 2026-08-01 monthly posting in supplied export
A331: GW-0506 | B331: Gullwing | C331: open | D331: OCCUPIED | E331: WL-03615 | F331: Kathryn Cook | G331: WIDGEON PASSAGE | H331: 45 | I331: 25.2 | J331: =MAX(H331,ROUNDUP(I331,0)) -> 45 | K331: =IF(C331="covered",10.4,7.55) -> 7.55 | P331: =J331*K331 -> 339.75 | Q331: =IF(L331="","",N331-K331) | R331: =IF(L331="","",M331-J331) | S331: =IF(L331="",-P331,O331-P331) -> -339.75 | T331: =IF(L331="","NO BILL IN SUPPLIED EXPORT",IF(ABS(Q331)>0.001,"RATE EXCEPTION",IF(ABS(R331)>0.001,"LENGTH EXCEPTION",IF(ABS(S331)>0.01,"AMOUNT EXCEPTION","OK")))) -> NO BILL IN SUPPLIED EXPORT | U331: slip_inventory_2026-08.csv row 839; no matching 2026-08-01 monthly posting in supplied export
A332: GW-0507 | B332: Gullwing | C332: open | D332: OCCUPIED | E332: WL-03057 | F332: Jennifer Stout | G332: BRANT ROSE | H332: 24 | I332: 38.3 | J332: =MAX(H332,ROUNDUP(I332,0)) -> 39 | K332: =IF(C332="covered",10.4,7.55) -> 7.55 | P332: =J332*K332 -> 294.45 | Q332: =IF(L332="","",N332-K332) | R332: =IF(L332="","",M332-J332) | S332: =IF(L332="",-P332,O332-P332) -> -294.45 | T332: =IF(L332="","NO BILL IN SUPPLIED EXPORT",IF(ABS(Q332)>0.001,"RATE EXCEPTION",IF(ABS(R332)>0.001,"LENGTH EXCEPTION",IF(ABS(S332)>0.01,"AMOUNT EXCEPTION","OK")))) -> NO BILL IN SUPPLIED EXPORT | U332: slip_inventory_2026-08.csv row 840; no matching 2026-08-01 monthly posting in supplied export
A333: GW-0508 | B333: Gullwing | C333: open | D333: OCCUPIED | E333: WL-03692 | F333: Warren Wilkins | G333: WIDGEON CREST | H333: 70 | I333: 25.9 | J333: =MAX(H333,ROUNDUP(I333,0)) -> 70 | K333: =IF(C333="covered",10.4,7.55) -> 7.55 | P333: =J333*K333 -> 528.5 | Q333: =IF(L333="","",N333-K333) | R333: =IF(L333="","",M333-J333) | S333: =IF(L333="",-P333,O333-P333) -> -528.5 | T333: =IF(L333="","NO BILL IN SUPPLIED EXPORT",IF(ABS(Q333)>0.001,"RATE EXCEPTION",IF(ABS(R333)>0.001,"LENGTH EXCEPTION",IF(ABS(S333)>0.01,"AMOUNT EXCEPTION","OK")))) -> NO BILL IN SUPPLIED EXPORT | U333: slip_inventory_2026-08.csv row 841; no matching 2026-08-01 monthly posting in supplied export
A334: GW-0509 | B334: Gullwing | C334: open | D334: OCCUPIED | E334: WL-03850 | F334: Teresa Greer | G334: COHO HARBOR | H334: 45 | I334: 35.6 | J334: =MAX(H334,ROUNDUP(I334,0)) -> 45 | K334: =IF(C334="covered",10.4,7.55) -> 7.55 | P334: =J334*K334 -> 339.75 | Q334: =IF(L334="","",N334-K334) | R334: =IF(L334="","",M334-J334) | S334: =IF(L334="",-P334,O334-P334) -> -339.75 | T334: =IF(L334="","NO BILL IN SUPPLIED EXPORT",IF(ABS(Q334)>0.001,"RATE EXCEPTION",IF(ABS(R334)>0.001,"LENGTH EXCEPTION",IF(ABS(S334)>0.01,"AMOUNT EXCEPTION","OK")))) -> NO BILL IN SUPPLIED EXPORT | U334: slip_inventory_2026-08.csv row 842; no matching 2026-08-01 monthly posting in supplied export
A335: GW-0511 | B335: Gullwing | C335: open | D335: OCCUPIED | E335: WL-02804 | F335: Danny Jones | G335: SCOTER ROCK | H335: 70 | I335: 28.7 | J335: =MAX(H335,ROUNDUP(I335,0)) -> 70 | K335: =IF(C335="covered",10.4,7.55) -> 7.55 | P335: =J335*K335 -> 528.5 | Q335: =IF(L335="","",N335-K335) | R335: =IF(L335="","",M335-J335) | S335: =IF(L335="",-P335,O335-P335) -> -528.5 | T335: =IF(L335="","NO BILL IN SUPPLIED EXPORT",IF(ABS(Q335)>0.001,"RATE EXCEPTION",IF(ABS(R335)>0.001,"LENGTH EXCEPTION",IF(ABS(S335)>0.01,"AMOUNT EXCEPTION","OK")))) -> NO BILL IN SUPPLIED EXPORT | U335: slip_inventory_2026-08.csv row 844; no matching 2026-08-01 monthly posting in supplied export
A336: GW-0512 | B336: Gullwing | C336: open | D336: OCCUPIED | E336: WL-03869 | F336: Seth Raymond | G336: MURRE LIGHT | H336: 32 | I336: 37 | J336: =MAX(H336,ROUNDUP(I336,0)) -> 37 | K336: =IF(C336="covered",10.4,7.55) -> 7.55 | P336: =J336*K336 -> 279.35 | Q336: =IF(L336="","",N336-K336) | R336: =IF(L336="","",M336-J336) | S336: =IF(L336="",-P336,O336-P336) -> -279.35 | T336: =IF(L336="","NO BILL IN SUPPLIED EXPORT",IF(ABS(Q336)>0.001,"RATE EXCEPTION",IF(ABS(R336)>0.001,"LENGTH EXCEPTION",IF(ABS(S336)>0.01,"AMOUNT EXCEPTION","OK")))) -> NO BILL IN SUPPLIED EXPORT | U336: slip_inventory_2026-08.csv row 845; no matching 2026-08-01 monthly posting in supplied export
...

Sheet Aging
A1: ACTIVE SLIPS MORE THAN 90 DAYS DELINQUENT
A2: July aging ledger dated 2026-07-31 | More-than-90 amount = 91-120 bucket + 120+ bucket
A4: CONTROL TOTALS
A5: Active accounts | E5: Total balance | I5: Amount >90 days | M5: Bucket tie-out
A6: =COUNTIF($M$11:$M$16,">0") -> 6 | E6: =SUM($K$11:$K$16) -> 13166.4 | I6: =SUM($M$11:$M$16) -> 4368 | M6: =SUM($L$11:$L$16) -> 0
A9: All six rows are occupied in slip_inventory_2026-08.csv. These six rows tie individually; the full aging workbook is incomplete relative to the 1,086 occupied-slip register and requires a complete invoice-level run as of 2026-08-01.
A10: Account | B10: Tenant | C10: Slip | D10: Basin | E10: Current | F10: 31-60 | G10: 61-90 | H10: 91-120 | I10: 120+ | J10: Source Total Due | K10: Bucket Sum | L10: Tie-Out Variance | M10: Amount >90 | N10: Active | O10: Evidence / Source
A11: AC-LP-0122 | B11: Paula Arroyo | C11: LP-0122 | D11: Ledgport | E11: 509.6 | F11: 509.6 | G11: 509.6 | H11: 509.6 | I11: 0 | J11: 2038.4 | K11: =SUM(E11:I11) -> 2038.4 | L11: =K11-J11 -> 0 | M11: =H11+I11 -> 509.6 | N11: OCCUPIED | O11: ar_aging_2026-07-31.xlsx, AR_Aging row 23; slip_inventory_2026-08.csv row 23
A12: AC-LP-0402 | B12: Dawn Brown | C12: LP-0402 | D12: Ledgport | E12: 384.8 | F12: 384.8 | G12: 384.8 | H12: 384.8 | I12: 0 | J12: 1539.2 | K12: =SUM(E12:I12) -> 1539.2 | L12: =K12-J12 -> 0 | M12: =H12+I12 -> 384.8 | N12: OCCUPIED | O12: ar_aging_2026-07-31.xlsx, AR_Aging row 68; slip_inventory_2026-08.csv row 75
A13: AC-LP-0602 | B13: Lee Maldonado | C13: LP-0602 | D13: Ledgport | E13: 603.2 | F13: 603.2 | G13: 603.2 | H13: 603.2 | I13: 603.2 | J13: 3016 | K13: =SUM(E13:I13) -> 3016 | L13: =K13-J13 -> 0 | M13: =H13+I13 -> 1206.4 | N13: OCCUPIED | O13: ar_aging_2026-07-31.xlsx, AR_Aging row 113; slip_inventory_2026-08.csv row 123
A14: AC-LP-0605 | B14: Andrew Anderson | C14: LP-0605 | D14: Ledgport | E14: 530.4 | F14: 530.4 | G14: 530.4 | H14: 530.4 | I14: 0 | J14: 2121.6 | K14: =SUM(E14:I14) -> 2121.6 | L14: =K14-J14 -> 0 | M14: =H14+I14 -> 530.4 | N14: OCCUPIED | O14: ar_aging_2026-07-31.xlsx, AR_Aging row 116; slip_inventory_2026-08.csv row 126
A15: AC-LP-0713 | B15: Stacey Mitchell | C15: LP-0713 | D15: Ledgport | E15: 416 | F15: 416 | G15: 416 | H15: 416 | I15: 832 | J15: 2496 | K15: =SUM(E15:I15) -> 2496 | L15: =K15-J15 -> 0 | M15: =H15+I15 -> 1248 | N15: OCCUPIED | O15: ar_aging_2026-07-31.xlsx, AR_Aging row 147; slip_inventory_2026-08.csv row 158
A16: AC-LP-0801 | B16: Allison Nguyen | C16: LP-0801 | D16: Ledgport | E16: 488.8 | F16: 488.8 | G16: 488.8 | H16: 488.8 | I16: 0 | J16: 1955.2 | K16: =SUM(E16:I16) -> 1955.2 | L16: =K16-J16 -> 0 | M16: =H16+I16 -> 488.8 | N16: OCCUPIED | O16: ar_aging_2026-07-31.xlsx, AR_Aging row 158; slip_inventory_2026-08.csv row 170
A18: Basis and limitation: the source workbook's Summary sheet labels days_90 as 91-120 and days_120_plus as 120+. The six displayed rows' bucket arithmetic ties to source total_due. The workbook contains only 260 accounts, so this is the complete >90 result within the supplied July ledger, not a complete census of all occupied slips. A 2026-08-01 invoice-level aging would identify any balance crossing the threshold overnight.
