Workbook

Sheet Summary
A1: Chaldale Moorage Audit
A2: Administrator review | As of 2026-08-01 | Queue scope 2023-01-01 through 2026-07-31 | Formula-driven summary linked to the three audit schedules
A4: Executive result
A5: Board action is warranted on queue documentation, one confirmed billing overcharge, and six collection accounts. Source-population conflicts require targeted reconstruction before applicant relief is ordered.
A7: Audit metric | B7: Formula result | C7: Interpretation / basis
A8: In-period skips screened | B8: =COUNTA('Queue Exceptions'!B6:B314) | C8: All skip_events rows dated 2023-01-01 through 2026-07-31.
A9: Unique queue exception records | B9: =COUNTIF('Queue Exceptions'!I6:I314,"<>No exception identified in screening") | C9: 19 proof exceptions plus 5 length-instrument items, with one overlap.
A10: Contemporaneous-proof exceptions | B10: =COUNTIF('Queue Exceptions'!I6:I314,"*proof*") | C10: Standing Order 15-3 ss.3.2-3.3; includes three supplied cover-only PDFs.
A11: Length instruments not furnished | B11: =COUNTIF('Queue Exceptions'!I6:I314,"*length*") | C11: Five outcome-determinative post-2022-08-01 LOA amendments; absence from the supplied set is not conclusive proof the instrument never existed.
A12: Skips predating current application date | B12: =COUNTIF('Queue Exceptions'!K6:K314,"*Predates*") | C12: Reconcile against day logs and historical register snapshots before relief.
A13: Offer IDs absent from offer export | B13: =COUNTIF('Queue Exceptions'!K6:K314,"*Offer ID absent*") | C13: Five orphan records ending in OFR-*-1487.
A14: Confirmed billing discrepancies | B14: =COUNTIF('Billing Reconciliations'!M16:M16,"<>0") | C14: One covered-slip overbilling; no confirmed open-basin rate/length discrepancy.
A15: Monthly billing variance | B15: =SUM('Billing Reconciliations'!M16:M16) | C15: Observed less correct, pre-tax; positive is overbilling.
A16: Occupied slips missing August bill row | B16: ='Billing Reconciliations'!D12 | C16: Population gap only; dollar variance cannot be established without complete run and check-in records.
A17: Active accounts over 90 days | B17: =COUNTIF(Aging!L6:L11,">0") | C17: All qualifying accounts in the supplied July aging ledger.
A18: Balance more than 90 days | B18: =SUM(Aging!L6:L11) | C18: 91-120 plus 120+ buckets.
A19: Total due on those accounts | B19: =SUM(Aging!M6:M11) | C19: All aging buckets for the six qualifying accounts.
A21: Category disposition
A22: Queue / proof: exceptions identified - see historical-rank review order in Queue Exceptions.
A23: Queue / certified length: five named instruments were not furnished; no conclusive finding of physical absence can be made without the original applicant files.
A24: Billing / covered: one confirmed exception. Billing / open: no confirmed rate or length exception in the observed August rows.
A25: Aging / covered: six accounts over 90 days. Aging / open: none in the supplied aging ledger.
A27: Recommended Board sequence
A28: 1. Reconcile the five orphan offers and 124 chronology conflicts to day logs and historical register snapshots.
A29: 2. Review the 23 queue exception records in Queue Exceptions column A order; relief remains class- and preference-specific.
A30: 3. Where a skip lacks same-day support or a required signed length instrument, expunge it, preserve rank/date, and give the first next matching vacancy without displacing a good-faith assignee (Appeal 2018-3, p.3).
A31: 4. Correct VB-0208 prospectively and calculate/credit the pre-tax overcharge; obtain a complete August billing run for the 317-slip gap.
A32: 5. Proceed under collections policy on the six July-aging accounts and obtain a district-wide aging extract.
A34: Principal sources
A35: skip_events_2022_2026.csv; offer_events_2022_2026.csv; applicant_register_2026-08.csv; amendment_log_2022_2026.csv; six WL skip-justification PDFs; Standing Order 15-3; Resolution 2022-06; Tariff Resolution 2019-14; Appeal 2018-3; slip_inventory_2026-08.csv; billing_transactions_2022_2026.csv; 2024-09-09_moorage_agreement_VB-0208.pdf; 2024-06-03 and 2024-09-03 measurement certificates; ar_aging_2026-07-31.xlsx (AR_Aging).

Sheet Queue Exceptions
A1: Queue Exceptions
A2: Scope: all skips worked 2023-01-01 through 2026-07-31. All 309 records remain in this worksheet; the print view shows the 23 prioritized exceptions. A CSV 'Y' is an attachment claim, not independent proof of same-day assembly.
A3: Governing basis: Standing Order 15-3 ss.3.2-3.3; Resolution 2022-06 s.4.3; Appeal 2018-3, pp.2-3. The day log and file as they existed when worked control. WL-02211's 2022-09-14 skip is outside scope.
A5: Board Review Order | B5: Source / Skip | C5: Worked / Offer | D5: Applicant | E5: Priority / Current Record | F5: Vacancy | G5: Reason / Support Index | H5: Evidence Review | I5: Exception Category | J5: Amendment / Instrument | K5: Data Integrity Flag | L5: Board-Directed Next Step
A6: 1 | B6: CSV row 329 | SKP-2025-0328 | C6: 2025-10-11 | OFR-2025-1230 | D6: WL-01089 | Erin Holmes | E6: Rank 89 | current app 2022-05-19 | ACTIVE_WAITLIST | F6: SB-0115 / 24 ft | Salmonberry | G6: vessel-fit | N / REPAIR_ESTIMATE | H6: CSV says no attachment; original file not furnished | I6: Contemporaneous proof missing | L6: Retrieve day log/original file; if no same-day support, expunge skip and preserve rank for first next matching vacancy.
A7: 2 | B7: CSV row 220 | SKP-2024-0219 | C7: 2024-06-05 | OFR-2024-0789 | D7: WL-01144 | James Lopez | E7: Rank 144 | current app 2022-07-15 | ACTIVE_WAITLIST | F7: LP-0216 / 32 ft | Ledgport | G7: vessel-fit | N / WRITTEN_STATEMENT | H7: CSV says no attachment; original file not furnished | I7: Contemporaneous proof missing | L7: Retrieve day log/original file; if no same-day support, expunge skip and preserve rank for first next matching vacancy.
A8: 3 | B8: CSV row 348 | SKP-2026-0347 | C8: 2026-02-22 | OFR-2026-1299 | D8: WL-01550 | Brittany Grant | E8: Rank 550 | current app 2023-04-12 | ACTIVE_WAITLIST | F8: EW-1015 / 24 ft | Eastwey | G8: vessel-fit | Y / OTHER_SUPPORT | H8: CSV says attachment present; underlying file not individually furnished | I8: Length instrument not furnished | J8: AMD-001204 (2024-07-01; 44.2 to 43.0 ft; amendment CSV row 1205); named source: Foldview haul-out sheet dated 2024-02-12 | L8: Produce the named signed instrument; if absent when amendment/skip was entered, disregard amended LOA and grant prospective rank-preserving relief.
A9: 4 | B9: CSV row 100 | SKP-2023-0099 | C9: 2023-01-10 | OFR-2023-0338 | D9: WL-01695 | Antonio Leach | E9: Rank 695 | current app 2023-07-03 | ACTIVE_WAITLIST | F9: EW-0203 / 28 ft | Eastwey | G9: vessel-fit | N / INSURANCE_DECL | H9: CSV says no attachment; original file not furnished | I9: Contemporaneous proof missing | K9: Predates current application date | L9: Retrieve day log/original file; if no same-day support, expunge skip and preserve rank for first next matching vacancy.
A10: 5 | B10: CSV row 132 | SKP-2023-0131 | C10: 2023-06-15 | OFR-2023-0448 | D10: WL-01781 | Crystal Parrish | E10: Rank 781 | current app 2023-08-22 | EXPIRED | F10: LP-0220 / 28 ft | Ledgport | G10: preference-mismatch | N / OTHER_SUPPORT | H10: CSV says no attachment; original file not furnished | I10: Contemporaneous proof missing | K10: Predates current application date | L10: Retrieve day log/original file; if no same-day support, expunge skip and preserve rank for first next matching vacancy.
A11: 6 | B11: CSV row 385 | SKP-2026-0384 | C11: 2026-06-22 | OFR-2026-1402 | D11: WL-01936 | Deanna Livingston | E11: Rank 936 | current app 2023-11-04 | ACTIVE_WAITLIST | F11: VB-0507 / 40 ft | Vessbank | G11: not-current | N / WRITTEN_STATEMENT | H11: CSV says no attachment; original file not furnished | I11: Contemporaneous proof missing | L11: Retrieve day log/original file; if no same-day support, expunge skip and preserve rank for first next matching vacancy.
A12: 7 | B12: CSV row 205 | SKP-2024-0204 | C12: 2024-04-02 | OFR-2024-0704 | D12: WL-01950 | Mathew Trujillo | E12: Rank 950 | current app 2023-11-09 | ACTIVE_WAITLIST | F12: EW-0608 / 28 ft | Eastwey | G12: vessel-fit | N / OTHER_SUPPORT | H12: CSV says no attachment; original file not furnished | I12: Contemporaneous proof missing | L12: Retrieve day log/original file; if no same-day support, expunge skip and preserve rank for first next matching vacancy.
A13: 8 | B13: CSV row 363 | SKP-2026-0362 | C13: 2026-04-13 | OFR-2026-1344 | D13: WL-02120 | Jerry Reyes | E13: Rank 1120 | current app 2024-01-31 | ACTIVE_WAITLIST | F13: LP-0312 / 24 ft | Ledgport | G13: vessel-fit | Y / INSURANCE_DECL | H13: CSV says attachment present; underlying file not individually furnished | I13: Length instrument not furnished | J13: AMD-000380 (2022-10-17; 43.5 to 42.6 ft; amendment CSV row 381); named source: MC-2022-0916 | L13: Produce the named signed instrument; if absent when amendment/skip was entered, disregard amended LOA and grant prospective rank-preserving relief.
A14: 9 | B14: CSV row 321 | SKP-2025-0320 | C14: 2025-09-09 | OFR-2025-1201 | D14: WL-02167 | Jonathan Anderson | E14: Rank 1167 | current app 2024-02-23 | ACTIVE_WAITLIST | F14: VB-0304 / 32 ft | Vessbank | G14: vessel-fit | Y / OTHER_SUPPORT | H14: CSV says attachment present; underlying file not individually furnished | I14: Length instrument not furnished | J14: AMD-001109 (2024-04-13; 34.8 to 34.9 ft; amendment CSV row 1110); named source: MC-2024-0712 | L14: Produce the named signed instrument; if absent when amendment/skip was entered, disregard amended LOA and grant prospective rank-preserving relief.
A15: 10 | B15: CSV row 175 | SKP-2023-0174 | C15: 2023-09-11 | OFR-2023-0578 | D15: WL-02285 | Brian Scott | E15: Rank 1285 | current app 2024-04-22 | ACTIVE_WAITLIST | F15: EW-0107 / 28 ft | Eastwey | G15: declined-prior-offer | N / WRITTEN_STATEMENT | H15: CSV says no attachment; original file not furnished | I15: Contemporaneous proof missing | K15: Predates current application date | L15: Retrieve day log/original file; if no same-day support, expunge skip and preserve rank for first next matching vacancy.
A16: 11 | B16: CSV row 293 | SKP-2025-0292 | C16: 2025-07-06 | OFR-2025-1117 | D16: WL-02298 | Ronald Simpson | E16: Rank 1298 | current app 2024-04-25 | ACTIVE_WAITLIST | F16: GW-1017 / 32 ft | Gullwing | G16: vessel-fit | N / REPAIR_ESTIMATE | H16: CSV says no attachment; original file not furnished | I16: Contemporaneous proof missing | L16: Retrieve day log/original file; if no same-day support, expunge skip and preserve rank for first next matching vacancy.
A17: 12 | B17: CSV row 250 | SKP-2024-0249 | C17: 2024-11-17 | OFR-2024-0930 | D17: WL-02598 | Nicole Rubio | E17: Rank 1598 | current app 2024-09-07 | ACTIVE_WAITLIST | F17: GW-0902 / 36 ft | Gullwing | G17: vessel-fit | N / INSURANCE_DECL | H17: CSV says no attachment; original file not furnished | I17: Contemporaneous proof missing | L17: Retrieve day log/original file; if no same-day support, expunge skip and preserve rank for first next matching vacancy.
A18: 13 | B18: CSV row 409 | SKP-2023-0408 | C18: 2023-05-02 | OFR-2023-1487 | D18: WL-02618 | Gary Tomlinson | E18: Rank 1618 | current app 2024-09-17 | RETAINER | F18: GW-0610 / 32 ft | Gullwing | G18: vessel-fit | N / blank | H18: Cover sheet only - confirmed; WL-02618 PDF p.1: cover only | I18: Contemporaneous proof missing | K18: Predates current application date; Offer ID absent from offer export | L18: Retrieve day log/original file; if no same-day support, expunge skip and preserve rank for first next matching vacancy.
A19: 14 | B19: CSV row 310 | SKP-2025-0309 | C19: 2025-08-28 | OFR-2025-1167 | D19: WL-02838 | Kimberly Griffin | E19: Rank 1838 | current app 2024-12-18 | ACTIVE_WAITLIST | F19: LP-0413 / 28 ft | Ledgport | G19: declined-prior-offer | N / WRITTEN_STATEMENT | H19: CSV says no attachment; original file not furnished | I19: Contemporaneous proof missing | L19: Retrieve day log/original file; if no same-day support, expunge skip and preserve rank for first next matching vacancy.
A20: 15 | B20: CSV row 208 | SKP-2024-0207 | C20: 2024-04-21 | OFR-2024-0729 | D20: WL-02948 | Michael Salinas | E20: Rank 1948 | current app 2025-02-01 | ACTIVE_WAITLIST | F20: GW-1013 / 60 ft | Gullwing | G20: vessel-fit | N / INSURANCE_DECL | H20: CSV says no attachment; original file not furnished | I20: Contemporaneous proof missing | K20: Predates current application date | L20: Retrieve day log/original file; if no same-day support, expunge skip and preserve rank for first next matching vacancy.
A21: 16 | B21: CSV row 410 | SKP-2024-0409 | C21: 2024-02-20 | OFR-2024-1487 | D21: WL-03044 | Iris Quan | E21: Rank 2044 | current app 2025-03-14 | ACTIVE_WAITLIST | F21: VB-0904 / 28 ft | Vessbank | G21: preference-mismatch | N / blank | H21: Cover sheet only - confirmed; WL-03044 PDF p.1: cover only | I21: Contemporaneous proof missing | K21: Predates current application date; Offer ID absent from offer export | L21: Retrieve day log/original file; if no same-day support, expunge skip and preserve rank for first next matching vacancy.
A22: 17 | B22: CSV row 344 | SKP-2026-0343 | C22: 2026-01-01 | OFR-2026-1285 | D22: WL-03054 | Amanda Schmidt | E22: Rank 2054 | current app 2025-03-18 | ACTIVE_WAITLIST | F22: VB-0224 / 28 ft | Vessbank | G22: vessel-fit | N / OTHER_SUPPORT | H22: CSV says no attachment; original file not furnished | I22: Both: proof missing; length instrument not furnished | J22: AMD-000288 (2022-08-09; 46.9 to 45.3 ft; amendment CSV row 289); named source: MC-2022-0411 | L22: Retrieve day log/file and signed instrument; if either was absent when worked, expunge skip and preserve rank for first next matching vacancy.
A23: 18 | B23: CSV row 298 | SKP-2025-0297 | C23: 2025-07-28 | OFR-2025-1129 | D23: WL-03094 | Christine Cook | E23: Rank 2094 | current app 2025-04-06 | ACTIVE_WAITLIST | F23: GW-0103 / 45 ft | Gullwing | G23: not-current | N / REPAIR_ESTIMATE | H23: CSV says no attachment; original file not furnished | I23: Contemporaneous proof missing | L23: Retrieve day log/original file; if no same-day support, expunge skip and preserve rank for first next matching vacancy.
A24: 19 | B24: CSV row 411 | SKP-2024-0410 | C24: 2024-11-05 | OFR-2024-1487 | D24: WL-03390 | Phillip Ard | E24: Rank 2390 | current app 2025-08-19 | RETAINER | F24: SB-0120 / 40 ft | Salmonberry | G24: declined-prior-offer | N / blank | H24: Cover sheet only - confirmed; WL-03390 PDF p.1: cover only | I24: Contemporaneous proof missing | K24: Predates current application date; Offer ID absent from offer export | L24: Retrieve day log/original file; if no same-day support, expunge skip and preserve rank for first next matching vacancy.
A25: 20 | B25: CSV row 332 | SKP-2025-0331 | C25: 2025-10-07 | OFR-2025-1246 | D25: WL-03455 | Taylor George | E25: Rank 2455 | current app 2025-09-25 | ACTIVE_WAITLIST | F25: SB-0402 / 32 ft | Salmonberry | G25: vessel-fit | Y / OTHER_SUPPORT | H25: CSV says attachment present; underlying file not individually furnished | I25: Length instrument not furnished | J25: AMD-000691 (2023-06-08; 36.5 to 39.0 ft; amendment CSV row 692); named source: MC-2023-0192 | L25: Produce the named signed instrument; if absent when amendment/skip was entered, disregard amended LOA and grant prospective rank-preserving relief.
A26: 21 | B26: CSV row 105 | SKP-2023-0104 | C26: 2023-03-15 | OFR-2023-0360 | D26: WL-03523 | Darlene Glover | E26: Rank 2523 | current app 2025-11-02 | ACTIVE_WAITLIST | F26: SB-0210 / 24 ft | Salmonberry | G26: vessel-fit | N / WRITTEN_STATEMENT | H26: CSV says no attachment; original file not furnished | I26: Contemporaneous proof missing | K26: Predates current application date | L26: Retrieve day log/original file; if no same-day support, expunge skip and preserve rank for first next matching vacancy.
A27: 22 | B27: CSV row 167 | SKP-2023-0166 | C27: 2023-09-16 | OFR-2023-0551 | D27: WL-03844 | Janet Medina | E27: Rank 2844 | current app 2026-05-17 | RETAINER | F27: EW-0109 / 60 ft | Eastwey | G27: vessel-fit | N / OTHER_SUPPORT | H27: CSV says no attachment; original file not furnished | I27: Contemporaneous proof missing | K27: Predates current application date | L27: Retrieve day log/original file; if no same-day support, expunge skip and preserve rank for first next matching vacancy.
A28: 23 | B28: CSV row 372 | SKP-2026-0371 | C28: 2026-05-08 | OFR-2026-1363 | D28: WL-03896 | Stephen Hammond | E28: Rank 2896 | current app 2026-07-05 | ACTIVE_WAITLIST | F28: LP-0220 / 28 ft | Ledgport | G28: vessel-fit | N / WRITTEN_STATEMENT | H28: CSV says no attachment; original file not furnished | I28: Contemporaneous proof missing | K28: Predates current application date | L28: Retrieve day log/original file; if no same-day support, expunge skip and preserve rank for first next matching vacancy.
B29: CSV row 96 | SKP-2023-0095 | C29: 2023-01-08 | OFR-2023-0323 | D29: WL-03099 | Ryan Robertson | E29: Rank 2099 | current app 2025-04-08 | ACTIVE_WAITLIST | F29: LP-0317 / 40 ft | Ledgport | G29: vessel-fit | Y / OTHER_SUPPORT | H29: CSV says attachment present; underlying file not individually furnished | I29: No exception identified in screening | K29: Predates current application date | L29: No Board remedy recommended from supplied screening record; retain file for source-population reconciliation.
B30: CSV row 97 | SKP-2023-0096 | C30: 2023-01-08 | OFR-2023-0324 | D30: WL-02685 | Stephanie Hill | E30: Rank 1685 | current app 2024-10-13 | ACTIVE_WAITLIST | F30: LP-0906 / 28 ft | Ledgport | G30: vessel-fit | Y / INSURANCE_DECL | H30: CSV says attachment present; underlying file not individually furnished | I30: No exception identified in screening | K30: Predates current application date | L30: No Board remedy recommended from supplied screening record; retain file for source-population reconciliation.
B31: CSV row 99 | SKP-2023-0098 | C31: 2023-01-08 | OFR-2023-0334 | D31: WL-01959 | Jonathan Moore | E31: Rank 959 | current app 2023-11-14 | ACTIVE_WAITLIST | F31: VB-1023 / 28 ft | Vessbank | G31: not-current | Y / WRITTEN_STATEMENT | H31: CSV says attachment present; underlying file not individually furnished | I31: No exception identified in screening | K31: Predates current application date | L31: No Board remedy recommended from supplied screening record; retain file for source-population reconciliation.
B32: CSV row 98 | SKP-2023-0097 | C32: 2023-01-26 | OFR-2023-0326 | D32: WL-01298 | Jason Boyd | E32: Rank 298 | current app 2022-11-17 | ACTIVE_WAITLIST | F32: GW-0708 / 70 ft | Gullwing | G32: vessel-fit | Y / OTHER_SUPPORT | H32: CSV says attachment present; underlying file not individually furnished | I32: No exception identified in screening | L32: No Board remedy recommended from supplied screening record; retain file for source-population reconciliation.
B33: CSV row 103 | SKP-2023-0102 | C33: 2023-02-10 | OFR-2023-0346 | D33: WL-03582 | Melissa Jones | E33: Rank 2582 | current app 2025-12-04 | ACTIVE_WAITLIST | F33: GW-0615 / 24 ft | Gullwing | G33: not-current | Y / INSURANCE_DECL | H33: CSV says attachment present; underlying file not individually furnished | I33: No exception identified in screening | K33: Predates current application date | L33: No Board remedy recommended from supplied screening record; retain file for source-population reconciliation.
B34: CSV row 104 | SKP-2023-0103 | C34: 2023-02-17 | OFR-2023-0350 | D34: WL-02918 | Kara Aguilar | E34: Rank 1918 | current app 2025-01-16 | EXPIRED | F34: LP-1116 / 28 ft | Ledgport | G34: declined-prior-offer | Y / OTHER_SUPPORT | H34: CSV says attachment present; underlying file not individually furnished | I34: No exception identified in screening | K34: Predates current application date | L34: No Board remedy recommended from supplied screening record; retain file for source-population reconciliation.
B35: CSV row 101 | SKP-2023-0100 | C35: 2023-02-18 | OFR-2023-0343 | D35: WL-02565 | Christina Smith | E35: Rank 1565 | current app 2024-08-26 | RETAINER | F35: GW-0116 / 32 ft | Gullwing | G35: vessel-fit | Y / REPAIR_ESTIMATE | H35: CSV says attachment present; underlying file not individually furnished | I35: No exception identified in screening | K35: Predates current application date | L35: No Board remedy recommended from supplied screening record; retain file for source-population reconciliation.
B36: CSV row 102 | SKP-2023-0101 | C36: 2023-02-19 | OFR-2023-0345 | D36: WL-02664 | Mark Smith | E36: Rank 1664 | current app 2024-10-04 | ACTIVE_WAITLIST | F36: GW-0220 / 60 ft | Gullwing | G36: preference-mismatch | Y / WRITTEN_STATEMENT | H36: CSV says attachment present; underlying file not individually furnished | I36: No exception identified in screening | K36: Predates current application date | L36: No Board remedy recommended from supplied screening record; retain file for source-population reconciliation.
B37: CSV row 106 | SKP-2023-0105 | C37: 2023-03-06 | OFR-2023-0361 | D37: WL-02366 | Megan Hoffman | E37: Rank 1366 | current app 2024-05-22 | SUSPENDED | F37: LP-1116 / 28 ft | Ledgport | G37: vessel-fit | Y / WRITTEN_STATEMENT | H37: CSV says attachment present; underlying file not individually furnished | I37: No exception identified in screening | K37: Predates current application date | L37: No Board remedy recommended from supplied screening record; retain file for source-population reconciliation.
B38: CSV row 108 | SKP-2023-0107 | C38: 2023-03-10 | OFR-2023-0368 | D38: WL-01984 | Vanessa Jackson | E38: Rank 984 | current app 2023-11-27 | ACTIVE_WAITLIST | F38: GW-0606 / 60 ft | Gullwing | G38: declined-prior-offer | Y / WRITTEN_STATEMENT | H38: CSV says attachment present; underlying file not individually furnished | I38: No exception identified in screening | K38: Predates current application date | L38: No Board remedy recommended from supplied screening record; retain file for source-population reconciliation.
B39: CSV row 109 | SKP-2023-0108 | C39: 2023-03-21 | OFR-2023-0370 | D39: WL-01649 | Amy Krueger | E39: Rank 649 | current app 2023-06-11 | ACTIVE_WAITLIST | F39: VB-0717 / 32 ft | Vessbank | G39: vessel-fit | Y / REPAIR_ESTIMATE | H39: CSV says attachment present; underlying file not individually furnished | I39: No exception identified in screening | K39: Predates current application date | L39: No Board remedy recommended from supplied screening record; retain file for source-population reconciliation.
B40: CSV row 110 | SKP-2023-0109 | C40: 2023-03-25 | OFR-2023-0371 | D40: WL-03535 | Allison Castro | E40: Rank 2535 | current app 2025-11-08 | RETAINER | F40: GW-0101 / 24 ft | Gullwing | G40: vessel-fit | Y / OTHER_SUPPORT | H40: CSV says attachment present; underlying file not individually furnished | I40: No exception identified in screening | K40: Predates current application date | L40: No Board remedy recommended from supplied screening record; retain file for source-population reconciliation.
B41: CSV row 107 | SKP-2023-0106 | C41: 2023-03-27 | OFR-2023-0364 | D41: WL-01388 | Sharon Young | E41: Rank 388 | current app 2023-01-07 | ACTIVE_WAITLIST | F41: SB-0617 / 36 ft | Salmonberry | G41: vessel-fit | Y / REPAIR_ESTIMATE | H41: CSV says attachment present; underlying file not individually furnished | I41: No exception identified in screening | L41: No Board remedy recommended from supplied screening record; retain file for source-population reconciliation.
...

Sheet Billing Reconciliations
A1: Billing Reconciliations
A2: Rates effective 2022-08-01: $10.40/foot-month covered; $7.55/foot-month open. Billable feet are the greater of posted slip length and check-in LOA rounded up. Positive variance means overbilling.
A3: Authority: Resolution 2022-06 ss.1.1-2.1 and Tariff Resolution 2019-14 ss.1.4, 2.4, 7.3. Charges shown pre-tax.
A5: August 2026 population control
A6: Basin | B6: Occupied Inventory | C6: August Moorage Accounts | D6: Difference | E6: Control Result
A7: Ledgport | B7: 241 | C7: 241 | D7: =B7-C7 | E7: =IF(D7=0,"Reconciled","Gap; dollar variance unavailable")
A8: Vessbank | B8: 227 | C8: 227 | D8: =B8-C8 | E8: =IF(D8=0,"Reconciled","Gap; dollar variance unavailable")
A9: Eastwey | B9: 215 | C9: 215 | D9: =B9-C9 | E9: =IF(D9=0,"Reconciled","Gap; dollar variance unavailable")
A10: Gullwing | B10: 213 | C10: 86 | D10: =B10-C10 | E10: =IF(D10=0,"Reconciled","Gap; dollar variance unavailable")
A11: Salmonberry | B11: 190 | C11: 0 | D11: =B11-C11 | E11: =IF(D11=0,"Reconciled","Gap; dollar variance unavailable")
A12: Formula total | B12: =SUM(B7:B11) | C12: =SUM(C7:C11) | D12: =SUM(D7:D11) | E12: =IF(D12=0,"Reconciled","Source files required")
A14: Confirmed customer-level discrepancy
A15: Exception ID | B15: Slip | C15: Account | D15: Governing Customer Record | E15: Class | F15: Nominal Slip Ft | G15: Certified Check-in LOA | H15: Correct Billable Ft | I15: Observed Billed Ft | J15: Rate / Ft-Month | K15: Observed Monthly Charge | L15: Correct Monthly Charge | M15: Monthly Variance | N15: First Affected Month | O15: Through Month | P15: Affected Months
A16: BR-001 | B16: VB-0208 | C16: AC-VB-0208 | D16: Laura T. Beesley / MARBLE WING | E16: Covered | F16: 32 | G16: 31.4 | H16: =MAX(F16,ROUNDUP(G16,0)) | I16: 40 | J16: 10.4 | K16: =I16*J16 | L16: =H16*J16 | M16: =K16-L16 | N16: 45566 | O16: 46235 | P16: =(YEAR(O16)-YEAR(N16))*12+MONTH(O16)-MONTH(N16)+1
A17: Formula total | L17: =SUM(L16:L16) | M17: =SUM(M16:M16) | P17: =SUM(P16:P16)
L18: Cumulative pre-tax variance | M18: =M16*P16
A19: Open-basin result | B19: =IF(COUNTIFS(E16:E16,"Open",M16:M16,"<>0")=0,"No confirmed open-basin rate or length exceptions in the observed August billing population.","See discrepancy rows.")
A21: Source and authority: billing_transactions_2022_2026.csv rows 21665, 22756, 23876, 24962, 26053, 27178, 28293, 29384, 30487, 31593, 32728, 33852, 34970, 36117, 37221, 38345, 39453, 40569, 41691, 42805, 43884, 44987, 46091; 2024-09-09_moorage_agreement_VB-0208.pdf p.1; 2024-06-03_measurement_certificate_WL-01893.pdf p.1.
A22: Record conflict: slip_inventory_2026-08.csv row 293 reports VB-0208 as 40 ft and Cameron Foster/WL-03499. The signed agreement identifies a 32-ft covered slip and Laura Beesley; the certificate matches Laura, vessel, HIN, and 31.4-ft LOA. The specific signed records govern absent a later executed reassignment.
A23: Population limitation: 317 occupied Gullwing/Salmonberry slips lack an August MONTHLY_MOORAGE row (formula control above). No customer-level dollar variance is stated because the complete billing run, agreements, and check-in measurements were not furnished.

Sheet Aging
A1: Aging
A2: Active slips with balances more than 90 days delinquent as of 2026-08-01. Basis: 91-120 plus 120+ buckets in the 2026-07-31 aging ledger. Formula totals are pre-tax ledger balances.
A3: The July aging ledger governs this point-in-time test. Six accounts qualify; all are occupied Ledgport slips. No qualifying open-basin account appears in the supplied ledger.
A5: Account | B5: Customer | C5: Applicant ID | D5: Slip | E5: Basin | F5: Rate Class | G5: Current | H5: 31-60 | I5: 61-90 | J5: 91-120 | K5: 120+ | L5: Over 90 | M5: Total Due | N5: Ledger Status | O5: Aging Row | P5: Inventory Row
A6: AC-LP-0122 | B6: Paula Arroyo | C6: WL-01974 | D6: LP-0122 | E6: Ledgport | F6: NON_COMM_MONTHLY | G6: 509.6 | H6: 509.6 | I6: 509.6 | J6: 509.6 | K6: 0 | L6: =SUM(J6:K6) | M6: =SUM(G6:K6) | N6: COLLECTIONS | O6: 23 | P6: 23
A7: AC-LP-0402 | B7: Dawn Brown | C7: WL-01188 | D7: LP-0402 | E7: Ledgport | F7: NON_COMM_MONTHLY | G7: 384.8 | H7: 384.8 | I7: 384.8 | J7: 384.8 | K7: 0 | L7: =SUM(J7:K7) | M7: =SUM(G7:K7) | N7: COLLECTIONS | O7: 68 | P7: 75
A8: AC-LP-0602 | B8: Lee Maldonado | C8: WL-01342 | D8: LP-0602 | E8: Ledgport | F8: NON_COMM_MONTHLY | G8: 603.2 | H8: 603.2 | I8: 603.2 | J8: 603.2 | K8: 603.2 | L8: =SUM(J8:K8) | M8: =SUM(G8:K8) | N8: COLLECTIONS | O8: 113 | P8: 123
A9: AC-LP-0605 | B9: Andrew Anderson | C9: WL-01747 | D9: LP-0605 | E9: Ledgport | F9: NON_COMM_MONTHLY | G9: 530.4 | H9: 530.4 | I9: 530.4 | J9: 530.4 | K9: 0 | L9: =SUM(J9:K9) | M9: =SUM(G9:K9) | N9: COLLECTIONS | O9: 116 | P9: 126
A10: AC-LP-0713 | B10: Stacey Mitchell | C10: WL-03438 | D10: LP-0713 | E10: Ledgport | F10: NON_COMM_MONTHLY | G10: 416 | H10: 416 | I10: 416 | J10: 416 | K10: 832 | L10: =SUM(J10:K10) | M10: =SUM(G10:K10) | N10: COLLECTIONS | O10: 147 | P10: 158
A11: AC-LP-0801 | B11: Allison Nguyen | C11: WL-02322 | D11: LP-0801 | E11: Ledgport | F11: NON_COMM_MONTHLY | G11: 488.8 | H11: 488.8 | I11: 488.8 | J11: 488.8 | K11: 0 | L11: =SUM(J11:K11) | M11: =SUM(G11:K11) | N11: COLLECTIONS | O11: 158 | P11: 170
A12: Formula total | G12: =SUM(G6:G11) | H12: =SUM(H6:H11) | I12: =SUM(I6:I11) | J12: =SUM(J6:J11) | K12: =SUM(K6:K11) | L12: =SUM(L6:L11) | M12: =SUM(M6:M11)
A14: Sources: ar_aging_2026-07-31.xlsx, AR_Aging rows shown; slip_inventory_2026-08.csv rows shown. The billing transaction export marks July invoices paid, but the specifically requested July 31 aging ledger is the controlling receivables record.
A15: Coverage limitation: the supplied aging ledger has 260 accounts, compared with 1,086 occupied inventory slips. These are all qualifying accounts in that ledger, not proof that no other District account is over 90 days.
