Workbook

Sheet Summary of Findings
A1: Summary of Findings
A2: Board-focused moorage audit as of 2026-08-01 | collection, billing, queue integrity, and aging.
A3: Calculated from the workbook analysis sheets. Dollar amounts are pre-tax where labeled; receivables are from ar_aging_2026-07-31.xlsx. See Parameters & Sources for authority and limitations.
A5: Billing and Revenue
A6: Occupied slips | B6: =ROWS('Billing Reconciliation'!$A$6:$A$1091) | D6: August 2026 occupied population from slip inventory.
A7: Posted charges matching tariff | B7: =COUNTIF('Billing Reconciliation'!$S$6:$S$1091,"MATCH") | D7: Every posted August moorage line matched billable feet x applicable rate.
A8: Missing August charges | B8: =COUNTIF('Billing Reconciliation'!$S$6:$S$1091,"MISSING CHARGE") | D8: All omissions are occupied open-basin slips; invoice before collection.
A9: Expected August moorage | B9: =SUM('Billing Reconciliation'!$M$6:$M$1091) | D9: Pre-tax recurring moorage; electricity excluded.
A10: Actually posted | B10: =SUM('Billing Reconciliation'!$Q$6:$Q$1091) | D10: 2026-08-01 MONTHLY_MOORAGE transaction amount.
A11: Unbilled pre-tax amount | B11: =-SUM('Billing Reconciliation'!$R$6:$R$1091) | D11: Expected less posted; not yet an overdue receivable.
A12: Covered assignments over 40 ft | B12: =COUNTIF('Billing Reconciliation'!$T$6:$T$1091,"BOARD REVIEW*") | D12: Separate eligibility control; posted billing arithmetic remains correct.
A14: Receivables and Collection
A15: All active overdue accounts | B15: =ROWS('Aging Report'!$A$6:$A$53) | D15: Nonzero 31+ bucket and occupied status confirmed.
A16: All 31+ overdue balance | B16: =SUM('Aging Report'!$M$6:$M$53) | D16: Sum of 31-60, 61-90, 91-120, and 120+ buckets; excludes current.
A17: Priority accounts with 91+ | B17: =COUNTIF('Aging Report'!$R$6:$R$53,"COLLECT - 91+") | D17: All are Active/Occupied by the August slip inventory.
A18: Priority 91+ balance | B18: =SUMIF('Aging Report'!$R$6:$R$53,"COLLECT - 91+",'Aging Report'!$N$6:$N$53) | D18: Exactly the 91-120 plus 120+ buckets for the six priority accounts.
A19: Priority accounts: all 31+ overdue | B19: =SUMIF('Aging Report'!$R$6:$R$53,"COLLECT - 91+",'Aging Report'!$M$6:$M$53) | D19: Collection balance excluding current charges.
A20: Priority accounts: full balance | B20: =SUMIF('Aging Report'!$R$6:$R$53,"COLLECT - 91+",'Aging Report'!$J$6:$J$53) | D20: Includes current charges; do not describe this full balance as overdue.
A21: Source total_due understatement | B21: =-SUM('Src_Aging'!$Q$6:$Q$265) | D21: Bucket recomputation exceeds the source total_due column across affected rows.
A23: Queue and Amendment Integrity
A24: Skips in requested period | B24: =ROWS('Skip Review'!$A$6:$A$314) | D24: 2023-01-01 through 2026-07-31 inclusive.
A25: In-period PDFs supplied | B25: =COUNTIF('Skip Review'!$J$6:$J$314,"Y") | D25: Five of six named skip PDFs fall in the period; WL-02211 is pre-window.
A26: Cover-sheet-only failures | B26: =COUNTIF('Skip Review'!$S$6:$S$314,"FAIL - COVER SHEET ONLY") | D26: Standing Order 15-3 s.3.2 says a cover sheet is insufficient.
A27: Support present / integrity exceptions | B27: =COUNTIF('Skip Review'!$S$6:$S$314,"EXCEPTION*") | D27: Supporting record exists, but event-to-file fields or offer linkage fail.
A28: PDFs not supplied for testing | B28: =COUNTIF('Skip Review'!$S$6:$S$314,"NOT INDEPENDENTLY VERIFIED*") | D28: A limitation, not proof that those files fail.
A29: Post-adoption LOA amendments | B29: =ROWS('Amendment Review'!$A$6:$A$205) | D29: Entered after 2022-08-01 through the audit cutoff.
A30: LOA entries with no source cited | B30: =COUNTIF('Amendment Review'!$K$6:$K$205,"FAIL*") | D30: Definite register cross-reference failures under Resolution 2022-06 s.4.3.
A31: Independently verified amendment | B31: =COUNTIF('Amendment Review'!$K$6:$K$205,"PASS*") | D31: AMD-001288 / WL-02401 is supported by supplied MC-2024-0091.
A32: Referenced only - not verified | B32: =COUNTIF('Amendment Review'!$K$6:$K$205,"REGISTER REFERENCE ONLY*")+COUNTIF('Amendment Review'!$K$6:$K$205,"BOARD REVIEW*") | D32: Cites an accepted document type, but the underlying file was not supplied for independent testing.
A34: Board Direction
A35: 1. Post and control-check the missing August open-basin invoice batch before treating the unbilled amount as collectible.
A36: 2. Pursue the six 91+ occupied accounts using the Aging Report; distinguish the 91+ portion, all 31+ overdue, and current amounts.
A37: 3. Freeze reliance on the five tested skip exceptions and reconstruct the offer and justification trail before further rank-order action.
A38: 4. Correct the AR total_due logic, retrieve support for uncited LOA amendments, and validate covered assignments over the 40 ft limit.

Sheet Queue Exceptions
A1: Queue Exceptions Requiring Board Attention
A2: Action queue: billing omissions, ledger controls, skip integrity, and unsupported post-adoption LOA amendments.
A3: Sources are named in each row. Financial exposure is formula-derived from the Billing Reconciliation and Aging Report; blank exposure denotes a governance/control issue rather than a quantified receivable.
A5: Priority | B5: Area | C5: Record / Population | D5: Applicant / Account | E5: Exception | F5: Financial Exposure $ | G5: Board Action | H5: Source
A6: 1 - Immediate | B6: Billing | C6: =COUNTIF('Billing Reconciliation'!$S$6:$S$1091,"MISSING CHARGE")&" occupied open slips" | D6: See Billing Reconciliation | E6: No 2026-08-01 monthly moorage transaction; charges must be posted before collection. | F6: =-SUMIF('Billing Reconciliation'!$S$6:$S$1091,"MISSING CHARGE",'Billing Reconciliation'!$R$6:$R$1091) | G6: Direct Finance to post and validate the omitted open-basin invoice batch before notices issue. | H6: slip_inventory_2026-08.csv; billing_transactions_2022_2026.csv
A7: 1 - Immediate | B7: A/R control | C7: =COUNTIF('Src_Aging'!$Q$6:$Q$265,"<>0")&" aging rows" | D7: See Src_Aging | E7: Source total_due does not equal the sum of its aging buckets; the source column understates the bucket recomputation. | F7: =-SUM('Src_Aging'!$Q$6:$Q$265) | G7: Rebuild the total_due formula and reconcile the subledger before relying on account totals. | H7: ar_aging_2026-07-31.xlsx, AR_Aging and Summary sheets
A8: 1 - Immediate | B8: Collections | C8: =COUNTIF('Aging Report'!$R$6:$R$53,"COLLECT - 91+")&" occupied accounts with 91+" | D8: See Aging Report | E8: 91-120 and 120+ balances require collection; inventory confirms all six are occupied. | F8: =SUMIF('Aging Report'!$R$6:$R$53,"COLLECT - 91+",'Aging Report'!$N$6:$N$53) | G8: Approve the six-account priority collection list and apply existing payment-plan/legal policy. | H8: ar_aging_2026-07-31.xlsx; slip_inventory_2026-08.csv
A9: 1 - Immediate | B9: Skip integrity | C9: SKP-2023-0408 | D9: WL-02618 | E9: Cover sheet only; event GW-0610/Gullwing differs from PDF EW-0414/Eastwey; offer link OFR-2023-1487 is missing. | G9: Suspend reliance on the skip for rank-order decisions; reconstruct the offer/file trail and determine remedy under Appeal 2018-3. | H9: skip_events row SKP-2023-0408; WL-02618_skip_justification.pdf; offer_events export
A10: 1 - Immediate | B10: Skip integrity | C10: SKP-2024-0409 | D10: WL-03044 | E10: Cover sheet only; event VB-0904/Vessbank differs from PDF EW-0603/Eastwey; offer link OFR-2024-1487 is missing. | G10: Suspend reliance on the skip for rank-order decisions; reconstruct the offer/file trail and determine remedy under Appeal 2018-3. | H10: skip_events row SKP-2024-0409; WL-03044_skip_justification.pdf; offer_events export
A11: 1 - Immediate | B11: Skip integrity | C11: SKP-2024-0410 | D11: WL-03390 | E11: Cover sheet only; event SB-0120/Salmonberry differs from PDF VB-0144/Vessbank; offer link OFR-2024-1487 is missing. | G11: Suspend reliance on the skip for rank-order decisions; reconstruct the offer/file trail and determine remedy under Appeal 2018-3. | H11: skip_events row SKP-2024-0410; WL-03390_skip_justification.pdf; offer_events export
A12: 2 - High | B12: Skip integrity | C12: SKP-2024-0411 | D12: WL-02877 | E12: Supporting register printout exists, but event GW-1012 differs from PDF GW-0702 and event document type says REPAIR_ESTIMATE; offer link is missing. | G12: Suspend reliance on the skip for rank-order decisions; reconstruct the offer/file trail and determine remedy under Appeal 2018-3. | H12: skip_events row SKP-2024-0411; WL-02877_skip_justification.pdf; offer_events export
A13: 2 - High | B13: Skip integrity | C13: SKP-2025-0412 | D13: WL-03102 | E13: Preference sheet exists, but event LP-0806 differs from PDF EW-0620; offer link is missing. The file cites a yard sheet not supplied separately. | G13: Suspend reliance on the skip for rank-order decisions; reconstruct the offer/file trail and determine remedy under Appeal 2018-3. | H13: skip_events row SKP-2025-0412; WL-03102_skip_justification.pdf; offer_events export
A14: 2 - High | B14: LOA amendment | C14: AMD-000338 | D14: WL-03600 | E14: LOA changed 51.4 ft to 49.0 ft with no source document cross-reference. | G14: Do not use the amended LOA for an offer, skip, slip class, or rate until compliant support is filed and reviewed. | H14: amendment_log row AMD-000338; Resolution 2022-06 s.4.3
A15: 2 - High | B15: LOA amendment | C15: AMD-000646 | D15: WL-02496 | E15: LOA changed 24.2 ft to 24.3 ft with no source document cross-reference. | G15: Do not use the amended LOA for an offer, skip, slip class, or rate until compliant support is filed and reviewed. | H15: amendment_log row AMD-000646; Resolution 2022-06 s.4.3
A16: 2 - High | B16: LOA amendment | C16: AMD-000808 | D16: WL-03319 | E16: LOA changed 38.6 ft to 37.8 ft with no source document cross-reference. | G16: Do not use the amended LOA for an offer, skip, slip class, or rate until compliant support is filed and reviewed. | H16: amendment_log row AMD-000808; Resolution 2022-06 s.4.3
A17: 2 - High | B17: LOA amendment | C17: AMD-001092 | D17: WL-01999 | E17: LOA changed 22.8 ft to 19.9 ft with no source document cross-reference. | G17: Do not use the amended LOA for an offer, skip, slip class, or rate until compliant support is filed and reviewed. | H17: amendment_log row AMD-001092; Resolution 2022-06 s.4.3
A18: 2 - High | B18: LOA amendment | C18: AMD-001453 | D18: WL-03650 | E18: LOA changed 49.2 ft to 47.5 ft with no source document cross-reference. | G18: Do not use the amended LOA for an offer, skip, slip class, or rate until compliant support is filed and reviewed. | H18: amendment_log row AMD-001453; Resolution 2022-06 s.4.3
A19: 2 - High | B19: LOA amendment | C19: AMD-001826 | D19: WL-01845 | E19: LOA changed 54.2 ft to 53.2 ft with no source document cross-reference. | G19: Do not use the amended LOA for an offer, skip, slip class, or rate until compliant support is filed and reviewed. | H19: amendment_log row AMD-001826; Resolution 2022-06 s.4.3
A20: 2 - High | B20: LOA amendment | C20: AMD-001859 | D20: WL-02085 | E20: LOA changed 48.6 ft to 49.0 ft with no source document cross-reference. | G20: Do not use the amended LOA for an offer, skip, slip class, or rate until compliant support is filed and reviewed. | H20: amendment_log row AMD-001859; Resolution 2022-06 s.4.3
... A26: 2 - High | B26: LOA downstream use | C26: AMD-001702 / SKP-2025-0412 | D26: WL-03102 | E26: The 35.8 ft amendment is cited in the later preference-mismatch skip file; the yard sheet itself is not supplied and the skip event/file slips disagree. | G26: Retrieve the 2025-06-29 yard measurement sheet and re-review the downstream skip before further rank-order action. | H26: amendment_log AMD-001702; WL-03102_skip_justification.pdf pp.1-3; skip_events SKP-2025-0412
A27: 3 - Control | B27: Evidence completeness | C27: =COUNTIF('Skip Review'!$S$6:$S$314,"NOT INDEPENDENTLY VERIFIED*")&" of "&ROWS('Skip Review'!$A$6:$A$314)&" skips" | D27: Period population | E27: No justification PDF was supplied for independent content testing; register attachment flags alone do not establish what each file contains. | G27: Order a records-completeness pull for the untested files; do not infer failure solely from absence in this audit packet. | H27: skip_events_2022_2026.csv; supplied skip PDF set; Standing Order 15-3 ss.3.2-3.3
A28: 3 - Control | B28: Covered eligibility | C28: =COUNTIF('Billing Reconciliation'!$T$6:$T$1091,"BOARD REVIEW*")&" occupied covered slips" | D28: See Billing Reconciliation | E28: Formula-derived billable length exceeds the 40 ft covered-basin limit; August charges nevertheless match the tariff calculation. | G28: Direct Harbor Operations to validate check-in measurements and assignment eligibility; keep billing collection separate from eligibility review. | H28: slip_inventory_2026-08.csv; Resolution 2022-06 s.1.1

Sheet Billing Reconciliation
A1: Billing Reconciliation
A2: August 2026 occupied slips: expected recurring moorage versus the 2026-08-01 invoice run.
A3: Sources: slip_inventory_2026-08.csv and billing_transactions_2022_2026.csv (MONTHLY_MOORAGE posted 2026-08-01). Formula basis: MAX(ROUNDUP(roster LOA,0), nominal slip length) x Resolution 2022-06 rate. Pre-tax; electricity excluded.
A5: Slip ID | B5: Basin | C5: Basin Type | D5: Account ID | E5: Tenant ID | F5: Tenant | G5: Vessel | H5: Roster LOA ft | I5: Rounded LOA | J5: Nominal Slip ft | K5: Billable ft | L5: Rate $/ft-month | M5: Expected Pre-tax $ | N5: Actual Txn Count | O5: Actual Billed ft | P5: Actual Rate | Q5: Actual Pre-tax $ | R5: Variance $ | S5: Reconciliation | T5: Covered-Limit Review | U5: Source
A6: ='Src_Inventory'!A6 | B6: ='Src_Inventory'!B6 | C6: ='Src_Inventory'!G6 | D6: ="AC-"&A6 | E6: ='Src_Inventory'!L6 | F6: ='Src_Inventory'!M6 | G6: ='Src_Inventory'!N6 | H6: ='Src_Inventory'!O6 | I6: =ROUNDUP(H6,0) | J6: ='Src_Inventory'!E6 | K6: =MAX(I6,J6) | L6: =IF(C6="COVERED",'Parameters & Sources'!$B$11,'Parameters & Sources'!$B$12) | M6: =K6*L6 | N6: =COUNTIFS('Src_Billing_Aug'!$E$6:$E$774,A6,'Src_Billing_Aug'!$D$6:$D$774,E6) | O6: =IF(N6=0,"",SUMIFS('Src_Billing_Aug'!$I$6:$I$774,'Src_Billing_Aug'!$E$6:$E$774,A6,'Src_Billing_Aug'!$D$6:$D$774,E6)) | P6: =IF(N6=0,"",SUMIFS('Src_Billing_Aug'!$L$6:$L$774,'Src_Billing_Aug'!$E$6:$E$774,A6,'Src_Billing_Aug'!$D$6:$D$774,E6)) | Q6: =SUMIFS('Src_Billing_Aug'!$M$6:$M$774,'Src_Billing_Aug'!$E$6:$E$774,A6,'Src_Billing_Aug'!$D$6:$D$774,E6) | R6: =Q6-M6 | S6: =IF(N6=0,"MISSING CHARGE",IF(N6>1,"DUPLICATE CHARGE",IF(ABS(R6)<0.005,"MATCH","VARIANCE"))) | T6: =IF(AND(C6="COVERED",K6>'Parameters & Sources'!$B$13),"BOARD REVIEW - OVER 40 FT","") | U6: slip_inventory_2026-08.csv; billing_transactions_2022_2026.csv
A7: ='Src_Inventory'!A7 | B7: ='Src_Inventory'!B7 | C7: ='Src_Inventory'!G7 | D7: ="AC-"&A7 | E7: ='Src_Inventory'!L7 | F7: ='Src_Inventory'!M7 | G7: ='Src_Inventory'!N7 | H7: ='Src_Inventory'!O7 | I7: =ROUNDUP(H7,0) | J7: ='Src_Inventory'!E7 | K7: =MAX(I7,J7) | L7: =IF(C7="COVERED",'Parameters & Sources'!$B$11,'Parameters & Sources'!$B$12) | M7: =K7*L7 | N7: =COUNTIFS('Src_Billing_Aug'!$E$6:$E$774,A7,'Src_Billing_Aug'!$D$6:$D$774,E7) | O7: =IF(N7=0,"",SUMIFS('Src_Billing_Aug'!$I$6:$I$774,'Src_Billing_Aug'!$E$6:$E$774,A7,'Src_Billing_Aug'!$D$6:$D$774,E7)) | P7: =IF(N7=0,"",SUMIFS('Src_Billing_Aug'!$L$6:$L$774,'Src_Billing_Aug'!$E$6:$E$774,A7,'Src_Billing_Aug'!$D$6:$D$774,E7)) | Q7: =SUMIFS('Src_Billing_Aug'!$M$6:$M$774,'Src_Billing_Aug'!$E$6:$E$774,A7,'Src_Billing_Aug'!$D$6:$D$774,E7) | R7: =Q7-M7 | S7: =IF(N7=0,"MISSING CHARGE",IF(N7>1,"DUPLICATE CHARGE",IF(ABS(R7)<0.005,"MATCH","VARIANCE"))) | T7: =IF(AND(C7="COVERED",K7>'Parameters & Sources'!$B$13),"BOARD REVIEW - OVER 40 FT","") | U7: slip_inventory_2026-08.csv; billing_transactions_2022_2026.csv
A8: ='Src_Inventory'!A8 | B8: ='Src_Inventory'!B8 | C8: ='Src_Inventory'!G8 | D8: ="AC-"&A8 | E8: ='Src_Inventory'!L8 | F8: ='Src_Inventory'!M8 | G8: ='Src_Inventory'!N8 | H8: ='Src_Inventory'!O8 | I8: =ROUNDUP(H8,0) | J8: ='Src_Inventory'!E8 | K8: =MAX(I8,J8) | L8: =IF(C8="COVERED",'Parameters & Sources'!$B$11,'Parameters & Sources'!$B$12) | M8: =K8*L8 | N8: =COUNTIFS('Src_Billing_Aug'!$E$6:$E$774,A8,'Src_Billing_Aug'!$D$6:$D$774,E8) | O8: =IF(N8=0,"",SUMIFS('Src_Billing_Aug'!$I$6:$I$774,'Src_Billing_Aug'!$E$6:$E$774,A8,'Src_Billing_Aug'!$D$6:$D$774,E8)) | P8: =IF(N8=0,"",SUMIFS('Src_Billing_Aug'!$L$6:$L$774,'Src_Billing_Aug'!$E$6:$E$774,A8,'Src_Billing_Aug'!$D$6:$D$774,E8)) | Q8: =SUMIFS('Src_Billing_Aug'!$M$6:$M$774,'Src_Billing_Aug'!$E$6:$E$774,A8,'Src_Billing_Aug'!$D$6:$D$774,E8) | R8: =Q8-M8 | S8: =IF(N8=0,"MISSING CHARGE",IF(N8>1,"DUPLICATE CHARGE",IF(ABS(R8)<0.005,"MATCH","VARIANCE"))) | T8: =IF(AND(C8="COVERED",K8>'Parameters & Sources'!$B$13),"BOARD REVIEW - OVER 40 FT","") | U8: slip_inventory_2026-08.csv; billing_transactions_2022_2026.csv
A9: ='Src_Inventory'!A9 | B9: ='Src_Inventory'!B9 | C9: ='Src_Inventory'!G9 | D9: ="AC-"&A9 | E9: ='Src_Inventory'!L9 | F9: ='Src_Inventory'!M9 | G9: ='Src_Inventory'!N9 | H9: ='Src_Inventory'!O9 | I9: =ROUNDUP(H9,0) | J9: ='Src_Inventory'!E9 | K9: =MAX(I9,J9) | L9: =IF(C9="COVERED",'Parameters & Sources'!$B$11,'Parameters & Sources'!$B$12) | M9: =K9*L9 | N9: =COUNTIFS('Src_Billing_Aug'!$E$6:$E$774,A9,'Src_Billing_Aug'!$D$6:$D$774,E9) | O9: =IF(N9=0,"",SUMIFS('Src_Billing_Aug'!$I$6:$I$774,'Src_Billing_Aug'!$E$6:$E$774,A9,'Src_Billing_Aug'!$D$6:$D$774,E9)) | P9: =IF(N9=0,"",SUMIFS('Src_Billing_Aug'!$L$6:$L$774,'Src_Billing_Aug'!$E$6:$E$774,A9,'Src_Billing_Aug'!$D$6:$D$774,E9)) | Q9: =SUMIFS('Src_Billing_Aug'!$M$6:$M$774,'Src_Billing_Aug'!$E$6:$E$774,A9,'Src_Billing_Aug'!$D$6:$D$774,E9) | R9: =Q9-M9 | S9: =IF(N9=0,"MISSING CHARGE",IF(N9>1,"DUPLICATE CHARGE",IF(ABS(R9)<0.005,"MATCH","VARIANCE"))) | T9: =IF(AND(C9="COVERED",K9>'Parameters & Sources'!$B$13),"BOARD REVIEW - OVER 40 FT","") | U9: slip_inventory_2026-08.csv; billing_transactions_2022_2026.csv
A10: ='Src_Inventory'!A10 | B10: ='Src_Inventory'!B10 | C10: ='Src_Inventory'!G10 | D10: ="AC-"&A10 | E10: ='Src_Inventory'!L10 | F10: ='Src_Inventory'!M10 | G10: ='Src_Inventory'!N10 | H10: ='Src_Inventory'!O10 | I10: =ROUNDUP(H10,0) | J10: ='Src_Inventory'!E10 | K10: =MAX(I10,J10) | L10: =IF(C10="COVERED",'Parameters & Sources'!$B$11,'Parameters & Sources'!$B$12) | M10: =K10*L10 | N10: =COUNTIFS('Src_Billing_Aug'!$E$6:$E$774,A10,'Src_Billing_Aug'!$D$6:$D$774,E10) | O10: =IF(N10=0,"",SUMIFS('Src_Billing_Aug'!$I$6:$I$774,'Src_Billing_Aug'!$E$6:$E$774,A10,'Src_Billing_Aug'!$D$6:$D$774,E10)) | P10: =IF(N10=0,"",SUMIFS('Src_Billing_Aug'!$L$6:$L$774,'Src_Billing_Aug'!$E$6:$E$774,A10,'Src_Billing_Aug'!$D$6:$D$774,E10)) | Q10: =SUMIFS('Src_Billing_Aug'!$M$6:$M$774,'Src_Billing_Aug'!$E$6:$E$774,A10,'Src_Billing_Aug'!$D$6:$D$774,E10) | R10: =Q10-M10 | S10: =IF(N10=0,"MISSING CHARGE",IF(N10>1,"DUPLICATE CHARGE",IF(ABS(R10)<0.005,"MATCH","VARIANCE"))) | T10: =IF(AND(C10="COVERED",K10>'Parameters & Sources'!$B$13),"BOARD REVIEW - OVER 40 FT","") | U10: slip_inventory_2026-08.csv; billing_transactions_2022_2026.csv
A11: ='Src_Inventory'!A11 | B11: ='Src_Inventory'!B11 | C11: ='Src_Inventory'!G11 | D11: ="AC-"&A11 | E11: ='Src_Inventory'!L11 | F11: ='Src_Inventory'!M11 | G11: ='Src_Inventory'!N11 | H11: ='Src_Inventory'!O11 | I11: =ROUNDUP(H11,0) | J11: ='Src_Inventory'!E11 | K11: =MAX(I11,J11) | L11: =IF(C11="COVERED",'Parameters & Sources'!$B$11,'Parameters & Sources'!$B$12) | M11: =K11*L11 | N11: =COUNTIFS('Src_Billing_Aug'!$E$6:$E$774,A11,'Src_Billing_Aug'!$D$6:$D$774,E11) | O11: =IF(N11=0,"",SUMIFS('Src_Billing_Aug'!$I$6:$I$774,'Src_Billing_Aug'!$E$6:$E$774,A11,'Src_Billing_Aug'!$D$6:$D$774,E11)) | P11: =IF(N11=0,"",SUMIFS('Src_Billing_Aug'!$L$6:$L$774,'Src_Billing_Aug'!$E$6:$E$774,A11,'Src_Billing_Aug'!$D$6:$D$774,E11)) | Q11: =SUMIFS('Src_Billing_Aug'!$M$6:$M$774,'Src_Billing_Aug'!$E$6:$E$774,A11,'Src_Billing_Aug'!$D$6:$D$774,E11) | R11: =Q11-M11 | S11: =IF(N11=0,"MISSING CHARGE",IF(N11>1,"DUPLICATE CHARGE",IF(ABS(R11)<0.005,"MATCH","VARIANCE"))) | T11: =IF(AND(C11="COVERED",K11>'Parameters & Sources'!$B$13),"BOARD REVIEW - OVER 40 FT","") | U11: slip_inventory_2026-08.csv; billing_transactions_2022_2026.csv
A12: ='Src_Inventory'!A12 | B12: ='Src_Inventory'!B12 | C12: ='Src_Inventory'!G12 | D12: ="AC-"&A12 | E12: ='Src_Inventory'!L12 | F12: ='Src_Inventory'!M12 | G12: ='Src_Inventory'!N12 | H12: ='Src_Inventory'!O12 | I12: =ROUNDUP(H12,0) | J12: ='Src_Inventory'!E12 | K12: =MAX(I12,J12) | L12: =IF(C12="COVERED",'Parameters & Sources'!$B$11,'Parameters & Sources'!$B$12) | M12: =K12*L12 | N12: =COUNTIFS('Src_Billing_Aug'!$E$6:$E$774,A12,'Src_Billing_Aug'!$D$6:$D$774,E12) | O12: =IF(N12=0,"",SUMIFS('Src_Billing_Aug'!$I$6:$I$774,'Src_Billing_Aug'!$E$6:$E$774,A12,'Src_Billing_Aug'!$D$6:$D$774,E12)) | P12: =IF(N12=0,"",SUMIFS('Src_Billing_Aug'!$L$6:$L$774,'Src_Billing_Aug'!$E$6:$E$774,A12,'Src_Billing_Aug'!$D$6:$D$774,E12)) | Q12: =SUMIFS('Src_Billing_Aug'!$M$6:$M$774,'Src_Billing_Aug'!$E$6:$E$774,A12,'Src_Billing_Aug'!$D$6:$D$774,E12) | R12: =Q12-M12 | S12: =IF(N12=0,"MISSING CHARGE",IF(N12>1,"DUPLICATE CHARGE",IF(ABS(R12)<0.005,"MATCH","VARIANCE"))) | T12: =IF(AND(C12="COVERED",K12>'Parameters & Sources'!$B$13),"BOARD REVIEW - OVER 40 FT","") | U12: slip_inventory_2026-08.csv; billing_transactions_2022_2026.csv
A13: ='Src_Inventory'!A13 | B13: ='Src_Inventory'!B13 | C13: ='Src_Inventory'!G13 | D13: ="AC-"&A13 | E13: ='Src_Inventory'!L13 | F13: ='Src_Inventory'!M13 | G13: ='Src_Inventory'!N13 | H13: ='Src_Inventory'!O13 | I13: =ROUNDUP(H13,0) | J13: ='Src_Inventory'!E13 | K13: =MAX(I13,J13) | L13: =IF(C13="COVERED",'Parameters & Sources'!$B$11,'Parameters & Sources'!$B$12) | M13: =K13*L13 | N13: =COUNTIFS('Src_Billing_Aug'!$E$6:$E$774,A13,'Src_Billing_Aug'!$D$6:$D$774,E13) | O13: =IF(N13=0,"",SUMIFS('Src_Billing_Aug'!$I$6:$I$774,'Src_Billing_Aug'!$E$6:$E$774,A13,'Src_Billing_Aug'!$D$6:$D$774,E13)) | P13: =IF(N13=0,"",SUMIFS('Src_Billing_Aug'!$L$6:$L$774,'Src_Billing_Aug'!$E$6:$E$774,A13,'Src_Billing_Aug'!$D$6:$D$774,E13)) | Q13: =SUMIFS('Src_Billing_Aug'!$M$6:$M$774,'Src_Billing_Aug'!$E$6:$E$774,A13,'Src_Billing_Aug'!$D$6:$D$774,E13) | R13: =Q13-M13 | S13: =IF(N13=0,"MISSING CHARGE",IF(N13>1,"DUPLICATE CHARGE",IF(ABS(R13)<0.005,"MATCH","VARIANCE"))) | T13: =IF(AND(C13="COVERED",K13>'Parameters & Sources'!$B$13),"BOARD REVIEW - OVER 40 FT","") | U13: slip_inventory_2026-08.csv; billing_transactions_2022_2026.csv
A14: ='Src_Inventory'!A14 | B14: ='Src_Inventory'!B14 | C14: ='Src_Inventory'!G14 | D14: ="AC-"&A14 | E14: ='Src_Inventory'!L14 | F14: ='Src_Inventory'!M14 | G14: ='Src_Inventory'!N14 | H14: ='Src_Inventory'!O14 | I14: =ROUNDUP(H14,0) | J14: ='Src_Inventory'!E14 | K14: =MAX(I14,J14) | L14: =IF(C14="COVERED",'Parameters & Sources'!$B$11,'Parameters & Sources'!$B$12) | M14: =K14*L14 | N14: =COUNTIFS('Src_Billing_Aug'!$E$6:$E$774,A14,'Src_Billing_Aug'!$D$6:$D$774,E14) | O14: =IF(N14=0,"",SUMIFS('Src_Billing_Aug'!$I$6:$I$774,'Src_Billing_Aug'!$E$6:$E$774,A14,'Src_Billing_Aug'!$D$6:$D$774,E14)) | P14: =IF(N14=0,"",SUMIFS('Src_Billing_Aug'!$L$6:$L$774,'Src_Billing_Aug'!$E$6:$E$774,A14,'Src_Billing_Aug'!$D$6:$D$774,E14)) | Q14: =SUMIFS('Src_Billing_Aug'!$M$6:$M$774,'Src_Billing_Aug'!$E$6:$E$774,A14,'Src_Billing_Aug'!$D$6:$D$774,E14) | R14: =Q14-M14 | S14: =IF(N14=0,"MISSING CHARGE",IF(N14>1,"DUPLICATE CHARGE",IF(ABS(R14)<0.005,"MATCH","VARIANCE"))) | T14: =IF(AND(C14="COVERED",K14>'Parameters & Sources'!$B$13),"BOARD REVIEW - OVER 40 FT","") | U14: slip_inventory_2026-08.csv; billing_transactions_2022_2026.csv
A15: ='Src_Inventory'!A15 | B15: ='Src_Inventory'!B15 | C15: ='Src_Inventory'!G15 | D15: ="AC-"&A15 | E15: ='Src_Inventory'!L15 | F15: ='Src_Inventory'!M15 | G15: ='Src_Inventory'!N15 | H15: ='Src_Inventory'!O15 | I15: =ROUNDUP(H15,0) | J15: ='Src_Inventory'!E15 | K15: =MAX(I15,J15) | L15: =IF(C15="COVERED",'Parameters & Sources'!$B$11,'Parameters & Sources'!$B$12) | M15: =K15*L15 | N15: =COUNTIFS('Src_Billing_Aug'!$E$6:$E$774,A15,'Src_Billing_Aug'!$D$6:$D$774,E15) | O15: =IF(N15=0,"",SUMIFS('Src_Billing_Aug'!$I$6:$I$774,'Src_Billing_Aug'!$E$6:$E$774,A15,'Src_Billing_Aug'!$D$6:$D$774,E15)) | P15: =IF(N15=0,"",SUMIFS('Src_Billing_Aug'!$L$6:$L$774,'Src_Billing_Aug'!$E$6:$E$774,A15,'Src_Billing_Aug'!$D$6:$D$774,E15)) | Q15: =SUMIFS('Src_Billing_Aug'!$M$6:$M$774,'Src_Billing_Aug'!$E$6:$E$774,A15,'Src_Billing_Aug'!$D$6:$D$774,E15) | R15: =Q15-M15 | S15: =IF(N15=0,"MISSING CHARGE",IF(N15>1,"DUPLICATE CHARGE",IF(ABS(R15)<0.005,"MATCH","VARIANCE"))) | T15: =IF(AND(C15="COVERED",K15>'Parameters & Sources'!$B$13),"BOARD REVIEW - OVER 40 FT","") | U15: slip_inventory_2026-08.csv; billing_transactions_2022_2026.csv
A16: ='Src_Inventory'!A16 | B16: ='Src_Inventory'!B16 | C16: ='Src_Inventory'!G16 | D16: ="AC-"&A16 | E16: ='Src_Inventory'!L16 | F16: ='Src_Inventory'!M16 | G16: ='Src_Inventory'!N16 | H16: ='Src_Inventory'!O16 | I16: =ROUNDUP(H16,0) | J16: ='Src_Inventory'!E16 | K16: =MAX(I16,J16) | L16: =IF(C16="COVERED",'Parameters & Sources'!$B$11,'Parameters & Sources'!$B$12) | M16: =K16*L16 | N16: =COUNTIFS('Src_Billing_Aug'!$E$6:$E$774,A16,'Src_Billing_Aug'!$D$6:$D$774,E16) | O16: =IF(N16=0,"",SUMIFS('Src_Billing_Aug'!$I$6:$I$774,'Src_Billing_Aug'!$E$6:$E$774,A16,'Src_Billing_Aug'!$D$6:$D$774,E16)) | P16: =IF(N16=0,"",SUMIFS('Src_Billing_Aug'!$L$6:$L$774,'Src_Billing_Aug'!$E$6:$E$774,A16,'Src_Billing_Aug'!$D$6:$D$774,E16)) | Q16: =SUMIFS('Src_Billing_Aug'!$M$6:$M$774,'Src_Billing_Aug'!$E$6:$E$774,A16,'Src_Billing_Aug'!$D$6:$D$774,E16) | R16: =Q16-M16 | S16: =IF(N16=0,"MISSING CHARGE",IF(N16>1,"DUPLICATE CHARGE",IF(ABS(R16)<0.005,"MATCH","VARIANCE"))) | T16: =IF(AND(C16="COVERED",K16>'Parameters & Sources'!$B$13),"BOARD REVIEW - OVER 40 FT","") | U16: slip_inventory_2026-08.csv; billing_transactions_2022_2026.csv
A17: ='Src_Inventory'!A18 | B17: ='Src_Inventory'!B18 | C17: ='Src_Inventory'!G18 | D17: ="AC-"&A17 | E17: ='Src_Inventory'!L18 | F17: ='Src_Inventory'!M18 | G17: ='Src_Inventory'!N18 | H17: ='Src_Inventory'!O18 | I17: =ROUNDUP(H17,0) | J17: ='Src_Inventory'!E18 | K17: =MAX(I17,J17) | L17: =IF(C17="COVERED",'Parameters & Sources'!$B$11,'Parameters & Sources'!$B$12) | M17: =K17*L17 | N17: =COUNTIFS('Src_Billing_Aug'!$E$6:$E$774,A17,'Src_Billing_Aug'!$D$6:$D$774,E17) | O17: =IF(N17=0,"",SUMIFS('Src_Billing_Aug'!$I$6:$I$774,'Src_Billing_Aug'!$E$6:$E$774,A17,'Src_Billing_Aug'!$D$6:$D$774,E17)) | P17: =IF(N17=0,"",SUMIFS('Src_Billing_Aug'!$L$6:$L$774,'Src_Billing_Aug'!$E$6:$E$774,A17,'Src_Billing_Aug'!$D$6:$D$774,E17)) | Q17: =SUMIFS('Src_Billing_Aug'!$M$6:$M$774,'Src_Billing_Aug'!$E$6:$E$774,A17,'Src_Billing_Aug'!$D$6:$D$774,E17) | R17: =Q17-M17 | S17: =IF(N17=0,"MISSING CHARGE",IF(N17>1,"DUPLICATE CHARGE",IF(ABS(R17)<0.005,"MATCH","VARIANCE"))) | T17: =IF(AND(C17="COVERED",K17>'Parameters & Sources'!$B$13),"BOARD REVIEW - OVER 40 FT","") | U17: slip_inventory_2026-08.csv; billing_transactions_2022_2026.csv
A18: ='Src_Inventory'!A19 | B18: ='Src_Inventory'!B19 | C18: ='Src_Inventory'!G19 | D18: ="AC-"&A18 | E18: ='Src_Inventory'!L19 | F18: ='Src_Inventory'!M19 | G18: ='Src_Inventory'!N19 | H18: ='Src_Inventory'!O19 | I18: =ROUNDUP(H18,0) | J18: ='Src_Inventory'!E19 | K18: =MAX(I18,J18) | L18: =IF(C18="COVERED",'Parameters & Sources'!$B$11,'Parameters & Sources'!$B$12) | M18: =K18*L18 | N18: =COUNTIFS('Src_Billing_Aug'!$E$6:$E$774,A18,'Src_Billing_Aug'!$D$6:$D$774,E18) | O18: =IF(N18=0,"",SUMIFS('Src_Billing_Aug'!$I$6:$I$774,'Src_Billing_Aug'!$E$6:$E$774,A18,'Src_Billing_Aug'!$D$6:$D$774,E18)) | P18: =IF(N18=0,"",SUMIFS('Src_Billing_Aug'!$L$6:$L$774,'Src_Billing_Aug'!$E$6:$E$774,A18,'Src_Billing_Aug'!$D$6:$D$774,E18)) | Q18: =SUMIFS('Src_Billing_Aug'!$M$6:$M$774,'Src_Billing_Aug'!$E$6:$E$774,A18,'Src_Billing_Aug'!$D$6:$D$774,E18) | R18: =Q18-M18 | S18: =IF(N18=0,"MISSING CHARGE",IF(N18>1,"DUPLICATE CHARGE",IF(ABS(R18)<0.005,"MATCH","VARIANCE"))) | T18: =IF(AND(C18="COVERED",K18>'Parameters & Sources'!$B$13),"BOARD REVIEW - OVER 40 FT","") | U18: slip_inventory_2026-08.csv; billing_transactions_2022_2026.csv
A19: ='Src_Inventory'!A20 | B19: ='Src_Inventory'!B20 | C19: ='Src_Inventory'!G20 | D19: ="AC-"&A19 | E19: ='Src_Inventory'!L20 | F19: ='Src_Inventory'!M20 | G19: ='Src_Inventory'!N20 | H19: ='Src_Inventory'!O20 | I19: =ROUNDUP(H19,0) | J19: ='Src_Inventory'!E20 | K19: =MAX(I19,J19) | L19: =IF(C19="COVERED",'Parameters & Sources'!$B$11,'Parameters & Sources'!$B$12) | M19: =K19*L19 | N19: =COUNTIFS('Src_Billing_Aug'!$E$6:$E$774,A19,'Src_Billing_Aug'!$D$6:$D$774,E19) | O19: =IF(N19=0,"",SUMIFS('Src_Billing_Aug'!$I$6:$I$774,'Src_Billing_Aug'!$E$6:$E$774,A19,'Src_Billing_Aug'!$D$6:$D$774,E19)) | P19: =IF(N19=0,"",SUMIFS('Src_Billing_Aug'!$L$6:$L$774,'Src_Billing_Aug'!$E$6:$E$774,A19,'Src_Billing_Aug'!$D$6:$D$774,E19)) | Q19: =SUMIFS('Src_Billing_Aug'!$M$6:$M$774,'Src_Billing_Aug'!$E$6:$E$774,A19,'Src_Billing_Aug'!$D$6:$D$774,E19) | R19: =Q19-M19 | S19: =IF(N19=0,"MISSING CHARGE",IF(N19>1,"DUPLICATE CHARGE",IF(ABS(R19)<0.005,"MATCH","VARIANCE"))) | T19: =IF(AND(C19="COVERED",K19>'Parameters & Sources'!$B$13),"BOARD REVIEW - OVER 40 FT","") | U19: slip_inventory_2026-08.csv; billing_transactions_2022_2026.csv
A20: ='Src_Inventory'!A21 | B20: ='Src_Inventory'!B21 | C20: ='Src_Inventory'!G21 | D20: ="AC-"&A20 | E20: ='Src_Inventory'!L21 | F20: ='Src_Inventory'!M21 | G20: ='Src_Inventory'!N21 | H20: ='Src_Inventory'!O21 | I20: =ROUNDUP(H20,0) | J20: ='Src_Inventory'!E21 | K20: =MAX(I20,J20) | L20: =IF(C20="COVERED",'Parameters & Sources'!$B$11,'Parameters & Sources'!$B$12) | M20: =K20*L20 | N20: =COUNTIFS('Src_Billing_Aug'!$E$6:$E$774,A20,'Src_Billing_Aug'!$D$6:$D$774,E20) | O20: =IF(N20=0,"",SUMIFS('Src_Billing_Aug'!$I$6:$I$774,'Src_Billing_Aug'!$E$6:$E$774,A20,'Src_Billing_Aug'!$D$6:$D$774,E20)) | P20: =IF(N20=0,"",SUMIFS('Src_Billing_Aug'!$L$6:$L$774,'Src_Billing_Aug'!$E$6:$E$774,A20,'Src_Billing_Aug'!$D$6:$D$774,E20)) | Q20: =SUMIFS('Src_Billing_Aug'!$M$6:$M$774,'Src_Billing_Aug'!$E$6:$E$774,A20,'Src_Billing_Aug'!$D$6:$D$774,E20) | R20: =Q20-M20 | S20: =IF(N20=0,"MISSING CHARGE",IF(N20>1,"DUPLICATE CHARGE",IF(ABS(R20)<0.005,"MATCH","VARIANCE"))) | T20: =IF(AND(C20="COVERED",K20>'Parameters & Sources'!$B$13),"BOARD REVIEW - OVER 40 FT","") | U20: slip_inventory_2026-08.csv; billing_transactions_2022_2026.csv
A21: ='Src_Inventory'!A22 | B21: ='Src_Inventory'!B22 | C21: ='Src_Inventory'!G22 | D21: ="AC-"&A21 | E21: ='Src_Inventory'!L22 | F21: ='Src_Inventory'!M22 | G21: ='Src_Inventory'!N22 | H21: ='Src_Inventory'!O22 | I21: =ROUNDUP(H21,0) | J21: ='Src_Inventory'!E22 | K21: =MAX(I21,J21) | L21: =IF(C21="COVERED",'Parameters & Sources'!$B$11,'Parameters & Sources'!$B$12) | M21: =K21*L21 | N21: =COUNTIFS('Src_Billing_Aug'!$E$6:$E$774,A21,'Src_Billing_Aug'!$D$6:$D$774,E21) | O21: =IF(N21=0,"",SUMIFS('Src_Billing_Aug'!$I$6:$I$774,'Src_Billing_Aug'!$E$6:$E$774,A21,'Src_Billing_Aug'!$D$6:$D$774,E21)) | P21: =IF(N21=0,"",SUMIFS('Src_Billing_Aug'!$L$6:$L$774,'Src_Billing_Aug'!$E$6:$E$774,A21,'Src_Billing_Aug'!$D$6:$D$774,E21)) | Q21: =SUMIFS('Src_Billing_Aug'!$M$6:$M$774,'Src_Billing_Aug'!$E$6:$E$774,A21,'Src_Billing_Aug'!$D$6:$D$774,E21) | R21: =Q21-M21 | S21: =IF(N21=0,"MISSING CHARGE",IF(N21>1,"DUPLICATE CHARGE",IF(ABS(R21)<0.005,"MATCH","VARIANCE"))) | T21: =IF(AND(C21="COVERED",K21>'Parameters & Sources'!$B$13),"BOARD REVIEW - OVER 40 FT","") | U21: slip_inventory_2026-08.csv; billing_transactions_2022_2026.csv
A22: ='Src_Inventory'!A23 | B22: ='Src_Inventory'!B23 | C22: ='Src_Inventory'!G23 | D22: ="AC-"&A22 | E22: ='Src_Inventory'!L23 | F22: ='Src_Inventory'!M23 | G22: ='Src_Inventory'!N23 | H22: ='Src_Inventory'!O23 | I22: =ROUNDUP(H22,0) | J22: ='Src_Inventory'!E23 | K22: =MAX(I22,J22) | L22: =IF(C22="COVERED",'Parameters & Sources'!$B$11,'Parameters & Sources'!$B$12) | M22: =K22*L22 | N22: =COUNTIFS('Src_Billing_Aug'!$E$6:$E$774,A22,'Src_Billing_Aug'!$D$6:$D$774,E22) | O22: =IF(N22=0,"",SUMIFS('Src_Billing_Aug'!$I$6:$I$774,'Src_Billing_Aug'!$E$6:$E$774,A22,'Src_Billing_Aug'!$D$6:$D$774,E22)) | P22: =IF(N22=0,"",SUMIFS('Src_Billing_Aug'!$L$6:$L$774,'Src_Billing_Aug'!$E$6:$E$774,A22,'Src_Billing_Aug'!$D$6:$D$774,E22)) | Q22: =SUMIFS('Src_Billing_Aug'!$M$6:$M$774,'Src_Billing_Aug'!$E$6:$E$774,A22,'Src_Billing_Aug'!$D$6:$D$774,E22) | R22: =Q22-M22 | S22: =IF(N22=0,"MISSING CHARGE",IF(N22>1,"DUPLICATE CHARGE",IF(ABS(R22)<0.005,"MATCH","VARIANCE"))) | T22: =IF(AND(C22="COVERED",K22>'Parameters & Sources'!$B$13),"BOARD REVIEW - OVER 40 FT","") | U22: slip_inventory_2026-08.csv; billing_transactions_2022_2026.csv
A23: ='Src_Inventory'!A24 | B23: ='Src_Inventory'!B24 | C23: ='Src_Inventory'!G24 | D23: ="AC-"&A23 | E23: ='Src_Inventory'!L24 | F23: ='Src_Inventory'!M24 | G23: ='Src_Inventory'!N24 | H23: ='Src_Inventory'!O24 | I23: =ROUNDUP(H23,0) | J23: ='Src_Inventory'!E24 | K23: =MAX(I23,J23) | L23: =IF(C23="COVERED",'Parameters & Sources'!$B$11,'Parameters & Sources'!$B$12) | M23: =K23*L23 | N23: =COUNTIFS('Src_Billing_Aug'!$E$6:$E$774,A23,'Src_Billing_Aug'!$D$6:$D$774,E23) | O23: =IF(N23=0,"",SUMIFS('Src_Billing_Aug'!$I$6:$I$774,'Src_Billing_Aug'!$E$6:$E$774,A23,'Src_Billing_Aug'!$D$6:$D$774,E23)) | P23: =IF(N23=0,"",SUMIFS('Src_Billing_Aug'!$L$6:$L$774,'Src_Billing_Aug'!$E$6:$E$774,A23,'Src_Billing_Aug'!$D$6:$D$774,E23)) | Q23: =SUMIFS('Src_Billing_Aug'!$M$6:$M$774,'Src_Billing_Aug'!$E$6:$E$774,A23,'Src_Billing_Aug'!$D$6:$D$774,E23) | R23: =Q23-M23 | S23: =IF(N23=0,"MISSING CHARGE",IF(N23>1,"DUPLICATE CHARGE",IF(ABS(R23)<0.005,"MATCH","VARIANCE"))) | T23: =IF(AND(C23="COVERED",K23>'Parameters & Sources'!$B$13),"BOARD REVIEW - OVER 40 FT","") | U23: slip_inventory_2026-08.csv; billing_transactions_2022_2026.csv
A24: ='Src_Inventory'!A25 | B24: ='Src_Inventory'!B25 | C24: ='Src_Inventory'!G25 | D24: ="AC-"&A24 | E24: ='Src_Inventory'!L25 | F24: ='Src_Inventory'!M25 | G24: ='Src_Inventory'!N25 | H24: ='Src_Inventory'!O25 | I24: =ROUNDUP(H24,0) | J24: ='Src_Inventory'!E25 | K24: =MAX(I24,J24) | L24: =IF(C24="COVERED",'Parameters & Sources'!$B$11,'Parameters & Sources'!$B$12) | M24: =K24*L24 | N24: =COUNTIFS('Src_Billing_Aug'!$E$6:$E$774,A24,'Src_Billing_Aug'!$D$6:$D$774,E24) | O24: =IF(N24=0,"",SUMIFS('Src_Billing_Aug'!$I$6:$I$774,'Src_Billing_Aug'!$E$6:$E$774,A24,'Src_Billing_Aug'!$D$6:$D$774,E24)) | P24: =IF(N24=0,"",SUMIFS('Src_Billing_Aug'!$L$6:$L$774,'Src_Billing_Aug'!$E$6:$E$774,A24,'Src_Billing_Aug'!$D$6:$D$774,E24)) | Q24: =SUMIFS('Src_Billing_Aug'!$M$6:$M$774,'Src_Billing_Aug'!$E$6:$E$774,A24,'Src_Billing_Aug'!$D$6:$D$774,E24) | R24: =Q24-M24 | S24: =IF(N24=0,"MISSING CHARGE",IF(N24>1,"DUPLICATE CHARGE",IF(ABS(R24)<0.005,"MATCH","VARIANCE"))) | T24: =IF(AND(C24="COVERED",K24>'Parameters & Sources'!$B$13),"BOARD REVIEW - OVER 40 FT","") | U24: slip_inventory_2026-08.csv; billing_transactions_2022_2026.csv
A25: ='Src_Inventory'!A26 | B25: ='Src_Inventory'!B26 | C25: ='Src_Inventory'!G26 | D25: ="AC-"&A25 | E25: ='Src_Inventory'!L26 | F25: ='Src_Inventory'!M26 | G25: ='Src_Inventory'!N26 | H25: ='Src_Inventory'!O26 | I25: =ROUNDUP(H25,0) | J25: ='Src_Inventory'!E26 | K25: =MAX(I25,J25) | L25: =IF(C25="COVERED",'Parameters & Sources'!$B$11,'Parameters & Sources'!$B$12) | M25: =K25*L25 | N25: =COUNTIFS('Src_Billing_Aug'!$E$6:$E$774,A25,'Src_Billing_Aug'!$D$6:$D$774,E25) | O25: =IF(N25=0,"",SUMIFS('Src_Billing_Aug'!$I$6:$I$774,'Src_Billing_Aug'!$E$6:$E$774,A25,'Src_Billing_Aug'!$D$6:$D$774,E25)) | P25: =IF(N25=0,"",SUMIFS('Src_Billing_Aug'!$L$6:$L$774,'Src_Billing_Aug'!$E$6:$E$774,A25,'Src_Billing_Aug'!$D$6:$D$774,E25)) | Q25: =SUMIFS('Src_Billing_Aug'!$M$6:$M$774,'Src_Billing_Aug'!$E$6:$E$774,A25,'Src_Billing_Aug'!$D$6:$D$774,E25) | R25: =Q25-M25 | S25: =IF(N25=0,"MISSING CHARGE",IF(N25>1,"DUPLICATE CHARGE",IF(ABS(R25)<0.005,"MATCH","VARIANCE"))) | T25: =IF(AND(C25="COVERED",K25>'Parameters & Sources'!$B$13),"BOARD REVIEW - OVER 40 FT","") | U25: slip_inventory_2026-08.csv; billing_transactions_2022_2026.csv
A26: ='Src_Inventory'!A27 | B26: ='Src_Inventory'!B27 | C26: ='Src_Inventory'!G27 | D26: ="AC-"&A26 | E26: ='Src_Inventory'!L27 | F26: ='Src_Inventory'!M27 | G26: ='Src_Inventory'!N27 | H26: ='Src_Inventory'!O27 | I26: =ROUNDUP(H26,0) | J26: ='Src_Inventory'!E27 | K26: =MAX(I26,J26) | L26: =IF(C26="COVERED",'Parameters & Sources'!$B$11,'Parameters & Sources'!$B$12) | M26: =K26*L26 | N26: =COUNTIFS('Src_Billing_Aug'!$E$6:$E$774,A26,'Src_Billing_Aug'!$D$6:$D$774,E26) | O26: =IF(N26=0,"",SUMIFS('Src_Billing_Aug'!$I$6:$I$774,'Src_Billing_Aug'!$E$6:$E$774,A26,'Src_Billing_Aug'!$D$6:$D$774,E26)) | P26: =IF(N26=0,"",SUMIFS('Src_Billing_Aug'!$L$6:$L$774,'Src_Billing_Aug'!$E$6:$E$774,A26,'Src_Billing_Aug'!$D$6:$D$774,E26)) | Q26: =SUMIFS('Src_Billing_Aug'!$M$6:$M$774,'Src_Billing_Aug'!$E$6:$E$774,A26,'Src_Billing_Aug'!$D$6:$D$774,E26) | R26: =Q26-M26 | S26: =IF(N26=0,"MISSING CHARGE",IF(N26>1,"DUPLICATE CHARGE",IF(ABS(R26)<0.005,"MATCH","VARIANCE"))) | T26: =IF(AND(C26="COVERED",K26>'Parameters & Sources'!$B$13),"BOARD REVIEW - OVER 40 FT","") | U26: slip_inventory_2026-08.csv; billing_transactions_2022_2026.csv
A27: ='Src_Inventory'!A28 | B27: ='Src_Inventory'!B28 | C27: ='Src_Inventory'!G28 | D27: ="AC-"&A27 | E27: ='Src_Inventory'!L28 | F27: ='Src_Inventory'!M28 | G27: ='Src_Inventory'!N28 | H27: ='Src_Inventory'!O28 | I27: =ROUNDUP(H27,0) | J27: ='Src_Inventory'!E28 | K27: =MAX(I27,J27) | L27: =IF(C27="COVERED",'Parameters & Sources'!$B$11,'Parameters & Sources'!$B$12) | M27: =K27*L27 | N27: =COUNTIFS('Src_Billing_Aug'!$E$6:$E$774,A27,'Src_Billing_Aug'!$D$6:$D$774,E27) | O27: =IF(N27=0,"",SUMIFS('Src_Billing_Aug'!$I$6:$I$774,'Src_Billing_Aug'!$E$6:$E$774,A27,'Src_Billing_Aug'!$D$6:$D$774,E27)) | P27: =IF(N27=0,"",SUMIFS('Src_Billing_Aug'!$L$6:$L$774,'Src_Billing_Aug'!$E$6:$E$774,A27,'Src_Billing_Aug'!$D$6:$D$774,E27)) | Q27: =SUMIFS('Src_Billing_Aug'!$M$6:$M$774,'Src_Billing_Aug'!$E$6:$E$774,A27,'Src_Billing_Aug'!$D$6:$D$774,E27) | R27: =Q27-M27 | S27: =IF(N27=0,"MISSING CHARGE",IF(N27>1,"DUPLICATE CHARGE",IF(ABS(R27)<0.005,"MATCH","VARIANCE"))) | T27: =IF(AND(C27="COVERED",K27>'Parameters & Sources'!$B$13),"BOARD REVIEW - OVER 40 FT","") | U27: slip_inventory_2026-08.csv; billing_transactions_2022_2026.csv
A28: ='Src_Inventory'!A29 | B28: ='Src_Inventory'!B29 | C28: ='Src_Inventory'!G29 | D28: ="AC-"&A28 | E28: ='Src_Inventory'!L29 | F28: ='Src_Inventory'!M29 | G28: ='Src_Inventory'!N29 | H28: ='Src_Inventory'!O29 | I28: =ROUNDUP(H28,0) | J28: ='Src_Inventory'!E29 | K28: =MAX(I28,J28) | L28: =IF(C28="COVERED",'Parameters & Sources'!$B$11,'Parameters & Sources'!$B$12) | M28: =K28*L28 | N28: =COUNTIFS('Src_Billing_Aug'!$E$6:$E$774,A28,'Src_Billing_Aug'!$D$6:$D$774,E28) | O28: =IF(N28=0,"",SUMIFS('Src_Billing_Aug'!$I$6:$I$774,'Src_Billing_Aug'!$E$6:$E$774,A28,'Src_Billing_Aug'!$D$6:$D$774,E28)) | P28: =IF(N28=0,"",SUMIFS('Src_Billing_Aug'!$L$6:$L$774,'Src_Billing_Aug'!$E$6:$E$774,A28,'Src_Billing_Aug'!$D$6:$D$774,E28)) | Q28: =SUMIFS('Src_Billing_Aug'!$M$6:$M$774,'Src_Billing_Aug'!$E$6:$E$774,A28,'Src_Billing_Aug'!$D$6:$D$774,E28) | R28: =Q28-M28 | S28: =IF(N28=0,"MISSING CHARGE",IF(N28>1,"DUPLICATE CHARGE",IF(ABS(R28)<0.005,"MATCH","VARIANCE"))) | T28: =IF(AND(C28="COVERED",K28>'Parameters & Sources'!$B$13),"BOARD REVIEW - OVER 40 FT","") | U28: slip_inventory_2026-08.csv; billing_transactions_2022_2026.csv
... A34: ='Src_Inventory'!A35 | B34: ='Src_Inventory'!B35 | C34: ='Src_Inventory'!G35 | D34: ="AC-"&A34 | E34: ='Src_Inventory'!L35 | F34: ='Src_Inventory'!M35 | G34: ='Src_Inventory'!N35 | H34: ='Src_Inventory'!O35 | I34: =ROUNDUP(H34,0) | J34: ='Src_Inventory'!E35 | K34: =MAX(I34,J34) | L34: =IF(C34="COVERED",'Parameters & Sources'!$B$11,'Parameters & Sources'!$B$12) | M34: =K34*L34 | N34: =COUNTIFS('Src_Billing_Aug'!$E$6:$E$774,A34,'Src_Billing_Aug'!$D$6:$D$774,E34) | O34: =IF(N34=0,"",SUMIFS('Src_Billing_Aug'!$I$6:$I$774,'Src_Billing_Aug'!$E$6:$E$774,A34,'Src_Billing_Aug'!$D$6:$D$774,E34)) | P34: =IF(N34=0,"",SUMIFS('Src_Billing_Aug'!$L$6:$L$774,'Src_Billing_Aug'!$E$6:$E$774,A34,'Src_Billing_Aug'!$D$6:$D$774,E34)) | Q34: =SUMIFS('Src_Billing_Aug'!$M$6:$M$774,'Src_Billing_Aug'!$E$6:$E$774,A34,'Src_Billing_Aug'!$D$6:$D$774,E34) | R34: =Q34-M34 | S34: =IF(N34=0,"MISSING CHARGE",IF(N34>1,"DUPLICATE CHARGE",IF(ABS(R34)<0.005,"MATCH","VARIANCE"))) | T34: =IF(AND(C34="COVERED",K34>'Parameters & Sources'!$B$13),"BOARD REVIEW - OVER 40 FT","") | U34: slip_inventory_2026-08.csv; billing_transactions_2022_2026.csv
A35: ='Src_Inventory'!A37 | B35: ='Src_Inventory'!B37 | C35: ='Src_Inventory'!G37 | D35: ="AC-"&A35 | E35: ='Src_Inventory'!L37 | F35: ='Src_Inventory'!M37 | G35: ='Src_Inventory'!N37 | H35: ='Src_Inventory'!O37 | I35: =ROUNDUP(H35,0) | J35: ='Src_Inventory'!E37 | K35: =MAX(I35,J35) | L35: =IF(C35="COVERED",'Parameters & Sources'!$B$11,'Parameters & Sources'!$B$12) | M35: =K35*L35 | N35: =COUNTIFS('Src_Billing_Aug'!$E$6:$E$774,A35,'Src_Billing_Aug'!$D$6:$D$774,E35) | O35: =IF(N35=0,"",SUMIFS('Src_Billing_Aug'!$I$6:$I$774,'Src_Billing_Aug'!$E$6:$E$774,A35,'Src_Billing_Aug'!$D$6:$D$774,E35)) | P35: =IF(N35=0,"",SUMIFS('Src_Billing_Aug'!$L$6:$L$774,'Src_Billing_Aug'!$E$6:$E$774,A35,'Src_Billing_Aug'!$D$6:$D$774,E35)) | Q35: =SUMIFS('Src_Billing_Aug'!$M$6:$M$774,'Src_Billing_Aug'!$E$6:$E$774,A35,'Src_Billing_Aug'!$D$6:$D$774,E35) | R35: =Q35-M35 | S35: =IF(N35=0,"MISSING CHARGE",IF(N35>1,"DUPLICATE CHARGE",IF(ABS(R35)<0.005,"MATCH","VARIANCE"))) | T35: =IF(AND(C35="COVERED",K35>'Parameters & Sources'!$B$13),"BOARD REVIEW - OVER 40 FT","") | U35: slip_inventory_2026-08.csv; billing_transactions_2022_2026.csv
A36: ='Src_Inventory'!A38 | B36: ='Src_Inventory'!B38 | C36: ='Src_Inventory'!G38 | D36: ="AC-"&A36 | E36: ='Src_Inventory'!L38 | F36: ='Src_Inventory'!M38 | G36: ='Src_Inventory'!N38 | H36: ='Src_Inventory'!O38 | I36: =ROUNDUP(H36,0) | J36: ='Src_Inventory'!E38 | K36: =MAX(I36,J36) | L36: =IF(C36="COVERED",'Parameters & Sources'!$B$11,'Parameters & Sources'!$B$12) | M36: =K36*L36 | N36: =COUNTIFS('Src_Billing_Aug'!$E$6:$E$774,A36,'Src_Billing_Aug'!$D$6:$D$774,E36) | O36: =IF(N36=0,"",SUMIFS('Src_Billing_Aug'!$I$6:$I$774,'Src_Billing_Aug'!$E$6:$E$774,A36,'Src_Billing_Aug'!$D$6:$D$774,E36)) | P36: =IF(N36=0,"",SUMIFS('Src_Billing_Aug'!$L$6:$L$774,'Src_Billing_Aug'!$E$6:$E$774,A36,'Src_Billing_Aug'!$D$6:$D$774,E36)) | Q36: =SUMIFS('Src_Billing_Aug'!$M$6:$M$774,'Src_Billing_Aug'!$E$6:$E$774,A36,'Src_Billing_Aug'!$D$6:$D$774,E36) | R36: =Q36-M36 | S36: =IF(N36=0,"MISSING CHARGE",IF(N36>1,"DUPLICATE CHARGE",IF(ABS(R36)<0.005,"MATCH","VARIANCE"))) | T36: =IF(AND(C36="COVERED",K36>'Parameters & Sources'!$B$13),"BOARD REVIEW - OVER 40 FT","") | U36: slip_inventory_2026-08.csv; billing_transactions_2022_2026.csv
A37: ='Src_Inventory'!A39 | B37: ='Src_Inventory'!B39 | C37: ='Src_Inventory'!G39 | D37: ="AC-"&A37 | E37: ='Src_Inventory'!L39 | F37: ='Src_Inventory'!M39 | G37: ='Src_Inventory'!N39 | H37: ='Src_Inventory'!O39 | I37: =ROUNDUP(H37,0) | J37: ='Src_Inventory'!E39 | K37: =MAX(I37,J37) | L37: =IF(C37="COVERED",'Parameters & Sources'!$B$11,'Parameters & Sources'!$B$12) | M37: =K37*L37 | N37: =COUNTIFS('Src_Billing_Aug'!$E$6:$E$774,A37,'Src_Billing_Aug'!$D$6:$D$774,E37) | O37: =IF(N37=0,"",SUMIFS('Src_Billing_Aug'!$I$6:$I$774,'Src_Billing_Aug'!$E$6:$E$774,A37,'Src_Billing_Aug'!$D$6:$D$774,E37)) | P37: =IF(N37=0,"",SUMIFS('Src_Billing_Aug'!$L$6:$L$774,'Src_Billing_Aug'!$E$6:$E$774,A37,'Src_Billing_Aug'!$D$6:$D$774,E37)) | Q37: =SUMIFS('Src_Billing_Aug'!$M$6:$M$774,'Src_Billing_Aug'!$E$6:$E$774,A37,'Src_Billing_Aug'!$D$6:$D$774,E37) | R37: =Q37-M37 | S37: =IF(N37=0,"MISSING CHARGE",IF(N37>1,"DUPLICATE CHARGE",IF(ABS(R37)<0.005,"MATCH","VARIANCE"))) | T37: =IF(AND(C37="COVERED",K37>'Parameters & Sources'!$B$13),"BOARD REVIEW - OVER 40 FT","") | U37: slip_inventory_2026-08.csv; billing_transactions_2022_2026.csv
A38: ='Src_Inventory'!A41 | B38: ='Src_Inventory'!B41 | C38: ='Src_Inventory'!G41 | D38: ="AC-"&A38 | E38: ='Src_Inventory'!L41 | F38: ='Src_Inventory'!M41 | G38: ='Src_Inventory'!N41 | H38: ='Src_Inventory'!O41 | I38: =ROUNDUP(H38,0) | J38: ='Src_Inventory'!E41 | K38: =MAX(I38,J38) | L38: =IF(C38="COVERED",'Parameters & Sources'!$B$11,'Parameters & Sources'!$B$12) | M38: =K38*L38 | N38: =COUNTIFS('Src_Billing_Aug'!$E$6:$E$774,A38,'Src_Billing_Aug'!$D$6:$D$774,E38) | O38: =IF(N38=0,"",SUMIFS('Src_Billing_Aug'!$I$6:$I$774,'Src_Billing_Aug'!$E$6:$E$774,A38,'Src_Billing_Aug'!$D$6:$D$774,E38)) | P38: =IF(N38=0,"",SUMIFS('Src_Billing_Aug'!$L$6:$L$774,'Src_Billing_Aug'!$E$6:$E$774,A38,'Src_Billing_Aug'!$D$6:$D$774,E38)) | Q38: =SUMIFS('Src_Billing_Aug'!$M$6:$M$774,'Src_Billing_Aug'!$E$6:$E$774,A38,'Src_Billing_Aug'!$D$6:$D$774,E38) | R38: =Q38-M38 | S38: =IF(N38=0,"MISSING CHARGE",IF(N38>1,"DUPLICATE CHARGE",IF(ABS(R38)<0.005,"MATCH","VARIANCE"))) | T38: =IF(AND(C38="COVERED",K38>'Parameters & Sources'!$B$13),"BOARD REVIEW - OVER 40 FT","") | U38: slip_inventory_2026-08.csv; billing_transactions_2022_2026.csv
A39: ='Src_Inventory'!A42 | B39: ='Src_Inventory'!B42 | C39: ='Src_Inventory'!G42 | D39: ="AC-"&A39 | E39: ='Src_Inventory'!L42 | F39: ='Src_Inventory'!M42 | G39: ='Src_Inventory'!N42 | H39: ='Src_Inventory'!O42 | I39: =ROUNDUP(H39,0) | J39: ='Src_Inventory'!E42 | K39: =MAX(I39,J39) | L39: =IF(C39="COVERED",'Parameters & Sources'!$B$11,'Parameters & Sources'!$B$12) | M39: =K39*L39 | N39: =COUNTIFS('Src_Billing_Aug'!$E$6:$E$774,A39,'Src_Billing_Aug'!$D$6:$D$774,E39) | O39: =IF(N39=0,"",SUMIFS('Src_Billing_Aug'!$I$6:$I$774,'Src_Billing_Aug'!$E$6:$E$774,A39,'Src_Billing_Aug'!$D$6:$D$774,E39)) | P39: =IF(N39=0,"",SUMIFS('Src_Billing_Aug'!$L$6:$L$774,'Src_Billing_Aug'!$E$6:$E$774,A39,'Src_Billing_Aug'!$D$6:$D$774,E39)) | Q39: =SUMIFS('Src_Billing_Aug'!$M$6:$M$774,'Src_Billing_Aug'!$E$6:$E$774,A39,'Src_Billing_Aug'!$D$6:$D$774,E39) | R39: =Q39-M39 | S39: =IF(N39=0,"MISSING CHARGE",IF(N39>1,"DUPLICATE CHARGE",IF(ABS(R39)<0.005,"MATCH","VARIANCE"))) | T39: =IF(AND(C39="COVERED",K39>'Parameters & Sources'!$B$13),"BOARD REVIEW - OVER 40 FT","") | U39: slip_inventory_2026-08.csv; billing_transactions_2022_2026.csv
A40: ='Src_Inventory'!A43 | B40: ='Src_Inventory'!B43 | C40: ='Src_Inventory'!G43 | D40: ="AC-"&A40 | E40: ='Src_Inventory'!L43 | F40: ='Src_Inventory'!M43 | G40: ='Src_Inventory'!N43 | H40: ='Src_Inventory'!O43 | I40: =ROUNDUP(H40,0) | J40: ='Src_Inventory'!E43 | K40: =MAX(I40,J40) | L40: =IF(C40="COVERED",'Parameters & Sources'!$B$11,'Parameters & Sources'!$B$12) | M40: =K40*L40 | N40: =COUNTIFS('Src_Billing_Aug'!$E$6:$E$774,A40,'Src_Billing_Aug'!$D$6:$D$774,E40) | O40: =IF(N40=0,"",SUMIFS('Src_Billing_Aug'!$I$6:$I$774,'Src_Billing_Aug'!$E$6:$E$774,A40,'Src_Billing_Aug'!$D$6:$D$774,E40)) | P40: =IF(N40=0,"",SUMIFS('Src_Billing_Aug'!$L$6:$L$774,'Src_Billing_Aug'!$E$6:$E$774,A40,'Src_Billing_Aug'!$D$6:$D$774,E40)) | Q40: =SUMIFS('Src_Billing_Aug'!$M$6:$M$774,'Src_Billing_Aug'!$E$6:$E$774,A40,'Src_Billing_Aug'!$D$6:$D$774,E40) | R40: =Q40-M40 | S40: =IF(N40=0,"MISSING CHARGE",IF(N40>1,"DUPLICATE CHARGE",IF(ABS(R40)<0.005,"MATCH","VARIANCE"))) | T40: =IF(AND(C40="COVERED",K40>'Parameters & Sources'!$B$13),"BOARD REVIEW - OVER 40 FT","") | U40: slip_inventory_2026-08.csv; billing_transactions_2022_2026.csv
A41: ='Src_Inventory'!A44 | B41: ='Src_Inventory'!B44 | C41: ='Src_Inventory'!G44 | D41: ="AC-"&A41 | E41: ='Src_Inventory'!L44 | F41: ='Src_Inventory'!M44 | G41: ='Src_Inventory'!N44 | H41: ='Src_Inventory'!O44 | I41: =ROUNDUP(H41,0) | J41: ='Src_Inventory'!E44 | K41: =MAX(I41,J41) | L41: =IF(C41="COVERED",'Parameters & Sources'!$B$11,'Parameters & Sources'!$B$12) | M41: =K41*L41 | N41: =COUNTIFS('Src_Billing_Aug'!$E$6:$E$774,A41,'Src_Billing_Aug'!$D$6:$D$774,E41) | O41: =IF(N41=0,"",SUMIFS('Src_Billing_Aug'!$I$6:$I$774,'Src_Billing_Aug'!$E$6:$E$774,A41,'Src_Billing_Aug'!$D$6:$D$774,E41)) | P41: =IF(N41=0,"",SUMIFS('Src_Billing_Aug'!$L$6:$L$774,'Src_Billing_Aug'!$E$6:$E$774,A41,'Src_Billing_Aug'!$D$6:$D$774,E41)) | Q41: =SUMIFS('Src_Billing_Aug'!$M$6:$M$774,'Src_Billing_Aug'!$E$6:$E$774,A41,'Src_Billing_Aug'!$D$6:$D$774,E41) | R41: =Q41-M41 | S41: =IF(N41=0,"MISSING CHARGE",IF(N41>1,"DUPLICATE CHARGE",IF(ABS(R41)<0.005,"MATCH","VARIANCE"))) | T41: =IF(AND(C41="COVERED",K41>'Parameters & Sources'!$B$13),"BOARD REVIEW - OVER 40 FT","") | U41: slip_inventory_2026-08.csv; billing_transactions_2022_2026.csv
A42: ='Src_Inventory'!A45 | B42: ='Src_Inventory'!B45 | C42: ='Src_Inventory'!G45 | D42: ="AC-"&A42 | E42: ='Src_Inventory'!L45 | F42: ='Src_Inventory'!M45 | G42: ='Src_Inventory'!N45 | H42: ='Src_Inventory'!O45 | I42: =ROUNDUP(H42,0) | J42: ='Src_Inventory'!E45 | K42: =MAX(I42,J42) | L42: =IF(C42="COVERED",'Parameters & Sources'!$B$11,'Parameters & Sources'!$B$12) | M42: =K42*L42 | N42: =COUNTIFS('Src_Billing_Aug'!$E$6:$E$774,A42,'Src_Billing_Aug'!$D$6:$D$774,E42) | O42: =IF(N42=0,"",SUMIFS('Src_Billing_Aug'!$I$6:$I$774,'Src_Billing_Aug'!$E$6:$E$774,A42,'Src_Billing_Aug'!$D$6:$D$774,E42)) | P42: =IF(N42=0,"",SUMIFS('Src_Billing_Aug'!$L$6:$L$774,'Src_Billing_Aug'!$E$6:$E$774,A42,'Src_Billing_Aug'!$D$6:$D$774,E42)) | Q42: =SUMIFS('Src_Billing_Aug'!$M$6:$M$774,'Src_Billing_Aug'!$E$6:$E$774,A42,'Src_Billing_Aug'!$D$6:$D$774,E42) | R42: =Q42-M42 | S42: =IF(N42=0,"MISSING CHARGE",IF(N42>1,"DUPLICATE CHARGE",IF(ABS(R42)<0.005,"MATCH","VARIANCE"))) | T42: =IF(AND(C42="COVERED",K42>'Parameters & Sources'!$B$13),"BOARD REVIEW - OVER 40 FT","") | U42: slip_inventory_2026-08.csv; billing_transactions_2022_2026.csv
A43: ='Src_Inventory'!A46 | B43: ='Src_Inventory'!B46 | C43: ='Src_Inventory'!G46 | D43: ="AC-"&A43 | E43: ='Src_Inventory'!L46 | F43: ='Src_Inventory'!M46 | G43: ='Src_Inventory'!N46 | H43: ='Src_Inventory'!O46 | I43: =ROUNDUP(H43,0) | J43: ='Src_Inventory'!E46 | K43: =MAX(I43,J43) | L43: =IF(C43="COVERED",'Parameters & Sources'!$B$11,'Parameters & Sources'!$B$12) | M43: =K43*L43 | N43: =COUNTIFS('Src_Billing_Aug'!$E$6:$E$774,A43,'Src_Billing_Aug'!$D$6:$D$774,E43) | O43: =IF(N43=0,"",SUMIFS('Src_Billing_Aug'!$I$6:$I$774,'Src_Billing_Aug'!$E$6:$E$774,A43,'Src_Billing_Aug'!$D$6:$D$774,E43)) | P43: =IF(N43=0,"",SUMIFS('Src_Billing_Aug'!$L$6:$L$774,'Src_Billing_Aug'!$E$6:$E$774,A43,'Src_Billing_Aug'!$D$6:$D$774,E43)) | Q43: =SUMIFS('Src_Billing_Aug'!$M$6:$M$774,'Src_Billing_Aug'!$E$6:$E$774,A43,'Src_Billing_Aug'!$D$6:$D$774,E43) | R43: =Q43-M43 | S43: =IF(N43=0,"MISSING CHARGE",IF(N43>1,"DUPLICATE CHARGE",IF(ABS(R43)<0.005,"MATCH","VARIANCE"))) | T43: =IF(AND(C43="COVERED",K43>'Parameters & Sources'!$B$13),"BOARD REVIEW - OVER 40 FT","") | U43: slip_inventory_2026-08.csv; billing_transactions_2022_2026.csv
A44: ='Src_Inventory'!A47 | B44: ='Src_Inventory'!B47 | C44: ='Src_Inventory'!G47 | D44: ="AC-"&A44 | E44: ='Src_Inventory'!L47 | F44: ='Src_Inventory'!M47 | G44: ='Src_Inventory'!N47 | H44: ='Src_Inventory'!O47 | I44: =ROUNDUP(H44,0) | J44: ='Src_Inventory'!E47 | K44: =MAX(I44,J44) | L44: =IF(C44="COVERED",'Parameters & Sources'!$B$11,'Parameters & Sources'!$B$12) | M44: =K44*L44 | N44: =COUNTIFS('Src_Billing_Aug'!$E$6:$E$774,A44,'Src_Billing_Aug'!$D$6:$D$774,E44) | O44: =IF(N44=0,"",SUMIFS('Src_Billing_Aug'!$I$6:$I$774,'Src_Billing_Aug'!$E$6:$E$774,A44,'Src_Billing_Aug'!$D$6:$D$774,E44)) | P44: =IF(N44=0,"",SUMIFS('Src_Billing_Aug'!$L$6:$L$774,'Src_Billing_Aug'!$E$6:$E$774,A44,'Src_Billing_Aug'!$D$6:$D$774,E44)) | Q44: =SUMIFS('Src_Billing_Aug'!$M$6:$M$774,'Src_Billing_Aug'!$E$6:$E$774,A44,'Src_Billing_Aug'!$D$6:$D$774,E44) | R44: =Q44-M44 | S44: =IF(N44=0,"MISSING CHARGE",IF(N44>1,"DUPLICATE CHARGE",IF(ABS(R44)<0.005,"MATCH","VARIANCE"))) | T44: =IF(AND(C44="COVERED",K44>'Parameters & Sources'!$B$13),"BOARD REVIEW - OVER 40 FT","") | U44: slip_inventory_2026-08.csv; billing_transactions_2022_2026.csv
A45: ='Src_Inventory'!A48 | B45: ='Src_Inventory'!B48 | C45: ='Src_Inventory'!G48 | D45: ="AC-"&A45 | E45: ='Src_Inventory'!L48 | F45: ='Src_Inventory'!M48 | G45: ='Src_Inventory'!N48 | H45: ='Src_Inventory'!O48 | I45: =ROUNDUP(H45,0) | J45: ='Src_Inventory'!E48 | K45: =MAX(I45,J45) | L45: =IF(C45="COVERED",'Parameters & Sources'!$B$11,'Parameters & Sources'!$B$12) | M45: =K45*L45 | N45: =COUNTIFS('Src_Billing_Aug'!$E$6:$E$774,A45,'Src_Billing_Aug'!$D$6:$D$774,E45) | O45: =IF(N45=0,"",SUMIFS('Src_Billing_Aug'!$I$6:$I$774,'Src_Billing_Aug'!$E$6:$E$774,A45,'Src_Billing_Aug'!$D$6:$D$774,E45)) | P45: =IF(N45=0,"",SUMIFS('Src_Billing_Aug'!$L$6:$L$774,'Src_Billing_Aug'!$E$6:$E$774,A45,'Src_Billing_Aug'!$D$6:$D$774,E45)) | Q45: =SUMIFS('Src_Billing_Aug'!$M$6:$M$774,'Src_Billing_Aug'!$E$6:$E$774,A45,'Src_Billing_Aug'!$D$6:$D$774,E45) | R45: =Q45-M45 | S45: =IF(N45=0,"MISSING CHARGE",IF(N45>1,"DUPLICATE CHARGE",IF(ABS(R45)<0.005,"MATCH","VARIANCE"))) | T45: =IF(AND(C45="COVERED",K45>'Parameters & Sources'!$B$13),"BOARD REVIEW - OVER 40 FT","") | U45: slip_inventory_2026-08.csv; billing_transactions_2022_2026.csv
A46: ='Src_Inventory'!A49 | B46: ='Src_Inventory'!B49 | C46: ='Src_Inventory'!G49 | D46: ="AC-"&A46 | E46: ='Src_Inventory'!L49 | F46: ='Src_Inventory'!M49 | G46: ='Src_Inventory'!N49 | H46: ='Src_Inventory'!O49 | I46: =ROUNDUP(H46,0) | J46: ='Src_Inventory'!E49 | K46: =MAX(I46,J46) | L46: =IF(C46="COVERED",'Parameters & Sources'!$B$11,'Parameters & Sources'!$B$12) | M46: =K46*L46 | N46: =COUNTIFS('Src_Billing_Aug'!$E$6:$E$774,A46,'Src_Billing_Aug'!$D$6:$D$774,E46) | O46: =IF(N46=0,"",SUMIFS('Src_Billing_Aug'!$I$6:$I$774,'Src_Billing_Aug'!$E$6:$E$774,A46,'Src_Billing_Aug'!$D$6:$D$774,E46)) | P46: =IF(N46=0,"",SUMIFS('Src_Billing_Aug'!$L$6:$L$774,'Src_Billing_Aug'!$E$6:$E$774,A46,'Src_Billing_Aug'!$D$6:$D$774,E46)) | Q46: =SUMIFS('Src_Billing_Aug'!$M$6:$M$774,'Src_Billing_Aug'!$E$6:$E$774,A46,'Src_Billing_Aug'!$D$6:$D$774,E46) | R46: =Q46-M46 | S46: =IF(N46=0,"MISSING CHARGE",IF(N46>1,"DUPLICATE CHARGE",IF(ABS(R46)<0.005,"MATCH","VARIANCE"))) | T46: =IF(AND(C46="COVERED",K46>'Parameters & Sources'!$B$13),"BOARD REVIEW - OVER 40 FT","") | U46: slip_inventory_2026-08.csv; billing_transactions_2022_2026.csv
...

Sheet Aging Report
A1: Aging Report - Overdue Accounts
A2: Active/occupied accounts with a nonzero 31+ bucket at 2026-07-31; 91+ accounts are highlighted for collection.
A3: Sources: ar_aging_2026-07-31.xlsx, AR_Aging sheet, rows 3-262; status confirmed against slip_inventory_2026-08.csv. Total due is recomputed as Current + 31-60 + 61-90 + 91-120 + 120+; overdue excludes Current.
A5: Account ID | B5: Tenant | C5: Slip | D5: Basin | E5: Current | F5: 31-60 | G5: 61-90 | H5: 91-120 | I5: 120+ | J5: Recalc Total Due | K5: Source Total Due | L5: Source Variance | M5: Overdue 31+ | N5: 91+ Balance | O5: Payment Status | P5: Inventory Status | Q5: Tenant Match | R5: Collection Priority | S5: Last Payment | T5: Last Contact | U5: Notes
A6: ='Src_Aging'!A12 | B6: ='Src_Aging'!B12 | C6: ='Src_Aging'!C12 | D6: ='Src_Aging'!D12 | E6: ='Src_Aging'!F12 | F6: ='Src_Aging'!G12 | G6: ='Src_Aging'!H12 | H6: ='Src_Aging'!I12 | I6: ='Src_Aging'!J12 | J6: =SUM(E6:I6) | K6: ='Src_Aging'!K12 | L6: =K6-J6 | M6: =SUM(F6:I6) | N6: =SUM(H6:I6) | O6: ='Src_Aging'!M12 | P6: ='Src_Aging'!R12 | Q6: ='Src_Aging'!S12 | R6: =IF(AND(P6="OCCUPIED",N6>0),"COLLECT - 91+",IF(P6="OCCUPIED","FOLLOW UP","STATUS EXCEPTION")) | S6: ='Src_Aging'!L12 | T6: ='Src_Aging'!N12 | U6: ='Src_Aging'!O12
A7: ='Src_Aging'!A14 | B7: ='Src_Aging'!B14 | C7: ='Src_Aging'!C14 | D7: ='Src_Aging'!D14 | E7: ='Src_Aging'!F14 | F7: ='Src_Aging'!G14 | G7: ='Src_Aging'!H14 | H7: ='Src_Aging'!I14 | I7: ='Src_Aging'!J14 | J7: =SUM(E7:I7) | K7: ='Src_Aging'!K14 | L7: =K7-J7 | M7: =SUM(F7:I7) | N7: =SUM(H7:I7) | O7: ='Src_Aging'!M14 | P7: ='Src_Aging'!R14 | Q7: ='Src_Aging'!S14 | R7: =IF(AND(P7="OCCUPIED",N7>0),"COLLECT - 91+",IF(P7="OCCUPIED","FOLLOW UP","STATUS EXCEPTION")) | S7: ='Src_Aging'!L14 | T7: ='Src_Aging'!N14 | U7: ='Src_Aging'!O14
A8: ='Src_Aging'!A16 | B8: ='Src_Aging'!B16 | C8: ='Src_Aging'!C16 | D8: ='Src_Aging'!D16 | E8: ='Src_Aging'!F16 | F8: ='Src_Aging'!G16 | G8: ='Src_Aging'!H16 | H8: ='Src_Aging'!I16 | I8: ='Src_Aging'!J16 | J8: =SUM(E8:I8) | K8: ='Src_Aging'!K16 | L8: =K8-J8 | M8: =SUM(F8:I8) | N8: =SUM(H8:I8) | O8: ='Src_Aging'!M16 | P8: ='Src_Aging'!R16 | Q8: ='Src_Aging'!S16 | R8: =IF(AND(P8="OCCUPIED",N8>0),"COLLECT - 91+",IF(P8="OCCUPIED","FOLLOW UP","STATUS EXCEPTION")) | S8: ='Src_Aging'!L16 | T8: ='Src_Aging'!N16 | U8: ='Src_Aging'!O16
A9: ='Src_Aging'!A19 | B9: ='Src_Aging'!B19 | C9: ='Src_Aging'!C19 | D9: ='Src_Aging'!D19 | E9: ='Src_Aging'!F19 | F9: ='Src_Aging'!G19 | G9: ='Src_Aging'!H19 | H9: ='Src_Aging'!I19 | I9: ='Src_Aging'!J19 | J9: =SUM(E9:I9) | K9: ='Src_Aging'!K19 | L9: =K9-J9 | M9: =SUM(F9:I9) | N9: =SUM(H9:I9) | O9: ='Src_Aging'!M19 | P9: ='Src_Aging'!R19 | Q9: ='Src_Aging'!S19 | R9: =IF(AND(P9="OCCUPIED",N9>0),"COLLECT - 91+",IF(P9="OCCUPIED","FOLLOW UP","STATUS EXCEPTION")) | S9: ='Src_Aging'!L19 | T9: ='Src_Aging'!N19 | U9: ='Src_Aging'!O19
A10: ='Src_Aging'!A26 | B10: ='Src_Aging'!B26 | C10: ='Src_Aging'!C26 | D10: ='Src_Aging'!D26 | E10: ='Src_Aging'!F26 | F10: ='Src_Aging'!G26 | G10: ='Src_Aging'!H26 | H10: ='Src_Aging'!I26 | I10: ='Src_Aging'!J26 | J10: =SUM(E10:I10) | K10: ='Src_Aging'!K26 | L10: =K10-J10 | M10: =SUM(F10:I10) | N10: =SUM(H10:I10) | O10: ='Src_Aging'!M26 | P10: ='Src_Aging'!R26 | Q10: ='Src_Aging'!S26 | R10: =IF(AND(P10="OCCUPIED",N10>0),"COLLECT - 91+",IF(P10="OCCUPIED","FOLLOW UP","STATUS EXCEPTION")) | S10: ='Src_Aging'!L26 | T10: ='Src_Aging'!N26 | U10: ='Src_Aging'!O26
A11: ='Src_Aging'!A31 | B11: ='Src_Aging'!B31 | C11: ='Src_Aging'!C31 | D11: ='Src_Aging'!D31 | E11: ='Src_Aging'!F31 | F11: ='Src_Aging'!G31 | G11: ='Src_Aging'!H31 | H11: ='Src_Aging'!I31 | I11: ='Src_Aging'!J31 | J11: =SUM(E11:I11) | K11: ='Src_Aging'!K31 | L11: =K11-J11 | M11: =SUM(F11:I11) | N11: =SUM(H11:I11) | O11: ='Src_Aging'!M31 | P11: ='Src_Aging'!R31 | Q11: ='Src_Aging'!S31 | R11: =IF(AND(P11="OCCUPIED",N11>0),"COLLECT - 91+",IF(P11="OCCUPIED","FOLLOW UP","STATUS EXCEPTION")) | S11: ='Src_Aging'!L31 | T11: ='Src_Aging'!N31 | U11: ='Src_Aging'!O31
A12: ='Src_Aging'!A35 | B12: ='Src_Aging'!B35 | C12: ='Src_Aging'!C35 | D12: ='Src_Aging'!D35 | E12: ='Src_Aging'!F35 | F12: ='Src_Aging'!G35 | G12: ='Src_Aging'!H35 | H12: ='Src_Aging'!I35 | I12: ='Src_Aging'!J35 | J12: =SUM(E12:I12) | K12: ='Src_Aging'!K35 | L12: =K12-J12 | M12: =SUM(F12:I12) | N12: =SUM(H12:I12) | O12: ='Src_Aging'!M35 | P12: ='Src_Aging'!R35 | Q12: ='Src_Aging'!S35 | R12: =IF(AND(P12="OCCUPIED",N12>0),"COLLECT - 91+",IF(P12="OCCUPIED","FOLLOW UP","STATUS EXCEPTION")) | S12: ='Src_Aging'!L35 | T12: ='Src_Aging'!N35 | U12: ='Src_Aging'!O35
A13: ='Src_Aging'!A36 | B13: ='Src_Aging'!B36 | C13: ='Src_Aging'!C36 | D13: ='Src_Aging'!D36 | E13: ='Src_Aging'!F36 | F13: ='Src_Aging'!G36 | G13: ='Src_Aging'!H36 | H13: ='Src_Aging'!I36 | I13: ='Src_Aging'!J36 | J13: =SUM(E13:I13) | K13: ='Src_Aging'!K36 | L13: =K13-J13 | M13: =SUM(F13:I13) | N13: =SUM(H13:I13) | O13: ='Src_Aging'!M36 | P13: ='Src_Aging'!R36 | Q13: ='Src_Aging'!S36 | R13: =IF(AND(P13="OCCUPIED",N13>0),"COLLECT - 91+",IF(P13="OCCUPIED","FOLLOW UP","STATUS EXCEPTION")) | S13: ='Src_Aging'!L36 | T13: ='Src_Aging'!N36 | U13: ='Src_Aging'!O36
A14: ='Src_Aging'!A37 | B14: ='Src_Aging'!B37 | C14: ='Src_Aging'!C37 | D14: ='Src_Aging'!D37 | E14: ='Src_Aging'!F37 | F14: ='Src_Aging'!G37 | G14: ='Src_Aging'!H37 | H14: ='Src_Aging'!I37 | I14: ='Src_Aging'!J37 | J14: =SUM(E14:I14) | K14: ='Src_Aging'!K37 | L14: =K14-J14 | M14: =SUM(F14:I14) | N14: =SUM(H14:I14) | O14: ='Src_Aging'!M37 | P14: ='Src_Aging'!R37 | Q14: ='Src_Aging'!S37 | R14: =IF(AND(P14="OCCUPIED",N14>0),"COLLECT - 91+",IF(P14="OCCUPIED","FOLLOW UP","STATUS EXCEPTION")) | S14: ='Src_Aging'!L37 | T14: ='Src_Aging'!N37 | U14: ='Src_Aging'!O37
A15: ='Src_Aging'!A38 | B15: ='Src_Aging'!B38 | C15: ='Src_Aging'!C38 | D15: ='Src_Aging'!D38 | E15: ='Src_Aging'!F38 | F15: ='Src_Aging'!G38 | G15: ='Src_Aging'!H38 | H15: ='Src_Aging'!I38 | I15: ='Src_Aging'!J38 | J15: =SUM(E15:I15) | K15: ='Src_Aging'!K38 | L15: =K15-J15 | M15: =SUM(F15:I15) | N15: =SUM(H15:I15) | O15: ='Src_Aging'!M38 | P15: ='Src_Aging'!R38 | Q15: ='Src_Aging'!S38 | R15: =IF(AND(P15="OCCUPIED",N15>0),"COLLECT - 91+",IF(P15="OCCUPIED","FOLLOW UP","STATUS EXCEPTION")) | S15: ='Src_Aging'!L38 | T15: ='Src_Aging'!N38 | U15: ='Src_Aging'!O38
