Workbook

Sheet Summary
A1: MOORAGE AUDIT | Administrator Review
A2: Audit date: 1 August 2026 | Queue scope: 1 January 2023 through 31 July 2026 | Dollar amounts before tax
A4: Decision view
A5: Metric | B5: Result | C5: Review signal | D5: Basis / governing source
A6: QUEUE AND PRIORITY
A7: In-period skip events reviewed | B7: =COUNTA('Queue Exceptions'!A5:A313) -> 309 | C7: Scope | D7: skip_events_2022_2026.csv; period is inclusive
A8: Events with one or more audit exceptions | B8: =COUNTIF('Queue Exceptions'!AH5:AH313,"EXCEPTION") -> 173 | C8: Board review | D8: Formula flags overlap; each event counted once
A9: No exception identified from structured metadata | B9: =COUNTIF('Queue Exceptions'!AH5:AH313,"NO EXCEPTION IDENTIFIED") -> 136 | C9: Not a certification | D9: Most physical justification files and day-log pages were not supplied
A10: Skip predates register application date | B10: =COUNTIF('Queue Exceptions'!AB5:AB313,"Y") -> 124 | C10: Priority exception | D10: Tariff Resolution 2019-14 ss.3.1, 4.1
A11: Required supporting record not attached | B11: =COUNTIF('Queue Exceptions'!AC5:AC313,"Y") -> 19 | C11: Documentation exception | D11: Standing Order 15-3 ss.3.2-3.3
A12: No prior same-class declined/expired offer evidenced | B12: =COUNTIF('Queue Exceptions'!AD5:AD313,"Y") -> 48 | C12: Eligibility exception | D12: Tariff Resolution 2019-14 Schedule C C-1(3); covered/open used as slip class
A13: Offer export or physical-file mismatch | B13: =COUNTIF('Queue Exceptions'!AE5:AE313,"Y") -> 5 | C13: Record-integrity exception | D13: offer_events export compared with five in-period PDF files
A14: Length amendment history not reconciled to register | B14: =COUNTIF('Queue Exceptions'!AF5:AF313,"Y") -> 14 | C14: Record-integrity exception | D14: amendment_log compared with applicant_register snapshot
A15: In-force post-adoption LOA amendment lacking named accepted source | B15: =COUNTIF('Queue Exceptions'!AG5:AG313,"Y") -> 0 | C15: =IF(B15=0,"None identified","Exceptions found") -> None identified | D15: Resolution 2022-06 ss.4.3, 6.1-6.2
A16: BILLING RECONCILIATION
A17: Active occupied slips | B17: =COUNTA('Billing Reconciliations'!A5:A1090) -> 1086 | C17: Scope | D17: slip_inventory_2026-08.csv; OCCUPIED is active
A18: Exact August postings | B18: =COUNTIF('Billing Reconciliations'!AA5:AA1090,"MATCH*") -> 769 | D18: 1 August 2026 MONTHLY_MOORAGE rows matched by slip and tenant
A19: Confirmed posted-charge discrepancies | B19: =COUNTIF('Billing Reconciliations'!AA5:AA1090,"POSTED CHARGE MISMATCH") -> 0 | C19: =IF(B19=0,"None identified","Exceptions found") -> None identified | D19: Tariff billable length multiplied by the adopted basin rate
A20: Covered active vessels above 40 billable feet | B20: =COUNTIF('Billing Reconciliations'!P5:P1090,">0") -> 228 | C20: Eligibility review | D20: Resolution 2022-06 s.1.1 limits covered-slip eligibility; it does not cap billing
A21: No August posting in supplied export | B21: =COUNTIF('Billing Reconciliations'!AA5:AA1090,"NO AUGUST POSTING IN EXPORT") -> 317 | C21: Complete the export | D21: Absence is not treated as proof of a $0 bill
A22: Expected monthly moorage - all active | B22: =SUM('Billing Reconciliations'!S5:S1090) -> 439918.3 | D22: Greater of rounded check-in LOA or nominal slip; no billing cap stated
A23: Posted monthly moorage evidenced | B23: =SUM('Billing Reconciliations'!X5:X1090) -> 319760.05 | D23: Supplied 1 August 2026 posting population only
A24: Confirmed monthly variance (posted - expected) | B24: =SUM('Billing Reconciliations'!Y5:Y1090) -> 0 | C24: Overbilling if positive | D24: Does not assume absent postings are zero
A25: Expected charge for no-posting population | B25: =SUMIF('Billing Reconciliations'!AA5:AA1090,"NO AUGUST POSTING IN EXPORT",'Billing Reconciliations'!S5:S1090) -> 120158.25 | C25: Exposure only | D25: Actual variance cannot be determined from supplied export
A26: Apparent all-active export gap | B26: =SUM('Billing Reconciliations'!Z5:Z1090) -> -120158.25 | C26: Do not book | D26: Treats absent export rows as $0 solely as a completeness control
A27: AGING
A28: Active accounts more than 90 days delinquent | B28: =COUNTA(Aging!A5:A10) -> 6 | C28: Collections review | D28: AR_Aging days_90 (91-120) + days_120_plus
A29: Balance more than 90 days | B29: =SUM(Aging!K5:K10) -> 4368 | D29: July 31 close used as August 1 opening position
A30: Total due - reported delinquent accounts | B30: =SUM(Aging!L5:L10) -> 13166.4 | D30: Current through 120+ buckets
A31: Active slips represented in aging ledger | B31: =260 -> 260 | C31: Ledger is partial | D31: ar_aging_2026-07-31.xlsx Summary rows 2-7; 826 active slips omitted

Sheet Queue Exceptions
A1: QUEUE EXCEPTIONS | Rank-order and contemporaneous-file audit
A2: All 309 in-period events are retained. EXCEPTION is formula-driven from flags AB:AG; blank physical-file evidence is not treated as affirmative compliance.
A4: Skip ID | B4: Skip Date | C4: Applicant ID | D4: Applicant Name | E4: Rank at Offer | F4: Application Date | G4: Days on List at Skip | H4: Offer ID | I4: Slip ID (Export) | J4: Basin | K4: Class | L4: Slip Size Ft | M4: Reason Code | N4: Justification Category | O4: Docs Attached | P4: Doc Type | Q4: PDF / File Status | R4: Offer Link | S4: Prior Qualifying Offer | T4: Prior Offer Date | U4: Prior Offer Slip | V4: Prior Outcome | W4: Latest Post-8/1/22 LOA Amendment | X4: Amendment Source | Y4: Source Accepted | Z4: Amended LOA | AA4: Current Register LOA | AB4: Priority Chronology | AC4: Missing Required Attachment | AD4: Missing Same-Class Prior | AE4: Offer / File Conflict | AF4: Length History Mismatch | AG4: Unsupported Length Source | AH4: Audit Result | AI4: Findings | AJ4: Source References
A5: SKP-2023-0095 | B5: 44934 | C5: WL-03099 | D5: Ryan Robertson | E5: 2099 | F5: 45755 | G5: =B5-F5 -> -821 | H5: OFR-2023-0323 | I5: LP-0317 | J5: Ledgport | K5: COVERED | L5: 40 | M5: vessel-fit | N5: SLIP_SIZE_MISMATCH | O5: Y | P5: OTHER_SUPPORT | Q5: Not supplied | R5: MATCH | AA5: 53 | AB5: =IF(B5<F5,"Y","") -> Y | AC5: =IF(O5<>"Y","Y","") | AD5: =IF(AND(M5="declined-prior-offer",S5=""),"Y","") | AE5: =IF(OR(R5<>"MATCH",ISNUMBER(SEARCH("conflict",Q5))),"Y","") | AF5: =IF(AND(ISNUMBER(Z5),ABS(Z5-AA5)>0.001),"Y","") | AG5: =IF(AND(W5<>"",Y5<>"ACCEPTED"),"Y","") | AH5: =IF(COUNTIF(AB5:AG5,"Y")>0,"EXCEPTION","NO EXCEPTION IDENTIFIED") -> EXCEPTION | AI5: Skip predates current register application date | AJ5: skip_events_2022_2026.csv row 96; applicant_register_2026-08.csv row 2100; offer_events_2022_2026.csv row 324
A6: SKP-2023-0096 | B6: 44934 | C6: WL-02685 | D6: Stephanie Hill | E6: 1685 | F6: 45578 | G6: =B6-F6 -> -644 | H6: OFR-2023-0324 | I6: LP-0906 | J6: Ledgport | K6: COVERED | L6: 28 | M6: vessel-fit | N6: SLIP_SIZE_MISMATCH | O6: Y | P6: INSURANCE_DECL | Q6: Not supplied | R6: MATCH | AA6: 50.2 | AB6: =IF(B6<F6,"Y","") -> Y | AC6: =IF(O6<>"Y","Y","") | AD6: =IF(AND(M6="declined-prior-offer",S6=""),"Y","") | AE6: =IF(OR(R6<>"MATCH",ISNUMBER(SEARCH("conflict",Q6))),"Y","") | AF6: =IF(AND(ISNUMBER(Z6),ABS(Z6-AA6)>0.001),"Y","") | AG6: =IF(AND(W6<>"",Y6<>"ACCEPTED"),"Y","") | AH6: =IF(COUNTIF(AB6:AG6,"Y")>0,"EXCEPTION","NO EXCEPTION IDENTIFIED") -> EXCEPTION | AI6: Skip predates current register application date | AJ6: skip_events_2022_2026.csv row 97; applicant_register_2026-08.csv row 1686; offer_events_2022_2026.csv row 325
A7: SKP-2023-0098 | B7: 44934 | C7: WL-01959 | D7: Jonathan Moore | E7: 959 | F7: 45244 | G7: =B7-F7 -> -310 | H7: OFR-2023-0334 | I7: VB-1023 | J7: Vessbank | K7: COVERED | L7: 28 | M7: not-current | N7: INSURANCE_LAPSE | O7: Y | P7: WRITTEN_STATEMENT | Q7: Not supplied | R7: MATCH | AA7: 46.8 | AB7: =IF(B7<F7,"Y","") -> Y | AC7: =IF(O7<>"Y","Y","") | AD7: =IF(AND(M7="declined-prior-offer",S7=""),"Y","") | AE7: =IF(OR(R7<>"MATCH",ISNUMBER(SEARCH("conflict",Q7))),"Y","") | AF7: =IF(AND(ISNUMBER(Z7),ABS(Z7-AA7)>0.001),"Y","") | AG7: =IF(AND(W7<>"",Y7<>"ACCEPTED"),"Y","") | AH7: =IF(COUNTIF(AB7:AG7,"Y")>0,"EXCEPTION","NO EXCEPTION IDENTIFIED") -> EXCEPTION | AI7: Skip predates current register application date | AJ7: skip_events_2022_2026.csv row 99; applicant_register_2026-08.csv row 960; offer_events_2022_2026.csv row 335
A8: SKP-2023-0099 | B8: 44936 | C8: WL-01695 | D8: Antonio Leach | E8: 695 | F8: 45110 | G8: =B8-F8 -> -174 | H8: OFR-2023-0338 | I8: EW-0203 | J8: Eastwey | K8: OPEN | L8: 28 | M8: vessel-fit | N8: SLIP_SIZE_MISMATCH | O8: N | P8: INSURANCE_DECL | Q8: Not supplied | R8: MATCH | AA8: 24.6 | AB8: =IF(B8<F8,"Y","") -> Y | AC8: =IF(O8<>"Y","Y","") -> Y | AD8: =IF(AND(M8="declined-prior-offer",S8=""),"Y","") | AE8: =IF(OR(R8<>"MATCH",ISNUMBER(SEARCH("conflict",Q8))),"Y","") | AF8: =IF(AND(ISNUMBER(Z8),ABS(Z8-AA8)>0.001),"Y","") | AG8: =IF(AND(W8<>"",Y8<>"ACCEPTED"),"Y","") | AH8: =IF(COUNTIF(AB8:AG8,"Y")>0,"EXCEPTION","NO EXCEPTION IDENTIFIED") -> EXCEPTION | AI8: Skip predates current register application date; Supporting record not attached | AJ8: skip_events_2022_2026.csv row 100; applicant_register_2026-08.csv row 696; offer_events_2022_2026.csv row 339
A9: SKP-2023-0097 | B9: 44952 | C9: WL-01298 | D9: Jason Boyd | E9: 298 | F9: 44882 | G9: =B9-F9 -> 70 | H9: OFR-2023-0326 | I9: GW-0708 | J9: Gullwing | K9: OPEN | L9: 70 | M9: vessel-fit | N9: SLIP_SIZE_MISMATCH | O9: Y | P9: OTHER_SUPPORT | Q9: Not supplied | R9: MATCH | AA9: 19.2 | AB9: =IF(B9<F9,"Y","") | AC9: =IF(O9<>"Y","Y","") | AD9: =IF(AND(M9="declined-prior-offer",S9=""),"Y","") | AE9: =IF(OR(R9<>"MATCH",ISNUMBER(SEARCH("conflict",Q9))),"Y","") | AF9: =IF(AND(ISNUMBER(Z9),ABS(Z9-AA9)>0.001),"Y","") | AG9: =IF(AND(W9<>"",Y9<>"ACCEPTED"),"Y","") | AH9: =IF(COUNTIF(AB9:AG9,"Y")>0,"EXCEPTION","NO EXCEPTION IDENTIFIED") -> NO EXCEPTION IDENTIFIED | AI9: No exception identified from structured metadata; physical file not supplied | AJ9: skip_events_2022_2026.csv row 98; applicant_register_2026-08.csv row 299; offer_events_2022_2026.csv row 327
A10: SKP-2023-0102 | B10: 44967 | C10: WL-03582 | D10: Melissa Jones | E10: 2582 | F10: 45995 | G10: =B10-F10 -> -1028 | H10: OFR-2023-0346 | I10: GW-0615 | J10: Gullwing | K10: OPEN | L10: 24 | M10: not-current | N10: INSURANCE_LAPSE | O10: Y | P10: INSURANCE_DECL | Q10: Not supplied | R10: MATCH | AA10: 19.9 | AB10: =IF(B10<F10,"Y","") -> Y | AC10: =IF(O10<>"Y","Y","") | AD10: =IF(AND(M10="declined-prior-offer",S10=""),"Y","") | AE10: =IF(OR(R10<>"MATCH",ISNUMBER(SEARCH("conflict",Q10))),"Y","") | AF10: =IF(AND(ISNUMBER(Z10),ABS(Z10-AA10)>0.001),"Y","") | AG10: =IF(AND(W10<>"",Y10<>"ACCEPTED"),"Y","") | AH10: =IF(COUNTIF(AB10:AG10,"Y")>0,"EXCEPTION","NO EXCEPTION IDENTIFIED") -> EXCEPTION | AI10: Skip predates current register application date | AJ10: skip_events_2022_2026.csv row 103; applicant_register_2026-08.csv row 2583; offer_events_2022_2026.csv row 347
A11: SKP-2023-0103 | B11: 44974 | C11: WL-02918 | D11: Kara Aguilar | E11: 1918 | F11: 45673 | G11: =B11-F11 -> -699 | H11: OFR-2023-0350 | I11: LP-1116 | J11: Ledgport | K11: COVERED | L11: 28 | M11: declined-prior-offer | N11: OTHER | O11: Y | P11: OTHER_SUPPORT | Q11: Not supplied | R11: MATCH | AA11: 50.6 | AB11: =IF(B11<F11,"Y","") -> Y | AC11: =IF(O11<>"Y","Y","") | AD11: =IF(AND(M11="declined-prior-offer",S11=""),"Y","") -> Y | AE11: =IF(OR(R11<>"MATCH",ISNUMBER(SEARCH("conflict",Q11))),"Y","") | AF11: =IF(AND(ISNUMBER(Z11),ABS(Z11-AA11)>0.001),"Y","") | AG11: =IF(AND(W11<>"",Y11<>"ACCEPTED"),"Y","") | AH11: =IF(COUNTIF(AB11:AG11,"Y")>0,"EXCEPTION","NO EXCEPTION IDENTIFIED") -> EXCEPTION | AI11: Skip predates current register application date; No earlier same-class declined/expired offer in export | AJ11: skip_events_2022_2026.csv row 104; applicant_register_2026-08.csv row 1919; offer_events_2022_2026.csv row 351
A12: SKP-2023-0100 | B12: 44975 | C12: WL-02565 | D12: Christina Smith | E12: 1565 | F12: 45530 | G12: =B12-F12 -> -555 | H12: OFR-2023-0343 | I12: GW-0116 | J12: Gullwing | K12: OPEN | L12: 32 | M12: vessel-fit | N12: SLIP_SIZE_MISMATCH | O12: Y | P12: REPAIR_ESTIMATE | Q12: Not supplied | R12: MATCH | AA12: 42.9 | AB12: =IF(B12<F12,"Y","") -> Y | AC12: =IF(O12<>"Y","Y","") | AD12: =IF(AND(M12="declined-prior-offer",S12=""),"Y","") | AE12: =IF(OR(R12<>"MATCH",ISNUMBER(SEARCH("conflict",Q12))),"Y","") | AF12: =IF(AND(ISNUMBER(Z12),ABS(Z12-AA12)>0.001),"Y","") | AG12: =IF(AND(W12<>"",Y12<>"ACCEPTED"),"Y","") | AH12: =IF(COUNTIF(AB12:AG12,"Y")>0,"EXCEPTION","NO EXCEPTION IDENTIFIED") -> EXCEPTION | AI12: Skip predates current register application date | AJ12: skip_events_2022_2026.csv row 101; applicant_register_2026-08.csv row 1566; offer_events_2022_2026.csv row 344
A13: SKP-2023-0101 | B13: 44976 | C13: WL-02664 | D13: Mark Smith | E13: 1664 | F13: 45569 | G13: =B13-F13 -> -593 | H13: OFR-2023-0345 | I13: GW-0220 | J13: Gullwing | K13: OPEN | L13: 60 | M13: preference-mismatch | N13: LOCATION_PREF | O13: Y | P13: WRITTEN_STATEMENT | Q13: Not supplied | R13: MATCH | AA13: 54.5 | AB13: =IF(B13<F13,"Y","") -> Y | AC13: =IF(O13<>"Y","Y","") | AD13: =IF(AND(M13="declined-prior-offer",S13=""),"Y","") | AE13: =IF(OR(R13<>"MATCH",ISNUMBER(SEARCH("conflict",Q13))),"Y","") | AF13: =IF(AND(ISNUMBER(Z13),ABS(Z13-AA13)>0.001),"Y","") | AG13: =IF(AND(W13<>"",Y13<>"ACCEPTED"),"Y","") | AH13: =IF(COUNTIF(AB13:AG13,"Y")>0,"EXCEPTION","NO EXCEPTION IDENTIFIED") -> EXCEPTION | AI13: Skip predates current register application date | AJ13: skip_events_2022_2026.csv row 102; applicant_register_2026-08.csv row 1665; offer_events_2022_2026.csv row 346
A14: SKP-2023-0105 | B14: 44991 | C14: WL-02366 | D14: Megan Hoffman | E14: 1366 | F14: 45434 | G14: =B14-F14 -> -443 | H14: OFR-2023-0361 | I14: LP-1116 | J14: Ledgport | K14: COVERED | L14: 28 | M14: vessel-fit | N14: SLIP_SIZE_MISMATCH | O14: Y | P14: WRITTEN_STATEMENT | Q14: Not supplied | R14: MATCH | AA14: 51.4 | AB14: =IF(B14<F14,"Y","") -> Y | AC14: =IF(O14<>"Y","Y","") | AD14: =IF(AND(M14="declined-prior-offer",S14=""),"Y","") | AE14: =IF(OR(R14<>"MATCH",ISNUMBER(SEARCH("conflict",Q14))),"Y","") | AF14: =IF(AND(ISNUMBER(Z14),ABS(Z14-AA14)>0.001),"Y","") | AG14: =IF(AND(W14<>"",Y14<>"ACCEPTED"),"Y","") | AH14: =IF(COUNTIF(AB14:AG14,"Y")>0,"EXCEPTION","NO EXCEPTION IDENTIFIED") -> EXCEPTION | AI14: Skip predates current register application date | AJ14: skip_events_2022_2026.csv row 106; applicant_register_2026-08.csv row 1367; offer_events_2022_2026.csv row 362
A15: SKP-2023-0107 | B15: 44995 | C15: WL-01984 | D15: Vanessa Jackson | E15: 984 | F15: 45257 | G15: =B15-F15 -> -262 | H15: OFR-2023-0368 | I15: GW-0606 | J15: Gullwing | K15: OPEN | L15: 60 | M15: declined-prior-offer | N15: OTHER | O15: Y | P15: WRITTEN_STATEMENT | Q15: Not supplied | R15: MATCH | AA15: 41.9 | AB15: =IF(B15<F15,"Y","") -> Y | AC15: =IF(O15<>"Y","Y","") | AD15: =IF(AND(M15="declined-prior-offer",S15=""),"Y","") -> Y | AE15: =IF(OR(R15<>"MATCH",ISNUMBER(SEARCH("conflict",Q15))),"Y","") | AF15: =IF(AND(ISNUMBER(Z15),ABS(Z15-AA15)>0.001),"Y","") | AG15: =IF(AND(W15<>"",Y15<>"ACCEPTED"),"Y","") | AH15: =IF(COUNTIF(AB15:AG15,"Y")>0,"EXCEPTION","NO EXCEPTION IDENTIFIED") -> EXCEPTION | AI15: Skip predates current register application date; No earlier same-class declined/expired offer in export | AJ15: skip_events_2022_2026.csv row 108; applicant_register_2026-08.csv row 985; offer_events_2022_2026.csv row 369
A16: SKP-2023-0104 | B16: 45000 | C16: WL-03523 | D16: Darlene Glover | E16: 2523 | F16: 45963 | G16: =B16-F16 -> -963 | H16: OFR-2023-0360 | I16: SB-0210 | J16: Salmonberry | K16: OPEN | L16: 24 | M16: vessel-fit | N16: SLIP_SIZE_MISMATCH | O16: N | P16: WRITTEN_STATEMENT | Q16: Not supplied | R16: MATCH | AA16: 53.1 | AB16: =IF(B16<F16,"Y","") -> Y | AC16: =IF(O16<>"Y","Y","") -> Y | AD16: =IF(AND(M16="declined-prior-offer",S16=""),"Y","") | AE16: =IF(OR(R16<>"MATCH",ISNUMBER(SEARCH("conflict",Q16))),"Y","") | AF16: =IF(AND(ISNUMBER(Z16),ABS(Z16-AA16)>0.001),"Y","") | AG16: =IF(AND(W16<>"",Y16<>"ACCEPTED"),"Y","") | AH16: =IF(COUNTIF(AB16:AG16,"Y")>0,"EXCEPTION","NO EXCEPTION IDENTIFIED") -> EXCEPTION | AI16: Skip predates current register application date; Supporting record not attached | AJ16: skip_events_2022_2026.csv row 105; applicant_register_2026-08.csv row 2524; offer_events_2022_2026.csv row 361
... A29: SKP-2023-0129 | B29: 45048 | C29: WL-03178 | D29: Kristen Schneider | E29: 2178 | F29: 45790 | G29: =B29-F29 -> -742 | H29: OFR-2023-0440 | I29: VB-0810 | J29: Vessbank | K29: COVERED | L29: 32 | M29: vessel-fit | N29: SLIP_SIZE_MISMATCH | O29: Y | P29: REPAIR_ESTIMATE | Q29: Not supplied | R29: MATCH | AA29: 34.2 | AB29: =IF(B29<F29,"Y","") -> Y | AC29: =IF(O29<>"Y","Y","") | AD29: =IF(AND(M29="declined-prior-offer",S29=""),"Y","") | AE29: =IF(OR(R29<>"MATCH",ISNUMBER(SEARCH("conflict",Q29))),"Y","") | AF29: =IF(AND(ISNUMBER(Z29),ABS(Z29-AA29)>0.001),"Y","") | AG29: =IF(AND(W29<>"",Y29<>"ACCEPTED"),"Y","") | AH29: =IF(COUNTIF(AB29:AG29,"Y")>0,"EXCEPTION","NO EXCEPTION IDENTIFIED") -> EXCEPTION | AI29: Skip predates current register application date | AJ29: skip_events_2022_2026.csv row 130; applicant_register_2026-08.csv row 2179; offer_events_2022_2026.csv row 441
A30: SKP-2023-0408 | B30: 45048 | C30: WL-02618 | D30: Gary Tomlinson | E30: 1618 | F30: 45552 | G30: =B30-F30 -> -504 | H30: OFR-2023-1487 | I30: GW-0610 | J30: Gullwing | K30: OPEN | L30: 32 | M30: vessel-fit | N30: SLIP_SIZE_MISMATCH | O30: N | Q30: COVER ONLY; supporting record absent | R30: NO OFFER ID IN EXPORT | AA30: 27.8 | AB30: =IF(B30<F30,"Y","") -> Y | AC30: =IF(O30<>"Y","Y","") -> Y | AD30: =IF(AND(M30="declined-prior-offer",S30=""),"Y","") | AE30: =IF(OR(R30<>"MATCH",ISNUMBER(SEARCH("conflict",Q30))),"Y","") -> Y | AF30: =IF(AND(ISNUMBER(Z30),ABS(Z30-AA30)>0.001),"Y","") | AG30: =IF(AND(W30<>"",Y30<>"ACCEPTED"),"Y","") | AH30: =IF(COUNTIF(AB30:AG30,"Y")>0,"EXCEPTION","NO EXCEPTION IDENTIFIED") -> EXCEPTION | AI30: Skip predates current register application date; Supporting record not attached; Offer ID absent from offer export; Physical file conflicts with skip export | AJ30: skip_events_2022_2026.csv row 409; applicant_register_2026-08.csv row 1619; WL-02618_skip_justification.pdf p.1
A31: SKP-2023-0128 | B31: 45050 | C31: WL-03537 | D31: Angel Wheeler | E31: 2537 | F31: 45969 | G31: =B31-F31 -> -919 | H31: OFR-2023-0436 | I31: GW-0709 | J31: Gullwing | K31: OPEN | L31: 32 | M31: not-current | N31: INSURANCE_LAPSE | O31: Y | P31: OTHER_SUPPORT | Q31: Not supplied | R31: MATCH | AA31: 42.9 | AB31: =IF(B31<F31,"Y","") -> Y | AC31: =IF(O31<>"Y","Y","") | AD31: =IF(AND(M31="declined-prior-offer",S31=""),"Y","") | AE31: =IF(OR(R31<>"MATCH",ISNUMBER(SEARCH("conflict",Q31))),"Y","") | AF31: =IF(AND(ISNUMBER(Z31),ABS(Z31-AA31)>0.001),"Y","") | AG31: =IF(AND(W31<>"",Y31<>"ACCEPTED"),"Y","") | AH31: =IF(COUNTIF(AB31:AG31,"Y")>0,"EXCEPTION","NO EXCEPTION IDENTIFIED") -> EXCEPTION | AI31: Skip predates current register application date | AJ31: skip_events_2022_2026.csv row 129; applicant_register_2026-08.csv row 2538; offer_events_2022_2026.csv row 437
A32: SKP-2023-0119 | B32: 45051 | C32: WL-03151 | D32: Elizabeth King | E32: 2151 | F32: 45780 | G32: =B32-F32 -> -729 | H32: OFR-2023-0412 | I32: VB-0220 | J32: Vessbank | K32: COVERED | L32: 28 | M32: declined-prior-offer | N32: OTHER | O32: Y | P32: REPAIR_ESTIMATE | Q32: Not supplied | R32: MATCH | AA32: 59.5 | AB32: =IF(B32<F32,"Y","") -> Y | AC32: =IF(O32<>"Y","Y","") | AD32: =IF(AND(M32="declined-prior-offer",S32=""),"Y","") -> Y | AE32: =IF(OR(R32<>"MATCH",ISNUMBER(SEARCH("conflict",Q32))),"Y","") | AF32: =IF(AND(ISNUMBER(Z32),ABS(Z32-AA32)>0.001),"Y","") | AG32: =IF(AND(W32<>"",Y32<>"ACCEPTED"),"Y","") | AH32: =IF(COUNTIF(AB32:AG32,"Y")>0,"EXCEPTION","NO EXCEPTION IDENTIFIED") -> EXCEPTION | AI32: Skip predates current register application date; No earlier same-class declined/expired offer in export | AJ32: skip_events_2022_2026.csv row 120; applicant_register_2026-08.csv row 2152; offer_events_2022_2026.csv row 413
A33: SKP-2023-0126 | B33: 45056 | C33: WL-02134 | D33: James Martin | E33: 1134 | F33: 45330 | G33: =B33-F33 -> -274 | H33: OFR-2023-0432 | I33: EW-0320 | J33: Eastwey | K33: OPEN | L33: 60 | M33: not-current | N33: INSURANCE_LAPSE | O33: Y | P33: INSURANCE_DECL | Q33: Not supplied | R33: MATCH | AA33: 24.1 | AB33: =IF(B33<F33,"Y","") -> Y | AC33: =IF(O33<>"Y","Y","") | AD33: =IF(AND(M33="declined-prior-offer",S33=""),"Y","") | AE33: =IF(OR(R33<>"MATCH",ISNUMBER(SEARCH("conflict",Q33))),"Y","") | AF33: =IF(AND(ISNUMBER(Z33),ABS(Z33-AA33)>0.001),"Y","") | AG33: =IF(AND(W33<>"",Y33<>"ACCEPTED"),"Y","") | AH33: =IF(COUNTIF(AB33:AG33,"Y")>0,"EXCEPTION","NO EXCEPTION IDENTIFIED") -> EXCEPTION | AI33: Skip predates current register application date | AJ33: skip_events_2022_2026.csv row 127; applicant_register_2026-08.csv row 1135; offer_events_2022_2026.csv row 433
A34: SKP-2023-0121 | B34: 45058 | C34: WL-03181 | D34: Annette Collins | E34: 2181 | F34: 45792 | G34: =B34-F34 -> -734 | H34: OFR-2023-0418 | I34: SB-0903 | J34: Salmonberry | K34: OPEN | L34: 80 | M34: vessel-fit | N34: SLIP_SIZE_MISMATCH | O34: Y | P34: OTHER_SUPPORT | Q34: Not supplied | R34: MATCH | AA34: 36.5 | AB34: =IF(B34<F34,"Y","") -> Y | AC34: =IF(O34<>"Y","Y","") | AD34: =IF(AND(M34="declined-prior-offer",S34=""),"Y","") | AE34: =IF(OR(R34<>"MATCH",ISNUMBER(SEARCH("conflict",Q34))),"Y","") | AF34: =IF(AND(ISNUMBER(Z34),ABS(Z34-AA34)>0.001),"Y","") | AG34: =IF(AND(W34<>"",Y34<>"ACCEPTED"),"Y","") | AH34: =IF(COUNTIF(AB34:AG34,"Y")>0,"EXCEPTION","NO EXCEPTION IDENTIFIED") -> EXCEPTION | AI34: Skip predates current register application date | AJ34: skip_events_2022_2026.csv row 122; applicant_register_2026-08.csv row 2182; offer_events_2022_2026.csv row 419
A35: SKP-2023-0118 | B35: 45059 | C35: WL-02485 | D35: Matthew Dickerson | E35: 1485 | F35: 45489 | G35: =B35-F35 -> -430 | H35: OFR-2023-0411 | I35: VB-0521 | J35: Vessbank | K35: COVERED | L35: 32 | M35: not-current | N35: INSURANCE_LAPSE | O35: Y | P35: INSURANCE_DECL | Q35: Not supplied | R35: MATCH | AA35: 30.6 | AB35: =IF(B35<F35,"Y","") -> Y | AC35: =IF(O35<>"Y","Y","") | AD35: =IF(AND(M35="declined-prior-offer",S35=""),"Y","") | AE35: =IF(OR(R35<>"MATCH",ISNUMBER(SEARCH("conflict",Q35))),"Y","") | AF35: =IF(AND(ISNUMBER(Z35),ABS(Z35-AA35)>0.001),"Y","") | AG35: =IF(AND(W35<>"",Y35<>"ACCEPTED"),"Y","") | AH35: =IF(COUNTIF(AB35:AG35,"Y")>0,"EXCEPTION","NO EXCEPTION IDENTIFIED") -> EXCEPTION | AI35: Skip predates current register application date | AJ35: skip_events_2022_2026.csv row 119; applicant_register_2026-08.csv row 1486; offer_events_2022_2026.csv row 412
A36: SKP-2023-0124 | B36: 45065 | C36: WL-02100 | D36: Michelle Pena | E36: 1100 | F36: 45312 | G36: =B36-F36 -> -247 | H36: OFR-2023-0422 | I36: VB-0504 | J36: Vessbank | K36: COVERED | L36: 36 | M36: preference-mismatch | N36: LOCATION_PREF | O36: Y | P36: INSURANCE_DECL | Q36: Not supplied | R36: MATCH | AA36: 51.9 | AB36: =IF(B36<F36,"Y","") -> Y | AC36: =IF(O36<>"Y","Y","") | AD36: =IF(AND(M36="declined-prior-offer",S36=""),"Y","") | AE36: =IF(OR(R36<>"MATCH",ISNUMBER(SEARCH("conflict",Q36))),"Y","") | AF36: =IF(AND(ISNUMBER(Z36),ABS(Z36-AA36)>0.001),"Y","") | AG36: =IF(AND(W36<>"",Y36<>"ACCEPTED"),"Y","") | AH36: =IF(COUNTIF(AB36:AG36,"Y")>0,"EXCEPTION","NO EXCEPTION IDENTIFIED") -> EXCEPTION | AI36: Skip predates current register application date | AJ36: skip_events_2022_2026.csv row 125; applicant_register_2026-08.csv row 1101; offer_events_2022_2026.csv row 423
A37: SKP-2023-0122 | B37: 45066 | C37: WL-03816 | D37: Brittany Lopez | E37: 2816 | F37: 46141 | G37: =B37-F37 -> -1075 | H37: OFR-2023-0419 | I37: VB-0113 | J37: Vessbank | K37: COVERED | L37: 28 | M37: preference-mismatch | N37: LOCATION_PREF | O37: Y | P37: OTHER_SUPPORT | Q37: Not supplied | R37: MATCH | AA37: 25.7 | AB37: =IF(B37<F37,"Y","") -> Y | AC37: =IF(O37<>"Y","Y","") | AD37: =IF(AND(M37="declined-prior-offer",S37=""),"Y","") | AE37: =IF(OR(R37<>"MATCH",ISNUMBER(SEARCH("conflict",Q37))),"Y","") | AF37: =IF(AND(ISNUMBER(Z37),ABS(Z37-AA37)>0.001),"Y","") | AG37: =IF(AND(W37<>"",Y37<>"ACCEPTED"),"Y","") | AH37: =IF(COUNTIF(AB37:AG37,"Y")>0,"EXCEPTION","NO EXCEPTION IDENTIFIED") -> EXCEPTION | AI37: Skip predates current register application date | AJ37: skip_events_2022_2026.csv row 123; applicant_register_2026-08.csv row 2817; offer_events_2022_2026.csv row 420
A38: SKP-2023-0123 | B38: 45067 | C38: WL-03712 | D38: Charles Graham | E38: 2712 | F38: 46065 | G38: =B38-F38 -> -998 | H38: OFR-2023-0421 | I38: LP-0113 | J38: Ledgport | K38: COVERED | L38: 36 | M38: declined-prior-offer | N38: OTHER | O38: Y | P38: INSURANCE_DECL | Q38: Not supplied | R38: MATCH | AA38: 38.8 | AB38: =IF(B38<F38,"Y","") -> Y | AC38: =IF(O38<>"Y","Y","") | AD38: =IF(AND(M38="declined-prior-offer",S38=""),"Y","") -> Y | AE38: =IF(OR(R38<>"MATCH",ISNUMBER(SEARCH("conflict",Q38))),"Y","") | AF38: =IF(AND(ISNUMBER(Z38),ABS(Z38-AA38)>0.001),"Y","") | AG38: =IF(AND(W38<>"",Y38<>"ACCEPTED"),"Y","") | AH38: =IF(COUNTIF(AB38:AG38,"Y")>0,"EXCEPTION","NO EXCEPTION IDENTIFIED") -> EXCEPTION | AI38: Skip predates current register application date; No earlier same-class declined/expired offer in export | AJ38: skip_events_2022_2026.csv row 124; applicant_register_2026-08.csv row 2713; offer_events_2022_2026.csv row 422
A39: SKP-2023-0125 | B39: 45067 | C39: WL-02777 | D39: Carolyn Johnson | E39: 1777 | F39: 45618 | G39: =B39-F39 -> -551 | H39: OFR-2023-0429 | I39: LP-0402 | J39: Ledgport | K39: COVERED | L39: 28 | M39: vessel-fit | N39: SLIP_SIZE_MISMATCH | O39: Y | P39: OTHER_SUPPORT | Q39: Not supplied | R39: MATCH | AA39: 30.7 | AB39: =IF(B39<F39,"Y","") -> Y | AC39: =IF(O39<>"Y","Y","") | AD39: =IF(AND(M39="declined-prior-offer",S39=""),"Y","") | AE39: =IF(OR(R39<>"MATCH",ISNUMBER(SEARCH("conflict",Q39))),"Y","") | AF39: =IF(AND(ISNUMBER(Z39),ABS(Z39-AA39)>0.001),"Y","") | AG39: =IF(AND(W39<>"",Y39<>"ACCEPTED"),"Y","") | AH39: =IF(COUNTIF(AB39:AG39,"Y")>0,"EXCEPTION","NO EXCEPTION IDENTIFIED") -> EXCEPTION | AI39: Skip predates current register application date | AJ39: skip_events_2022_2026.csv row 126; applicant_register_2026-08.csv row 1778; offer_events_2022_2026.csv row 430
A40: SKP-2023-0127 | B40: 45067 | C40: WL-01420 | D40: Patricia Wilson | E40: 420 | F40: 44951 | G40: =B40-F40 -> 116 | H40: OFR-2023-0435 | I40: SB-0405 | J40: Salmonberry | K40: OPEN | L40: 45 | M40: vessel-fit | N40: SLIP_SIZE_MISMATCH | O40: Y | P40: REPAIR_ESTIMATE | Q40: Not supplied | R40: MATCH | AA40: 26.2 | AB40: =IF(B40<F40,"Y","") | AC40: =IF(O40<>"Y","Y","") | AD40: =IF(AND(M40="declined-prior-offer",S40=""),"Y","") | AE40: =IF(OR(R40<>"MATCH",ISNUMBER(SEARCH("conflict",Q40))),"Y","") | AF40: =IF(AND(ISNUMBER(Z40),ABS(Z40-AA40)>0.001),"Y","") | AG40: =IF(AND(W40<>"",Y40<>"ACCEPTED"),"Y","") | AH40: =IF(COUNTIF(AB40:AG40,"Y")>0,"EXCEPTION","NO EXCEPTION IDENTIFIED") -> NO EXCEPTION IDENTIFIED | AI40: No exception identified from structured metadata; physical file not supplied | AJ40: skip_events_2022_2026.csv row 128; applicant_register_2026-08.csv row 421; offer_events_2022_2026.csv row 436
A41: SKP-2023-0137 | B41: 45084 | C41: WL-02535 | D41: Shari Hess | E41: 1535 | F41: 45514 | G41: =B41-F41 -> -430 | H41: OFR-2023-0462 | I41: VB-0805 | J41: Vessbank | K41: COVERED | L41: 32 | M41: declined-prior-offer | N41: OTHER | O41: Y | P41: INSURANCE_DECL | Q41: Not supplied | R41: MATCH | S41: OFR-2022-0264 | T41: 44853 | U41: LP-1019 | V41: EXPIRED | AA41: 19.4 | AB41: =IF(B41<F41,"Y","") -> Y | AC41: =IF(O41<>"Y","Y","") | AD41: =IF(AND(M41="declined-prior-offer",S41=""),"Y","") | AE41: =IF(OR(R41<>"MATCH",ISNUMBER(SEARCH("conflict",Q41))),"Y","") | AF41: =IF(AND(ISNUMBER(Z41),ABS(Z41-AA41)>0.001),"Y","") | AG41: =IF(AND(W41<>"",Y41<>"ACCEPTED"),"Y","") | AH41: =IF(COUNTIF(AB41:AG41,"Y")>0,"EXCEPTION","NO EXCEPTION IDENTIFIED") -> EXCEPTION | AI41: Skip predates current register application date | AJ41: skip_events_2022_2026.csv row 138; applicant_register_2026-08.csv row 1536; offer_events_2022_2026.csv row 463
A42: SKP-2023-0132 | B42: 45085 | C42: WL-01193 | D42: Mindy Medina | E42: 193 | F42: 44799 | G42: =B42-F42 -> 286 | H42: OFR-2023-0449 | I42: VB-0205 | J42: Vessbank | K42: COVERED | L42: 28 | M42: declined-prior-offer | N42: OTHER | O42: Y | P42: REPAIR_ESTIMATE | Q42: Not supplied | R42: MATCH | AA42: 20.2 | AB42: =IF(B42<F42,"Y","") | AC42: =IF(O42<>"Y","Y","") | AD42: =IF(AND(M42="declined-prior-offer",S42=""),"Y","") -> Y | AE42: =IF(OR(R42<>"MATCH",ISNUMBER(SEARCH("conflict",Q42))),"Y","") | AF42: =IF(AND(ISNUMBER(Z42),ABS(Z42-AA42)>0.001),"Y","") | AG42: =IF(AND(W42<>"",Y42<>"ACCEPTED"),"Y","") | AH42: =IF(COUNTIF(AB42:AG42,"Y")>0,"EXCEPTION","NO EXCEPTION IDENTIFIED") -> EXCEPTION | AI42: No earlier same-class declined/expired offer in export | AJ42: skip_events_2022_2026.csv row 133; applicant_register_2026-08.csv row 194; offer_events_2022_2026.csv row 450
A43: SKP-2023-0136 | B43: 45085 | C43: WL-03758 | D43: Sean Cherry | E43: 2758 | F43: 46098 | G43: =B43-F43 -> -1013 | H43: OFR-2023-0461 | I43: LP-0121 | J43: Ledgport | K43: COVERED | L43: 32 | M43: preference-mismatch | N43: LOCATION_PREF | O43: Y | P43: OTHER_SUPPORT | Q43: Not supplied | R43: MATCH | W43: 44895 | X43: MC-2022-0410 | Y43: ACCEPTED | Z43: 51.4 | AA43: 41.1 | AB43: =IF(B43<F43,"Y","") -> Y | AC43: =IF(O43<>"Y","Y","") | AD43: =IF(AND(M43="declined-prior-offer",S43=""),"Y","") | AE43: =IF(OR(R43<>"MATCH",ISNUMBER(SEARCH("conflict",Q43))),"Y","") | AF43: =IF(AND(ISNUMBER(Z43),ABS(Z43-AA43)>0.001),"Y","") -> Y | AG43: =IF(AND(W43<>"",Y43<>"ACCEPTED"),"Y","") | AH43: =IF(COUNTIF(AB43:AG43,"Y")>0,"EXCEPTION","NO EXCEPTION IDENTIFIED") -> EXCEPTION | AI43: Skip predates current register application date; In-force amendment does not reconcile to current register LOA | AJ43: skip_events_2022_2026.csv row 137; applicant_register_2026-08.csv row 2759; offer_events_2022_2026.csv row 462; amendment_log_2022_2026.csv row 436
A44: SKP-2023-0139 | B44: 45086 | C44: WL-01129 | D44: Alexander Thompson | E44: 129 | F44: 44741 | G44: =B44-F44 -> 345 | H44: OFR-2023-0469 | I44: GW-0414 | J44: Gullwing | K44: OPEN | L44: 45 | M44: preference-mismatch | N44: LOCATION_PREF | O44: Y | P44: WRITTEN_STATEMENT | Q44: Not supplied | R44: MATCH | AA44: 27.8 | AB44: =IF(B44<F44,"Y","") | AC44: =IF(O44<>"Y","Y","") | AD44: =IF(AND(M44="declined-prior-offer",S44=""),"Y","") | AE44: =IF(OR(R44<>"MATCH",ISNUMBER(SEARCH("conflict",Q44))),"Y","") | AF44: =IF(AND(ISNUMBER(Z44),ABS(Z44-AA44)>0.001),"Y","") | AG44: =IF(AND(W44<>"",Y44<>"ACCEPTED"),"Y","") | AH44: =IF(COUNTIF(AB44:AG44,"Y")>0,"EXCEPTION","NO EXCEPTION IDENTIFIED") -> NO EXCEPTION IDENTIFIED | AI44: No exception identified from structured metadata; physical file not supplied | AJ44: skip_events_2022_2026.csv row 140; applicant_register_2026-08.csv row 130; offer_events_2022_2026.csv row 470
A45: SKP-2023-0133 | B45: 45087 | C45: WL-01319 | D45: Janice Roy | E45: 319 | F45: 44898 | G45: =B45-F45 -> 189 | H45: OFR-2023-0457 | I45: GW-1008 | J45: Gullwing | K45: OPEN | L45: 60 | M45: not-current | N45: INSURANCE_LAPSE | O45: Y | P45: INSURANCE_DECL | Q45: Not supplied | R45: MATCH | AA45: 59.6 | AB45: =IF(B45<F45,"Y","") | AC45: =IF(O45<>"Y","Y","") | AD45: =IF(AND(M45="declined-prior-offer",S45=""),"Y","") | AE45: =IF(OR(R45<>"MATCH",ISNUMBER(SEARCH("conflict",Q45))),"Y","") | AF45: =IF(AND(ISNUMBER(Z45),ABS(Z45-AA45)>0.001),"Y","") | AG45: =IF(AND(W45<>"",Y45<>"ACCEPTED"),"Y","") | AH45: =IF(COUNTIF(AB45:AG45,"Y")>0,"EXCEPTION","NO EXCEPTION IDENTIFIED") -> NO EXCEPTION IDENTIFIED | AI45: No exception identified from structured metadata; physical file not supplied | AJ45: skip_events_2022_2026.csv row 134; applicant_register_2026-08.csv row 320; offer_events_2022_2026.csv row 458
A46: SKP-2023-0130 | B46: 45089 | C46: WL-02924 | D46: Heather Hall | E46: 1924 | F46: 45678 | G46: =B46-F46 -> -589 | H46: OFR-2023-0447 | I46: VB-0720 | J46: Vessbank | K46: COVERED | L46: 40 | M46: not-current | N46: INSURANCE_LAPSE | O46: Y | P46: INSURANCE_DECL | Q46: Not supplied | R46: MATCH | AA46: 22.2 | AB46: =IF(B46<F46,"Y","") -> Y | AC46: =IF(O46<>"Y","Y","") | AD46: =IF(AND(M46="declined-prior-offer",S46=""),"Y","") | AE46: =IF(OR(R46<>"MATCH",ISNUMBER(SEARCH("conflict",Q46))),"Y","") | AF46: =IF(AND(ISNUMBER(Z46),ABS(Z46-AA46)>0.001),"Y","") | AG46: =IF(AND(W46<>"",Y46<>"ACCEPTED"),"Y","") | AH46: =IF(COUNTIF(AB46:AG46,"Y")>0,"EXCEPTION","NO EXCEPTION IDENTIFIED") -> EXCEPTION | AI46: Skip predates current register application date | AJ46: skip_events_2022_2026.csv row 131; applicant_register_2026-08.csv row 1925; offer_events_2022_2026.csv row 448
A47: SKP-2023-0140 | B47: 45089 | C47: WL-03100 | D47: Andrew Contreras | E47: 2100 | F47: 45755 | G47: =B47-F47 -> -666 | H47: OFR-2023-0473 | I47: EW-0622 | J47: Eastwey | K47: OPEN | L47: 70 | M47: vessel-fit | N47: SLIP_SIZE_MISMATCH | O47: Y | P47: REPAIR_ESTIMATE | Q47: Not supplied | R47: MATCH | AA47: 52.1 | AB47: =IF(B47<F47,"Y","") -> Y | AC47: =IF(O47<>"Y","Y","") | AD47: =IF(AND(M47="declined-prior-offer",S47=""),"Y","") | AE47: =IF(OR(R47<>"MATCH",ISNUMBER(SEARCH("conflict",Q47))),"Y","") | AF47: =IF(AND(ISNUMBER(Z47),ABS(Z47-AA47)>0.001),"Y","") | AG47: =IF(AND(W47<>"",Y47<>"ACCEPTED"),"Y","") | AH47: =IF(COUNTIF(AB47:AG47,"Y")>0,"EXCEPTION","NO EXCEPTION IDENTIFIED") -> EXCEPTION | AI47: Skip predates current register application date | AJ47: skip_events_2022_2026.csv row 141; applicant_register_2026-08.csv row 2101; offer_events_2022_2026.csv row 474
A48: SKP-2023-0138 | B48: 45090 | C48: WL-02663 | D48: Susan Thompson | E48: 1663 | F48: 45569 | G48: =B48-F48 -> -479 | H48: OFR-2023-0464 | I48: GW-0810 | J48: Gullwing | K48: OPEN | L48: 70 | M48: vessel-fit | N48: SLIP_SIZE_MISMATCH | O48: Y | P48: INSURANCE_DECL | Q48: Not supplied | R48: MATCH | AA48: 43.8 | AB48: =IF(B48<F48,"Y","") -> Y | AC48: =IF(O48<>"Y","Y","") | AD48: =IF(AND(M48="declined-prior-offer",S48=""),"Y","") | AE48: =IF(OR(R48<>"MATCH",ISNUMBER(SEARCH("conflict",Q48))),"Y","") | AF48: =IF(AND(ISNUMBER(Z48),ABS(Z48-AA48)>0.001),"Y","") | AG48: =IF(AND(W48<>"",Y48<>"ACCEPTED"),"Y","") | AH48: =IF(COUNTIF(AB48:AG48,"Y")>0,"EXCEPTION","NO EXCEPTION IDENTIFIED") -> EXCEPTION | AI48: Skip predates current register application date | AJ48: skip_events_2022_2026.csv row 139; applicant_register_2026-08.csv row 1664; offer_events_2022_2026.csv row 465
A49: SKP-2023-0131 | B49: 45092 | C49: WL-01781 | D49: Crystal Parrish | E49: 781 | F49: 45160 | G49: =B49-F49 -> -68 | H49: OFR-2023-0448 | I49: LP-0220 | J49: Ledgport | K49: COVERED | L49: 28 | M49: preference-mismatch | N49: LOCATION_PREF | O49: N | P49: OTHER_SUPPORT | Q49: Not supplied | R49: MATCH | AA49: 35.2 | AB49: =IF(B49<F49,"Y","") -> Y | AC49: =IF(O49<>"Y","Y","") -> Y | AD49: =IF(AND(M49="declined-prior-offer",S49=""),"Y","") | AE49: =IF(OR(R49<>"MATCH",ISNUMBER(SEARCH("conflict",Q49))),"Y","") | AF49: =IF(AND(ISNUMBER(Z49),ABS(Z49-AA49)>0.001),"Y","") | AG49: =IF(AND(W49<>"",Y49<>"ACCEPTED"),"Y","") | AH49: =IF(COUNTIF(AB49:AG49,"Y")>0,"EXCEPTION","NO EXCEPTION IDENTIFIED") -> EXCEPTION | AI49: Skip predates current register application date; Supporting record not attached | AJ49: skip_events_2022_2026.csv row 132; applicant_register_2026-08.csv row 782; offer_events_2022_2026.csv row 449
A50: SKP-2023-0134 | B50: 45101 | C50: WL-02173 | D50: Lisa Parker | E50: 1173 | F50: 45350 | G50: =B50-F50 -> -249 | H50: OFR-2023-0458 | I50: SB-0205 | J50: Salmonberry | K50: OPEN | L50: 45 | M50: vessel-fit | N50: SLIP_SIZE_MISMATCH | O50: Y | P50: WRITTEN_STATEMENT | Q50: Not supplied | R50: MATCH | AA50: 38.4 | AB50: =IF(B50<F50,"Y","") -> Y | AC50: =IF(O50<>"Y","Y","") | AD50: =IF(AND(M50="declined-prior-offer",S50=""),"Y","") | AE50: =IF(OR(R50<>"MATCH",ISNUMBER(SEARCH("conflict",Q50))),"Y","") | AF50: =IF(AND(ISNUMBER(Z50),ABS(Z50-AA50)>0.001),"Y","") | AG50: =IF(AND(W50<>"",Y50<>"ACCEPTED"),"Y","") | AH50: =IF(COUNTIF(AB50:AG50,"Y")>0,"EXCEPTION","NO EXCEPTION IDENTIFIED") -> EXCEPTION | AI50: Skip predates current register application date | AJ50: skip_events_2022_2026.csv row 135; applicant_register_2026-08.csv row 1174; offer_events_2022_2026.csv row 459
A51: SKP-2023-0135 | B51: 45102 | C51: WL-01568 | D51: Rebecca Lozano | E51: 568 | F51: 45039 | G51: =B51-F51 -> 63 | H51: OFR-2023-0460 | I51: LP-0219 | J51: Ledgport | K51: COVERED | L51: 28 | M51: declined-prior-offer | N51: OTHER | O51: Y | P51: INSURANCE_DECL | Q51: Not supplied | R51: MATCH | AA51: 27.4 | AB51: =IF(B51<F51,"Y","") | AC51: =IF(O51<>"Y","Y","") | AD51: =IF(AND(M51="declined-prior-offer",S51=""),"Y","") -> Y | AE51: =IF(OR(R51<>"MATCH",ISNUMBER(SEARCH("conflict",Q51))),"Y","") | AF51: =IF(AND(ISNUMBER(Z51),ABS(Z51-AA51)>0.001),"Y","") | AG51: =IF(AND(W51<>"",Y51<>"ACCEPTED"),"Y","") | AH51: =IF(COUNTIF(AB51:AG51,"Y")>0,"EXCEPTION","NO EXCEPTION IDENTIFIED") -> EXCEPTION | AI51: No earlier same-class declined/expired offer in export | AJ51: skip_events_2022_2026.csv row 136; applicant_register_2026-08.csv row 569; offer_events_2022_2026.csv row 461
A52: SKP-2023-0143 | B52: 45110 | C52: WL-01712 | D52: Kevin Liu | E52: 712 | F52: 45120 | G52: =B52-F52 -> -10 | H52: OFR-2023-0481 | I52: GW-0118 | J52: Gullwing | K52: OPEN | L52: 60 | M52: vessel-fit | N52: SLIP_SIZE_MISMATCH | O52: Y | P52: INSURANCE_DECL | Q52: Not supplied | R52: MATCH | AA52: 49.4 | AB52: =IF(B52<F52,"Y","") -> Y | AC52: =IF(O52<>"Y","Y","") | AD52: =IF(AND(M52="declined-prior-offer",S52=""),"Y","") | AE52: =IF(OR(R52<>"MATCH",ISNUMBER(SEARCH("conflict",Q52))),"Y","") | AF52: =IF(AND(ISNUMBER(Z52),ABS(Z52-AA52)>0.001),"Y","") | AG52: =IF(AND(W52<>"",Y52<>"ACCEPTED"),"Y","") | AH52: =IF(COUNTIF(AB52:AG52,"Y")>0,"EXCEPTION","NO EXCEPTION IDENTIFIED") -> EXCEPTION | AI52: Skip predates current register application date | AJ52: skip_events_2022_2026.csv row 144; applicant_register_2026-08.csv row 713; offer_events_2022_2026.csv row 482
A53: SKP-2023-0150 | B53: 45110 | C53: WL-01924 | D53: Angela Alexander | E53: 924 | F53: 45230 | G53: =B53-F53 -> -120 | H53: OFR-2023-0501 | I53: EW-0111 | J53: Eastwey | K53: OPEN | L53: 28 | M53: vessel-fit | N53: SLIP_SIZE_MISMATCH | O53: Y | P53: WRITTEN_STATEMENT | Q53: Not supplied | R53: MATCH | AA53: 21.2 | AB53: =IF(B53<F53,"Y","") -> Y | AC53: =IF(O53<>"Y","Y","") | AD53: =IF(AND(M53="declined-prior-offer",S53=""),"Y","") | AE53: =IF(OR(R53<>"MATCH",ISNUMBER(SEARCH("conflict",Q53))),"Y","") | AF53: =IF(AND(ISNUMBER(Z53),ABS(Z53-AA53)>0.001),"Y","") | AG53: =IF(AND(W53<>"",Y53<>"ACCEPTED"),"Y","") | AH53: =IF(COUNTIF(AB53:AG53,"Y")>0,"EXCEPTION","NO EXCEPTION IDENTIFIED") -> EXCEPTION | AI53: Skip predates current register application date | AJ53: skip_events_2022_2026.csv row 151; applicant_register_2026-08.csv row 925; offer_events_2022_2026.csv row 502
...

Sheet Billing Reconciliations
A1: BILLING RECONCILIATIONS | Active slips at 1 August 2026
A2: Variance Y = posted minus expected and is blank where no posting is evidenced. Control gap Z treats absent export rows as $0 only to test completeness.
A4: Slip ID | B4: Basin | C4: Basin Class | D4: Status | E4: Agreement | F4: Tenant ID | G4: Tenant Name | H4: Vessel | I4: Nominal Slip Ft | J4: Inventory LOA | K4: Certificate | L4: Certificate LOA | M4: Measurement Used | N4: Rounded Vessel Ft | O4: Raw Billable Ft | P4: Covered Eligibility Excess Ft | Q4: Expected Billable Ft | R4: Tariff Rate | S4: Expected Monthly | T4: Transaction ID | U4: Post Date | V4: Posted Feet | W4: Posted Rate | X4: Posted Monthly | Y4: Confirmed Variance | Z4: Apparent Export Gap | AA4: Reconciliation Result | AB4: Source References
A5: EW-0101 | B5: Eastwey | C5: OPEN | D5: OCCUPIED | E5: MA-2024-0101 | F5: WL-01414 | G5: Phillip Massey | H5: POINT SHORE | I5: 80 | J5: 29.3 | M5: =IF(ISNUMBER(L5),L5,J5) -> 29.3 | N5: =ROUNDUP(M5,0) -> 30 | O5: =MAX(I5,N5) -> 80 | P5: =IF(C5="COVERED",MAX(0,O5-40),0) -> 0 | Q5: =O5 -> 80 | R5: =IF(C5="COVERED",10.4,7.55) -> 7.55 | S5: =Q5*R5 -> 604 | T5: TXN-202608-028684 | U5: 46235 | V5: 80 | W5: 7.55 | X5: 604 | Y5: =IF(ISNUMBER(X5),X5-S5,"") -> 0 | Z5: =IF(ISNUMBER(X5),X5-S5,-S5) -> 0 | AA5: =IF(NOT(ISNUMBER(X5)),"NO AUGUST POSTING IN EXPORT",IF(ABS(Y5)>=0.005,"POSTED CHARGE MISMATCH",IF(P5>0,"MATCH - COVERED ELIGIBILITY EXCEPTION","MATCH"))) -> MATCH | AB5: slip_inventory_2026-08.csv row 502; billing_transactions_2022_2026.csv row 46365
A6: EW-0102 | B6: Eastwey | C6: OPEN | D6: OCCUPIED | E6: MA-2024-0102 | F6: WL-03666 | G6: Andrea Franco | H6: GRAY SONG | I6: 24 | J6: 55.3 | M6: =IF(ISNUMBER(L6),L6,J6) -> 55.3 | N6: =ROUNDUP(M6,0) -> 56 | O6: =MAX(I6,N6) -> 56 | P6: =IF(C6="COVERED",MAX(0,O6-40),0) -> 0 | Q6: =O6 -> 56 | R6: =IF(C6="COVERED",10.4,7.55) -> 7.55 | S6: =Q6*R6 -> 422.8 | T6: TXN-202608-028767 | U6: 46235 | V6: 56 | W6: 7.55 | X6: 422.8 | Y6: =IF(ISNUMBER(X6),X6-S6,"") -> 0 | Z6: =IF(ISNUMBER(X6),X6-S6,-S6) -> 0 | AA6: =IF(NOT(ISNUMBER(X6)),"NO AUGUST POSTING IN EXPORT",IF(ABS(Y6)>=0.005,"POSTED CHARGE MISMATCH",IF(P6>0,"MATCH - COVERED ELIGIBILITY EXCEPTION","MATCH"))) -> MATCH | AB6: slip_inventory_2026-08.csv row 503; billing_transactions_2022_2026.csv row 46367
A7: EW-0103 | B7: Eastwey | C7: OPEN | D7: OCCUPIED | E7: MA-2024-0103 | F7: WL-01149 | G7: David Hoffman | H7: MURRE RUNNER | I7: 36 | J7: 42.6 | M7: =IF(ISNUMBER(L7),L7,J7) -> 42.6 | N7: =ROUNDUP(M7,0) -> 43 | O7: =MAX(I7,N7) -> 43 | P7: =IF(C7="COVERED",MAX(0,O7-40),0) -> 0 | Q7: =O7 -> 43 | R7: =IF(C7="COVERED",10.4,7.55) -> 7.55 | S7: =Q7*R7 -> 324.65 | T7: TXN-202608-028831 | U7: 46235 | V7: 43 | W7: 7.55 | X7: 324.65 | Y7: =IF(ISNUMBER(X7),X7-S7,"") -> 0 | Z7: =IF(ISNUMBER(X7),X7-S7,-S7) -> 0 | AA7: =IF(NOT(ISNUMBER(X7)),"NO AUGUST POSTING IN EXPORT",IF(ABS(Y7)>=0.005,"POSTED CHARGE MISMATCH",IF(P7>0,"MATCH - COVERED ELIGIBILITY EXCEPTION","MATCH"))) -> MATCH | AB7: slip_inventory_2026-08.csv row 504; billing_transactions_2022_2026.csv row 46369
A8: EW-0105 | B8: Eastwey | C8: OPEN | D8: OCCUPIED | E8: MA-2024-0105 | F8: WL-03242 | G8: Micheal Navarro | H8: SABLE MOON | I8: 36 | J8: 60.2 | M8: =IF(ISNUMBER(L8),L8,J8) -> 60.2 | N8: =ROUNDUP(M8,0) -> 61 | O8: =MAX(I8,N8) -> 61 | P8: =IF(C8="COVERED",MAX(0,O8-40),0) -> 0 | Q8: =O8 -> 61 | R8: =IF(C8="COVERED",10.4,7.55) -> 7.55 | S8: =Q8*R8 -> 460.55 | T8: TXN-202608-028897 | U8: 46235 | V8: 61 | W8: 7.55 | X8: 460.55 | Y8: =IF(ISNUMBER(X8),X8-S8,"") -> 0 | Z8: =IF(ISNUMBER(X8),X8-S8,-S8) -> 0 | AA8: =IF(NOT(ISNUMBER(X8)),"NO AUGUST POSTING IN EXPORT",IF(ABS(Y8)>=0.005,"POSTED CHARGE MISMATCH",IF(P8>0,"MATCH - COVERED ELIGIBILITY EXCEPTION","MATCH"))) -> MATCH | AB8: slip_inventory_2026-08.csv row 506; billing_transactions_2022_2026.csv row 46371
A9: EW-0106 | B9: Eastwey | C9: OPEN | D9: OCCUPIED | E9: MA-2024-0106 | F9: WL-03380 | G9: Charles Snyder | H9: PETREL STAR | I9: 45 | J9: 47.5 | M9: =IF(ISNUMBER(L9),L9,J9) -> 47.5 | N9: =ROUNDUP(M9,0) -> 48 | O9: =MAX(I9,N9) -> 48 | P9: =IF(C9="COVERED",MAX(0,O9-40),0) -> 0 | Q9: =O9 -> 48 | R9: =IF(C9="COVERED",10.4,7.55) -> 7.55 | S9: =Q9*R9 -> 362.4 | T9: TXN-202608-028973 | U9: 46235 | V9: 48 | W9: 7.55 | X9: 362.4 | Y9: =IF(ISNUMBER(X9),X9-S9,"") -> 0 | Z9: =IF(ISNUMBER(X9),X9-S9,-S9) -> 0 | AA9: =IF(NOT(ISNUMBER(X9)),"NO AUGUST POSTING IN EXPORT",IF(ABS(Y9)>=0.005,"POSTED CHARGE MISMATCH",IF(P9>0,"MATCH - COVERED ELIGIBILITY EXCEPTION","MATCH"))) -> MATCH | AB9: slip_inventory_2026-08.csv row 507; billing_transactions_2022_2026.csv row 46372
A10: EW-0107 | B10: Eastwey | C10: OPEN | D10: OCCUPIED | E10: MA-2024-0107 | F10: WL-01368 | G10: Justin Turner | H10: SABLE WIND | I10: 28 | J10: 23.7 | M10: =IF(ISNUMBER(L10),L10,J10) -> 23.7 | N10: =ROUNDUP(M10,0) -> 24 | O10: =MAX(I10,N10) -> 28 | P10: =IF(C10="COVERED",MAX(0,O10-40),0) -> 0 | Q10: =O10 -> 28 | R10: =IF(C10="COVERED",10.4,7.55) -> 7.55 | S10: =Q10*R10 -> 211.4 | T10: TXN-202608-029048 | U10: 46235 | V10: 28 | W10: 7.55 | X10: 211.4 | Y10: =IF(ISNUMBER(X10),X10-S10,"") -> 0 | Z10: =IF(ISNUMBER(X10),X10-S10,-S10) -> 0 | AA10: =IF(NOT(ISNUMBER(X10)),"NO AUGUST POSTING IN EXPORT",IF(ABS(Y10)>=0.005,"POSTED CHARGE MISMATCH",IF(P10>0,"MATCH - COVERED ELIGIBILITY EXCEPTION","MATCH"))) -> MATCH | AB10: slip_inventory_2026-08.csv row 508; billing_transactions_2022_2026.csv row 46373
A11: EW-0108 | B11: Eastwey | C11: OPEN | D11: OCCUPIED | E11: MA-2024-0108 | F11: WL-02070 | G11: Leslie Thomas | H11: FOUL ROCK | I11: 40 | J11: 59.3 | M11: =IF(ISNUMBER(L11),L11,J11) -> 59.3 | N11: =ROUNDUP(M11,0) -> 60 | O11: =MAX(I11,N11) -> 60 | P11: =IF(C11="COVERED",MAX(0,O11-40),0) -> 0 | Q11: =O11 -> 60 | R11: =IF(C11="COVERED",10.4,7.55) -> 7.55 | S11: =Q11*R11 -> 453 | T11: TXN-202608-029120 | U11: 46235 | V11: 60 | W11: 7.55 | X11: 453 | Y11: =IF(ISNUMBER(X11),X11-S11,"") -> 0 | Z11: =IF(ISNUMBER(X11),X11-S11,-S11) -> 0 | AA11: =IF(NOT(ISNUMBER(X11)),"NO AUGUST POSTING IN EXPORT",IF(ABS(Y11)>=0.005,"POSTED CHARGE MISMATCH",IF(P11>0,"MATCH - COVERED ELIGIBILITY EXCEPTION","MATCH"))) -> MATCH | AB11: slip_inventory_2026-08.csv row 509; billing_transactions_2022_2026.csv row 46374
A12: EW-0109 | B12: Eastwey | C12: OPEN | D12: OCCUPIED | E12: MA-2024-0109 | F12: WL-03624 | G12: Robert Rodriguez | H12: COHO ANN | I12: 60 | J12: 30.9 | M12: =IF(ISNUMBER(L12),L12,J12) -> 30.9 | N12: =ROUNDUP(M12,0) -> 31 | O12: =MAX(I12,N12) -> 60 | P12: =IF(C12="COVERED",MAX(0,O12-40),0) -> 0 | Q12: =O12 -> 60 | R12: =IF(C12="COVERED",10.4,7.55) -> 7.55 | S12: =Q12*R12 -> 453 | T12: TXN-202608-029186 | U12: 46235 | V12: 60 | W12: 7.55 | X12: 453 | Y12: =IF(ISNUMBER(X12),X12-S12,"") -> 0 | Z12: =IF(ISNUMBER(X12),X12-S12,-S12) -> 0 | AA12: =IF(NOT(ISNUMBER(X12)),"NO AUGUST POSTING IN EXPORT",IF(ABS(Y12)>=0.005,"POSTED CHARGE MISMATCH",IF(P12>0,"MATCH - COVERED ELIGIBILITY EXCEPTION","MATCH"))) -> MATCH | AB12: slip_inventory_2026-08.csv row 510; billing_transactions_2022_2026.csv row 46375
A13: EW-0110 | B13: Eastwey | C13: OPEN | D13: OCCUPIED | E13: MA-2024-0110 | F13: WL-01831 | G13: Angela Andersen | H13: BRANT WAKE | I13: 28 | J13: 36.3 | M13: =IF(ISNUMBER(L13),L13,J13) -> 36.3 | N13: =ROUNDUP(M13,0) -> 37 | O13: =MAX(I13,N13) -> 37 | P13: =IF(C13="COVERED",MAX(0,O13-40),0) -> 0 | Q13: =O13 -> 37 | R13: =IF(C13="COVERED",10.4,7.55) -> 7.55 | S13: =Q13*R13 -> 279.35 | T13: TXN-202608-029246 | U13: 46235 | V13: 37 | W13: 7.55 | X13: 279.35 | Y13: =IF(ISNUMBER(X13),X13-S13,"") -> 0 | Z13: =IF(ISNUMBER(X13),X13-S13,-S13) -> 0 | AA13: =IF(NOT(ISNUMBER(X13)),"NO AUGUST POSTING IN EXPORT",IF(ABS(Y13)>=0.005,"POSTED CHARGE MISMATCH",IF(P13>0,"MATCH - COVERED ELIGIBILITY EXCEPTION","MATCH"))) -> MATCH | AB13: slip_inventory_2026-08.csv row 511; billing_transactions_2022_2026.csv row 46377
A14: EW-0111 | B14: Eastwey | C14: OPEN | D14: OCCUPIED | E14: MA-2024-0111 | F14: WL-01617 | G14: James Ferguson | H14: POINT DANCER | I14: 28 | J14: 43.9 | M14: =IF(ISNUMBER(L14),L14,J14) -> 43.9 | N14: =ROUNDUP(M14,0) -> 44 | O14: =MAX(I14,N14) -> 44 | P14: =IF(C14="COVERED",MAX(0,O14-40),0) -> 0 | Q14: =O14 -> 44 | R14: =IF(C14="COVERED",10.4,7.55) -> 7.55 | S14: =Q14*R14 -> 332.2 | T14: TXN-202608-029329 | U14: 46235 | V14: 44 | W14: 7.55 | X14: 332.2 | Y14: =IF(ISNUMBER(X14),X14-S14,"") -> 0 | Z14: =IF(ISNUMBER(X14),X14-S14,-S14) -> 0 | AA14: =IF(NOT(ISNUMBER(X14)),"NO AUGUST POSTING IN EXPORT",IF(ABS(Y14)>=0.005,"POSTED CHARGE MISMATCH",IF(P14>0,"MATCH - COVERED ELIGIBILITY EXCEPTION","MATCH"))) -> MATCH | AB14: slip_inventory_2026-08.csv row 512; billing_transactions_2022_2026.csv row 46378
A15: EW-0112 | B15: Eastwey | C15: OPEN | D15: OCCUPIED | E15: MA-2024-0112 | F15: WL-01533 | G15: Beth Cooper | H15: SPINDRIFT WIND | I15: 70 | J15: 38.7 | M15: =IF(ISNUMBER(L15),L15,J15) -> 38.7 | N15: =ROUNDUP(M15,0) -> 39 | O15: =MAX(I15,N15) -> 70 | P15: =IF(C15="COVERED",MAX(0,O15-40),0) -> 0 | Q15: =O15 -> 70 | R15: =IF(C15="COVERED",10.4,7.55) -> 7.55 | S15: =Q15*R15 -> 528.5 | T15: TXN-202608-029415 | U15: 46235 | V15: 70 | W15: 7.55 | X15: 528.5 | Y15: =IF(ISNUMBER(X15),X15-S15,"") -> 0 | Z15: =IF(ISNUMBER(X15),X15-S15,-S15) -> 0 | AA15: =IF(NOT(ISNUMBER(X15)),"NO AUGUST POSTING IN EXPORT",IF(ABS(Y15)>=0.005,"POSTED CHARGE MISMATCH",IF(P15>0,"MATCH - COVERED ELIGIBILITY EXCEPTION","MATCH"))) -> MATCH | AB15: slip_inventory_2026-08.csv row 513; billing_transactions_2022_2026.csv row 46380
A16: EW-0113 | B16: Eastwey | C16: OPEN | D16: OCCUPIED | E16: MA-2024-0113 | F16: WL-01482 | G16: Brandon Boyer | H16: TIDE MOON | I16: 45 | J16: 61.3 | M16: =IF(ISNUMBER(L16),L16,J16) -> 61.3 | N16: =ROUNDUP(M16,0) -> 62 | O16: =MAX(I16,N16) -> 62 | P16: =IF(C16="COVERED",MAX(0,O16-40),0) -> 0 | Q16: =O16 -> 62 | R16: =IF(C16="COVERED",10.4,7.55) -> 7.55 | S16: =Q16*R16 -> 468.1 | T16: TXN-202608-029475 | U16: 46235 | V16: 62 | W16: 7.55 | X16: 468.1 | Y16: =IF(ISNUMBER(X16),X16-S16,"") -> 0 | Z16: =IF(ISNUMBER(X16),X16-S16,-S16) -> 0 | AA16: =IF(NOT(ISNUMBER(X16)),"NO AUGUST POSTING IN EXPORT",IF(ABS(Y16)>=0.005,"POSTED CHARGE MISMATCH",IF(P16>0,"MATCH - COVERED ELIGIBILITY EXCEPTION","MATCH"))) -> MATCH | AB16: slip_inventory_2026-08.csv row 514; billing_transactions_2022_2026.csv row 46381
... A305: GW-0501 | B305: Gullwing | C305: OPEN | D305: OCCUPIED | E305: MA-2024-0501 | F305: WL-01450 | G305: Joel Barnes | H305: DRIFT WIND | I305: 40 | J305: 22.6 | M305: =IF(ISNUMBER(L305),L305,J305) -> 22.6 | N305: =ROUNDUP(M305,0) -> 23 | O305: =MAX(I305,N305) -> 40 | P305: =IF(C305="COVERED",MAX(0,O305-40),0) -> 0 | Q305: =O305 -> 40 | R305: =IF(C305="COVERED",10.4,7.55) -> 7.55 | S305: =Q305*R305 -> 302 | T305: TXN-202608-046797 | U305: 46235 | V305: 40 | W305: 7.55 | X305: 302 | Y305: =IF(ISNUMBER(X305),X305-S305,"") -> 0 | Z305: =IF(ISNUMBER(X305),X305-S305,-S305) -> 0 | AA305: =IF(NOT(ISNUMBER(X305)),"NO AUGUST POSTING IN EXPORT",IF(ABS(Y305)>=0.005,"POSTED CHARGE MISMATCH",IF(P305>0,"MATCH - COVERED ELIGIBILITY EXCEPTION","MATCH"))) -> MATCH | AB305: slip_inventory_2026-08.csv row 834; billing_transactions_2022_2026.csv row 46801
A306: GW-0502 | B306: Gullwing | C306: OPEN | D306: OCCUPIED | E306: MA-2024-0502 | F306: WL-03559 | G306: David Sanders | H306: KESTREL VEER | I306: 60 | J306: 36.5 | M306: =IF(ISNUMBER(L306),L306,J306) -> 36.5 | N306: =ROUNDUP(M306,0) -> 37 | O306: =MAX(I306,N306) -> 60 | P306: =IF(C306="COVERED",MAX(0,O306-40),0) -> 0 | Q306: =O306 -> 60 | R306: =IF(C306="COVERED",10.4,7.55) -> 7.55 | S306: =Q306*R306 -> 453 | Y306: =IF(ISNUMBER(X306),X306-S306,"") | Z306: =IF(ISNUMBER(X306),X306-S306,-S306) -> -453 | AA306: =IF(NOT(ISNUMBER(X306)),"NO AUGUST POSTING IN EXPORT",IF(ABS(Y306)>=0.005,"POSTED CHARGE MISMATCH",IF(P306>0,"MATCH - COVERED ELIGIBILITY EXCEPTION","MATCH"))) -> NO AUGUST POSTING IN EXPORT | AB306: slip_inventory_2026-08.csv row 835
A307: GW-0503 | B307: Gullwing | C307: OPEN | D307: OCCUPIED | E307: MA-2024-0503 | F307: WL-01494 | G307: Ashley Park | H307: COHO WEATHER | I307: 32 | J307: 43.9 | M307: =IF(ISNUMBER(L307),L307,J307) -> 43.9 | N307: =ROUNDUP(M307,0) -> 44 | O307: =MAX(I307,N307) -> 44 | P307: =IF(C307="COVERED",MAX(0,O307-40),0) -> 0 | Q307: =O307 -> 44 | R307: =IF(C307="COVERED",10.4,7.55) -> 7.55 | S307: =Q307*R307 -> 332.2 | Y307: =IF(ISNUMBER(X307),X307-S307,"") | Z307: =IF(ISNUMBER(X307),X307-S307,-S307) -> -332.2 | AA307: =IF(NOT(ISNUMBER(X307)),"NO AUGUST POSTING IN EXPORT",IF(ABS(Y307)>=0.005,"POSTED CHARGE MISMATCH",IF(P307>0,"MATCH - COVERED ELIGIBILITY EXCEPTION","MATCH"))) -> NO AUGUST POSTING IN EXPORT | AB307: slip_inventory_2026-08.csv row 836
A308: GW-0504 | B308: Gullwing | C308: OPEN | D308: OCCUPIED | E308: MA-2024-0504 | F308: WL-01500 | G308: Patricia Marquez | H308: OSPREY GLIDE | I308: 50 | J308: 25.2 | M308: =IF(ISNUMBER(L308),L308,J308) -> 25.2 | N308: =ROUNDUP(M308,0) -> 26 | O308: =MAX(I308,N308) -> 50 | P308: =IF(C308="COVERED",MAX(0,O308-40),0) -> 0 | Q308: =O308 -> 50 | R308: =IF(C308="COVERED",10.4,7.55) -> 7.55 | S308: =Q308*R308 -> 377.5 | Y308: =IF(ISNUMBER(X308),X308-S308,"") | Z308: =IF(ISNUMBER(X308),X308-S308,-S308) -> -377.5 | AA308: =IF(NOT(ISNUMBER(X308)),"NO AUGUST POSTING IN EXPORT",IF(ABS(Y308)>=0.005,"POSTED CHARGE MISMATCH",IF(P308>0,"MATCH - COVERED ELIGIBILITY EXCEPTION","MATCH"))) -> NO AUGUST POSTING IN EXPORT | AB308: slip_inventory_2026-08.csv row 837
A309: GW-0505 | B309: Gullwing | C309: OPEN | D309: OCCUPIED | E309: MA-2024-0505 | F309: WL-01089 | G309: Erin Holmes | H309: CORMORANT WIND | I309: 60 | J309: 54.3 | M309: =IF(ISNUMBER(L309),L309,J309) -> 54.3 | N309: =ROUNDUP(M309,0) -> 55 | O309: =MAX(I309,N309) -> 60 | P309: =IF(C309="COVERED",MAX(0,O309-40),0) -> 0 | Q309: =O309 -> 60 | R309: =IF(C309="COVERED",10.4,7.55) -> 7.55 | S309: =Q309*R309 -> 453 | Y309: =IF(ISNUMBER(X309),X309-S309,"") | Z309: =IF(ISNUMBER(X309),X309-S309,-S309) -> -453 | AA309: =IF(NOT(ISNUMBER(X309)),"NO AUGUST POSTING IN EXPORT",IF(ABS(Y309)>=0.005,"POSTED CHARGE MISMATCH",IF(P309>0,"MATCH - COVERED ELIGIBILITY EXCEPTION","MATCH"))) -> NO AUGUST POSTING IN EXPORT | AB309: slip_inventory_2026-08.csv row 838
A310: GW-0506 | B310: Gullwing | C310: OPEN | D310: OCCUPIED | E310: MA-2024-0506 | F310: WL-03615 | G310: Kathryn Cook | H310: WIDGEON PASSAGE | I310: 45 | J310: 25.2 | M310: =IF(ISNUMBER(L310),L310,J310) -> 25.2 | N310: =ROUNDUP(M310,0) -> 26 | O310: =MAX(I310,N310) -> 45 | P310: =IF(C310="COVERED",MAX(0,O310-40),0) -> 0 | Q310: =O310 -> 45 | R310: =IF(C310="COVERED",10.4,7.55) -> 7.55 | S310: =Q310*R310 -> 339.75 | Y310: =IF(ISNUMBER(X310),X310-S310,"") | Z310: =IF(ISNUMBER(X310),X310-S310,-S310) -> -339.75 | AA310: =IF(NOT(ISNUMBER(X310)),"NO AUGUST POSTING IN EXPORT",IF(ABS(Y310)>=0.005,"POSTED CHARGE MISMATCH",IF(P310>0,"MATCH - COVERED ELIGIBILITY EXCEPTION","MATCH"))) -> NO AUGUST POSTING IN EXPORT | AB310: slip_inventory_2026-08.csv row 839
A311: GW-0507 | B311: Gullwing | C311: OPEN | D311: OCCUPIED | E311: MA-2024-0507 | F311: WL-03057 | G311: Jennifer Stout | H311: BRANT ROSE | I311: 24 | J311: 38.3 | M311: =IF(ISNUMBER(L311),L311,J311) -> 38.3 | N311: =ROUNDUP(M311,0) -> 39 | O311: =MAX(I311,N311) -> 39 | P311: =IF(C311="COVERED",MAX(0,O311-40),0) -> 0 | Q311: =O311 -> 39 | R311: =IF(C311="COVERED",10.4,7.55) -> 7.55 | S311: =Q311*R311 -> 294.45 | Y311: =IF(ISNUMBER(X311),X311-S311,"") | Z311: =IF(ISNUMBER(X311),X311-S311,-S311) -> -294.45 | AA311: =IF(NOT(ISNUMBER(X311)),"NO AUGUST POSTING IN EXPORT",IF(ABS(Y311)>=0.005,"POSTED CHARGE MISMATCH",IF(P311>0,"MATCH - COVERED ELIGIBILITY EXCEPTION","MATCH"))) -> NO AUGUST POSTING IN EXPORT | AB311: slip_inventory_2026-08.csv row 840
A312: GW-0508 | B312: Gullwing | C312: OPEN | D312: OCCUPIED | E312: MA-2024-0508 | F312: WL-03692 | G312: Warren Wilkins | H312: WIDGEON CREST | I312: 70 | J312: 25.9 | M312: =IF(ISNUMBER(L312),L312,J312) -> 25.9 | N312: =ROUNDUP(M312,0) -> 26 | O312: =MAX(I312,N312) -> 70 | P312: =IF(C312="COVERED",MAX(0,O312-40),0) -> 0 | Q312: =O312 -> 70 | R312: =IF(C312="COVERED",10.4,7.55) -> 7.55 | S312: =Q312*R312 -> 528.5 | Y312: =IF(ISNUMBER(X312),X312-S312,"") | Z312: =IF(ISNUMBER(X312),X312-S312,-S312) -> -528.5 | AA312: =IF(NOT(ISNUMBER(X312)),"NO AUGUST POSTING IN EXPORT",IF(ABS(Y312)>=0.005,"POSTED CHARGE MISMATCH",IF(P312>0,"MATCH - COVERED ELIGIBILITY EXCEPTION","MATCH"))) -> NO AUGUST POSTING IN EXPORT | AB312: slip_inventory_2026-08.csv row 841
A313: GW-0509 | B313: Gullwing | C313: OPEN | D313: OCCUPIED | E313: MA-2024-0509 | F313: WL-03850 | G313: Teresa Greer | H313: COHO HARBOR | I313: 45 | J313: 35.6 | M313: =IF(ISNUMBER(L313),L313,J313) -> 35.6 | N313: =ROUNDUP(M313,0) -> 36 | O313: =MAX(I313,N313) -> 45 | P313: =IF(C313="COVERED",MAX(0,O313-40),0) -> 0 | Q313: =O313 -> 45 | R313: =IF(C313="COVERED",10.4,7.55) -> 7.55 | S313: =Q313*R313 -> 339.75 | Y313: =IF(ISNUMBER(X313),X313-S313,"") | Z313: =IF(ISNUMBER(X313),X313-S313,-S313) -> -339.75 | AA313: =IF(NOT(ISNUMBER(X313)),"NO AUGUST POSTING IN EXPORT",IF(ABS(Y313)>=0.005,"POSTED CHARGE MISMATCH",IF(P313>0,"MATCH - COVERED ELIGIBILITY EXCEPTION","MATCH"))) -> NO AUGUST POSTING IN EXPORT | AB313: slip_inventory_2026-08.csv row 842
A314: GW-0511 | B314: Gullwing | C314: OPEN | D314: OCCUPIED | E314: MA-2024-0511 | F314: WL-02804 | G314: Danny Jones | H314: SCOTER ROCK | I314: 70 | J314: 28.7 | M314: =IF(ISNUMBER(L314),L314,J314) -> 28.7 | N314: =ROUNDUP(M314,0) -> 29 | O314: =MAX(I314,N314) -> 70 | P314: =IF(C314="COVERED",MAX(0,O314-40),0) -> 0 | Q314: =O314 -> 70 | R314: =IF(C314="COVERED",10.4,7.55) -> 7.55 | S314: =Q314*R314 -> 528.5 | Y314: =IF(ISNUMBER(X314),X314-S314,"") | Z314: =IF(ISNUMBER(X314),X314-S314,-S314) -> -528.5 | AA314: =IF(NOT(ISNUMBER(X314)),"NO AUGUST POSTING IN EXPORT",IF(ABS(Y314)>=0.005,"POSTED CHARGE MISMATCH",IF(P314>0,"MATCH - COVERED ELIGIBILITY EXCEPTION","MATCH"))) -> NO AUGUST POSTING IN EXPORT | AB314: slip_inventory_2026-08.csv row 844
A315: GW-0512 | B315: Gullwing | C315: OPEN | D315: OCCUPIED | E315: MA-2024-0512 | F315: WL-03869 | G315: Seth Raymond | H315: MURRE LIGHT | I315: 32 | J315: 37 | M315: =IF(ISNUMBER(L315),L315,J315) -> 37 | N315: =ROUNDUP(M315,0) -> 37 | O315: =MAX(I315,N315) -> 37 | P315: =IF(C315="COVERED",MAX(0,O315-40),0) -> 0 | Q315: =O315 -> 37 | R315: =IF(C315="COVERED",10.4,7.55) -> 7.55 | S315: =Q315*R315 -> 279.35 | Y315: =IF(ISNUMBER(X315),X315-S315,"") | Z315: =IF(ISNUMBER(X315),X315-S315,-S315) -> -279.35 | AA315: =IF(NOT(ISNUMBER(X315)),"NO AUGUST POSTING IN EXPORT",IF(ABS(Y315)>=0.005,"POSTED CHARGE MISMATCH",IF(P315>0,"MATCH - COVERED ELIGIBILITY EXCEPTION","MATCH"))) -> NO AUGUST POSTING IN EXPORT | AB315: slip_inventory_2026-08.csv row 845
A316: GW-0513 | B316: Gullwing | C316: OPEN | D316: OCCUPIED | E316: MA-2024-0513 | F316: WL-03045 | G316: Karen Davis | H316: GRAY BAY | I316: 32 | J316: 51.6 | M316: =IF(ISNUMBER(L316),L316,J316) -> 51.6 | N316: =ROUNDUP(M316,0) -> 52 | O316: =MAX(I316,N316) -> 52 | P316: =IF(C316="COVERED",MAX(0,O316-40),0) -> 0 | Q316: =O316 -> 52 | R316: =IF(C316="COVERED",10.4,7.55) -> 7.55 | S316: =Q316*R316 -> 392.6 | Y316: =IF(ISNUMBER(X316),X316-S316,"") | Z316: =IF(ISNUMBER(X316),X316-S316,-S316) -> -392.6 | AA316: =IF(NOT(ISNUMBER(X316)),"NO AUGUST POSTING IN EXPORT",IF(ABS(Y316)>=0.005,"POSTED CHARGE MISMATCH",IF(P316>0,"MATCH - COVERED ELIGIBILITY EXCEPTION","MATCH"))) -> NO AUGUST POSTING IN EXPORT | AB316: slip_inventory_2026-08.csv row 846
A317: GW-0514 | B317: Gullwing | C317: OPEN | D317: OCCUPIED | E317: MA-2024-0514 | F317: WL-03143 | G317: Timothy Jennings | H317: POINT RUNNER | I317: 40 | J317: 32.5 | M317: =IF(ISNUMBER(L317),L317,J317) -> 32.5 | N317: =ROUNDUP(M317,0) -> 33 | O317: =MAX(I317,N317) -> 40 | P317: =IF(C317="COVERED",MAX(0,O317-40),0) -> 0 | Q317: =O317 -> 40 | R317: =IF(C317="COVERED",10.4,7.55) -> 7.55 | S317: =Q317*R317 -> 302 | Y317: =IF(ISNUMBER(X317),X317-S317,"") | Z317: =IF(ISNUMBER(X317),X317-S317,-S317) -> -302 | AA317: =IF(NOT(ISNUMBER(X317)),"NO AUGUST POSTING IN EXPORT",IF(ABS(Y317)>=0.005,"POSTED CHARGE MISMATCH",IF(P317>0,"MATCH - COVERED ELIGIBILITY EXCEPTION","MATCH"))) -> NO AUGUST POSTING IN EXPORT | AB317: slip_inventory_2026-08.csv row 847
... A432: GW-1023 | B432: Gullwing | C432: OPEN | D432: OCCUPIED | E432: MA-2024-1023 | F432: WL-02832 | G432: Mia Schwartz | H432: PINTAIL WIND | I432: 28 | J432: 35 | M432: =IF(ISNUMBER(L432),L432,J432) -> 35 | N432: =ROUNDUP(M432,0) -> 35 | O432: =MAX(I432,N432) -> 35 | P432: =IF(C432="COVERED",MAX(0,O432-40),0) -> 0 | Q432: =O432 -> 35 | R432: =IF(C432="COVERED",10.4,7.55) -> 7.55 | S432: =Q432*R432 -> 264.25 | Y432: =IF(ISNUMBER(X432),X432-S432,"") | Z432: =IF(ISNUMBER(X432),X432-S432,-S432) -> -264.25 | AA432: =IF(NOT(ISNUMBER(X432)),"NO AUGUST POSTING IN EXPORT",IF(ABS(Y432)>=0.005,"POSTED CHARGE MISMATCH",IF(P432>0,"MATCH - COVERED ELIGIBILITY EXCEPTION","MATCH"))) -> NO AUGUST POSTING IN EXPORT | AB432: slip_inventory_2026-08.csv row 971
