Workbook

Sheet Summary
A1: Chaldale Harbor Moorage Audit
A2: Board review edition | Audit date: Friday, August 7, 2026 | Dollar reconciliation is base moorage before tax, electricity, and surcharges.
A4: PRIORITY 1 | D4: PRIORITY 2 | G4: PRIORITY 3 | J4: COLLECTION CANDIDATES
A5: =COUNTIF('Skip Audit'!$A$5:$A$313,"Priority 1")+COUNTIF('Amendment Audit'!$A$5:$A$204,"Priority 1") | D5: =COUNTIF('Skip Audit'!$A$5:$A$313,"Priority 2")+COUNTIF('Amendment Audit'!$A$5:$A$204,"Priority 2") | G5: =COUNTIF('Aging & Collections'!$V$5:$V$264,"Priority 3") | J5: =COUNTIF('Aging & Collections'!$U$5:$U$264,"YES")
A8: Board Decision Dashboard
A9: Decision Area | C9: Formula Result | E9: Basis | H9: Recommended Board Direction
A10: Collection | C10: =COUNTIF('Aging & Collections'!$U$5:$U$264,"YES") | E10: Occupied accounts with a nonzero 91-120 or 120+ bucket and no row arithmetic error. | H10: Authorize collection review for the listed six accounts; validate required notice and payment-plan status before action.
A11: Queue integrity | C11: =COUNTIF('Skip Audit'!$B$5:$B$313,"YES") | E11: Verified contemporaneous skip packets under the user-specified strict test. | H11: Treat the supplied record as insufficient to sustain audited skips; prioritize 15 unsupported LOA amendments followed by skips.
A12: Billing completeness | C12: =COUNTIF('Billing Reconciliation'!$Q$5:$Q$1090,"NO AUG TRANSACTION IN SUPPLIED EXTRACT") | E12: Occupied slips without an August 1 monthly-moorage row in the supplied extract. | H12: Re-extract billing before posting adjustments or treating the apparent shortfall as customer delinquency.
A13: Aging control | C13: =COUNTIF('Aging & Collections'!$V$5:$V$264,"Priority 3") | E13: Rows where reported total_due differs from the formula sum of aging buckets. | H13: Correct the aging subledger before using total_due as a collection demand.
A15: Formula Reconciliations
A16: Area | C16: Metric | E16: Formula Result | H16: Arithmetic / source basis
A17: Skips | C17: Events in audit window | E17: =ROWS('Skip Audit'!$C$5:$C$313) | H17: skip_events_2022_2026.csv; skip_date filter
A18: Skips | C18: No supplied PDF | E18: =COUNTIF('Skip Audit'!$L$5:$L$313,"NO") | H18: Strict supplied-file test
A19: Skips | C19: Verified contemporaneous proof | E19: =COUNTIF('Skip Audit'!$B$5:$B$313,"YES") | H19: PDF + support + timely review + document/event + offer/event match
A20: LOA amendments | C20: Unsubstantiated | E20: =COUNTIF('Amendment Audit'!$J$5:$J$204,"NO") | H20: 200 scoped rows less valid supplied support
A21: LOA amendments | C21: Unsubstantiated with downstream skip | E21: =COUNTIFS('Amendment Audit'!$J$5:$J$204,"NO",'Amendment Audit'!$K$5:$K$204,">0") | H21: Resolution 2022-06 s.4.3 + skip_events join
A22: Billing | C22: Expected base charges | E22: =SUM('Billing Reconciliation'!$K$5:$K$1090) | H22: SUM billable feet x covered/open rate
A23: Billing | C23: Actual base charges | E23: =SUM('Billing Reconciliation'!$L$5:$L$1090) | H23: SUM August 1 monthly-moorage amount
A24: Billing | C24: Variance (actual - expected) | E24: =SUM('Billing Reconciliation'!$M$5:$M$1090) | H24: Actual less expected; missing transaction rows contribute zero actual
A25: Aging | C25: 91-120 balance | E25: =SUM('Aging & Collections'!$I$5:$I$264) | H25: AR_Aging days_90 column (captioned 91-120 in source Summary)
A26: Aging | C26: 120+ balance | E26: =SUM('Aging & Collections'!$J$5:$J$264) | H26: AR_Aging days_120_plus column
A27: Aging | C27: Collection candidates total due | E27: =SUMIFS('Aging & Collections'!$K$5:$K$264,'Aging & Collections'!$U$5:$U$264,"YES") | H27: Reported total_due for six arithmetic-clean, occupied target accounts
A28: Aging | C28: Net total_due error | E28: =SUM('Aging & Collections'!$R$5:$R$264) | H28: SUM(reported total_due - calculated bucket total)
A30: Interpretive limit | B30: The 317 missing August transaction rows are an extract gap, not proof of nonbilling. The supplied certificates do not map to current tenants, so inventory vessel_loa_ft is the available current-occupant LOA proxy.
A33: Workbook navigation | B33: Use Queue Exceptions for priority counts and named records; Document Recon for the eight supplied PDFs; Skip Audit and Amendment Audit for complete queue populations; Billing Reconciliation for all occupied slips; Aging & Collections for collection candidates and subledger errors; Methodology for authority and source paths.

Sheet Queue Exceptions
A1: Queue Exceptions Requiring Board Attention
A2: Priority totals are formulas over the Skip Audit, Amendment Audit, and Aging & Collections sheets. Complete populations remain filterable on those sheets.
A4: Priority Summary
A5: Priority | B5: Exception Class | C5: Formula Count | D5: Board Significance | E5: Complete Detail | F5: Basis | G5: Owner | H5: Proposed Disposition
A6: Priority 1 | B6: Skips with no supplied supporting record | C6: =COUNTIF('Skip Audit'!$A$5:$A$313,"Priority 1") | D6: Departure from rank order lacks supplied support. | E6: Skip Audit | F6: User priority rule; Standing Order 15-3 ss.3.2-3.3 | G6: Harbormaster / Clerk | H6: Hold reliance; reconstruct only if Board-authorized evidence exists.
A7: Priority 1 | B7: Unsubstantiated LOA amendments with downstream skips | C7: =COUNTIFS('Amendment Audit'!$A$5:$A$204,"Priority 1") | D7: Unsupported LOA may have affected later skip decisions. | E7: Amendment Audit | F7: Resolution 2022-06 s.4.3 | G7: Harbormaster | H7: Legal/records review before further reliance.
A8: Priority 2 | B8: Supported packets assembled after skip date | C8: =COUNTIF('Skip Audit'!$A$5:$A$313,"Priority 2") | D8: Packet has content but misses contemporaneous timing standard. | E8: Skip Audit | F8: User priority rule; Appeal 2018-3 IV-A | G8: Harbormaster / Clerk | H8: Board review; do not treat as verified contemporaneous proof.
A9: Priority 2 | B9: Unsubstantiated LOA amendments without downstream skips | C9: =COUNTIFS('Amendment Audit'!$A$5:$A$204,"Priority 2") | D9: No supplied independent measurement file. | E9: Amendment Audit | F9: Resolution 2022-06 s.4.3 | G9: Records Officer | H9: Obtain support or flag amendment against future use.
A10: Priority 3 | B10: Aging subledger arithmetic errors | C10: =COUNTIF('Aging & Collections'!$V$5:$V$264,"Priority 3") | D10: Reported total_due does not equal bucket sum. | E10: Aging & Collections | F10: User priority rule; formula reconciliation | G10: Finance | H10: Correct subledger before collection based on total_due.
A13: Named Record-Level Exceptions
A14: Type | B14: Record ID | C14: Subject | D14: Date | E14: Related Record | F14: Priority | G14: Dollar Variance | H14: Finding
A15: Skip packet | B15: ='Skip Audit'!C309 | C15: ='Skip Audit'!F309 | D15: ='Skip Audit'!E309 | E15: ='Skip Audit'!D309 | F15: ='Skip Audit'!A309 | H15: ='Skip Audit'!S309
A16: Skip packet | B16: ='Skip Audit'!C312 | C16: ='Skip Audit'!F312 | D16: ='Skip Audit'!E312 | E16: ='Skip Audit'!D312 | F16: ='Skip Audit'!A312 | H16: ='Skip Audit'!S312
A17: Skip packet | B17: ='Skip Audit'!C310 | C17: ='Skip Audit'!F310 | D17: ='Skip Audit'!E310 | E17: ='Skip Audit'!D310 | F17: ='Skip Audit'!A310 | H17: ='Skip Audit'!S310
A18: Skip packet | B18: ='Skip Audit'!C313 | C18: ='Skip Audit'!F313 | D18: ='Skip Audit'!E313 | E18: ='Skip Audit'!D313 | F18: ='Skip Audit'!A313 | H18: ='Skip Audit'!S313
A19: Skip packet | B19: ='Skip Audit'!C311 | C19: ='Skip Audit'!F311 | D19: ='Skip Audit'!E311 | E19: ='Skip Audit'!D311 | F19: ='Skip Audit'!A311 | H19: ='Skip Audit'!S311
A20: LOA amendment | B20: ='Amendment Audit'!B7 | C20: ='Amendment Audit'!D7 | D20: ='Amendment Audit'!C7 | E20: ='Amendment Audit'!L7 | F20: ='Amendment Audit'!A7 | H20: ='Amendment Audit'!M7
A21: LOA amendment | B21: ='Amendment Audit'!B14 | C21: ='Amendment Audit'!D14 | D21: ='Amendment Audit'!C14 | E21: ='Amendment Audit'!L14 | F21: ='Amendment Audit'!A14 | H21: ='Amendment Audit'!M14
A22: LOA amendment | B22: ='Amendment Audit'!B16 | C22: ='Amendment Audit'!D16 | D22: ='Amendment Audit'!C16 | E22: ='Amendment Audit'!L16 | F22: ='Amendment Audit'!A16 | H22: ='Amendment Audit'!M16
A23: LOA amendment | B23: ='Amendment Audit'!B23 | C23: ='Amendment Audit'!D23 | D23: ='Amendment Audit'!C23 | E23: ='Amendment Audit'!L23 | F23: ='Amendment Audit'!A23 | H23: ='Amendment Audit'!M23
A24: LOA amendment | B24: ='Amendment Audit'!B32 | C24: ='Amendment Audit'!D32 | D24: ='Amendment Audit'!C32 | E24: ='Amendment Audit'!L32 | F24: ='Amendment Audit'!A32 | H24: ='Amendment Audit'!M32
A25: LOA amendment | B25: ='Amendment Audit'!B42 | C25: ='Amendment Audit'!D42 | D25: ='Amendment Audit'!C42 | E25: ='Amendment Audit'!L42 | F25: ='Amendment Audit'!A42 | H25: ='Amendment Audit'!M42
A26: LOA amendment | B26: ='Amendment Audit'!B44 | C26: ='Amendment Audit'!D44 | D26: ='Amendment Audit'!C44 | E26: ='Amendment Audit'!L44 | F26: ='Amendment Audit'!A44 | H26: ='Amendment Audit'!M44
A27: LOA amendment | B27: ='Amendment Audit'!B51 | C27: ='Amendment Audit'!D51 | D27: ='Amendment Audit'!C51 | E27: ='Amendment Audit'!L51 | F27: ='Amendment Audit'!A51 | H27: ='Amendment Audit'!M51
A28: LOA amendment | B28: ='Amendment Audit'!B66 | C28: ='Amendment Audit'!D66 | D28: ='Amendment Audit'!C66 | E28: ='Amendment Audit'!L66 | F28: ='Amendment Audit'!A66 | H28: ='Amendment Audit'!M66
A29: LOA amendment | B29: ='Amendment Audit'!B77 | C29: ='Amendment Audit'!D77 | D29: ='Amendment Audit'!C77 | E29: ='Amendment Audit'!L77 | F29: ='Amendment Audit'!A77 | H29: ='Amendment Audit'!M77
A30: LOA amendment | B30: ='Amendment Audit'!B84 | C30: ='Amendment Audit'!D84 | D30: ='Amendment Audit'!C84 | E30: ='Amendment Audit'!L84 | F30: ='Amendment Audit'!A84 | H30: ='Amendment Audit'!M84
A31: LOA amendment | B31: ='Amendment Audit'!B86 | C31: ='Amendment Audit'!D86 | D31: ='Amendment Audit'!C86 | E31: ='Amendment Audit'!L86 | F31: ='Amendment Audit'!A86 | H31: ='Amendment Audit'!M86
A32: LOA amendment | B32: ='Amendment Audit'!B103 | C32: ='Amendment Audit'!D103 | D32: ='Amendment Audit'!C103 | E32: ='Amendment Audit'!L103 | F32: ='Amendment Audit'!A103 | H32: ='Amendment Audit'!M103
A33: LOA amendment | B33: ='Amendment Audit'!B150 | C33: ='Amendment Audit'!D150 | D33: ='Amendment Audit'!C150 | E33: ='Amendment Audit'!L150 | F33: ='Amendment Audit'!A150 | H33: ='Amendment Audit'!M150
A34: LOA amendment | B34: ='Amendment Audit'!B175 | C34: ='Amendment Audit'!D175 | D34: ='Amendment Audit'!C175 | E34: ='Amendment Audit'!L175 | F34: ='Amendment Audit'!A175 | H34: ='Amendment Audit'!M175
A35: Aging arithmetic | B35: ='Aging & Collections'!A6 | C35: ='Aging & Collections'!B6 | E35: ='Aging & Collections'!C6 | F35: ='Aging & Collections'!V6 | G35: ='Aging & Collections'!R6 | H35: Reported total_due differs from formula sum of aging buckets.
A36: Aging arithmetic | B36: ='Aging & Collections'!A37 | C36: ='Aging & Collections'!B37 | E36: ='Aging & Collections'!C37 | F36: ='Aging & Collections'!V37 | G36: ='Aging & Collections'!R37 | H36: Reported total_due differs from formula sum of aging buckets.
A37: Aging arithmetic | B37: ='Aging & Collections'!A38 | C37: ='Aging & Collections'!B38 | E37: ='Aging & Collections'!C38 | F37: ='Aging & Collections'!V38 | G37: ='Aging & Collections'!R38 | H37: Reported total_due differs from formula sum of aging buckets.
A38: Aging arithmetic | B38: ='Aging & Collections'!A45 | C38: ='Aging & Collections'!B45 | E38: ='Aging & Collections'!C45 | F38: ='Aging & Collections'!V45 | G38: ='Aging & Collections'!R45 | H38: Reported total_due differs from formula sum of aging buckets.
A39: Aging arithmetic | B39: ='Aging & Collections'!A47 | C39: ='Aging & Collections'!B47 | E39: ='Aging & Collections'!C47 | F39: ='Aging & Collections'!V47 | G39: ='Aging & Collections'!R47 | H39: Reported total_due differs from formula sum of aging buckets.
A40: Aging arithmetic | B40: ='Aging & Collections'!A50 | C40: ='Aging & Collections'!B50 | E40: ='Aging & Collections'!C50 | F40: ='Aging & Collections'!V50 | G40: ='Aging & Collections'!R50 | H40: Reported total_due differs from formula sum of aging buckets.
A41: Aging arithmetic | B41: ='Aging & Collections'!A53 | C41: ='Aging & Collections'!B53 | E41: ='Aging & Collections'!C53 | F41: ='Aging & Collections'!V53 | G41: ='Aging & Collections'!R53 | H41: Reported total_due differs from formula sum of aging buckets.
A42: Aging arithmetic | B42: ='Aging & Collections'!A61 | C42: ='Aging & Collections'!B61 | E42: ='Aging & Collections'!C61 | F42: ='Aging & Collections'!V61 | G42: ='Aging & Collections'!R61 | H42: Reported total_due differs from formula sum of aging buckets.
A43: Aging arithmetic | B43: ='Aging & Collections'!A69 | C43: ='Aging & Collections'!B69 | E43: ='Aging & Collections'!C69 | F43: ='Aging & Collections'!V69 | G43: ='Aging & Collections'!R69 | H43: Reported total_due differs from formula sum of aging buckets.
...

Sheet Document Recon
A1: Document Reconciliation
A2: Each supplied skip packet is tested against both ledgers. Each certificate is tested against LOA amendments and, where a slip is stated, the August inventory.
A4: Skip Justification Packets
A5: Filename | B5: Applicant ID | C5: PDF Work Date | D5: PDF Slip | E5: PDF Reason | F5: Pages | G5: Contains Support | H5: Logged Slip (same applicant/date) | I5: Exact Skip Match | J5: Exact Offer Match | K5: In Audit Window | L5: Reconciled | M5: Finding
A6: WL-02211_skip_justification.pdf | B6: WL-02211 | C6: 44818 | D6: LP-0307 | E6: not-current | F6: 1 | G6: NO | H6: GW-0417 | I6: =COUNTIFS('All Skips'!$D$2:$D$413,B6,'All Skips'!$C$2:$C$413,C6,'All Skips'!$F$2:$F$413,D6,'All Skips'!$I$2:$I$413,E6) | J6: =COUNTIFS(Offers!$C$2:$C$1487,B6,Offers!$B$2:$B$1487,C6,Offers!$E$2:$E$1487,D6,Offers!$I$2:$I$1487,"SKIPPED") | K6: =IF(AND(C6>='Methodology'!$B$6,C6<='Methodology'!$B$7),"YES","NO") | L6: =IF(AND(I6=1,J6=1),"YES","NO") | M6: =IF(L6="YES","Packet reconciles",IF(H6<>D6,"PDF slip conflicts with skip event; offer does not reconcile",IF(G6="NO","Cover-only packet","Offer/skip ledger mismatch")))
A7: WL-02618_skip_justification.pdf | B7: WL-02618 | C7: 45048 | D7: EW-0414 | E7: vessel-fit | F7: 1 | G7: NO | H7: GW-0610 | I7: =COUNTIFS('All Skips'!$D$2:$D$413,B7,'All Skips'!$C$2:$C$413,C7,'All Skips'!$F$2:$F$413,D7,'All Skips'!$I$2:$I$413,E7) | J7: =COUNTIFS(Offers!$C$2:$C$1487,B7,Offers!$B$2:$B$1487,C7,Offers!$E$2:$E$1487,D7,Offers!$I$2:$I$1487,"SKIPPED") | K7: =IF(AND(C7>='Methodology'!$B$6,C7<='Methodology'!$B$7),"YES","NO") | L7: =IF(AND(I7=1,J7=1),"YES","NO") | M7: =IF(L7="YES","Packet reconciles",IF(H7<>D7,"PDF slip conflicts with skip event; offer does not reconcile",IF(G7="NO","Cover-only packet","Offer/skip ledger mismatch")))
A8: WL-02877_skip_justification.pdf | B8: WL-02877 | C8: 45370 | D8: GW-0702 | E8: vessel-fit | F8: 3 | G8: YES | H8: GW-1012 | I8: =COUNTIFS('All Skips'!$D$2:$D$413,B8,'All Skips'!$C$2:$C$413,C8,'All Skips'!$F$2:$F$413,D8,'All Skips'!$I$2:$I$413,E8) | J8: =COUNTIFS(Offers!$C$2:$C$1487,B8,Offers!$B$2:$B$1487,C8,Offers!$E$2:$E$1487,D8,Offers!$I$2:$I$1487,"SKIPPED") | K8: =IF(AND(C8>='Methodology'!$B$6,C8<='Methodology'!$B$7),"YES","NO") | L8: =IF(AND(I8=1,J8=1),"YES","NO") | M8: =IF(L8="YES","Packet reconciles",IF(H8<>D8,"PDF slip conflicts with skip event; offer does not reconcile",IF(G8="NO","Cover-only packet","Offer/skip ledger mismatch")))
A9: WL-03044_skip_justification.pdf | B9: WL-03044 | C9: 45342 | D9: EW-0603 | E9: preference-mismatch | F9: 1 | G9: NO | H9: VB-0904 | I9: =COUNTIFS('All Skips'!$D$2:$D$413,B9,'All Skips'!$C$2:$C$413,C9,'All Skips'!$F$2:$F$413,D9,'All Skips'!$I$2:$I$413,E9) | J9: =COUNTIFS(Offers!$C$2:$C$1487,B9,Offers!$B$2:$B$1487,C9,Offers!$E$2:$E$1487,D9,Offers!$I$2:$I$1487,"SKIPPED") | K9: =IF(AND(C9>='Methodology'!$B$6,C9<='Methodology'!$B$7),"YES","NO") | L9: =IF(AND(I9=1,J9=1),"YES","NO") | M9: =IF(L9="YES","Packet reconciles",IF(H9<>D9,"PDF slip conflicts with skip event; offer does not reconcile",IF(G9="NO","Cover-only packet","Offer/skip ledger mismatch")))
A10: WL-03102_skip_justification.pdf | B10: WL-03102 | C10: 45909 | D10: EW-0620 | E10: preference-mismatch | F10: 3 | G10: YES | H10: LP-0806 | I10: =COUNTIFS('All Skips'!$D$2:$D$413,B10,'All Skips'!$C$2:$C$413,C10,'All Skips'!$F$2:$F$413,D10,'All Skips'!$I$2:$I$413,E10) | J10: =COUNTIFS(Offers!$C$2:$C$1487,B10,Offers!$B$2:$B$1487,C10,Offers!$E$2:$E$1487,D10,Offers!$I$2:$I$1487,"SKIPPED") | K10: =IF(AND(C10>='Methodology'!$B$6,C10<='Methodology'!$B$7),"YES","NO") | L10: =IF(AND(I10=1,J10=1),"YES","NO") | M10: =IF(L10="YES","Packet reconciles",IF(H10<>D10,"PDF slip conflicts with skip event; offer does not reconcile",IF(G10="NO","Cover-only packet","Offer/skip ledger mismatch")))
A11: WL-03390_skip_justification.pdf | B11: WL-03390 | C11: 45601 | D11: VB-0144 | E11: declined-prior-offer | F11: 1 | G11: NO | H11: SB-0120 | I11: =COUNTIFS('All Skips'!$D$2:$D$413,B11,'All Skips'!$C$2:$C$413,C11,'All Skips'!$F$2:$F$413,D11,'All Skips'!$I$2:$I$413,E11) | J11: =COUNTIFS(Offers!$C$2:$C$1487,B11,Offers!$B$2:$B$1487,C11,Offers!$E$2:$E$1487,D11,Offers!$I$2:$I$1487,"SKIPPED") | K11: =IF(AND(C11>='Methodology'!$B$6,C11<='Methodology'!$B$7),"YES","NO") | L11: =IF(AND(I11=1,J11=1),"YES","NO") | M11: =IF(L11="YES","Packet reconciles",IF(H11<>D11,"PDF slip conflicts with skip event; offer does not reconcile",IF(G11="NO","Cover-only packet","Offer/skip ledger mismatch")))
A14: Measurement Certificates
A15: Filename | B15: Applicant ID | C15: Certificate | D15: Certificate Date | E15: Measured LOA | F15: Signed | G15: Certificate Slip | H15: Inventory Class | I15: Current Inventory Tenant | J15: Billable Feet | K15: Illustrative Base Charge | L15: Matching LOA Amendment | M15: Finding
A16: 2024-06-03_measurement_certificate_WL-01893.pdf | B16: WL-01893 | C16: MC-2024-0062 | D16: 45446 | E16: 31.4 | F16: YES | G16: VB-0208 | H16: =IF(G16="","NOT DETERMINABLE",IFERROR(INDEX(Inventory!$C$2:$C$1181,MATCH(G16,Inventory!$A$2:$A$1181,0)),"NOT FOUND")) | I16: =IF(G16="","NO CURRENT SLIP MATCH",IFERROR(INDEX(Inventory!$G$2:$G$1181,MATCH(G16,Inventory!$A$2:$A$1181,0)),"NOT FOUND")) | J16: =IF(G16="","",ROUNDUP(MAX(E16,INDEX(Inventory!$D$2:$D$1181,MATCH(G16,Inventory!$A$2:$A$1181,0))),0)) | K16: =IF(J16="","",J16*IF(H16="COVERED",'Methodology'!$B$9,'Methodology'!$B$10)) | L16: =COUNTIFS('Amendment Audit'!$D$5:$D$204,B16,'Amendment Audit'!$G$5:$G$204,E16,'Amendment Audit'!$C$5:$C$204,">="&D16,'Amendment Audit'!$J$5:$J$204,"YES") | M16: =IF(L16>0,"Certificate substantiates LOA amendment",IF(B16="WL-01893","Certificate post-dates and conflicts in value with the 2022 amendment","No matching amendment"))
A17: 2024-09-03_measurement_certificate_WL-02401.pdf | B17: WL-02401 | C17: MC-2024-0091 | D17: 45538 | E17: 31.7 | F17: YES | H17: =IF(G17="","NOT DETERMINABLE",IFERROR(INDEX(Inventory!$C$2:$C$1181,MATCH(G17,Inventory!$A$2:$A$1181,0)),"NOT FOUND")) | I17: =IF(G17="","NO CURRENT SLIP MATCH",IFERROR(INDEX(Inventory!$G$2:$G$1181,MATCH(G17,Inventory!$A$2:$A$1181,0)),"NOT FOUND")) | J17: =IF(G17="","",ROUNDUP(MAX(E17,INDEX(Inventory!$D$2:$D$1181,MATCH(G17,Inventory!$A$2:$A$1181,0))),0)) | K17: =IF(J17="","",J17*IF(H17="COVERED",'Methodology'!$B$9,'Methodology'!$B$10)) | L17: =COUNTIFS('Amendment Audit'!$D$5:$D$204,B17,'Amendment Audit'!$G$5:$G$204,E17,'Amendment Audit'!$C$5:$C$204,">="&D17,'Amendment Audit'!$J$5:$J$204,"YES") | M17: =IF(L17>0,"Certificate substantiates LOA amendment",IF(B17="WL-01893","Certificate post-dates and conflicts in value with the 2022 amendment","No matching amendment"))

Sheet Skip Audit
A1: Skip Audit
A2: Population: skip_events_2022_2026.csv, skip_date 2023-01-01 through 2026-07-31. PDF tests use the six supplied justification packets.
A4: Priority | B4: Contemporaneous Proof | C4: Skip ID | D4: Offer ID | E4: Skip Date | F4: Applicant ID | G4: Applicant Name | H4: Slip ID | I4: Basin | J4: Reason Code | K4: Review Date | L4: PDF Present | M4: PDF Contains Support | N4: Review Timing | O4: Offer Reconciled | P4: Document Reconciled | Q4: Metadata Attached | R4: Disposition | S4: Finding
A5: =IF(M5="NO","Priority 1",IF(N5="LATE","Priority 2",IF(B5="YES","OK","Priority 1"))) | B5: =IF(AND(L5="YES",M5="YES",N5="ON/BEFORE",O5="YES",P5="YES"),"YES","NO") | C5: SKP-2023-0095 | D5: OFR-2023-0323 | E5: 44934 | F5: WL-03099 | G5: =IFERROR(INDEX(Applicants!$C$2:$C$2911,MATCH(F5,Applicants!$A$2:$A$2911,0))&" "&INDEX(Applicants!$B$2:$B$2911,MATCH(F5,Applicants!$A$2:$A$2911,0)),"") | H5: LP-0317 | I5: Ledgport | J5: vessel-fit | K5: 44936 | L5: =IF(COUNTIFS('Skip Docs'!$A$2:$A$7,F5,'Skip Docs'!$C$2:$C$7,E5)>0,"YES","NO") | M5: =IF(L5="NO","NO",INDEX('Skip Docs'!$G$2:$G$7,MATCH(1,INDEX(('Skip Docs'!$A$2:$A$7=F5)*('Skip Docs'!$C$2:$C$7=E5),0),0))) | N5: =IF(K5<=E5,"ON/BEFORE","LATE") | O5: =IF(COUNTIFS(Offers!$A$2:$A$1487,D5,Offers!$C$2:$C$1487,F5,Offers!$B$2:$B$1487,E5,Offers!$E$2:$E$1487,H5,Offers!$I$2:$I$1487,"SKIPPED")=1,"YES","NO") | P5: =IF(L5="NO","N/A",IF(COUNTIFS('Skip Docs'!$A$2:$A$7,F5,'Skip Docs'!$C$2:$C$7,E5,'Skip Docs'!$D$2:$D$7,H5,'Skip Docs'!$E$2:$E$7,J5)=1,"YES","NO")) | Q5: Y | R5: SUSTAINED | S5: =IF(B5="YES","Verified contemporaneous proof",IF(L5="NO","No justification PDF supplied",IF(M5="NO","PDF is cover-only",IF(P5="NO","PDF content does not match logged slip/reason",IF(O5="NO","Offer event does not reconcile","Assembled after skip date")))))
A6: =IF(M6="NO","Priority 1",IF(N6="LATE","Priority 2",IF(B6="YES","OK","Priority 1"))) | B6: =IF(AND(L6="YES",M6="YES",N6="ON/BEFORE",O6="YES",P6="YES"),"YES","NO") | C6: SKP-2023-0096 | D6: OFR-2023-0324 | E6: 44934 | F6: WL-02685 | G6: =IFERROR(INDEX(Applicants!$C$2:$C$2911,MATCH(F6,Applicants!$A$2:$A$2911,0))&" "&INDEX(Applicants!$B$2:$B$2911,MATCH(F6,Applicants!$A$2:$A$2911,0)),"") | H6: LP-0906 | I6: Ledgport | J6: vessel-fit | K6: 44937 | L6: =IF(COUNTIFS('Skip Docs'!$A$2:$A$7,F6,'Skip Docs'!$C$2:$C$7,E6)>0,"YES","NO") | M6: =IF(L6="NO","NO",INDEX('Skip Docs'!$G$2:$G$7,MATCH(1,INDEX(('Skip Docs'!$A$2:$A$7=F6)*('Skip Docs'!$C$2:$C$7=E6),0),0))) | N6: =IF(K6<=E6,"ON/BEFORE","LATE") | O6: =IF(COUNTIFS(Offers!$A$2:$A$1487,D6,Offers!$C$2:$C$1487,F6,Offers!$B$2:$B$1487,E6,Offers!$E$2:$E$1487,H6,Offers!$I$2:$I$1487,"SKIPPED")=1,"YES","NO") | P6: =IF(L6="NO","N/A",IF(COUNTIFS('Skip Docs'!$A$2:$A$7,F6,'Skip Docs'!$C$2:$C$7,E6,'Skip Docs'!$D$2:$D$7,H6,'Skip Docs'!$E$2:$E$7,J6)=1,"YES","NO")) | Q6: Y | R6: SUSTAINED | S6: =IF(B6="YES","Verified contemporaneous proof",IF(L6="NO","No justification PDF supplied",IF(M6="NO","PDF is cover-only",IF(P6="NO","PDF content does not match logged slip/reason",IF(O6="NO","Offer event does not reconcile","Assembled after skip date")))))
A7: =IF(M7="NO","Priority 1",IF(N7="LATE","Priority 2",IF(B7="YES","OK","Priority 1"))) | B7: =IF(AND(L7="YES",M7="YES",N7="ON/BEFORE",O7="YES",P7="YES"),"YES","NO") | C7: SKP-2023-0097 | D7: OFR-2023-0326 | E7: 44952 | F7: WL-01298 | G7: =IFERROR(INDEX(Applicants!$C$2:$C$2911,MATCH(F7,Applicants!$A$2:$A$2911,0))&" "&INDEX(Applicants!$B$2:$B$2911,MATCH(F7,Applicants!$A$2:$A$2911,0)),"") | H7: GW-0708 | I7: Gullwing | J7: vessel-fit | K7: 44955 | L7: =IF(COUNTIFS('Skip Docs'!$A$2:$A$7,F7,'Skip Docs'!$C$2:$C$7,E7)>0,"YES","NO") | M7: =IF(L7="NO","NO",INDEX('Skip Docs'!$G$2:$G$7,MATCH(1,INDEX(('Skip Docs'!$A$2:$A$7=F7)*('Skip Docs'!$C$2:$C$7=E7),0),0))) | N7: =IF(K7<=E7,"ON/BEFORE","LATE") | O7: =IF(COUNTIFS(Offers!$A$2:$A$1487,D7,Offers!$C$2:$C$1487,F7,Offers!$B$2:$B$1487,E7,Offers!$E$2:$E$1487,H7,Offers!$I$2:$I$1487,"SKIPPED")=1,"YES","NO") | P7: =IF(L7="NO","N/A",IF(COUNTIFS('Skip Docs'!$A$2:$A$7,F7,'Skip Docs'!$C$2:$C$7,E7,'Skip Docs'!$D$2:$D$7,H7,'Skip Docs'!$E$2:$E$7,J7)=1,"YES","NO")) | Q7: Y | R7: SUSTAINED | S7: =IF(B7="YES","Verified contemporaneous proof",IF(L7="NO","No justification PDF supplied",IF(M7="NO","PDF is cover-only",IF(P7="NO","PDF content does not match logged slip/reason",IF(O7="NO","Offer event does not reconcile","Assembled after skip date")))))
A8: =IF(M8="NO","Priority 1",IF(N8="LATE","Priority 2",IF(B8="YES","OK","Priority 1"))) | B8: =IF(AND(L8="YES",M8="YES",N8="ON/BEFORE",O8="YES",P8="YES"),"YES","NO") | C8: SKP-2023-0098 | D8: OFR-2023-0334 | E8: 44934 | F8: WL-01959 | G8: =IFERROR(INDEX(Applicants!$C$2:$C$2911,MATCH(F8,Applicants!$A$2:$A$2911,0))&" "&INDEX(Applicants!$B$2:$B$2911,MATCH(F8,Applicants!$A$2:$A$2911,0)),"") | H8: VB-1023 | I8: Vessbank | J8: not-current | K8: 44937 | L8: =IF(COUNTIFS('Skip Docs'!$A$2:$A$7,F8,'Skip Docs'!$C$2:$C$7,E8)>0,"YES","NO") | M8: =IF(L8="NO","NO",INDEX('Skip Docs'!$G$2:$G$7,MATCH(1,INDEX(('Skip Docs'!$A$2:$A$7=F8)*('Skip Docs'!$C$2:$C$7=E8),0),0))) | N8: =IF(K8<=E8,"ON/BEFORE","LATE") | O8: =IF(COUNTIFS(Offers!$A$2:$A$1487,D8,Offers!$C$2:$C$1487,F8,Offers!$B$2:$B$1487,E8,Offers!$E$2:$E$1487,H8,Offers!$I$2:$I$1487,"SKIPPED")=1,"YES","NO") | P8: =IF(L8="NO","N/A",IF(COUNTIFS('Skip Docs'!$A$2:$A$7,F8,'Skip Docs'!$C$2:$C$7,E8,'Skip Docs'!$D$2:$D$7,H8,'Skip Docs'!$E$2:$E$7,J8)=1,"YES","NO")) | Q8: Y | R8: SUSTAINED | S8: =IF(B8="YES","Verified contemporaneous proof",IF(L8="NO","No justification PDF supplied",IF(M8="NO","PDF is cover-only",IF(P8="NO","PDF content does not match logged slip/reason",IF(O8="NO","Offer event does not reconcile","Assembled after skip date")))))
A9: =IF(M9="NO","Priority 1",IF(N9="LATE","Priority 2",IF(B9="YES","OK","Priority 1"))) | B9: =IF(AND(L9="YES",M9="YES",N9="ON/BEFORE",O9="YES",P9="YES"),"YES","NO") | C9: SKP-2023-0099 | D9: OFR-2023-0338 | E9: 44936 | F9: WL-01695 | G9: =IFERROR(INDEX(Applicants!$C$2:$C$2911,MATCH(F9,Applicants!$A$2:$A$2911,0))&" "&INDEX(Applicants!$B$2:$B$2911,MATCH(F9,Applicants!$A$2:$A$2911,0)),"") | H9: EW-0203 | I9: Eastwey | J9: vessel-fit | K9: 44939 | L9: =IF(COUNTIFS('Skip Docs'!$A$2:$A$7,F9,'Skip Docs'!$C$2:$C$7,E9)>0,"YES","NO") | M9: =IF(L9="NO","NO",INDEX('Skip Docs'!$G$2:$G$7,MATCH(1,INDEX(('Skip Docs'!$A$2:$A$7=F9)*('Skip Docs'!$C$2:$C$7=E9),0),0))) | N9: =IF(K9<=E9,"ON/BEFORE","LATE") | O9: =IF(COUNTIFS(Offers!$A$2:$A$1487,D9,Offers!$C$2:$C$1487,F9,Offers!$B$2:$B$1487,E9,Offers!$E$2:$E$1487,H9,Offers!$I$2:$I$1487,"SKIPPED")=1,"YES","NO") | P9: =IF(L9="NO","N/A",IF(COUNTIFS('Skip Docs'!$A$2:$A$7,F9,'Skip Docs'!$C$2:$C$7,E9,'Skip Docs'!$D$2:$D$7,H9,'Skip Docs'!$E$2:$E$7,J9)=1,"YES","NO")) | Q9: N | R9: SUSTAINED | S9: =IF(B9="YES","Verified contemporaneous proof",IF(L9="NO","No justification PDF supplied",IF(M9="NO","PDF is cover-only",IF(P9="NO","PDF content does not match logged slip/reason",IF(O9="NO","Offer event does not reconcile","Assembled after skip date")))))
A10: =IF(M10="NO","Priority 1",IF(N10="LATE","Priority 2",IF(B10="YES","OK","Priority 1"))) | B10: =IF(AND(L10="YES",M10="YES",N10="ON/BEFORE",O10="YES",P10="YES"),"YES","NO") | C10: SKP-2023-0100 | D10: OFR-2023-0343 | E10: 44975 | F10: WL-02565 | G10: =IFERROR(INDEX(Applicants!$C$2:$C$2911,MATCH(F10,Applicants!$A$2:$A$2911,0))&" "&INDEX(Applicants!$B$2:$B$2911,MATCH(F10,Applicants!$A$2:$A$2911,0)),"") | H10: GW-0116 | I10: Gullwing | J10: vessel-fit | K10: 44980 | L10: =IF(COUNTIFS('Skip Docs'!$A$2:$A$7,F10,'Skip Docs'!$C$2:$C$7,E10)>0,"YES","NO") | M10: =IF(L10="NO","NO",INDEX('Skip Docs'!$G$2:$G$7,MATCH(1,INDEX(('Skip Docs'!$A$2:$A$7=F10)*('Skip Docs'!$C$2:$C$7=E10),0),0))) | N10: =IF(K10<=E10,"ON/BEFORE","LATE") | O10: =IF(COUNTIFS(Offers!$A$2:$A$1487,D10,Offers!$C$2:$C$1487,F10,Offers!$B$2:$B$1487,E10,Offers!$E$2:$E$1487,H10,Offers!$I$2:$I$1487,"SKIPPED")=1,"YES","NO") | P10: =IF(L10="NO","N/A",IF(COUNTIFS('Skip Docs'!$A$2:$A$7,F10,'Skip Docs'!$C$2:$C$7,E10,'Skip Docs'!$D$2:$D$7,H10,'Skip Docs'!$E$2:$E$7,J10)=1,"YES","NO")) | Q10: Y | R10: SUSTAINED | S10: =IF(B10="YES","Verified contemporaneous proof",IF(L10="NO","No justification PDF supplied",IF(M10="NO","PDF is cover-only",IF(P10="NO","PDF content does not match logged slip/reason",IF(O10="NO","Offer event does not reconcile","Assembled after skip date")))))
A11: =IF(M11="NO","Priority 1",IF(N11="LATE","Priority 2",IF(B11="YES","OK","Priority 1"))) | B11: =IF(AND(L11="YES",M11="YES",N11="ON/BEFORE",O11="YES",P11="YES"),"YES","NO") | C11: SKP-2023-0101 | D11: OFR-2023-0345 | E11: 44976 | F11: WL-02664 | G11: =IFERROR(INDEX(Applicants!$C$2:$C$2911,MATCH(F11,Applicants!$A$2:$A$2911,0))&" "&INDEX(Applicants!$B$2:$B$2911,MATCH(F11,Applicants!$A$2:$A$2911,0)),"") | H11: GW-0220 | I11: Gullwing | J11: preference-mismatch | K11: 44976 | L11: =IF(COUNTIFS('Skip Docs'!$A$2:$A$7,F11,'Skip Docs'!$C$2:$C$7,E11)>0,"YES","NO") | M11: =IF(L11="NO","NO",INDEX('Skip Docs'!$G$2:$G$7,MATCH(1,INDEX(('Skip Docs'!$A$2:$A$7=F11)*('Skip Docs'!$C$2:$C$7=E11),0),0))) | N11: =IF(K11<=E11,"ON/BEFORE","LATE") | O11: =IF(COUNTIFS(Offers!$A$2:$A$1487,D11,Offers!$C$2:$C$1487,F11,Offers!$B$2:$B$1487,E11,Offers!$E$2:$E$1487,H11,Offers!$I$2:$I$1487,"SKIPPED")=1,"YES","NO") | P11: =IF(L11="NO","N/A",IF(COUNTIFS('Skip Docs'!$A$2:$A$7,F11,'Skip Docs'!$C$2:$C$7,E11,'Skip Docs'!$D$2:$D$7,H11,'Skip Docs'!$E$2:$E$7,J11)=1,"YES","NO")) | Q11: Y | R11: SUSTAINED | S11: =IF(B11="YES","Verified contemporaneous proof",IF(L11="NO","No justification PDF supplied",IF(M11="NO","PDF is cover-only",IF(P11="NO","PDF content does not match logged slip/reason",IF(O11="NO","Offer event does not reconcile","Assembled after skip date")))))
A12: =IF(M12="NO","Priority 1",IF(N12="LATE","Priority 2",IF(B12="YES","OK","Priority 1"))) | B12: =IF(AND(L12="YES",M12="YES",N12="ON/BEFORE",O12="YES",P12="YES"),"YES","NO") | C12: SKP-2023-0102 | D12: OFR-2023-0346 | E12: 44967 | F12: WL-03582 | G12: =IFERROR(INDEX(Applicants!$C$2:$C$2911,MATCH(F12,Applicants!$A$2:$A$2911,0))&" "&INDEX(Applicants!$B$2:$B$2911,MATCH(F12,Applicants!$A$2:$A$2911,0)),"") | H12: GW-0615 | I12: Gullwing | J12: not-current | K12: 44971 | L12: =IF(COUNTIFS('Skip Docs'!$A$2:$A$7,F12,'Skip Docs'!$C$2:$C$7,E12)>0,"YES","NO") | M12: =IF(L12="NO","NO",INDEX('Skip Docs'!$G$2:$G$7,MATCH(1,INDEX(('Skip Docs'!$A$2:$A$7=F12)*('Skip Docs'!$C$2:$C$7=E12),0),0))) | N12: =IF(K12<=E12,"ON/BEFORE","LATE") | O12: =IF(COUNTIFS(Offers!$A$2:$A$1487,D12,Offers!$C$2:$C$1487,F12,Offers!$B$2:$B$1487,E12,Offers!$E$2:$E$1487,H12,Offers!$I$2:$I$1487,"SKIPPED")=1,"YES","NO") | P12: =IF(L12="NO","N/A",IF(COUNTIFS('Skip Docs'!$A$2:$A$7,F12,'Skip Docs'!$C$2:$C$7,E12,'Skip Docs'!$D$2:$D$7,H12,'Skip Docs'!$E$2:$E$7,J12)=1,"YES","NO")) | Q12: Y | R12: SUSTAINED | S12: =IF(B12="YES","Verified contemporaneous proof",IF(L12="NO","No justification PDF supplied",IF(M12="NO","PDF is cover-only",IF(P12="NO","PDF content does not match logged slip/reason",IF(O12="NO","Offer event does not reconcile","Assembled after skip date")))))
A13: =IF(M13="NO","Priority 1",IF(N13="LATE","Priority 2",IF(B13="YES","OK","Priority 1"))) | B13: =IF(AND(L13="YES",M13="YES",N13="ON/BEFORE",O13="YES",P13="YES"),"YES","NO") | C13: SKP-2023-0103 | D13: OFR-2023-0350 | E13: 44974 | F13: WL-02918 | G13: =IFERROR(INDEX(Applicants!$C$2:$C$2911,MATCH(F13,Applicants!$A$2:$A$2911,0))&" "&INDEX(Applicants!$B$2:$B$2911,MATCH(F13,Applicants!$A$2:$A$2911,0)),"") | H13: LP-1116 | I13: Ledgport | J13: declined-prior-offer | K13: 44978 | L13: =IF(COUNTIFS('Skip Docs'!$A$2:$A$7,F13,'Skip Docs'!$C$2:$C$7,E13)>0,"YES","NO") | M13: =IF(L13="NO","NO",INDEX('Skip Docs'!$G$2:$G$7,MATCH(1,INDEX(('Skip Docs'!$A$2:$A$7=F13)*('Skip Docs'!$C$2:$C$7=E13),0),0))) | N13: =IF(K13<=E13,"ON/BEFORE","LATE") | O13: =IF(COUNTIFS(Offers!$A$2:$A$1487,D13,Offers!$C$2:$C$1487,F13,Offers!$B$2:$B$1487,E13,Offers!$E$2:$E$1487,H13,Offers!$I$2:$I$1487,"SKIPPED")=1,"YES","NO") | P13: =IF(L13="NO","N/A",IF(COUNTIFS('Skip Docs'!$A$2:$A$7,F13,'Skip Docs'!$C$2:$C$7,E13,'Skip Docs'!$D$2:$D$7,H13,'Skip Docs'!$E$2:$E$7,J13)=1,"YES","NO")) | Q13: Y | R13: SUSTAINED | S13: =IF(B13="YES","Verified contemporaneous proof",IF(L13="NO","No justification PDF supplied",IF(M13="NO","PDF is cover-only",IF(P13="NO","PDF content does not match logged slip/reason",IF(O13="NO","Offer event does not reconcile","Assembled after skip date")))))
A14: =IF(M14="NO","Priority 1",IF(N14="LATE","Priority 2",IF(B14="YES","OK","Priority 1"))) | B14: =IF(AND(L14="YES",M14="YES",N14="ON/BEFORE",O14="YES",P14="YES"),"YES","NO") | C14: SKP-2023-0104 | D14: OFR-2023-0360 | E14: 45000 | F14: WL-03523 | G14: =IFERROR(INDEX(Applicants!$C$2:$C$2911,MATCH(F14,Applicants!$A$2:$A$2911,0))&" "&INDEX(Applicants!$B$2:$B$2911,MATCH(F14,Applicants!$A$2:$A$2911,0)),"") | H14: SB-0210 | I14: Salmonberry | J14: vessel-fit | K14: 45003 | L14: =IF(COUNTIFS('Skip Docs'!$A$2:$A$7,F14,'Skip Docs'!$C$2:$C$7,E14)>0,"YES","NO") | M14: =IF(L14="NO","NO",INDEX('Skip Docs'!$G$2:$G$7,MATCH(1,INDEX(('Skip Docs'!$A$2:$A$7=F14)*('Skip Docs'!$C$2:$C$7=E14),0),0))) | N14: =IF(K14<=E14,"ON/BEFORE","LATE") | O14: =IF(COUNTIFS(Offers!$A$2:$A$1487,D14,Offers!$C$2:$C$1487,F14,Offers!$B$2:$B$1487,E14,Offers!$E$2:$E$1487,H14,Offers!$I$2:$I$1487,"SKIPPED")=1,"YES","NO") | P14: =IF(L14="NO","N/A",IF(COUNTIFS('Skip Docs'!$A$2:$A$7,F14,'Skip Docs'!$C$2:$C$7,E14,'Skip Docs'!$D$2:$D$7,H14,'Skip Docs'!$E$2:$E$7,J14)=1,"YES","NO")) | Q14: N | R14: SUSTAINED | S14: =IF(B14="YES","Verified contemporaneous proof",IF(L14="NO","No justification PDF supplied",IF(M14="NO","PDF is cover-only",IF(P14="NO","PDF content does not match logged slip/reason",IF(O14="NO","Offer event does not reconcile","Assembled after skip date")))))
A15: =IF(M15="NO","Priority 1",IF(N15="LATE","Priority 2",IF(B15="YES","OK","Priority 1"))) | B15: =IF(AND(L15="YES",M15="YES",N15="ON/BEFORE",O15="YES",P15="YES"),"YES","NO") | C15: SKP-2023-0105 | D15: OFR-2023-0361 | E15: 44991 | F15: WL-02366 | G15: =IFERROR(INDEX(Applicants!$C$2:$C$2911,MATCH(F15,Applicants!$A$2:$A$2911,0))&" "&INDEX(Applicants!$B$2:$B$2911,MATCH(F15,Applicants!$A$2:$A$2911,0)),"") | H15: LP-1116 | I15: Ledgport | J15: vessel-fit | K15: 44995 | L15: =IF(COUNTIFS('Skip Docs'!$A$2:$A$7,F15,'Skip Docs'!$C$2:$C$7,E15)>0,"YES","NO") | M15: =IF(L15="NO","NO",INDEX('Skip Docs'!$G$2:$G$7,MATCH(1,INDEX(('Skip Docs'!$A$2:$A$7=F15)*('Skip Docs'!$C$2:$C$7=E15),0),0))) | N15: =IF(K15<=E15,"ON/BEFORE","LATE") | O15: =IF(COUNTIFS(Offers!$A$2:$A$1487,D15,Offers!$C$2:$C$1487,F15,Offers!$B$2:$B$1487,E15,Offers!$E$2:$E$1487,H15,Offers!$I$2:$I$1487,"SKIPPED")=1,"YES","NO") | P15: =IF(L15="NO","N/A",IF(COUNTIFS('Skip Docs'!$A$2:$A$7,F15,'Skip Docs'!$C$2:$C$7,E15,'Skip Docs'!$D$2:$D$7,H15,'Skip Docs'!$E$2:$E$7,J15)=1,"YES","NO")) | Q15: Y | R15: SUSTAINED | S15: =IF(B15="YES","Verified contemporaneous proof",IF(L15="NO","No justification PDF supplied",IF(M15="NO","PDF is cover-only",IF(P15="NO","PDF content does not match logged slip/reason",IF(O15="NO","Offer event does not reconcile","Assembled after skip date")))))
A16: =IF(M16="NO","Priority 1",IF(N16="LATE","Priority 2",IF(B16="YES","OK","Priority 1"))) | B16: =IF(AND(L16="YES",M16="YES",N16="ON/BEFORE",O16="YES",P16="YES"),"YES","NO") | C16: SKP-2023-0106 | D16: OFR-2023-0364 | E16: 45012 | F16: WL-01388 | G16: =IFERROR(INDEX(Applicants!$C$2:$C$2911,MATCH(F16,Applicants!$A$2:$A$2911,0))&" "&INDEX(Applicants!$B$2:$B$2911,MATCH(F16,Applicants!$A$2:$A$2911,0)),"") | H16: SB-0617 | I16: Salmonberry | J16: vessel-fit | K16: 45015 | L16: =IF(COUNTIFS('Skip Docs'!$A$2:$A$7,F16,'Skip Docs'!$C$2:$C$7,E16)>0,"YES","NO") | M16: =IF(L16="NO","NO",INDEX('Skip Docs'!$G$2:$G$7,MATCH(1,INDEX(('Skip Docs'!$A$2:$A$7=F16)*('Skip Docs'!$C$2:$C$7=E16),0),0))) | N16: =IF(K16<=E16,"ON/BEFORE","LATE") | O16: =IF(COUNTIFS(Offers!$A$2:$A$1487,D16,Offers!$C$2:$C$1487,F16,Offers!$B$2:$B$1487,E16,Offers!$E$2:$E$1487,H16,Offers!$I$2:$I$1487,"SKIPPED")=1,"YES","NO") | P16: =IF(L16="NO","N/A",IF(COUNTIFS('Skip Docs'!$A$2:$A$7,F16,'Skip Docs'!$C$2:$C$7,E16,'Skip Docs'!$D$2:$D$7,H16,'Skip Docs'!$E$2:$E$7,J16)=1,"YES","NO")) | Q16: Y | R16: SUSTAINED | S16: =IF(B16="YES","Verified contemporaneous proof",IF(L16="NO","No justification PDF supplied",IF(M16="NO","PDF is cover-only",IF(P16="NO","PDF content does not match logged slip/reason",IF(O16="NO","Offer event does not reconcile","Assembled after skip date")))))
... A313: =IF(M313="NO","Priority 1",IF(N313="LATE","Priority 2",IF(B313="YES","OK","Priority 1"))) | B313: =IF(AND(L313="YES",M313="YES",N313="ON/BEFORE",O313="YES",P313="YES"),"YES","NO") | C313: SKP-2025-0412 | D313: OFR-2025-1487 | E313: 45909 | F313: WL-03102 | G313: =IFERROR(INDEX(Applicants!$C$2:$C$2911,MATCH(F313,Applicants!$A$2:$A$2911,0))&" "&INDEX(Applicants!$B$2:$B$2911,MATCH(F313,Applicants!$A$2:$A$2911,0)),"") | H313: LP-0806 | I313: Ledgport | J313: preference-mismatch | K313: 45911 | L313: =IF(COUNTIFS('Skip Docs'!$A$2:$A$7,F313,'Skip Docs'!$C$2:$C$7,E313)>0,"YES","NO") | M313: =IF(L313="NO","NO",INDEX('Skip Docs'!$G$2:$G$7,MATCH(1,INDEX(('Skip Docs'!$A$2:$A$7=F313)*('Skip Docs'!$C$2:$C$7=E313),0),0))) | N313: =IF(K313<=E313,"ON/BEFORE","LATE") | O313: =IF(COUNTIFS(Offers!$A$2:$A$1487,D313,Offers!$C$2:$C$1487,F313,Offers!$B$2:$B$1487,E313,Offers!$E$2:$E$1487,H313,Offers!$I$2:$I$1487,"SKIPPED")=1,"YES","NO") | P313: =IF(L313="NO","N/A",IF(COUNTIFS('Skip Docs'!$A$2:$A$7,F313,'Skip Docs'!$C$2:$C$7,E313,'Skip Docs'!$D$2:$D$7,H313,'Skip Docs'!$E$2:$E$7,J313)=1,"YES","NO")) | Q313: Y | R313: SUSTAINED | S313: =IF(B313="YES","Verified contemporaneous proof",IF(L313="NO","No justification PDF supplied",IF(M313="NO","PDF is cover-only",IF(P313="NO","PDF content does not match logged slip/reason",IF(O313="NO","Offer event does not reconcile","Assembled after skip date")))))

Sheet Amendment Audit
A1: LOA Amendment Audit
A2: Population: amendment_log_2022_2026.csv, LOA entries from 2022-08-01 through the audit date. Actual supplied files, not source_document labels, control support status.
A4: Priority | B4: Amendment ID | C4: Amendment Date | D4: Applicant ID | E4: Applicant Name | F4: Old LOA | G4: New LOA | H4: Source Document Label | I4: Certificate PDF Present | J4: Valid Support Match | K4: Downstream Skip Count | L4: First Downstream Skip | M4: Finding | N4: Counter Log | O4: Workstation
A5: =IF(J5="YES","OK",IF(K5>0,"Priority 1","Priority 2")) | B5: AMD-000285 | C5: 44778 | D5: WL-02933 | E5: =IFERROR(INDEX(Applicants!$C$2:$C$2911,MATCH(D5,Applicants!$A$2:$A$2911,0))&" "&INDEX(Applicants!$B$2:$B$2911,MATCH(D5,Applicants!$A$2:$A$2911,0)),"") | F5: 44.5 | G5: 46.4 | H5: Foldview Marine Services haul-out sheet 2022-08-02 | I5: =IF(COUNTIF('Cert Docs'!$A$2:$A$3,D5)>0,"YES","NO") | J5: =IF(COUNTIFS('Cert Docs'!$A$2:$A$3,D5,'Cert Docs'!$E$2:$E$3,G5,'Cert Docs'!$H$2:$H$3,"YES",'Cert Docs'!$D$2:$D$3,"<="&C5)>0,"YES","NO") | K5: =COUNTIFS('Skip Audit'!$F$5:$F$313,D5,'Skip Audit'!$E$5:$E$313,">="&C5) | M5: =IF(J5="YES","Substantiated by supplied signed certificate",IF(I5="YES","Supplied certificate does not match amendment date/value","No signed certificate or yard sheet supplied")) | N5: day log 2022-08-05 | O5: HB-COUNTER-2
A6: =IF(J6="YES","OK",IF(K6>0,"Priority 1","Priority 2")) | B6: AMD-000287 | C6: 44782 | D6: WL-01893 | E6: =IFERROR(INDEX(Applicants!$C$2:$C$2911,MATCH(D6,Applicants!$A$2:$A$2911,0))&" "&INDEX(Applicants!$B$2:$B$2911,MATCH(D6,Applicants!$A$2:$A$2911,0)),"") | F6: 26.4 | G6: 25.8 | H6: Foldview Marine Services haul-out sheet 2022-08-08 | I6: =IF(COUNTIF('Cert Docs'!$A$2:$A$3,D6)>0,"YES","NO") | J6: =IF(COUNTIFS('Cert Docs'!$A$2:$A$3,D6,'Cert Docs'!$E$2:$E$3,G6,'Cert Docs'!$H$2:$H$3,"YES",'Cert Docs'!$D$2:$D$3,"<="&C6)>0,"YES","NO") | K6: =COUNTIFS('Skip Audit'!$F$5:$F$313,D6,'Skip Audit'!$E$5:$E$313,">="&C6) | M6: =IF(J6="YES","Substantiated by supplied signed certificate",IF(I6="YES","Supplied certificate does not match amendment date/value","No signed certificate or yard sheet supplied")) | N6: day log 2022-08-09 | O6: HB-COUNTER-2
A7: =IF(J7="YES","OK",IF(K7>0,"Priority 1","Priority 2")) | B7: AMD-000288 | C7: 44782 | D7: WL-03054 | E7: =IFERROR(INDEX(Applicants!$C$2:$C$2911,MATCH(D7,Applicants!$A$2:$A$2911,0))&" "&INDEX(Applicants!$B$2:$B$2911,MATCH(D7,Applicants!$A$2:$A$2911,0)),"") | F7: 46.9 | G7: 45.3 | H7: MC-2022-0411 | I7: =IF(COUNTIF('Cert Docs'!$A$2:$A$3,D7)>0,"YES","NO") | J7: =IF(COUNTIFS('Cert Docs'!$A$2:$A$3,D7,'Cert Docs'!$E$2:$E$3,G7,'Cert Docs'!$H$2:$H$3,"YES",'Cert Docs'!$D$2:$D$3,"<="&C7)>0,"YES","NO") | K7: =COUNTIFS('Skip Audit'!$F$5:$F$313,D7,'Skip Audit'!$E$5:$E$313,">="&C7) | L7: SKP-2026-0343 | M7: =IF(J7="YES","Substantiated by supplied signed certificate",IF(I7="YES","Supplied certificate does not match amendment date/value","No signed certificate or yard sheet supplied")) | N7: day log 2022-08-09 | O7: HB-COUNTER-2
A8: =IF(J8="YES","OK",IF(K8>0,"Priority 1","Priority 2")) | B8: AMD-000289 | C8: 44783 | D8: WL-03103 | E8: =IFERROR(INDEX(Applicants!$C$2:$C$2911,MATCH(D8,Applicants!$A$2:$A$2911,0))&" "&INDEX(Applicants!$B$2:$B$2911,MATCH(D8,Applicants!$A$2:$A$2911,0)),"") | F8: 51 | G8: 51.1 | H8: Foldview Marine Services haul-out sheet 2022-08-04 | I8: =IF(COUNTIF('Cert Docs'!$A$2:$A$3,D8)>0,"YES","NO") | J8: =IF(COUNTIFS('Cert Docs'!$A$2:$A$3,D8,'Cert Docs'!$E$2:$E$3,G8,'Cert Docs'!$H$2:$H$3,"YES",'Cert Docs'!$D$2:$D$3,"<="&C8)>0,"YES","NO") | K8: =COUNTIFS('Skip Audit'!$F$5:$F$313,D8,'Skip Audit'!$E$5:$E$313,">="&C8) | M8: =IF(J8="YES","Substantiated by supplied signed certificate",IF(I8="YES","Supplied certificate does not match amendment date/value","No signed certificate or yard sheet supplied")) | N8: day log 2022-08-10 | O8: HB-COUNTER-2
A9: =IF(J9="YES","OK",IF(K9>0,"Priority 1","Priority 2")) | B9: AMD-000316 | C9: 44805 | D9: WL-03085 | E9: =IFERROR(INDEX(Applicants!$C$2:$C$2911,MATCH(D9,Applicants!$A$2:$A$2911,0))&" "&INDEX(Applicants!$B$2:$B$2911,MATCH(D9,Applicants!$A$2:$A$2911,0)),"") | F9: 28.7 | G9: 26.4 | H9: Foldview Marine Services haul-out sheet 2022-08-03 | I9: =IF(COUNTIF('Cert Docs'!$A$2:$A$3,D9)>0,"YES","NO") | J9: =IF(COUNTIFS('Cert Docs'!$A$2:$A$3,D9,'Cert Docs'!$E$2:$E$3,G9,'Cert Docs'!$H$2:$H$3,"YES",'Cert Docs'!$D$2:$D$3,"<="&C9)>0,"YES","NO") | K9: =COUNTIFS('Skip Audit'!$F$5:$F$313,D9,'Skip Audit'!$E$5:$E$313,">="&C9) | M9: =IF(J9="YES","Substantiated by supplied signed certificate",IF(I9="YES","Supplied certificate does not match amendment date/value","No signed certificate or yard sheet supplied")) | N9: day log 2022-09-01 | O9: HB-COUNTER-2
A10: =IF(J10="YES","OK",IF(K10>0,"Priority 1","Priority 2")) | B10: AMD-000322 | C10: 44811 | D10: WL-01962 | E10: =IFERROR(INDEX(Applicants!$C$2:$C$2911,MATCH(D10,Applicants!$A$2:$A$2911,0))&" "&INDEX(Applicants!$B$2:$B$2911,MATCH(D10,Applicants!$A$2:$A$2911,0)),"") | F10: 30.4 | G10: 31.5 | H10: Foldview Marine Services haul-out sheet 2022-09-01 | I10: =IF(COUNTIF('Cert Docs'!$A$2:$A$3,D10)>0,"YES","NO") | J10: =IF(COUNTIFS('Cert Docs'!$A$2:$A$3,D10,'Cert Docs'!$E$2:$E$3,G10,'Cert Docs'!$H$2:$H$3,"YES",'Cert Docs'!$D$2:$D$3,"<="&C10)>0,"YES","NO") | K10: =COUNTIFS('Skip Audit'!$F$5:$F$313,D10,'Skip Audit'!$E$5:$E$313,">="&C10) | M10: =IF(J10="YES","Substantiated by supplied signed certificate",IF(I10="YES","Supplied certificate does not match amendment date/value","No signed certificate or yard sheet supplied")) | N10: day log 2022-09-07 | O10: HB-COUNTER-2
A11: =IF(J11="YES","OK",IF(K11>0,"Priority 1","Priority 2")) | B11: AMD-000338 | C11: 44824 | D11: WL-03600 | E11: =IFERROR(INDEX(Applicants!$C$2:$C$2911,MATCH(D11,Applicants!$A$2:$A$2911,0))&" "&INDEX(Applicants!$B$2:$B$2911,MATCH(D11,Applicants!$A$2:$A$2911,0)),"") | F11: 51.4 | G11: 49 | I11: =IF(COUNTIF('Cert Docs'!$A$2:$A$3,D11)>0,"YES","NO") | J11: =IF(COUNTIFS('Cert Docs'!$A$2:$A$3,D11,'Cert Docs'!$E$2:$E$3,G11,'Cert Docs'!$H$2:$H$3,"YES",'Cert Docs'!$D$2:$D$3,"<="&C11)>0,"YES","NO") | K11: =COUNTIFS('Skip Audit'!$F$5:$F$313,D11,'Skip Audit'!$E$5:$E$313,">="&C11) | M11: =IF(J11="YES","Substantiated by supplied signed certificate",IF(I11="YES","Supplied certificate does not match amendment date/value","No signed certificate or yard sheet supplied")) | N11: day log 2022-09-20 | O11: HB-COUNTER-2
A12: =IF(J12="YES","OK",IF(K12>0,"Priority 1","Priority 2")) | B12: AMD-000339 | C12: 44826 | D12: WL-02493 | E12: =IFERROR(INDEX(Applicants!$C$2:$C$2911,MATCH(D12,Applicants!$A$2:$A$2911,0))&" "&INDEX(Applicants!$B$2:$B$2911,MATCH(D12,Applicants!$A$2:$A$2911,0)),"") | F12: 42.8 | G12: 42.9 | H12: Foldview Marine Services haul-out sheet 2022-08-21 | I12: =IF(COUNTIF('Cert Docs'!$A$2:$A$3,D12)>0,"YES","NO") | J12: =IF(COUNTIFS('Cert Docs'!$A$2:$A$3,D12,'Cert Docs'!$E$2:$E$3,G12,'Cert Docs'!$H$2:$H$3,"YES",'Cert Docs'!$D$2:$D$3,"<="&C12)>0,"YES","NO") | K12: =COUNTIFS('Skip Audit'!$F$5:$F$313,D12,'Skip Audit'!$E$5:$E$313,">="&C12) | M12: =IF(J12="YES","Substantiated by supplied signed certificate",IF(I12="YES","Supplied certificate does not match amendment date/value","No signed certificate or yard sheet supplied")) | N12: day log 2022-09-22 | O12: HB-COUNTER-2
A13: =IF(J13="YES","OK",IF(K13>0,"Priority 1","Priority 2")) | B13: AMD-000343 | C13: 44827 | D13: WL-03241 | E13: =IFERROR(INDEX(Applicants!$C$2:$C$2911,MATCH(D13,Applicants!$A$2:$A$2911,0))&" "&INDEX(Applicants!$B$2:$B$2911,MATCH(D13,Applicants!$A$2:$A$2911,0)),"") | F13: 37.1 | G13: 38.3 | H13: MC-2022-0705 | I13: =IF(COUNTIF('Cert Docs'!$A$2:$A$3,D13)>0,"YES","NO") | J13: =IF(COUNTIFS('Cert Docs'!$A$2:$A$3,D13,'Cert Docs'!$E$2:$E$3,G13,'Cert Docs'!$H$2:$H$3,"YES",'Cert Docs'!$D$2:$D$3,"<="&C13)>0,"YES","NO") | K13: =COUNTIFS('Skip Audit'!$F$5:$F$313,D13,'Skip Audit'!$E$5:$E$313,">="&C13) | M13: =IF(J13="YES","Substantiated by supplied signed certificate",IF(I13="YES","Supplied certificate does not match amendment date/value","No signed certificate or yard sheet supplied")) | N13: day log 2022-09-23 | O13: HB-COUNTER-2
A14: =IF(J14="YES","OK",IF(K14>0,"Priority 1","Priority 2")) | B14: AMD-000356 | C14: 44839 | D14: WL-01333 | E14: =IFERROR(INDEX(Applicants!$C$2:$C$2911,MATCH(D14,Applicants!$A$2:$A$2911,0))&" "&INDEX(Applicants!$B$2:$B$2911,MATCH(D14,Applicants!$A$2:$A$2911,0)),"") | F14: 22.6 | G14: 20.2 | H14: MC-2022-0134 | I14: =IF(COUNTIF('Cert Docs'!$A$2:$A$3,D14)>0,"YES","NO") | J14: =IF(COUNTIFS('Cert Docs'!$A$2:$A$3,D14,'Cert Docs'!$E$2:$E$3,G14,'Cert Docs'!$H$2:$H$3,"YES",'Cert Docs'!$D$2:$D$3,"<="&C14)>0,"YES","NO") | K14: =COUNTIFS('Skip Audit'!$F$5:$F$313,D14,'Skip Audit'!$E$5:$E$313,">="&C14) | L14: SKP-2025-0283 | M14: =IF(J14="YES","Substantiated by supplied signed certificate",IF(I14="YES","Supplied certificate does not match amendment date/value","No signed certificate or yard sheet supplied")) | N14: day log 2022-10-05 | O14: HB-COUNTER-2
A15: =IF(J15="YES","OK",IF(K15>0,"Priority 1","Priority 2")) | B15: AMD-000368 | C15: 44846 | D15: WL-01115 | E15: =IFERROR(INDEX(Applicants!$C$2:$C$2911,MATCH(D15,Applicants!$A$2:$A$2911,0))&" "&INDEX(Applicants!$B$2:$B$2911,MATCH(D15,Applicants!$A$2:$A$2911,0)),"") | F15: 42.1 | G15: 43.7 | H15: MC-2022-0882 | I15: =IF(COUNTIF('Cert Docs'!$A$2:$A$3,D15)>0,"YES","NO") | J15: =IF(COUNTIFS('Cert Docs'!$A$2:$A$3,D15,'Cert Docs'!$E$2:$E$3,G15,'Cert Docs'!$H$2:$H$3,"YES",'Cert Docs'!$D$2:$D$3,"<="&C15)>0,"YES","NO") | K15: =COUNTIFS('Skip Audit'!$F$5:$F$313,D15,'Skip Audit'!$E$5:$E$313,">="&C15) | M15: =IF(J15="YES","Substantiated by supplied signed certificate",IF(I15="YES","Supplied certificate does not match amendment date/value","No signed certificate or yard sheet supplied")) | N15: day log 2022-10-12 | O15: HB-COUNTER-2
A16: =IF(J16="YES","OK",IF(K16>0,"Priority 1","Priority 2")) | B16: AMD-000380 | C16: 44851 | D16: WL-02120 | E16: =IFERROR(INDEX(Applicants!$C$2:$C$2911,MATCH(D16,Applicants!$A$2:$A$2911,0))&" "&INDEX(Applicants!$B$2:$B$2911,MATCH(D16,Applicants!$A$2:$A$2911,0)),"") | F16: 43.5 | G16: 42.6 | H16: MC-2022-0916 | I16: =IF(COUNTIF('Cert Docs'!$A$2:$A$3,D16)>0,"YES","NO") | J16: =IF(COUNTIFS('Cert Docs'!$A$2:$A$3,D16,'Cert Docs'!$E$2:$E$3,G16,'Cert Docs'!$H$2:$H$3,"YES",'Cert Docs'!$D$2:$D$3,"<="&C16)>0,"YES","NO") | K16: =COUNTIFS('Skip Audit'!$F$5:$F$313,D16,'Skip Audit'!$E$5:$E$313,">="&C16) | L16: SKP-2026-0362 | M16: =IF(J16="YES","Substantiated by supplied signed certificate",IF(I16="YES","Supplied certificate does not match amendment date/value","No signed certificate or yard sheet supplied")) | N16: day log 2022-10-17 | O16: HB-COUNTER-2
A17: =IF(J17="YES","OK",IF(K17>0,"Priority 1","Priority 2")) | B17: AMD-000403 | C17: 44873 | D17: WL-01088 | E17: =IFERROR(INDEX(Applicants!$C$2:$C$2911,MATCH(D17,Applicants!$A$2:$A$2911,0))&" "&INDEX(Applicants!$B$2:$B$2911,MATCH(D17,Applicants!$A$2:$A$2911,0)),"") | F17: 28.2 | G17: 28.9 | H17: Foldview Marine Services haul-out sheet 2022-10-02 | I17: =IF(COUNTIF('Cert Docs'!$A$2:$A$3,D17)>0,"YES","NO") | J17: =IF(COUNTIFS('Cert Docs'!$A$2:$A$3,D17,'Cert Docs'!$E$2:$E$3,G17,'Cert Docs'!$H$2:$H$3,"YES",'Cert Docs'!$D$2:$D$3,"<="&C17)>0,"YES","NO") | K17: =COUNTIFS('Skip Audit'!$F$5:$F$313,D17,'Skip Audit'!$E$5:$E$313,">="&C17) | M17: =IF(J17="YES","Substantiated by supplied signed certificate",IF(I17="YES","Supplied certificate does not match amendment date/value","No signed certificate or yard sheet supplied")) | N17: day log 2022-11-08 | O17: HB-COUNTER-2
A18: =IF(J18="YES","OK",IF(K18>0,"Priority 1","Priority 2")) | B18: AMD-000413 | C18: 44878 | D18: WL-02512 | E18: =IFERROR(INDEX(Applicants!$C$2:$C$2911,MATCH(D18,Applicants!$A$2:$A$2911,0))&" "&INDEX(Applicants!$B$2:$B$2911,MATCH(D18,Applicants!$A$2:$A$2911,0)),"") | F18: 41.9 | G18: 40.7 | H18: MC-2022-0143 | I18: =IF(COUNTIF('Cert Docs'!$A$2:$A$3,D18)>0,"YES","NO") | J18: =IF(COUNTIFS('Cert Docs'!$A$2:$A$3,D18,'Cert Docs'!$E$2:$E$3,G18,'Cert Docs'!$H$2:$H$3,"YES",'Cert Docs'!$D$2:$D$3,"<="&C18)>0,"YES","NO") | K18: =COUNTIFS('Skip Audit'!$F$5:$F$313,D18,'Skip Audit'!$E$5:$E$313,">="&C18) | M18: =IF(J18="YES","Substantiated by supplied signed certificate",IF(I18="YES","Supplied certificate does not match amendment date/value","No signed certificate or yard sheet supplied")) | N18: day log 2022-11-13 | O18: HB-COUNTER-2
A19: =IF(J19="YES","OK",IF(K19>0,"Priority 1","Priority 2")) | B19: AMD-000415 | C19: 44881 | D19: WL-02107 | E19: =IFERROR(INDEX(Applicants!$C$2:$C$2911,MATCH(D19,Applicants!$A$2:$A$2911,0))&" "&INDEX(Applicants!$B$2:$B$2911,MATCH(D19,Applicants!$A$2:$A$2911,0)),"") | F19: 48.4 | G19: 47.3 | H19: Foldview Marine Services haul-out sheet 2022-09-01 | I19: =IF(COUNTIF('Cert Docs'!$A$2:$A$3,D19)>0,"YES","NO") | J19: =IF(COUNTIFS('Cert Docs'!$A$2:$A$3,D19,'Cert Docs'!$E$2:$E$3,G19,'Cert Docs'!$H$2:$H$3,"YES",'Cert Docs'!$D$2:$D$3,"<="&C19)>0,"YES","NO") | K19: =COUNTIFS('Skip Audit'!$F$5:$F$313,D19,'Skip Audit'!$E$5:$E$313,">="&C19) | M19: =IF(J19="YES","Substantiated by supplied signed certificate",IF(I19="YES","Supplied certificate does not match amendment date/value","No signed certificate or yard sheet supplied")) | N19: day log 2022-11-16 | O19: HB-COUNTER-2
A20: =IF(J20="YES","OK",IF(K20>0,"Priority 1","Priority 2")) | B20: AMD-000416 | C20: 44881 | D20: WL-03636 | E20: =IFERROR(INDEX(Applicants!$C$2:$C$2911,MATCH(D20,Applicants!$A$2:$A$2911,0))&" "&INDEX(Applicants!$B$2:$B$2911,MATCH(D20,Applicants!$A$2:$A$2911,0)),"") | F20: 23 | G20: 24.8 | H20: Foldview Marine Services haul-out sheet 2022-09-21 | I20: =IF(COUNTIF('Cert Docs'!$A$2:$A$3,D20)>0,"YES","NO") | J20: =IF(COUNTIFS('Cert Docs'!$A$2:$A$3,D20,'Cert Docs'!$E$2:$E$3,G20,'Cert Docs'!$H$2:$H$3,"YES",'Cert Docs'!$D$2:$D$3,"<="&C20)>0,"YES","NO") | K20: =COUNTIFS('Skip Audit'!$F$5:$F$313,D20,'Skip Audit'!$E$5:$E$313,">="&C20) | M20: =IF(J20="YES","Substantiated by supplied signed certificate",IF(I20="YES","Supplied certificate does not match amendment date/value","No signed certificate or yard sheet supplied")) | N20: day log 2022-11-16 | O20: HB-COUNTER-2
A21: =IF(J21="YES","OK",IF(K21>0,"Priority 1","Priority 2")) | B21: AMD-000425 | C21: 44889 | D21: WL-03350 | E21: =IFERROR(INDEX(Applicants!$C$2:$C$2911,MATCH(D21,Applicants!$A$2:$A$2911,0))&" "&INDEX(Applicants!$B$2:$B$2911,MATCH(D21,Applicants!$A$2:$A$2911,0)),"") | F21: 37.5 | G21: 35.2 | H21: MC-2022-0209 | I21: =IF(COUNTIF('Cert Docs'!$A$2:$A$3,D21)>0,"YES","NO") | J21: =IF(COUNTIFS('Cert Docs'!$A$2:$A$3,D21,'Cert Docs'!$E$2:$E$3,G21,'Cert Docs'!$H$2:$H$3,"YES",'Cert Docs'!$D$2:$D$3,"<="&C21)>0,"YES","NO") | K21: =COUNTIFS('Skip Audit'!$F$5:$F$313,D21,'Skip Audit'!$E$5:$E$313,">="&C21) | M21: =IF(J21="YES","Substantiated by supplied signed certificate",IF(I21="YES","Supplied certificate does not match amendment date/value","No signed certificate or yard sheet supplied")) | N21: day log 2022-11-24 | O21: HB-COUNTER-2
A22: =IF(J22="YES","OK",IF(K22>0,"Priority 1","Priority 2")) | B22: AMD-000431 | C22: 44893 | D22: WL-03727 | E22: =IFERROR(INDEX(Applicants!$C$2:$C$2911,MATCH(D22,Applicants!$A$2:$A$2911,0))&" "&INDEX(Applicants!$B$2:$B$2911,MATCH(D22,Applicants!$A$2:$A$2911,0)),"") | F22: 42.3 | G22: 44 | H22: Foldview Marine Services haul-out sheet 2022-08-20 | I22: =IF(COUNTIF('Cert Docs'!$A$2:$A$3,D22)>0,"YES","NO") | J22: =IF(COUNTIFS('Cert Docs'!$A$2:$A$3,D22,'Cert Docs'!$E$2:$E$3,G22,'Cert Docs'!$H$2:$H$3,"YES",'Cert Docs'!$D$2:$D$3,"<="&C22)>0,"YES","NO") | K22: =COUNTIFS('Skip Audit'!$F$5:$F$313,D22,'Skip Audit'!$E$5:$E$313,">="&C22) | M22: =IF(J22="YES","Substantiated by supplied signed certificate",IF(I22="YES","Supplied certificate does not match amendment date/value","No signed certificate or yard sheet supplied")) | N22: day log 2022-11-28 | O22: HB-COUNTER-2
A23: =IF(J23="YES","OK",IF(K23>0,"Priority 1","Priority 2")) | B23: AMD-000435 | C23: 44895 | D23: WL-03758 | E23: =IFERROR(INDEX(Applicants!$C$2:$C$2911,MATCH(D23,Applicants!$A$2:$A$2911,0))&" "&INDEX(Applicants!$B$2:$B$2911,MATCH(D23,Applicants!$A$2:$A$2911,0)),"") | F23: 53.2 | G23: 51.4 | H23: MC-2022-0410 | I23: =IF(COUNTIF('Cert Docs'!$A$2:$A$3,D23)>0,"YES","NO") | J23: =IF(COUNTIFS('Cert Docs'!$A$2:$A$3,D23,'Cert Docs'!$E$2:$E$3,G23,'Cert Docs'!$H$2:$H$3,"YES",'Cert Docs'!$D$2:$D$3,"<="&C23)>0,"YES","NO") | K23: =COUNTIFS('Skip Audit'!$F$5:$F$313,D23,'Skip Audit'!$E$5:$E$313,">="&C23) | L23: SKP-2023-0136 | M23: =IF(J23="YES","Substantiated by supplied signed certificate",IF(I23="YES","Supplied certificate does not match amendment date/value","No signed certificate or yard sheet supplied")) | N23: day log 2022-11-30 | O23: HB-COUNTER-2
A24: =IF(J24="YES","OK",IF(K24>0,"Priority 1","Priority 2")) | B24: AMD-000436 | C24: 44897 | D24: WL-02036 | E24: =IFERROR(INDEX(Applicants!$C$2:$C$2911,MATCH(D24,Applicants!$A$2:$A$2911,0))&" "&INDEX(Applicants!$B$2:$B$2911,MATCH(D24,Applicants!$A$2:$A$2911,0)),"") | F24: 23.5 | G24: 23.5 | H24: MC-2022-0629 | I24: =IF(COUNTIF('Cert Docs'!$A$2:$A$3,D24)>0,"YES","NO") | J24: =IF(COUNTIFS('Cert Docs'!$A$2:$A$3,D24,'Cert Docs'!$E$2:$E$3,G24,'Cert Docs'!$H$2:$H$3,"YES",'Cert Docs'!$D$2:$D$3,"<="&C24)>0,"YES","NO") | K24: =COUNTIFS('Skip Audit'!$F$5:$F$313,D24,'Skip Audit'!$E$5:$E$313,">="&C24) | M24: =IF(J24="YES","Substantiated by supplied signed certificate",IF(I24="YES","Supplied certificate does not match amendment date/value","No signed certificate or yard sheet supplied")) | N24: day log 2022-12-02 | O24: HB-COUNTER-2
A25: =IF(J25="YES","OK",IF(K25>0,"Priority 1","Priority 2")) | B25: AMD-000461 | C25: 44915 | D25: WL-03633 | E25: =IFERROR(INDEX(Applicants!$C$2:$C$2911,MATCH(D25,Applicants!$A$2:$A$2911,0))&" "&INDEX(Applicants!$B$2:$B$2911,MATCH(D25,Applicants!$A$2:$A$2911,0)),"") | F25: 30.8 | G25: 33.4 | H25: Foldview Marine Services haul-out sheet 2022-09-09 | I25: =IF(COUNTIF('Cert Docs'!$A$2:$A$3,D25)>0,"YES","NO") | J25: =IF(COUNTIFS('Cert Docs'!$A$2:$A$3,D25,'Cert Docs'!$E$2:$E$3,G25,'Cert Docs'!$H$2:$H$3,"YES",'Cert Docs'!$D$2:$D$3,"<="&C25)>0,"YES","NO") | K25: =COUNTIFS('Skip Audit'!$F$5:$F$313,D25,'Skip Audit'!$E$5:$E$313,">="&C25) | M25: =IF(J25="YES","Substantiated by supplied signed certificate",IF(I25="YES","Supplied certificate does not match amendment date/value","No signed certificate or yard sheet supplied")) | N25: day log 2022-12-20 | O25: HB-COUNTER-2
A26: =IF(J26="YES","OK",IF(K26>0,"Priority 1","Priority 2")) | B26: AMD-000462 | C26: 44916 | D26: WL-02309 | E26: =IFERROR(INDEX(Applicants!$C$2:$C$2911,MATCH(D26,Applicants!$A$2:$A$2911,0))&" "&INDEX(Applicants!$B$2:$B$2911,MATCH(D26,Applicants!$A$2:$A$2911,0)),"") | F26: 32.1 | G26: 29.7 | H26: MC-2022-0151 | I26: =IF(COUNTIF('Cert Docs'!$A$2:$A$3,D26)>0,"YES","NO") | J26: =IF(COUNTIFS('Cert Docs'!$A$2:$A$3,D26,'Cert Docs'!$E$2:$E$3,G26,'Cert Docs'!$H$2:$H$3,"YES",'Cert Docs'!$D$2:$D$3,"<="&C26)>0,"YES","NO") | K26: =COUNTIFS('Skip Audit'!$F$5:$F$313,D26,'Skip Audit'!$E$5:$E$313,">="&C26) | M26: =IF(J26="YES","Substantiated by supplied signed certificate",IF(I26="YES","Supplied certificate does not match amendment date/value","No signed certificate or yard sheet supplied")) | N26: day log 2022-12-21 | O26: HB-COUNTER-2
A27: =IF(J27="YES","OK",IF(K27>0,"Priority 1","Priority 2")) | B27: AMD-000471 | C27: 44921 | D27: WL-02957 | E27: =IFERROR(INDEX(Applicants!$C$2:$C$2911,MATCH(D27,Applicants!$A$2:$A$2911,0))&" "&INDEX(Applicants!$B$2:$B$2911,MATCH(D27,Applicants!$A$2:$A$2911,0)),"") | F27: 50.6 | G27: 48.9 | H27: MC-2022-0675 | I27: =IF(COUNTIF('Cert Docs'!$A$2:$A$3,D27)>0,"YES","NO") | J27: =IF(COUNTIFS('Cert Docs'!$A$2:$A$3,D27,'Cert Docs'!$E$2:$E$3,G27,'Cert Docs'!$H$2:$H$3,"YES",'Cert Docs'!$D$2:$D$3,"<="&C27)>0,"YES","NO") | K27: =COUNTIFS('Skip Audit'!$F$5:$F$313,D27,'Skip Audit'!$E$5:$E$313,">="&C27) | M27: =IF(J27="YES","Substantiated by supplied signed certificate",IF(I27="YES","Supplied certificate does not match amendment date/value","No signed certificate or yard sheet supplied")) | N27: day log 2022-12-26 | O27: HB-COUNTER-2
A28: =IF(J28="YES","OK",IF(K28>0,"Priority 1","Priority 2")) | B28: AMD-000478 | C28: 44925 | D28: WL-03274 | E28: =IFERROR(INDEX(Applicants!$C$2:$C$2911,MATCH(D28,Applicants!$A$2:$A$2911,0))&" "&INDEX(Applicants!$B$2:$B$2911,MATCH(D28,Applicants!$A$2:$A$2911,0)),"") | F28: 26.3 | G28: 27.5 | H28: MC-2022-0649 | I28: =IF(COUNTIF('Cert Docs'!$A$2:$A$3,D28)>0,"YES","NO") | J28: =IF(COUNTIFS('Cert Docs'!$A$2:$A$3,D28,'Cert Docs'!$E$2:$E$3,G28,'Cert Docs'!$H$2:$H$3,"YES",'Cert Docs'!$D$2:$D$3,"<="&C28)>0,"YES","NO") | K28: =COUNTIFS('Skip Audit'!$F$5:$F$313,D28,'Skip Audit'!$E$5:$E$313,">="&C28) | M28: =IF(J28="YES","Substantiated by supplied signed certificate",IF(I28="YES","Supplied certificate does not match amendment date/value","No signed certificate or yard sheet supplied")) | N28: day log 2022-12-30 | O28: HB-COUNTER-2
A29: =IF(J29="YES","OK",IF(K29>0,"Priority 1","Priority 2")) | B29: AMD-000482 | C29: 44927 | D29: WL-03883 | E29: =IFERROR(INDEX(Applicants!$C$2:$C$2911,MATCH(D29,Applicants!$A$2:$A$2911,0))&" "&INDEX(Applicants!$B$2:$B$2911,MATCH(D29,Applicants!$A$2:$A$2911,0)),"") | F29: 23.8 | G29: 24 | H29: MC-2023-0263 | I29: =IF(COUNTIF('Cert Docs'!$A$2:$A$3,D29)>0,"YES","NO") | J29: =IF(COUNTIFS('Cert Docs'!$A$2:$A$3,D29,'Cert Docs'!$E$2:$E$3,G29,'Cert Docs'!$H$2:$H$3,"YES",'Cert Docs'!$D$2:$D$3,"<="&C29)>0,"YES","NO") | K29: =COUNTIFS('Skip Audit'!$F$5:$F$313,D29,'Skip Audit'!$E$5:$E$313,">="&C29) | M29: =IF(J29="YES","Substantiated by supplied signed certificate",IF(I29="YES","Supplied certificate does not match amendment date/value","No signed certificate or yard sheet supplied")) | N29: day log 2023-01-01 | O29: HB-COUNTER-2
A30: =IF(J30="YES","OK",IF(K30>0,"Priority 1","Priority 2")) | B30: AMD-000506 | C30: 44948 | D30: WL-02724 | E30: =IFERROR(INDEX(Applicants!$C$2:$C$2911,MATCH(D30,Applicants!$A$2:$A$2911,0))&" "&INDEX(Applicants!$B$2:$B$2911,MATCH(D30,Applicants!$A$2:$A$2911,0)),"") | F30: 45.4 | G30: 44.5 | H30: MC-2023-0238 | I30: =IF(COUNTIF('Cert Docs'!$A$2:$A$3,D30)>0,"YES","NO") | J30: =IF(COUNTIFS('Cert Docs'!$A$2:$A$3,D30,'Cert Docs'!$E$2:$E$3,G30,'Cert Docs'!$H$2:$H$3,"YES",'Cert Docs'!$D$2:$D$3,"<="&C30)>0,"YES","NO") | K30: =COUNTIFS('Skip Audit'!$F$5:$F$313,D30,'Skip Audit'!$E$5:$E$313,">="&C30) | M30: =IF(J30="YES","Substantiated by supplied signed certificate",IF(I30="YES","Supplied certificate does not match amendment date/value","No signed certificate or yard sheet supplied")) | N30: day log 2023-01-22 | O30: HB-COUNTER-2
