Workbook

Sheet Summary
A1: MOORAGE AUDIT | BOARD REVIEW
A2: Prepared for Administrator Ginny Marina | As of August 1, 2026 | Skip period January 1, 2023 - July 31, 2026
A4: QUEUE EXCEPTIONS | C4: CONFIRMED LEAKAGE | E4: HOLDERS >90 DAYS | G4: OVER-90 BALANCE
A5: =COUNTIF('Queue Exceptions'!$S$35:$S$345,"EXCEPTION") -> 23 | C5: =SUM('Billing Reconciliations'!$T$17:$T$1102) -> 0 | E5: =COUNTA(Aging!$A$7:$A$12) -> 6 | G5: =SUM(Aging!$J$7:$J$12) -> 4368
A8: AUDIT RESULTS
A9: Area | B9: Population | C9: Exceptions / gap | D9: Financial basis | E9: Status | F9: Board interpretation
A10: Queue skips | B10: =COUNTIF('Queue Exceptions'!$A$35:$A$345,"REGISTER") -> 309 | C10: =COUNTIF('Queue Exceptions'!$S$35:$S$345,"EXCEPTION") -> 23 | D10: N/A | E10: =IF(C10=0,"No exceptions identified","Action required") -> Action required | F10: Dedicated skip register governs; offer export contains five fewer scoped events.
A11: Length amendments | B11: =COUNTA('Queue Exceptions'!$A$351:$A$551) -> 200 | C11: =COUNTIF('Queue Exceptions'!$I$351:$I$551,"EXCEPTION*") -> 0 | D11: 12 unsupported entries, but no scoped skip use | E11: =IF(C11=0,"No use exceptions identified","Action required") -> No use exceptions identified | F11: Resolution 2022-06 s.4.3 was applied prospectively from August 1, 2022.
A12: July monthly billings | B12: =COUNTIF('Billing Reconciliations'!$V$17:$V$1102,"OK")+COUNTIF('Billing Reconciliations'!$V$17:$V$1102,"EXCEPTION") -> 769 | C12: =COUNTIF('Billing Reconciliations'!$V$17:$V$1102,"EXCEPTION") -> 0 | D12: =SUM('Billing Reconciliations'!$T$17:$T$1102) -> 0 | E12: =IF(C12=0,"No rate/measurement exceptions","Action required") -> No rate/measurement exceptions | F12: Tested rows reprice at tariff rates using greater of rounded LOA or posted slip length.
A13: Billing coverage | B13: =COUNTA('Billing Reconciliations'!$A$17:$A$1102) -> 1086 | C13: =COUNTIF('Billing Reconciliations'!$V$17:$V$1102,"NOT SCORED*") -> 317 | D13: =SUMIF('Billing Reconciliations'!$V$17:$V$1102,"NOT SCORED*",'Billing Reconciliations'!$Y$17:$Y$1102) -> 120158.25 | E13: =IF(C13=0,"Complete","Agreement schedule needed") -> Agreement schedule needed | F13: Occupied slips without a July monthly row are not called leakage; term/prepayment evidence is required.
A14: Aging >90 days | B14: =COUNTA(Aging!$A$7:$A$12) -> 6 | C14: =COUNTA(Aging!$A$7:$A$12) -> 6 | D14: =SUM(Aging!$J$7:$J$12) -> 4368 | E14: =IF(B14=0,"No exceptions identified","Collections action") -> Collections action | F14: Six active holders have 91+ day balances; two include 120+ day amounts.
A16: GOVERNING BASIS AND SOURCE HIERARCHY
A17: 1. Skip population: skip_events_2022_2026.csv governs because Standing Order 15-3 s.5.1 names the skip event register as a District record. offer_events_2022_2026.csv is the cross-check.
A18: 2. Skip evidence: Standing Order 15-3 ss.3.2-3.3 requires same-day cover and supporting record. Physical skip files govern their contents; Appeal 2018-3 rejects later reconstruction.
A19: 3. LOA evidence: amendment_log_2022_2026.csv tested against Resolution 2022-06 s.4.3; only signed measurement certificates or yard haul-out measurement sheets qualify from 2022-08-01.
A20: 4. Billing: tariff_resolution_2019-14 ss.1-2 and Resolution 2022-06 ss.1-2; billable length is MAX(rounded-up check-in LOA, posted slip length). July transactions are pre-tax.
A21: 5. Aging: ar_aging_2026-07-31.xlsx, AR_Aging sheet. More than 90 days is the 91-120 plus 120+ buckets, not total account due.
A23: BOARD PRIORITIES
A24: 1 | Preserve and reconcile the seven Tier 1 queue records before the next matching vacancy is worked.
A25: 2 | Obtain the agreement-term and prepayment schedule for 317 occupied slips not represented by a July monthly billing row.
A26: 3 | Begin collections review for the two 120+ day accounts, then the four 91-120 day accounts.

Sheet Queue Exceptions
A1: QUEUE EXCEPTIONS
A2: Scope: January 1, 2023 - July 31, 2026 | Printed view lists confirmed exceptions; full populations follow below
A3: Registered skips | B3: =COUNTIF($A$35:$A$345,"REGISTER") -> 309 | C3: Offer-export matches | D3: =COUNTIF($Q$35:$Q$345,"Y") -> 304 | E3: Confirmed exceptions | F3: =COUNTIF($S$35:$S$345,"EXCEPTION") -> 23 | G3: Uncertified LOA uses | H3: =COUNTIF($T$35:$T$345,"Uncertified length used") -> 0 | I3: Orphan event links | J3: =COUNTIFS($A$35:$A$345,"REGISTER",$Q$35:$Q$345,"N") -> 5
A6: Priority | B6: Applicant | C6: Name | D6: Date | E6: Reason | F6: Register slip | G6: File slip | H6: Exception | I6: Current status | J6: Evidence / action
A7: Tier 1 | B7: WL-02618 | C7: Gary Tomlinson | D7: 2023-05-02 | E7: vessel-fit | F7: GW-0610 | G7: EW-0414 | H7: Missing contemporaneous support | I7: RETAINER | J7: Cover sheet only — supporting record not attached WL-02618 file has no supporting particulars; file slip EW-0414 differs from register slip GW-0610.
A8: Tier 1 | B8: WL-03044 | C8: Iris Quan | D8: 2024-02-20 | E8: preference-mismatch | F8: VB-0904 | G8: EW-0603 | H8: Missing contemporaneous support | I8: ACTIVE_WAITLIST | J8: Cover sheet only — supporting record not attached WL-03044 file has no preference sheet; file slip EW-0603 differs from register slip VB-0904.
A9: Tier 1 | B9: WL-02877 | C9: Sandra Milovich | D9: 2024-03-19 | E9: vessel-fit | F9: GW-1012 | G9: GW-0702 | H9: File/event identity mismatch | I9: ACTIVE_WAITLIST | J9: WL-02877 file supports GW-0702, not the registered event for GW-1012.
A10: Tier 1 | B10: WL-03390 | C10: Phillip Ard | D10: 2024-11-05 | E10: declined-prior-offer | F10: SB-0120 | G10: VB-0144 | H10: Missing contemporaneous support | I10: RETAINER | J10: Cover sheet only — supporting record not attached WL-03390 file has no cited prior offer; file slip VB-0144 differs from register slip SB-0120.
A11: Tier 1 | B11: WL-03102 | C11: Dennis Farlow | D11: 2025-09-09 | E11: preference-mismatch | F11: LP-0806 | G11: EW-0620 | H11: File/event identity mismatch | I11: ACTIVE_WAITLIST | J11: WL-03102 file supports EW-0620, not the registered event for LP-0806; LOA support itself is valid.
A12: Tier 1 | B12: WL-02319 | C12: Elizabeth Pacheco | D12: Not stated | E12: Not stated | F12: Not stated | G12: Not stated | H12: Late supporting record | I12: ACTIVE_WAITLIST | J12: 2025-Q3 calibration workpaper: supporting record was dated 3 days after the slip was worked; event is absent from offer and skip exports.
A13: Tier 1 | B13: WL-02712 | C13: Sarah Garcia | D13: Not stated | E13: vessel-fit | F13: 28-ft slip (workpaper) | G13: Not stated | H13: Invalid vessel-fit basis | I13: ACTIVE_WAITLIST | J13: 2025-Q3 calibration workpaper: particulars showed 27.9 ft for a 28-ft slip, so vessel-fit did not establish ineligibility; event is absent from event exports.
A14: Tier 2 | B14: WL-01695 | C14: Antonio Leach | D14: 2023-01-10 | E14: vessel-fit | F14: EW-0203 | G14: Not inspected | H14: Missing contemporaneous support | I14: ACTIVE_WAITLIST | J14: Skip event register explicitly records documentation_attached=N; physical file was not among the supplied skip files.
A15: Tier 2 | B15: WL-03523 | C15: Darlene Glover | D15: 2023-03-15 | E15: vessel-fit | F15: SB-0210 | G15: Not inspected | H15: Missing contemporaneous support | I15: ACTIVE_WAITLIST | J15: Skip event register explicitly records documentation_attached=N; physical file was not among the supplied skip files.
A16: Tier 2 | B16: WL-01781 | C16: Crystal Parrish | D16: 2023-06-15 | E16: preference-mismatch | F16: LP-0220 | G16: Not inspected | H16: Missing contemporaneous support | I16: EXPIRED | J16: Skip event register explicitly records documentation_attached=N; physical file was not among the supplied skip files.
A17: Tier 2 | B17: WL-02285 | C17: Brian Scott | D17: 2023-09-11 | E17: declined-prior-offer | F17: EW-0107 | G17: Not inspected | H17: Missing contemporaneous support | I17: ACTIVE_WAITLIST | J17: Skip event register explicitly records documentation_attached=N; physical file was not among the supplied skip files.
... A29: Tier 2 | B29: WL-01936 | C29: Deanna Livingston | D29: 2026-06-22 | E29: not-current | F29: VB-0507 | G29: Not inspected | H29: Missing contemporaneous support | I29: ACTIVE_WAITLIST | J29: Skip event register explicitly records documentation_attached=N; physical file was not among the supplied skip files.
A34: Row Type | B34: Skip ID | C34: Offer ID | D34: Skip Date | E34: Applicant ID | F34: Applicant Name | G34: Rank | H34: Current Status | I34: Application Date | J34: Register Slip | K34: File Slip | L34: Basin | M34: Slip Size | N34: Reason | O34: Doc Attached | P34: File Review | Q34: Offer Match | R34: LOA Certification Trace | S34: Finding Status | T34: Exception Category | U34: Appeal Priority | V34: Evidence / Notes
A35: REGISTER | B35: SKP-2023-0408 | C35: OFR-2023-1487 | D35: 2023-05-02 | E35: WL-02618 | F35: Gary Tomlinson | G35: 1618 | H35: RETAINER | I35: 2024-09-17 | J35: GW-0610 | K35: EW-0414 | L35: Gullwing | M35: 32 | N35: vessel-fit | O35: N | P35: COVER ONLY | Q35: N | R35: N/A - no post-effective LOA amendment | S35: EXCEPTION | T35: Missing contemporaneous support | U35: Tier 1 | V35: Cover sheet only — supporting record not attached WL-02618 file has no supporting particulars; file slip EW-0414 differs from register slip GW-0610.
A36: REGISTER | B36: SKP-2024-0409 | C36: OFR-2024-1487 | D36: 2024-02-20 | E36: WL-03044 | F36: Iris Quan | G36: 2044 | H36: ACTIVE_WAITLIST | I36: 2025-03-14 | J36: VB-0904 | K36: EW-0603 | L36: Vessbank | M36: 28 | N36: preference-mismatch | O36: N | P36: COVER ONLY | Q36: N | R36: N/A - no post-effective LOA amendment | S36: EXCEPTION | T36: Missing contemporaneous support | U36: Tier 1 | V36: Cover sheet only — supporting record not attached WL-03044 file has no preference sheet; file slip EW-0603 differs from register slip VB-0904.
A37: REGISTER | B37: SKP-2024-0411 | C37: OFR-2024-1487 | D37: 2024-03-19 | E37: WL-02877 | F37: Sandra Milovich | G37: 1877 | H37: ACTIVE_WAITLIST | I37: 2025-01-03 | J37: GW-1012 | K37: GW-0702 | L37: Gullwing | M37: 80 | N37: vessel-fit | O37: Y | P37: COMPLETE - DIFFERENT SLIP | Q37: N | R37: N/A - no post-effective LOA amendment | S37: EXCEPTION | T37: File/event identity mismatch | U37: Tier 1 | V37: WL-02877 file supports GW-0702, not the registered event for GW-1012.
A38: REGISTER | B38: SKP-2024-0410 | C38: OFR-2024-1487 | D38: 2024-11-05 | E38: WL-03390 | F38: Phillip Ard | G38: 2390 | H38: RETAINER | I38: 2025-08-19 | J38: SB-0120 | K38: VB-0144 | L38: Salmonberry | M38: 40 | N38: declined-prior-offer | O38: N | P38: COVER ONLY | Q38: N | R38: N/A - no post-effective LOA amendment | S38: EXCEPTION | T38: Missing contemporaneous support | U38: Tier 1 | V38: Cover sheet only — supporting record not attached WL-03390 file has no cited prior offer; file slip VB-0144 differs from register slip SB-0120.
A39: REGISTER | B39: SKP-2025-0412 | C39: OFR-2025-1487 | D39: 2025-09-09 | E39: WL-03102 | F39: Dennis Farlow | G39: 2102 | H39: ACTIVE_WAITLIST | I39: 2025-04-10 | J39: LP-0806 | K39: EW-0620 | L39: Ledgport | M39: 36 | N39: preference-mismatch | O39: Y | P39: COMPLETE - DIFFERENT SLIP | Q39: N | R39: SUPPORTED: AMD-001702 / Foldview Marine Services haul-out measurement sheet 2025-06-29 | S39: EXCEPTION | T39: File/event identity mismatch | U39: Tier 1 | V39: WL-03102 file supports EW-0620, not the registered event for LP-0806; LOA support itself is valid.
A40: CALIBRATION | B40: CAL-WL-02319 | C40: Not in event exports | D40: Not stated | E40: WL-02319 | F40: Elizabeth Pacheco | G40: 1319 | H40: ACTIVE_WAITLIST | I40: 2024-05-02 | J40: Not stated | K40: Not stated | L40: Not stated | N40: Not stated | O40: Y | P40: LATE SUPPORT | Q40: N | R40: N/A | S40: EXCEPTION | T40: Late supporting record | U40: Tier 1 | V40: 2025-Q3 calibration workpaper: supporting record was dated 3 days after the slip was worked; event is absent from offer and skip exports.
A41: CALIBRATION | B41: CAL-WL-02712 | C41: Not in event exports | D41: Not stated | E41: WL-02712 | F41: Sarah Garcia | G41: 1712 | H41: ACTIVE_WAITLIST | I41: 2024-10-27 | J41: 28-ft slip (workpaper) | K41: Not stated | L41: Not stated | M41: 28 | N41: vessel-fit | O41: Y | P41: INVALID VESSEL-FIT BASIS | Q41: N | R41: N/A | S41: EXCEPTION | T41: Invalid vessel-fit basis | U41: Tier 1 | V41: 2025-Q3 calibration workpaper: particulars showed 27.9 ft for a 28-ft slip, so vessel-fit did not establish ineligibility; event is absent from event exports.
A42: REGISTER | B42: SKP-2023-0099 | C42: OFR-2023-0338 | D42: 2023-01-10 | E42: WL-01695 | F42: Antonio Leach | G42: 695 | H42: ACTIVE_WAITLIST | I42: 2023-07-03 | J42: EW-0203 | K42: Not inspected | L42: Eastwey | M42: 28 | N42: vessel-fit | O42: N | P42: REGISTER METADATA ONLY | Q42: Y | R42: N/A - no post-effective LOA amendment | S42: EXCEPTION | T42: Missing contemporaneous support | U42: Tier 2 | V42: Skip event register explicitly records documentation_attached=N; physical file was not among the supplied skip files.
A43: REGISTER | B43: SKP-2023-0104 | C43: OFR-2023-0360 | D43: 2023-03-15 | E43: WL-03523 | F43: Darlene Glover | G43: 2523 | H43: ACTIVE_WAITLIST | I43: 2025-11-02 | J43: SB-0210 | K43: Not inspected | L43: Salmonberry | M43: 24 | N43: vessel-fit | O43: N | P43: REGISTER METADATA ONLY | Q43: Y | R43: N/A - no post-effective LOA amendment | S43: EXCEPTION | T43: Missing contemporaneous support | U43: Tier 2 | V43: Skip event register explicitly records documentation_attached=N; physical file was not among the supplied skip files.
A44: REGISTER | B44: SKP-2023-0131 | C44: OFR-2023-0448 | D44: 2023-06-15 | E44: WL-01781 | F44: Crystal Parrish | G44: 781 | H44: EXPIRED | I44: 2023-08-22 | J44: LP-0220 | K44: Not inspected | L44: Ledgport | M44: 28 | N44: preference-mismatch | O44: N | P44: REGISTER METADATA ONLY | Q44: Y | R44: N/A - no post-effective LOA amendment | S44: EXCEPTION | T44: Missing contemporaneous support | U44: Tier 2 | V44: Skip event register explicitly records documentation_attached=N; physical file was not among the supplied skip files.
A45: REGISTER | B45: SKP-2023-0174 | C45: OFR-2023-0578 | D45: 2023-09-11 | E45: WL-02285 | F45: Brian Scott | G45: 1285 | H45: ACTIVE_WAITLIST | I45: 2024-04-22 | J45: EW-0107 | K45: Not inspected | L45: Eastwey | M45: 28 | N45: declined-prior-offer | O45: N | P45: REGISTER METADATA ONLY | Q45: Y | R45: N/A - no post-effective LOA amendment | S45: EXCEPTION | T45: Missing contemporaneous support | U45: Tier 2 | V45: Skip event register explicitly records documentation_attached=N; physical file was not among the supplied skip files.
A46: REGISTER | B46: SKP-2023-0166 | C46: OFR-2023-0551 | D46: 2023-09-16 | E46: WL-03844 | F46: Janet Medina | G46: 2844 | H46: RETAINER | I46: 2026-05-17 | J46: EW-0109 | K46: Not inspected | L46: Eastwey | M46: 60 | N46: vessel-fit | O46: N | P46: REGISTER METADATA ONLY | Q46: Y | R46: N/A - no post-effective LOA amendment | S46: EXCEPTION | T46: Missing contemporaneous support | U46: Tier 2 | V46: Skip event register explicitly records documentation_attached=N; physical file was not among the supplied skip files.
A47: REGISTER | B47: SKP-2024-0204 | C47: OFR-2024-0704 | D47: 2024-04-02 | E47: WL-01950 | F47: Mathew Trujillo | G47: 950 | H47: ACTIVE_WAITLIST | I47: 2023-11-09 | J47: EW-0608 | K47: Not inspected | L47: Eastwey | M47: 28 | N47: vessel-fit | O47: N | P47: REGISTER METADATA ONLY | Q47: Y | R47: N/A - no post-effective LOA amendment | S47: EXCEPTION | T47: Missing contemporaneous support | U47: Tier 2 | V47: Skip event register explicitly records documentation_attached=N; physical file was not among the supplied skip files.
A48: REGISTER | B48: SKP-2024-0207 | C48: OFR-2024-0729 | D48: 2024-04-21 | E48: WL-02948 | F48: Michael Salinas | G48: 1948 | H48: ACTIVE_WAITLIST | I48: 2025-02-01 | J48: GW-1013 | K48: Not inspected | L48: Gullwing | M48: 60 | N48: vessel-fit | O48: N | P48: REGISTER METADATA ONLY | Q48: Y | R48: N/A - no post-effective LOA amendment | S48: EXCEPTION | T48: Missing contemporaneous support | U48: Tier 2 | V48: Skip event register explicitly records documentation_attached=N; physical file was not among the supplied skip files.
A49: REGISTER | B49: SKP-2024-0219 | C49: OFR-2024-0789 | D49: 2024-06-05 | E49: WL-01144 | F49: James Lopez | G49: 144 | H49: ACTIVE_WAITLIST | I49: 2022-07-15 | J49: LP-0216 | K49: Not inspected | L49: Ledgport | M49: 32 | N49: vessel-fit | O49: N | P49: REGISTER METADATA ONLY | Q49: Y | R49: N/A - no post-effective LOA amendment | S49: EXCEPTION | T49: Missing contemporaneous support | U49: Tier 2 | V49: Skip event register explicitly records documentation_attached=N; physical file was not among the supplied skip files.
A50: REGISTER | B50: SKP-2024-0249 | C50: OFR-2024-0930 | D50: 2024-11-17 | E50: WL-02598 | F50: Nicole Rubio | G50: 1598 | H50: ACTIVE_WAITLIST | I50: 2024-09-07 | J50: GW-0902 | K50: Not inspected | L50: Gullwing | M50: 36 | N50: vessel-fit | O50: N | P50: REGISTER METADATA ONLY | Q50: Y | R50: N/A - no post-effective LOA amendment | S50: EXCEPTION | T50: Missing contemporaneous support | U50: Tier 2 | V50: Skip event register explicitly records documentation_attached=N; physical file was not among the supplied skip files.
A51: REGISTER | B51: SKP-2025-0292 | C51: OFR-2025-1117 | D51: 2025-07-06 | E51: WL-02298 | F51: Ronald Simpson | G51: 1298 | H51: ACTIVE_WAITLIST | I51: 2024-04-25 | J51: GW-1017 | K51: Not inspected | L51: Gullwing | M51: 32 | N51: vessel-fit | O51: N | P51: REGISTER METADATA ONLY | Q51: Y | R51: N/A - no post-effective LOA amendment | S51: EXCEPTION | T51: Missing contemporaneous support | U51: Tier 2 | V51: Skip event register explicitly records documentation_attached=N; physical file was not among the supplied skip files.
A52: REGISTER | B52: SKP-2025-0297 | C52: OFR-2025-1129 | D52: 2025-07-28 | E52: WL-03094 | F52: Christine Cook | G52: 2094 | H52: ACTIVE_WAITLIST | I52: 2025-04-06 | J52: GW-0103 | K52: Not inspected | L52: Gullwing | M52: 45 | N52: not-current | O52: N | P52: REGISTER METADATA ONLY | Q52: Y | R52: N/A - no post-effective LOA amendment | S52: EXCEPTION | T52: Missing contemporaneous support | U52: Tier 2 | V52: Skip event register explicitly records documentation_attached=N; physical file was not among the supplied skip files.
... A57: REGISTER | B57: SKP-2026-0384 | C57: OFR-2026-1402 | D57: 2026-06-22 | E57: WL-01936 | F57: Deanna Livingston | G57: 936 | H57: ACTIVE_WAITLIST | I57: 2023-11-04 | J57: VB-0507 | K57: Not inspected | L57: Vessbank | M57: 40 | N57: not-current | O57: N | P57: REGISTER METADATA ONLY | Q57: Y | R57: N/A - no post-effective LOA amendment | S57: EXCEPTION | T57: Missing contemporaneous support | U57: Tier 2 | V57: Skip event register explicitly records documentation_attached=N; physical file was not among the supplied skip files.
A58: REGISTER | B58: SKP-2023-0098 | C58: OFR-2023-0334 | D58: 2023-01-08 | E58: WL-01959 | F58: Jonathan Moore | G58: 959 | H58: ACTIVE_WAITLIST | I58: 2023-11-14 | J58: VB-1023 | K58: Not inspected | L58: Vessbank | M58: 28 | N58: not-current | O58: Y | P58: REGISTER METADATA ONLY | Q58: Y | R58: N/A - no post-effective LOA amendment | S58: NO EXCEPTION IDENTIFIED
A59: REGISTER | B59: SKP-2023-0096 | C59: OFR-2023-0324 | D59: 2023-01-08 | E59: WL-02685 | F59: Stephanie Hill | G59: 1685 | H59: ACTIVE_WAITLIST | I59: 2024-10-13 | J59: LP-0906 | K59: Not inspected | L59: Ledgport | M59: 28 | N59: vessel-fit | O59: Y | P59: REGISTER METADATA ONLY | Q59: Y | R59: N/A - no post-effective LOA amendment | S59: NO EXCEPTION IDENTIFIED
A60: REGISTER | B60: SKP-2023-0095 | C60: OFR-2023-0323 | D60: 2023-01-08 | E60: WL-03099 | F60: Ryan Robertson | G60: 2099 | H60: ACTIVE_WAITLIST | I60: 2025-04-08 | J60: LP-0317 | K60: Not inspected | L60: Ledgport | M60: 40 | N60: vessel-fit | O60: Y | P60: REGISTER METADATA ONLY | Q60: Y | R60: N/A - no post-effective LOA amendment | S60: NO EXCEPTION IDENTIFIED
A61: REGISTER | B61: SKP-2023-0097 | C61: OFR-2023-0326 | D61: 2023-01-26 | E61: WL-01298 | F61: Jason Boyd | G61: 298 | H61: ACTIVE_WAITLIST | I61: 2022-11-17 | J61: GW-0708 | K61: Not inspected | L61: Gullwing | M61: 70 | N61: vessel-fit | O61: Y | P61: REGISTER METADATA ONLY | Q61: Y | R61: N/A - no post-effective LOA amendment | S61: NO EXCEPTION IDENTIFIED
...

Sheet Billing Reconciliations
A1: BILLING RECONCILIATIONS
A2: July 2026 recurring moorage | Pre-tax | Source: slip inventory 2026-08 and billing transactions 2022-2026
A3: Occupied slips | B3: =COUNTA($A$17:$A$1102) -> 1086 | C3: Rows tested | D3: =COUNTIF($V$17:$V$1102,"OK")+COUNTIF($V$17:$V$1102,"EXCEPTION") -> 769 | E3: Rate/length exceptions | F3: =COUNTIF($V$17:$V$1102,"EXCEPTION") -> 0
A4: Unscored - no July row | B4: =COUNTIF($V$17:$V$1102,"NOT SCORED*") -> 317 | C4: Confirmed leakage | D4: =SUM($T$17:$T$1102) -> 0 | E4: Unverified monthly basis | F4: =SUMIF($V$17:$V$1102,"NOT SCORED*",$Y$17:$Y$1102) -> 120158.25
A6: COVERAGE BY BASIN
A7: Basin | B7: Occupied | C7: July rows | D7: Unscored | E7: Unverified monthly tariff basis | F7: Status
A8: Ledgport | B8: =COUNTIF($B$17:$B$1102,A8) -> 241 | C8: =COUNTIFS($B$17:$B$1102,A8,$V$17:$V$1102,"OK")+COUNTIFS($B$17:$B$1102,A8,$V$17:$V$1102,"EXCEPTION") -> 241 | D8: =COUNTIFS($B$17:$B$1102,A8,$V$17:$V$1102,"NOT SCORED*") -> 0 | E8: =SUMIFS($Y$17:$Y$1102,$B$17:$B$1102,A8,$V$17:$V$1102,"NOT SCORED*") -> 0 | F8: =IF(D8=0,"Complete","Agreement schedule needed") -> Complete
A9: Vessbank | B9: =COUNTIF($B$17:$B$1102,A9) -> 227 | C9: =COUNTIFS($B$17:$B$1102,A9,$V$17:$V$1102,"OK")+COUNTIFS($B$17:$B$1102,A9,$V$17:$V$1102,"EXCEPTION") -> 227 | D9: =COUNTIFS($B$17:$B$1102,A9,$V$17:$V$1102,"NOT SCORED*") -> 0 | E9: =SUMIFS($Y$17:$Y$1102,$B$17:$B$1102,A9,$V$17:$V$1102,"NOT SCORED*") -> 0 | F9: =IF(D9=0,"Complete","Agreement schedule needed") -> Complete
A10: Eastwey | B10: =COUNTIF($B$17:$B$1102,A10) -> 215 | C10: =COUNTIFS($B$17:$B$1102,A10,$V$17:$V$1102,"OK")+COUNTIFS($B$17:$B$1102,A10,$V$17:$V$1102,"EXCEPTION") -> 215 | D10: =COUNTIFS($B$17:$B$1102,A10,$V$17:$V$1102,"NOT SCORED*") -> 0 | E10: =SUMIFS($Y$17:$Y$1102,$B$17:$B$1102,A10,$V$17:$V$1102,"NOT SCORED*") -> 0 | F10: =IF(D10=0,"Complete","Agreement schedule needed") -> Complete
A11: Gullwing | B11: =COUNTIF($B$17:$B$1102,A11) -> 213 | C11: =COUNTIFS($B$17:$B$1102,A11,$V$17:$V$1102,"OK")+COUNTIFS($B$17:$B$1102,A11,$V$17:$V$1102,"EXCEPTION") -> 86 | D11: =COUNTIFS($B$17:$B$1102,A11,$V$17:$V$1102,"NOT SCORED*") -> 127 | E11: =SUMIFS($Y$17:$Y$1102,$B$17:$B$1102,A11,$V$17:$V$1102,"NOT SCORED*") -> 49762.05 | F11: =IF(D11=0,"Complete","Agreement schedule needed") -> Agreement schedule needed
A12: Salmonberry | B12: =COUNTIF($B$17:$B$1102,A12) -> 190 | C12: =COUNTIFS($B$17:$B$1102,A12,$V$17:$V$1102,"OK")+COUNTIFS($B$17:$B$1102,A12,$V$17:$V$1102,"EXCEPTION") -> 0 | D12: =COUNTIFS($B$17:$B$1102,A12,$V$17:$V$1102,"NOT SCORED*") -> 190 | E12: =SUMIFS($Y$17:$Y$1102,$B$17:$B$1102,A12,$V$17:$V$1102,"NOT SCORED*") -> 70396.2 | F12: =IF(D12=0,"Complete","Agreement schedule needed") -> Agreement schedule needed
A14: No rate, length, or amount exceptions were identified in the 769 July monthly rows. The 317 absent rows require agreement-term/prepayment evidence before they can be classified.
A16: Slip ID | B16: Basin | C16: Basin Type | D16: Agreement ID | E16: Applicant ID | F16: Tenant | G16: Vessel | H16: Slip Size Ft | I16: Check-in LOA Ft | J16: Billed Length | K16: Expected Billable Length | L16: Length Variance | M16: Billed Rate | N16: Expected Rate | O16: Rate Variance | P16: Months | Q16: Billed Amount | R16: Expected Amount | S16: Amount Variance | T16: Revenue Leakage | U16: Overbilling | V16: Result | W16: Transaction ID | X16: Evidence | Y16: Monthly Tariff Basis
A17: GW-0502 | B17: Gullwing | C17: open | D17: MA-2024-0502 | E17: WL-03559 | F17: David Sanders | G17: KESTREL VEER | H17: 60 | I17: 36.5 | K17: =MAX(ROUNDUP(I17,0),H17) -> 60 | L17: =IF(J17="","",J17-K17) | N17: =IF(C17="covered",10.4,7.55) -> 7.55 | O17: =IF(M17="","",M17-N17) | R17: =IF(OR(J17="",P17=""),"",K17*N17*P17) | S17: =IF(Q17="","",Q17-R17) | T17: =IF(S17="","",MAX(0,-S17)) | U17: =IF(S17="","",MAX(0,S17)) | V17: =IF(J17="","NOT SCORED - NO JULY MONTHLY ROW",IF(OR(ABS(L17)>0.005,ABS(O17)>0.005,ABS(S17)>0.005),"EXCEPTION","OK")) -> NOT SCORED - NO JULY MONTHLY ROW | X17: No July MONTHLY_MOORAGE row in billing_transactions_2022_2026.csv | Y17: =K17*N17 -> 453
A18: GW-0503 | B18: Gullwing | C18: open | D18: MA-2024-0503 | E18: WL-01494 | F18: Ashley Park | G18: COHO WEATHER | H18: 32 | I18: 43.9 | K18: =MAX(ROUNDUP(I18,0),H18) -> 44 | L18: =IF(J18="","",J18-K18) | N18: =IF(C18="covered",10.4,7.55) -> 7.55 | O18: =IF(M18="","",M18-N18) | R18: =IF(OR(J18="",P18=""),"",K18*N18*P18) | S18: =IF(Q18="","",Q18-R18) | T18: =IF(S18="","",MAX(0,-S18)) | U18: =IF(S18="","",MAX(0,S18)) | V18: =IF(J18="","NOT SCORED - NO JULY MONTHLY ROW",IF(OR(ABS(L18)>0.005,ABS(O18)>0.005,ABS(S18)>0.005),"EXCEPTION","OK")) -> NOT SCORED - NO JULY MONTHLY ROW | X18: No July MONTHLY_MOORAGE row in billing_transactions_2022_2026.csv | Y18: =K18*N18 -> 332.2
A19: GW-0504 | B19: Gullwing | C19: open | D19: MA-2024-0504 | E19: WL-01500 | F19: Patricia Marquez | G19: OSPREY GLIDE | H19: 50 | I19: 25.2 | K19: =MAX(ROUNDUP(I19,0),H19) -> 50 | L19: =IF(J19="","",J19-K19) | N19: =IF(C19="covered",10.4,7.55) -> 7.55 | O19: =IF(M19="","",M19-N19) | R19: =IF(OR(J19="",P19=""),"",K19*N19*P19) | S19: =IF(Q19="","",Q19-R19) | T19: =IF(S19="","",MAX(0,-S19)) | U19: =IF(S19="","",MAX(0,S19)) | V19: =IF(J19="","NOT SCORED - NO JULY MONTHLY ROW",IF(OR(ABS(L19)>0.005,ABS(O19)>0.005,ABS(S19)>0.005),"EXCEPTION","OK")) -> NOT SCORED - NO JULY MONTHLY ROW | X19: No July MONTHLY_MOORAGE row in billing_transactions_2022_2026.csv | Y19: =K19*N19 -> 377.5
A20: GW-0505 | B20: Gullwing | C20: open | D20: MA-2024-0505 | E20: WL-01089 | F20: Erin Holmes | G20: CORMORANT WIND | H20: 60 | I20: 54.3 | K20: =MAX(ROUNDUP(I20,0),H20) -> 60 | L20: =IF(J20="","",J20-K20) | N20: =IF(C20="covered",10.4,7.55) -> 7.55 | O20: =IF(M20="","",M20-N20) | R20: =IF(OR(J20="",P20=""),"",K20*N20*P20) | S20: =IF(Q20="","",Q20-R20) | T20: =IF(S20="","",MAX(0,-S20)) | U20: =IF(S20="","",MAX(0,S20)) | V20: =IF(J20="","NOT SCORED - NO JULY MONTHLY ROW",IF(OR(ABS(L20)>0.005,ABS(O20)>0.005,ABS(S20)>0.005),"EXCEPTION","OK")) -> NOT SCORED - NO JULY MONTHLY ROW | X20: No July MONTHLY_MOORAGE row in billing_transactions_2022_2026.csv | Y20: =K20*N20 -> 453
A21: GW-0506 | B21: Gullwing | C21: open | D21: MA-2024-0506 | E21: WL-03615 | F21: Kathryn Cook | G21: WIDGEON PASSAGE | H21: 45 | I21: 25.2 | K21: =MAX(ROUNDUP(I21,0),H21) -> 45 | L21: =IF(J21="","",J21-K21) | N21: =IF(C21="covered",10.4,7.55) -> 7.55 | O21: =IF(M21="","",M21-N21) | R21: =IF(OR(J21="",P21=""),"",K21*N21*P21) | S21: =IF(Q21="","",Q21-R21) | T21: =IF(S21="","",MAX(0,-S21)) | U21: =IF(S21="","",MAX(0,S21)) | V21: =IF(J21="","NOT SCORED - NO JULY MONTHLY ROW",IF(OR(ABS(L21)>0.005,ABS(O21)>0.005,ABS(S21)>0.005),"EXCEPTION","OK")) -> NOT SCORED - NO JULY MONTHLY ROW | X21: No July MONTHLY_MOORAGE row in billing_transactions_2022_2026.csv | Y21: =K21*N21 -> 339.75
A22: GW-0507 | B22: Gullwing | C22: open | D22: MA-2024-0507 | E22: WL-03057 | F22: Jennifer Stout | G22: BRANT ROSE | H22: 24 | I22: 38.3 | K22: =MAX(ROUNDUP(I22,0),H22) -> 39 | L22: =IF(J22="","",J22-K22) | N22: =IF(C22="covered",10.4,7.55) -> 7.55 | O22: =IF(M22="","",M22-N22) | R22: =IF(OR(J22="",P22=""),"",K22*N22*P22) | S22: =IF(Q22="","",Q22-R22) | T22: =IF(S22="","",MAX(0,-S22)) | U22: =IF(S22="","",MAX(0,S22)) | V22: =IF(J22="","NOT SCORED - NO JULY MONTHLY ROW",IF(OR(ABS(L22)>0.005,ABS(O22)>0.005,ABS(S22)>0.005),"EXCEPTION","OK")) -> NOT SCORED - NO JULY MONTHLY ROW | X22: No July MONTHLY_MOORAGE row in billing_transactions_2022_2026.csv | Y22: =K22*N22 -> 294.45
A23: GW-0508 | B23: Gullwing | C23: open | D23: MA-2024-0508 | E23: WL-03692 | F23: Warren Wilkins | G23: WIDGEON CREST | H23: 70 | I23: 25.9 | K23: =MAX(ROUNDUP(I23,0),H23) -> 70 | L23: =IF(J23="","",J23-K23) | N23: =IF(C23="covered",10.4,7.55) -> 7.55 | O23: =IF(M23="","",M23-N23) | R23: =IF(OR(J23="",P23=""),"",K23*N23*P23) | S23: =IF(Q23="","",Q23-R23) | T23: =IF(S23="","",MAX(0,-S23)) | U23: =IF(S23="","",MAX(0,S23)) | V23: =IF(J23="","NOT SCORED - NO JULY MONTHLY ROW",IF(OR(ABS(L23)>0.005,ABS(O23)>0.005,ABS(S23)>0.005),"EXCEPTION","OK")) -> NOT SCORED - NO JULY MONTHLY ROW | X23: No July MONTHLY_MOORAGE row in billing_transactions_2022_2026.csv | Y23: =K23*N23 -> 528.5
A24: GW-0509 | B24: Gullwing | C24: open | D24: MA-2024-0509 | E24: WL-03850 | F24: Teresa Greer | G24: COHO HARBOR | H24: 45 | I24: 35.6 | K24: =MAX(ROUNDUP(I24,0),H24) -> 45 | L24: =IF(J24="","",J24-K24) | N24: =IF(C24="covered",10.4,7.55) -> 7.55 | O24: =IF(M24="","",M24-N24) | R24: =IF(OR(J24="",P24=""),"",K24*N24*P24) | S24: =IF(Q24="","",Q24-R24) | T24: =IF(S24="","",MAX(0,-S24)) | U24: =IF(S24="","",MAX(0,S24)) | V24: =IF(J24="","NOT SCORED - NO JULY MONTHLY ROW",IF(OR(ABS(L24)>0.005,ABS(O24)>0.005,ABS(S24)>0.005),"EXCEPTION","OK")) -> NOT SCORED - NO JULY MONTHLY ROW | X24: No July MONTHLY_MOORAGE row in billing_transactions_2022_2026.csv | Y24: =K24*N24 -> 339.75
A25: GW-0511 | B25: Gullwing | C25: open | D25: MA-2024-0511 | E25: WL-02804 | F25: Danny Jones | G25: SCOTER ROCK | H25: 70 | I25: 28.7 | K25: =MAX(ROUNDUP(I25,0),H25) -> 70 | L25: =IF(J25="","",J25-K25) | N25: =IF(C25="covered",10.4,7.55) -> 7.55 | O25: =IF(M25="","",M25-N25) | R25: =IF(OR(J25="",P25=""),"",K25*N25*P25) | S25: =IF(Q25="","",Q25-R25) | T25: =IF(S25="","",MAX(0,-S25)) | U25: =IF(S25="","",MAX(0,S25)) | V25: =IF(J25="","NOT SCORED - NO JULY MONTHLY ROW",IF(OR(ABS(L25)>0.005,ABS(O25)>0.005,ABS(S25)>0.005),"EXCEPTION","OK")) -> NOT SCORED - NO JULY MONTHLY ROW | X25: No July MONTHLY_MOORAGE row in billing_transactions_2022_2026.csv | Y25: =K25*N25 -> 528.5
A26: GW-0512 | B26: Gullwing | C26: open | D26: MA-2024-0512 | E26: WL-03869 | F26: Seth Raymond | G26: MURRE LIGHT | H26: 32 | I26: 37 | K26: =MAX(ROUNDUP(I26,0),H26) -> 37 | L26: =IF(J26="","",J26-K26) | N26: =IF(C26="covered",10.4,7.55) -> 7.55 | O26: =IF(M26="","",M26-N26) | R26: =IF(OR(J26="",P26=""),"",K26*N26*P26) | S26: =IF(Q26="","",Q26-R26) | T26: =IF(S26="","",MAX(0,-S26)) | U26: =IF(S26="","",MAX(0,S26)) | V26: =IF(J26="","NOT SCORED - NO JULY MONTHLY ROW",IF(OR(ABS(L26)>0.005,ABS(O26)>0.005,ABS(S26)>0.005),"EXCEPTION","OK")) -> NOT SCORED - NO JULY MONTHLY ROW | X26: No July MONTHLY_MOORAGE row in billing_transactions_2022_2026.csv | Y26: =K26*N26 -> 279.35
A27: GW-0513 | B27: Gullwing | C27: open | D27: MA-2024-0513 | E27: WL-03045 | F27: Karen Davis | G27: GRAY BAY | H27: 32 | I27: 51.6 | K27: =MAX(ROUNDUP(I27,0),H27) -> 52 | L27: =IF(J27="","",J27-K27) | N27: =IF(C27="covered",10.4,7.55) -> 7.55 | O27: =IF(M27="","",M27-N27) | R27: =IF(OR(J27="",P27=""),"",K27*N27*P27) | S27: =IF(Q27="","",Q27-R27) | T27: =IF(S27="","",MAX(0,-S27)) | U27: =IF(S27="","",MAX(0,S27)) | V27: =IF(J27="","NOT SCORED - NO JULY MONTHLY ROW",IF(OR(ABS(L27)>0.005,ABS(O27)>0.005,ABS(S27)>0.005),"EXCEPTION","OK")) -> NOT SCORED - NO JULY MONTHLY ROW | X27: No July MONTHLY_MOORAGE row in billing_transactions_2022_2026.csv | Y27: =K27*N27 -> 392.6
A28: GW-0514 | B28: Gullwing | C28: open | D28: MA-2024-0514 | E28: WL-03143 | F28: Timothy Jennings | G28: POINT RUNNER | H28: 40 | I28: 32.5 | K28: =MAX(ROUNDUP(I28,0),H28) -> 40 | L28: =IF(J28="","",J28-K28) | N28: =IF(C28="covered",10.4,7.55) -> 7.55 | O28: =IF(M28="","",M28-N28) | R28: =IF(OR(J28="",P28=""),"",K28*N28*P28) | S28: =IF(Q28="","",Q28-R28) | T28: =IF(S28="","",MAX(0,-S28)) | U28: =IF(S28="","",MAX(0,S28)) | V28: =IF(J28="","NOT SCORED - NO JULY MONTHLY ROW",IF(OR(ABS(L28)>0.005,ABS(O28)>0.005,ABS(S28)>0.005),"EXCEPTION","OK")) -> NOT SCORED - NO JULY MONTHLY ROW | X28: No July MONTHLY_MOORAGE row in billing_transactions_2022_2026.csv | Y28: =K28*N28 -> 302
... A333: SB-0918 | B333: Salmonberry | C333: open | D333: MA-2024-0918 | E333: WL-03420 | F333: Laura Franklin | G333: CORMORANT STAR | H333: 80 | I333: 56.6 | K333: =MAX(ROUNDUP(I333,0),H333) -> 80 | L333: =IF(J333="","",J333-K333) | N333: =IF(C333="covered",10.4,7.55) -> 7.55 | O333: =IF(M333="","",M333-N333) | R333: =IF(OR(J333="",P333=""),"",K333*N333*P333) | S333: =IF(Q333="","",Q333-R333) | T333: =IF(S333="","",MAX(0,-S333)) | U333: =IF(S333="","",MAX(0,S333)) | V333: =IF(J333="","NOT SCORED - NO JULY MONTHLY ROW",IF(OR(ABS(L333)>0.005,ABS(O333)>0.005,ABS(S333)>0.005),"EXCEPTION","OK")) -> NOT SCORED - NO JULY MONTHLY ROW | X333: No July MONTHLY_MOORAGE row in billing_transactions_2022_2026.csv | Y333: =K333*N333 -> 604
A334: EW-0101 | B334: Eastwey | C334: open | D334: MA-2024-0101 | E334: WL-01414 | F334: Phillip Massey | G334: POINT SHORE | H334: 80 | I334: 29.3 | J334: 80 | K334: =MAX(ROUNDUP(I334,0),H334) -> 80 | L334: =IF(J334="","",J334-K334) -> 0 | M334: 7.55 | N334: =IF(C334="covered",10.4,7.55) -> 7.55 | O334: =IF(M334="","",M334-N334) -> 0 | P334: 1 | Q334: 604 | R334: =IF(OR(J334="",P334=""),"",K334*N334*P334) -> 604 | S334: =IF(Q334="","",Q334-R334) -> 0 | T334: =IF(S334="","",MAX(0,-S334)) -> 0 | U334: =IF(S334="","",MAX(0,S334)) -> 0 | V334: =IF(J334="","NOT SCORED - NO JULY MONTHLY ROW",IF(OR(ABS(L334)>0.005,ABS(O334)>0.005,ABS(S334)>0.005),"EXCEPTION","OK")) -> OK | W334: TXN-202607-028683 | X334: slip_inventory_2026-08.csv + July MONTHLY_MOORAGE row | Y334: =K334*N334 -> 604
A335: EW-0102 | B335: Eastwey | C335: open | D335: MA-2024-0102 | E335: WL-03666 | F335: Andrea Franco | G335: GRAY SONG | H335: 24 | I335: 55.3 | J335: 56 | K335: =MAX(ROUNDUP(I335,0),H335) -> 56 | L335: =IF(J335="","",J335-K335) -> 0 | M335: 7.55 | N335: =IF(C335="covered",10.4,7.55) -> 7.55 | O335: =IF(M335="","",M335-N335) -> 0 | P335: 1 | Q335: 422.8 | R335: =IF(OR(J335="",P335=""),"",K335*N335*P335) -> 422.8 | S335: =IF(Q335="","",Q335-R335) -> 0 | T335: =IF(S335="","",MAX(0,-S335)) -> 0 | U335: =IF(S335="","",MAX(0,S335)) -> 0 | V335: =IF(J335="","NOT SCORED - NO JULY MONTHLY ROW",IF(OR(ABS(L335)>0.005,ABS(O335)>0.005,ABS(S335)>0.005),"EXCEPTION","OK")) -> OK | W335: TXN-202607-028766 | X335: slip_inventory_2026-08.csv + July MONTHLY_MOORAGE row | Y335: =K335*N335 -> 422.8
A336: EW-0103 | B336: Eastwey | C336: open | D336: MA-2024-0103 | E336: WL-01149 | F336: David Hoffman | G336: MURRE RUNNER | H336: 36 | I336: 42.6 | J336: 43 | K336: =MAX(ROUNDUP(I336,0),H336) -> 43 | L336: =IF(J336="","",J336-K336) -> 0 | M336: 7.55 | N336: =IF(C336="covered",10.4,7.55) -> 7.55 | O336: =IF(M336="","",M336-N336) -> 0 | P336: 1 | Q336: 324.65 | R336: =IF(OR(J336="",P336=""),"",K336*N336*P336) -> 324.65 | S336: =IF(Q336="","",Q336-R336) -> 0 | T336: =IF(S336="","",MAX(0,-S336)) -> 0 | U336: =IF(S336="","",MAX(0,S336)) -> 0 | V336: =IF(J336="","NOT SCORED - NO JULY MONTHLY ROW",IF(OR(ABS(L336)>0.005,ABS(O336)>0.005,ABS(S336)>0.005),"EXCEPTION","OK")) -> OK | W336: TXN-202607-028830 | X336: slip_inventory_2026-08.csv + July MONTHLY_MOORAGE row | Y336: =K336*N336 -> 324.65
A337: EW-0105 | B337: Eastwey | C337: open | D337: MA-2024-0105 | E337: WL-03242 | F337: Micheal Navarro | G337: SABLE MOON | H337: 36 | I337: 60.2 | J337: 61 | K337: =MAX(ROUNDUP(I337,0),H337) -> 61 | L337: =IF(J337="","",J337-K337) -> 0 | M337: 7.55 | N337: =IF(C337="covered",10.4,7.55) -> 7.55 | O337: =IF(M337="","",M337-N337) -> 0 | P337: 1 | Q337: 460.55 | R337: =IF(OR(J337="",P337=""),"",K337*N337*P337) -> 460.55 | S337: =IF(Q337="","",Q337-R337) -> 0 | T337: =IF(S337="","",MAX(0,-S337)) -> 0 | U337: =IF(S337="","",MAX(0,S337)) -> 0 | V337: =IF(J337="","NOT SCORED - NO JULY MONTHLY ROW",IF(OR(ABS(L337)>0.005,ABS(O337)>0.005,ABS(S337)>0.005),"EXCEPTION","OK")) -> OK | W337: TXN-202607-028896 | X337: slip_inventory_2026-08.csv + July MONTHLY_MOORAGE row | Y337: =K337*N337 -> 460.55
A338: EW-0106 | B338: Eastwey | C338: open | D338: MA-2024-0106 | E338: WL-03380 | F338: Charles Snyder | G338: PETREL STAR | H338: 45 | I338: 47.5 | J338: 48 | K338: =MAX(ROUNDUP(I338,0),H338) -> 48 | L338: =IF(J338="","",J338-K338) -> 0 | M338: 7.55 | N338: =IF(C338="covered",10.4,7.55) -> 7.55 | O338: =IF(M338="","",M338-N338) -> 0 | P338: 1 | Q338: 362.4 | R338: =IF(OR(J338="",P338=""),"",K338*N338*P338) -> 362.4 | S338: =IF(Q338="","",Q338-R338) -> 0 | T338: =IF(S338="","",MAX(0,-S338)) -> 0 | U338: =IF(S338="","",MAX(0,S338)) -> 0 | V338: =IF(J338="","NOT SCORED - NO JULY MONTHLY ROW",IF(OR(ABS(L338)>0.005,ABS(O338)>0.005,ABS(S338)>0.005),"EXCEPTION","OK")) -> OK | W338: TXN-202607-028972 | X338: slip_inventory_2026-08.csv + July MONTHLY_MOORAGE row | Y338: =K338*N338 -> 362.4
A339: EW-0107 | B339: Eastwey | C339: open | D339: MA-2024-0107 | E339: WL-01368 | F339: Justin Turner | G339: SABLE WIND | H339: 28 | I339: 23.7 | J339: 28 | K339: =MAX(ROUNDUP(I339,0),H339) -> 28 | L339: =IF(J339="","",J339-K339) -> 0 | M339: 7.55 | N339: =IF(C339="covered",10.4,7.55) -> 7.55 | O339: =IF(M339="","",M339-N339) -> 0 | P339: 1 | Q339: 211.4 | R339: =IF(OR(J339="",P339=""),"",K339*N339*P339) -> 211.4 | S339: =IF(Q339="","",Q339-R339) -> 0 | T339: =IF(S339="","",MAX(0,-S339)) -> 0 | U339: =IF(S339="","",MAX(0,S339)) -> 0 | V339: =IF(J339="","NOT SCORED - NO JULY MONTHLY ROW",IF(OR(ABS(L339)>0.005,ABS(O339)>0.005,ABS(S339)>0.005),"EXCEPTION","OK")) -> OK | W339: TXN-202607-029047 | X339: slip_inventory_2026-08.csv + July MONTHLY_MOORAGE row | Y339: =K339*N339 -> 211.4
A340: EW-0108 | B340: Eastwey | C340: open | D340: MA-2024-0108 | E340: WL-02070 | F340: Leslie Thomas | G340: FOUL ROCK | H340: 40 | I340: 59.3 | J340: 60 | K340: =MAX(ROUNDUP(I340,0),H340) -> 60 | L340: =IF(J340="","",J340-K340) -> 0 | M340: 7.55 | N340: =IF(C340="covered",10.4,7.55) -> 7.55 | O340: =IF(M340="","",M340-N340) -> 0 | P340: 1 | Q340: 453 | R340: =IF(OR(J340="",P340=""),"",K340*N340*P340) -> 453 | S340: =IF(Q340="","",Q340-R340) -> 0 | T340: =IF(S340="","",MAX(0,-S340)) -> 0 | U340: =IF(S340="","",MAX(0,S340)) -> 0 | V340: =IF(J340="","NOT SCORED - NO JULY MONTHLY ROW",IF(OR(ABS(L340)>0.005,ABS(O340)>0.005,ABS(S340)>0.005),"EXCEPTION","OK")) -> OK | W340: TXN-202607-029118 | X340: slip_inventory_2026-08.csv + July MONTHLY_MOORAGE row | Y340: =K340*N340 -> 453
A341: EW-0109 | B341: Eastwey | C341: open | D341: MA-2024-0109 | E341: WL-03624 | F341: Robert Rodriguez | G341: COHO ANN | H341: 60 | I341: 30.9 | J341: 60 | K341: =MAX(ROUNDUP(I341,0),H341) -> 60 | L341: =IF(J341="","",J341-K341) -> 0 | M341: 7.55 | N341: =IF(C341="covered",10.4,7.55) -> 7.55 | O341: =IF(M341="","",M341-N341) -> 0 | P341: 1 | Q341: 453 | R341: =IF(OR(J341="",P341=""),"",K341*N341*P341) -> 453 | S341: =IF(Q341="","",Q341-R341) -> 0 | T341: =IF(S341="","",MAX(0,-S341)) -> 0 | U341: =IF(S341="","",MAX(0,S341)) -> 0 | V341: =IF(J341="","NOT SCORED - NO JULY MONTHLY ROW",IF(OR(ABS(L341)>0.005,ABS(O341)>0.005,ABS(S341)>0.005),"EXCEPTION","OK")) -> OK | W341: TXN-202607-029184 | X341: slip_inventory_2026-08.csv + July MONTHLY_MOORAGE row | Y341: =K341*N341 -> 453
A342: EW-0110 | B342: Eastwey | C342: open | D342: MA-2024-0110 | E342: WL-01831 | F342: Angela Andersen | G342: BRANT WAKE | H342: 28 | I342: 36.3 | J342: 37 | K342: =MAX(ROUNDUP(I342,0),H342) -> 37 | L342: =IF(J342="","",J342-K342) -> 0 | M342: 7.55 | N342: =IF(C342="covered",10.4,7.55) -> 7.55 | O342: =IF(M342="","",M342-N342) -> 0 | P342: 1 | Q342: 279.35 | R342: =IF(OR(J342="",P342=""),"",K342*N342*P342) -> 279.35 | S342: =IF(Q342="","",Q342-R342) -> 0 | T342: =IF(S342="","",MAX(0,-S342)) -> 0 | U342: =IF(S342="","",MAX(0,S342)) -> 0 | V342: =IF(J342="","NOT SCORED - NO JULY MONTHLY ROW",IF(OR(ABS(L342)>0.005,ABS(O342)>0.005,ABS(S342)>0.005),"EXCEPTION","OK")) -> OK | W342: TXN-202607-029245 | X342: slip_inventory_2026-08.csv + July MONTHLY_MOORAGE row | Y342: =K342*N342 -> 279.35
A343: EW-0111 | B343: Eastwey | C343: open | D343: MA-2024-0111 | E343: WL-01617 | F343: James Ferguson | G343: POINT DANCER | H343: 28 | I343: 43.9 | J343: 44 | K343: =MAX(ROUNDUP(I343,0),H343) -> 44 | L343: =IF(J343="","",J343-K343) -> 0 | M343: 7.55 | N343: =IF(C343="covered",10.4,7.55) -> 7.55 | O343: =IF(M343="","",M343-N343) -> 0 | P343: 1 | Q343: 332.2 | R343: =IF(OR(J343="",P343=""),"",K343*N343*P343) -> 332.2 | S343: =IF(Q343="","",Q343-R343) -> 0 | T343: =IF(S343="","",MAX(0,-S343)) -> 0 | U343: =IF(S343="","",MAX(0,S343)) -> 0 | V343: =IF(J343="","NOT SCORED - NO JULY MONTHLY ROW",IF(OR(ABS(L343)>0.005,ABS(O343)>0.005,ABS(S343)>0.005),"EXCEPTION","OK")) -> OK | W343: TXN-202607-029327 | X343: slip_inventory_2026-08.csv + July MONTHLY_MOORAGE row | Y343: =K343*N343 -> 332.2
A344: EW-0112 | B344: Eastwey | C344: open | D344: MA-2024-0112 | E344: WL-01533 | F344: Beth Cooper | G344: SPINDRIFT WIND | H344: 70 | I344: 38.7 | J344: 70 | K344: =MAX(ROUNDUP(I344,0),H344) -> 70 | L344: =IF(J344="","",J344-K344) -> 0 | M344: 7.55 | N344: =IF(C344="covered",10.4,7.55) -> 7.55 | O344: =IF(M344="","",M344-N344) -> 0 | P344: 1 | Q344: 528.5 | R344: =IF(OR(J344="",P344=""),"",K344*N344*P344) -> 528.5 | S344: =IF(Q344="","",Q344-R344) -> 0 | T344: =IF(S344="","",MAX(0,-S344)) -> 0 | U344: =IF(S344="","",MAX(0,S344)) -> 0 | V344: =IF(J344="","NOT SCORED - NO JULY MONTHLY ROW",IF(OR(ABS(L344)>0.005,ABS(O344)>0.005,ABS(S344)>0.005),"EXCEPTION","OK")) -> OK | W344: TXN-202607-029413 | X344: slip_inventory_2026-08.csv + July MONTHLY_MOORAGE row | Y344: =K344*N344 -> 528.5
A345: EW-0113 | B345: Eastwey | C345: open | D345: MA-2024-0113 | E345: WL-01482 | F345: Brandon Boyer | G345: TIDE MOON | H345: 45 | I345: 61.3 | J345: 62 | K345: =MAX(ROUNDUP(I345,0),H345) -> 62 | L345: =IF(J345="","",J345-K345) -> 0 | M345: 7.55 | N345: =IF(C345="covered",10.4,7.55) -> 7.55 | O345: =IF(M345="","",M345-N345) -> 0 | P345: 1 | Q345: 468.1 | R345: =IF(OR(J345="",P345=""),"",K345*N345*P345) -> 468.1 | S345: =IF(Q345="","",Q345-R345) -> 0 | T345: =IF(S345="","",MAX(0,-S345)) -> 0 | U345: =IF(S345="","",MAX(0,S345)) -> 0 | V345: =IF(J345="","NOT SCORED - NO JULY MONTHLY ROW",IF(OR(ABS(L345)>0.005,ABS(O345)>0.005,ABS(S345)>0.005),"EXCEPTION","OK")) -> OK | W345: TXN-202607-029473 | X345: slip_inventory_2026-08.csv + July MONTHLY_MOORAGE row | Y345: =K345*N345 -> 468.1
... A1102: VB-1024 | B1102: Vessbank | C1102: covered | D1102: MA-2024-1024 | E1102: WL-02463 | F1102: Lauren Oconnor | G1102: PINTAIL BAY | H1102: 32 | I1102: 55.7 | J1102: 56 | K1102: =MAX(ROUNDUP(I1102,0),H1102) -> 56 | L1102: =IF(J1102="","",J1102-K1102) -> 0 | M1102: 10.4 | N1102: =IF(C1102="covered",10.4,7.55) -> 10.4 | O1102: =IF(M1102="","",M1102-N1102) -> 0 | P1102: 1 | Q1102: 582.4 | R1102: =IF(OR(J1102="",P1102=""),"",K1102*N1102*P1102) -> 582.4 | S1102: =IF(Q1102="","",Q1102-R1102) -> 0 | T1102: =IF(S1102="","",MAX(0,-S1102)) -> 0 | U1102: =IF(S1102="","",MAX(0,S1102)) -> 0 | V1102: =IF(J1102="","NOT SCORED - NO JULY MONTHLY ROW",IF(OR(ABS(L1102)>0.005,ABS(O1102)>0.005,ABS(S1102)>0.005),"EXCEPTION","OK")) -> OK | W1102: TXN-202607-028607 | X1102: slip_inventory_2026-08.csv + July MONTHLY_MOORAGE row | Y1102: =K1102*N1102 -> 582.4

Sheet Aging
A1: AGING | ACTIVE HOLDERS OVER 90 DAYS
A2: Source: ar_aging_2026-07-31.xlsx, AR_Aging sheet | Active status cross-checked to slip_inventory_2026-08.csv
A3: Active holders | B3: =COUNTA($A$7:$A$12) -> 6 | C3: 91-120 balance | D3: =SUM($H$7:$H$12) -> 2932.8 | E3: 120+ balance | F3: =SUM($I$7:$I$12) -> 1435.2 | G3: Over-90 balance | H3: =SUM($J$7:$J$12) -> 4368 | I3: Total due - these accounts | J3: =SUM($K$7:$K$12) -> 13166.4
A6: Account ID | B6: Tenant | C6: Slip ID | D6: Basin | E6: Current | F6: 31-60 | G6: 61-90 | H6: 91-120 | I6: 120+ | J6: Over 90 | K6: Total Due | L6: Last Payment | M6: Ledger Status | N6: Last Contact | O6: Notes | P6: Active Slip | Q6: Priority
A7: AC-LP-0122 | B7: Paula Arroyo | C7: LP-0122 | D7: Ledgport | E7: 509.6 | F7: 509.6 | G7: 509.6 | H7: 509.6 | I7: 0 | J7: =H7+I7 -> 509.6 | K7: 2038.4 | L7: 2026-05-29 | M7: COLLECTIONS | N7: 2026-06-25 | P7: OCCUPIED | Q7: =IF(I7>0,"Immediate: 120+","High: 91-120") -> High: 91-120
A8: AC-LP-0402 | B8: Dawn Brown | C8: LP-0402 | D8: Ledgport | E8: 384.8 | F8: 384.8 | G8: 384.8 | H8: 384.8 | I8: 0 | J8: =H8+I8 -> 384.8 | K8: 1539.2 | L8: 2026-07-11 | M8: COLLECTIONS | N8: 2026-06-18 | P8: OCCUPIED | Q8: =IF(I8>0,"Immediate: 120+","High: 91-120") -> High: 91-120
A9: AC-LP-0602 | B9: Lee Maldonado | C9: LP-0602 | D9: Ledgport | E9: 603.2 | F9: 603.2 | G9: 603.2 | H9: 603.2 | I9: 603.2 | J9: =H9+I9 -> 1206.4 | K9: 3016 | L9: 2026-07-18 | M9: COLLECTIONS | N9: 2026-06-22 | P9: OCCUPIED | Q9: =IF(I9>0,"Immediate: 120+","High: 91-120") -> Immediate: 120+
A10: AC-LP-0605 | B10: Andrew Anderson | C10: LP-0605 | D10: Ledgport | E10: 530.4 | F10: 530.4 | G10: 530.4 | H10: 530.4 | I10: 0 | J10: =H10+I10 -> 530.4 | K10: 2121.6 | L10: 2026-05-06 | M10: COLLECTIONS | N10: 2026-07-14 | P10: OCCUPIED | Q10: =IF(I10>0,"Immediate: 120+","High: 91-120") -> High: 91-120
A11: AC-LP-0713 | B11: Stacey Mitchell | C11: LP-0713 | D11: Ledgport | E11: 416 | F11: 416 | G11: 416 | H11: 416 | I11: 832 | J11: =H11+I11 -> 1248 | K11: 2496 | L11: 2026-05-15 | M11: COLLECTIONS | N11: 2026-07-02 | P11: OCCUPIED | Q11: =IF(I11>0,"Immediate: 120+","High: 91-120") -> Immediate: 120+
A12: AC-LP-0801 | B12: Allison Nguyen | C12: LP-0801 | D12: Ledgport | E12: 488.8 | F12: 488.8 | G12: 488.8 | H12: 488.8 | I12: 0 | J12: =H12+I12 -> 488.8 | K12: 1955.2 | L12: 2026-07-08 | M12: COLLECTIONS | N12: 2026-07-03 | P12: OCCUPIED | Q12: =IF(I12>0,"Immediate: 120+","High: 91-120") -> High: 91-120
