Workbook

Sheet Summary
A1: Chaldale Moorage Audit | Board Review
A2: Audit date 2026-08-07 | Formula-driven totals and variances | Prepared for the Board of Harbor Commissioners
A4: Board Decisions
A5: 1. Confirm cash receipts posted from 2026-08-01 through 2026-08-07, then pursue collection on each occupied account with a 91+ day balance.
A6: 2. Refer Priority 1 queue exceptions for immediate independent review; do not rely on unsupported skips or downstream effects until resolved.
A7: 3. Complete the August billing run and correct AR total_due arithmetic before using the subledger for collection notices or financial reporting.
A9: Queue Integrity
A10: Skips audited | B10: =COUNTA('Skip Audit'!$A$6:$A$314) -> 309 | C10: records | D10: skip_events_2022_2026.csv; user scope
A11: Skip Priority 1 | B11: =COUNTIF('Skip Audit'!$U$6:$U$314,"Priority 1") -> 309 | C11: records | D11: Skip Audit formulas; Standing Order 15-3 ss.3.2-3.3
A12: Skip Priority 2 | B12: =COUNTIF('Skip Audit'!$U$6:$U$314,"Priority 2") -> 0 | C12: records | D12: Skip Audit formulas
A13: LOA amendments audited | B13: =COUNTA('Amendment Audit'!$A$6:$A$205) -> 200 | C13: records | D13: amendment_log_2022_2026.csv; Resolution 2022-06 s.4.3
A14: Amendment Priority 1 | B14: =COUNTIF('Amendment Audit'!$M$6:$M$205,"Priority 1") -> 15 | C14: records | D14: Unsupported amendment with downstream skip
A15: Amendment Priority 2 | B15: =COUNTIF('Amendment Audit'!$M$6:$M$205,"Priority 2") -> 184 | C15: records | D15: Unsupported amendment without downstream skip
A16: Substantiated LOA amendments | B16: =COUNTIF('Amendment Audit'!$I$6:$I$205,"SUBSTANTIATED") -> 1 | C16: records | D16: Two supplied measurement certificates; exact applicant/date/value test
A18: Billing Reconciliation | August 2026 Base Moorage
A19: Occupied slips | B19: =COUNTA('Billing Recon'!$A$6:$A$1091) -> 1086 | C19: records | D19: slip_inventory_2026-08.csv; status=OCCUPIED
A20: Occupied slips with posted charge | B20: =COUNTIF('Billing Recon'!$O$6:$O$1091,">0") -> 769 | C20: records | D20: billing_transactions_2022_2026.csv; 2026-08-01 MONTHLY_MOORAGE
A21: Occupied slips missing charge | B21: =COUNTIF('Billing Recon'!$R$6:$R$1091,"No August moorage transaction") -> 317 | C21: records | D21: Billing Recon completeness formula
A22: Expected charges | B22: =SUM('Billing Recon'!$N$6:$N$1091) -> 439918.3 | C22: dollars | D22: Resolution 2022-06 ss.1.1-1.3; Tariff Resolution 2019-14 s.1(4)
A23: Actual posted charges | B23: =SUM('Billing Recon'!$P$6:$P$1091) -> 319760.05 | C23: dollars | D23: billing_transactions_2022_2026.csv amount field; pre-tax
A24: Variance: actual - expected | B24: =SUM('Billing Recon'!$Q$6:$Q$1091) -> -120158.25 | C24: dollars | D24: Billing Recon row formulas
A26: Aging and Collection
A27: Occupied accounts with 91+ balance | B27: =COUNTIF('Aging Report'!$S$6:$S$265,"YES") -> 6 | C27: accounts | D27: ar_aging_2026-07-31.xlsx AR_Aging; embedded slip verified in inventory
A28: 91-120 balance | B28: =SUMIFS('Aging Report'!$I$6:$I$265,'Aging Report'!$S$6:$S$265,"YES") -> 2932.8 | C28: dollars | D28: AR_Aging days_90 field
A29: 120+ balance | B29: =SUMIFS('Aging Report'!$J$6:$J$265,'Aging Report'!$S$6:$S$265,"YES") -> 1435.2 | C29: dollars | D29: AR_Aging days_120_plus field
A30: Combined 91+ delinquent balance | B30: =SUMIFS('Aging Report'!$R$6:$R$265,'Aging Report'!$S$6:$S$265,"YES") -> 4368 | C30: dollars | D30: Aging Report formula: 91-120 + 120+
A31: Total account due for collection candidates | B31: =SUMIFS('Aging Report'!$L$6:$L$265,'Aging Report'!$S$6:$S$265,"YES") -> 13166.4 | C31: dollars | D31: Bucket sum, not source total_due
A32: Priority 3 AR arithmetic errors | B32: =COUNTIF('Aging Report'!$Y$6:$Y$265,"Priority 3") -> 39 | C32: accounts | D32: Aging Report reported total_due vs bucket sum
A33: AR total_due understatement | B33: =-SUMIF('Aging Report'!$Y$6:$Y$265,"Priority 3",'Aging Report'!$M$6:$M$265) -> 17108 | C33: dollars | D33: Aging Report arithmetic variance
A35: Collection Candidates | 91+ Days
A36: Account | B36: Tenant | C36: Slip | D36: 91-120 | E36: 120+ | F36: 91+ balance | G36: Total due | H36: Occupied
A37: ='Aging Report'!A26 -> AC-LP-0122 | B37: ='Aging Report'!B26 -> Paula Arroyo | C37: ='Aging Report'!N26 -> LP-0122 | D37: ='Aging Report'!I26 -> 509.6 | E37: ='Aging Report'!J26 -> 0 | F37: ='Aging Report'!R26 -> 509.6 | G37: ='Aging Report'!L26 -> 2038.4 | H37: ='Aging Report'!Q26 -> Y
A38: ='Aging Report'!A71 -> AC-LP-0402 | B38: ='Aging Report'!B71 -> Dawn Brown | C38: ='Aging Report'!N71 -> LP-0402 | D38: ='Aging Report'!I71 -> 384.8 | E38: ='Aging Report'!J71 -> 0 | F38: ='Aging Report'!R71 -> 384.8 | G38: ='Aging Report'!L71 -> 1539.2 | H38: ='Aging Report'!Q71 -> Y
A39: ='Aging Report'!A116 -> AC-LP-0602 | B39: ='Aging Report'!B116 -> Lee Maldonado | C39: ='Aging Report'!N116 -> LP-0602 | D39: ='Aging Report'!I116 -> 603.2 | E39: ='Aging Report'!J116 -> 603.2 | F39: ='Aging Report'!R116 -> 1206.4 | G39: ='Aging Report'!L116 -> 3016 | H39: ='Aging Report'!Q116 -> Y
A40: ='Aging Report'!A119 -> AC-LP-0605 | B40: ='Aging Report'!B119 -> Andrew Anderson | C40: ='Aging Report'!N119 -> LP-0605 | D40: ='Aging Report'!I119 -> 530.4 | E40: ='Aging Report'!J119 -> 0 | F40: ='Aging Report'!R119 -> 530.4 | G40: ='Aging Report'!L119 -> 2121.6 | H40: ='Aging Report'!Q119 -> Y
A41: ='Aging Report'!A150 -> AC-LP-0713 | B41: ='Aging Report'!B150 -> Stacey Mitchell | C41: ='Aging Report'!N150 -> LP-0713 | D41: ='Aging Report'!I150 -> 416 | E41: ='Aging Report'!J150 -> 832 | F41: ='Aging Report'!R150 -> 1248 | G41: ='Aging Report'!L150 -> 2496 | H41: ='Aging Report'!Q150 -> Y
A42: ='Aging Report'!A161 -> AC-LP-0801 | B42: ='Aging Report'!B161 -> Allison Nguyen | C42: ='Aging Report'!N161 -> LP-0801 | D42: ='Aging Report'!I161 -> 488.8 | E42: ='Aging Report'!J161 -> 0 | F42: ='Aging Report'!R161 -> 488.8 | G42: ='Aging Report'!L161 -> 1955.2 | H42: ='Aging Report'!Q161 -> Y
A43: TOTAL | D43: =SUM(D37:D42) -> 2932.8 | E43: =SUM(E37:E42) -> 1435.2 | F43: =SUM(F37:F42) -> 4368 | G43: =SUM(G37:G42) -> 13166.4 | H43: =COUNTIF(H37:H42,"Y")&" verified" -> 6 verified

Sheet Controls & Sources
A1: Audit Controls, Authority, and Sources
A2: Source inputs are transcribed from the named records; calculated findings are formulas in the audit sheets.
A4: Control | B4: Value | C4: Source | D4: Basis | E4: Workbook use
A5: Covered rate per foot-month | B5: 10.4 | C5: resolution_2022-06.pdf | D5: s.1.1; effective for periods from 2022-08-01 | E5: Formula input
A6: Open rate per foot-month | B6: 7.55 | C6: resolution_2022-06.pdf | D6: s.1.2; effective for periods from 2022-08-01 | E6: Formula input
A7: Billing month | B7: 46235 | C7: billing_transactions_2022_2026.csv | D7: latest monthly cycle in file | E7: Formula input
A8: Audit date | B8: 46241 | C8: User instruction | D8: Board review date | E8: Formula input
A9: Skip audit start | B9: 44927 | C9: User instruction | D9: inclusive | E9: Formula input
A10: Skip audit end | B10: 46234 | C10: User instruction | D10: inclusive | E10: Formula input
A11: LOA amendment start | B11: 44774 | C11: resolution_2022-06.pdf | D11: s.4.3 and s.8.1 | E11: Formula input
A13: Record | B13: Section / location | C13: Rule used | D13: Authority conclusion | E13: Notes
A14: Standing Order 15-3 | B14: ss.3.2-3.3 | C14: Cover sheet plus supporting record assembled on day worked; cover alone is insufficient. | D14: Governs skip procedure. | E14: The user's explicit PDF existence test is applied in addition to the standing-order content rule.
A15: Resolution 2022-06 | B15: ss.4.3, 6.1-6.2, 8.1 | C15: LOA amendments from 2022-08-01 require a signed certificate or yard haul-out measurement sheet at entry. | D15: Controls conflicts with prior resolutions under s.7.2. | E15: A register reference is not treated as physical proof unless a supplied file substantiates it.
A16: Tariff Resolution 2019-14 | B16: ss.1(4), 2.3-2.4, Schedule A | C16: Billable length is greater of rounded-up check-in LOA or nominal slip length; rates are foot-month before tax. | D16: Billing basis, as amended by Resolution 2022-06. | E16: Expected charges exclude tax and electricity so they match the tariff's base moorage rate.
A17: Appeal 2018-3 decision | B17: III-A, IV-A, Order 4 | C17: District bears the burden for departures from rank; later-assembled material does not cure the file. | D17: Interpretive authority for strict contemporaneous proof. | E17: No conflict changes the governing rate or documentation standard.
A18: AR aging workbook | B18: AR_Aging rows 3-262; Summary | C18: 91-120 is source field days_90; 120+ is days_120_plus. Bucket detail governs when total_due disagrees. | D18: Summary bucket totals agree with detail; 39 total_due rows do not. | E18: No cash-receipts record for 2026-08-01 through 2026-08-07 was supplied.
A20: Source file(s) | B20: Workbook sheet | C20: Use | D20: Scope | E20: Status
A21: applicant_register_2026-08.csv | B21: Applicant Lookup | C21: applicant ID, name, current register status | D21: Supplied package | E21: Read-only source
A22: offer_events_2022_2026.csv | B22: Offer Events | C22: offer-to-skip reconciliation | D22: Supplied package | E22: Read-only source
A23: skip_events_2022_2026.csv | B23: Skip Events / Skip Audit | C23: skip scope and review dates | D23: Supplied package | E23: Read-only source
A24: amendment_log_2022_2026.csv | B24: Amendment Audit | C24: LOA changes from effective date | D24: Supplied package | E24: Read-only source
A25: billing_transactions_2022_2026.csv | B25: Billing Actual | C25: 2026-08 monthly moorage actuals | D25: Supplied package | E25: Read-only source
... A29: two measurement certificate PDFs | B29: Certificate Check | C29: physical LOA support and check-in classification | D29: Supplied package | E29: Read-only source

Sheet Applicant Lookup
A1: applicant_id | B1: applicant_name | C1: status | D1: vessel_name | E1: loa_ft | F1: preference_basin
A2: WL-01001 | B2: Valerie Jones | C2: EXPIRED | D2: MURRE WEATHER | E2: 51.6 | F2: Vessbank
A3: WL-01002 | B3: Virginia Ramirez | C3: ACTIVE_WAITLIST | D3: HERON MIST | E3: 38.2 | F3: ANY
A4: WL-01003 | B4: Shannon Phillips | C4: ACTIVE_WAITLIST | D4: HALIBUT REACH | E4: 55 | F4: ANY
A5: WL-01004 | B5: Joseph Lopez | C5: ACTIVE_WAITLIST | D5: OTTER HARBOR | E5: 61.6 | F5: OPEN_ONLY
A6: WL-01005 | B6: Joseph Sharp | C6: ACTIVE_WAITLIST | D6: POINT ROSE | E6: 49.9 | F6: COVERED_ONLY
A7: WL-01006 | B7: Gregory Hammond | C7: ACTIVE_WAITLIST | D7: FOUL ROSE | E7: 34.4 | F7: COVERED_ONLY
A8: WL-01007 | B8: Victoria Henderson | C8: ACTIVE_WAITLIST | D8: HERON QUEEN | E8: 47.6 | F8: Vessbank
A9: WL-01008 | B9: Thomas Houston | C9: ACTIVE_WAITLIST | D9: KESTREL REACH | E9: 52.8 | F9: ANY
A10: WL-01009 | B10: Mark Moon | C10: ACTIVE_WAITLIST | D10: KESTREL HRABOR | E10: 22.2 | F10: Salmonberry
A11: WL-01010 | B11: Steven Hanson | C11: ACTIVE_WAITLIST | D11: SANDERLING WEATHER | E11: 26.5 | F11: ANY
A12: WL-01011 | B12: Kristen Hughes | C12: ACTIVE_WAITLIST | D12: TIDE BAY | E12: 60.3 | F12: COVERED_ONLY
A13: WL-01012 | B13: Janet Jones | C13: ACTIVE_WAITLIST | D13: SALISH REACH | E13: 23 | F13: Ledgport
... A2911: WL-03910 | B2911: Brian Buchanan | C2911: ACTIVE_WAITLIST | D2911: HERON WIND | E2911: 44.8 | F2911: Eastwey

Sheet Slip Inventory
A1: slip_id | B1: basin | C1: basin_type | D1: dock_row | E1: slip_size_ft | F1: slip_class | G1: covered | H1: beam_max_ft | I1: amenities | J1: status | K1: current_agreement_id | L1: tenant_id | M1: tenant_name | N1: vessel_name | O1: vessel_loa_ft | P1: monthly_rate | Q1: last_inspection_date | R1: notes
A2: LP-0101 | B2: Ledgport | C2: covered | D2: A | E2: 24 | F2: Small | G2: COVERED | H2: 9 | I2: Water, 30A/50A Power | J2: OCCUPIED | K2: MA-2024-0101 | L2: WL-02442 | M2: Elizabeth Burns | N2: SABLE REACH | O2: 51 | P2: 10.4 | Q2: 2025-12-23
A3: LP-0102 | B3: Ledgport | C3: covered | D3: A | E3: 40 | F3: Medium | G3: COVERED | H3: 14 | I3: Water, 50A Power | J3: OCCUPIED | K3: MA-2024-0102 | L3: WL-02413 | M3: Damon Phillips | N3: SEAL ROCK | O3: 21.9 | P3: 10.4 | Q3: 2026-04-24
A4: LP-0103 | B4: Ledgport | C4: covered | D4: A | E4: 28 | F4: Small | G4: COVERED | H4: 10 | I4: Water, 30A/50A Power | J4: OCCUPIED | K4: MA-2024-0103 | L4: WL-01449 | M4: Charles Hudson | N4: HALIBUT HARBOR | O4: 32.7 | P4: 10.4 | Q4: 2024-12-10
A5: LP-0104 | B5: Ledgport | C5: covered | D5: A | E5: 24 | F5: Small | G5: COVERED | H5: 9 | I5: Water, 30A/50A Power | J5: OCCUPIED | K5: MA-2024-0104 | L5: WL-03625 | M5: Vincent Johnson | N5: ANCHOR DANCER | O5: 42.8 | P5: 10.4 | Q5: 2025-06-05
A6: LP-0105 | B6: Ledgport | C6: covered | D6: A | E6: 36 | F6: Medium | G6: COVERED | H6: 13 | I6: Water, 50A Power | J6: OCCUPIED | K6: MA-2024-0105 | L6: WL-03876 | M6: John Heath | N6: CORMORANT GLIDE | O6: 39 | P6: 10.4 | Q6: 2025-01-17
A7: LP-0106 | B7: Ledgport | C7: covered | D7: A | E7: 24 | F7: Small | G7: COVERED | H7: 9 | I7: Water, 30A/50A Power | J7: OCCUPIED | K7: MA-2024-0106 | L7: WL-02316 | M7: Cheryl Elliott | N7: POINT ROSE | O7: 39 | P7: 10.4 | Q7: 2026-01-22
A8: LP-0107 | B8: Ledgport | C8: covered | D8: A | E8: 24 | F8: Small | G8: COVERED | H8: 9 | I8: Water, 30A/50A Power | J8: OCCUPIED | K8: MA-2024-0107 | L8: WL-02607 | M8: Sean Charles | N8: KESTREL REACH | O8: 30.4 | P8: 10.4 | Q8: 2025-06-28
A9: LP-0108 | B9: Ledgport | C9: covered | D9: A | E9: 32 | F9: Medium | G9: COVERED | H9: 12 | I9: Water, 30A/50A Power | J9: OCCUPIED | K9: MA-2024-0108 | L9: WL-01567 | M9: Alan Thomas | N9: PETREL HARBOR | O9: 23.4 | P9: 10.4 | Q9: 2025-01-07
A10: LP-0109 | B10: Ledgport | C10: covered | D10: A | E10: 32 | F10: Medium | G10: COVERED | H10: 12 | I10: Water, 30A/50A Power | J10: OCCUPIED | K10: MA-2024-0109 | L10: WL-02768 | M10: Sandra Sweeney | N10: CORMORANT REACH | O10: 20.8 | P10: 10.4 | Q10: 2026-03-08
A11: LP-0110 | B11: Ledgport | C11: covered | D11: A | E11: 28 | F11: Small | G11: COVERED | H11: 10 | I11: Water, 30A/50A Power | J11: OCCUPIED | K11: MA-2024-0110 | L11: WL-03140 | M11: Jason Martinez | N11: PINTAIL STAR | O11: 26 | P11: 10.4 | Q11: 2025-08-24
A12: LP-0111 | B12: Ledgport | C12: covered | D12: A | E12: 40 | F12: Medium | G12: COVERED | H12: 14 | I12: Water, 50A Power | J12: OCCUPIED | K12: MA-2024-0111 | L12: WL-03621 | M12: Denise Powers | N12: SALISH WAKE | O12: 53.5 | P12: 10.4 | Q12: 2026-01-30
A13: LP-0112 | B13: Ledgport | C13: covered | D13: A | E13: 32 | F13: Medium | G13: COVERED | H13: 12 | I13: Water, 30A/50A Power | J13: GUEST | P13: 10.4 | Q13: 2025-04-19
A14: LP-0113 | B14: Ledgport | C14: covered | D14: A | E14: 36 | F14: Medium | G14: COVERED | H14: 13 | I14: Water, 50A Power | J14: OCCUPIED | K14: MA-2024-0113 | L14: WL-02762 | M14: Elizabeth Williams | N14: MURRE WAKE | O14: 26 | P14: 10.4 | Q14: 2026-05-27
A15: LP-0114 | B15: Ledgport | C15: covered | D15: A | E15: 24 | F15: Small | G15: COVERED | H15: 9 | I15: Water, 30A/50A Power | J15: OCCUPIED | K15: MA-2024-0114 | L15: WL-02237 | M15: William Powell | N15: SCOTER WEATHER | O15: 28.2 | P15: 10.4 | Q15: 2026-01-16
A16: LP-0115 | B16: Ledgport | C16: covered | D16: A | E16: 28 | F16: Small | G16: COVERED | H16: 10 | I16: Water, 30A/50A Power | J16: OCCUPIED | K16: MA-2024-0115 | L16: WL-02943 | M16: Matthew Thomas | N16: PINTAIL CREST | O16: 18.8 | P16: 10.4 | Q16: 2025-05-09
A17: LP-0116 | B17: Ledgport | C17: covered | D17: A | E17: 28 | F17: Small | G17: COVERED | H17: 10 | I17: Water, 30A/50A Power | J17: OCCUPIED | K17: MA-2024-0116 | L17: WL-02031 | M17: Joseph Bishop | N17: ANCHOR LIGHT | O17: 19.2 | P17: 10.4 | Q17: 2025-10-28
A18: LP-0117 | B18: Ledgport | C18: covered | D18: A | E18: 32 | F18: Medium | G18: COVERED | H18: 12 | I18: Water, 30A/50A Power | J18: OCCUPIED | K18: MA-2024-0117 | L18: WL-01361 | M18: Benjamin Willis | N18: COHO BAY | O18: 28.7 | P18: 10.4 | Q18: 2025-03-20
A19: LP-0118 | B19: Ledgport | C19: covered | D19: A | E19: 24 | F19: Small | G19: COVERED | H19: 9 | I19: Water, 30A/50A Power | J19: OCCUPIED | K19: MA-2024-0118 | L19: WL-03633 | M19: Keith Powell | N19: PINTAIL RUNNER | O19: 22.1 | P19: 10.4 | Q19: 2024-11-02
A20: LP-0119 | B20: Ledgport | C20: covered | D20: A | E20: 24 | F20: Small | G20: COVERED | H20: 9 | I20: Water, 30A/50A Power | J20: OCCUPIED | K20: MA-2024-0119 | L20: WL-01880 | M20: Walter Torres | N20: CORMORANT WEATHER | O20: 43.5 | P20: 10.4 | Q20: 2026-06-14
A21: LP-0120 | B21: Ledgport | C21: covered | D21: A | E21: 32 | F21: Medium | G21: COVERED | H21: 12 | I21: Water, 30A/50A Power | J21: OCCUPIED | K21: MA-2024-0120 | L21: WL-03128 | M21: Kayla Johnson | N21: FOUL SONG | O21: 30.8 | P21: 10.4 | Q21: 2026-02-03
A22: LP-0121 | B22: Ledgport | C22: covered | D22: A | E22: 32 | F22: Medium | G22: COVERED | H22: 12 | I22: Water, 30A/50A Power | J22: OCCUPIED | K22: MA-2024-0121 | L22: WL-03477 | M22: Darryl Garcia | N22: TIDE SHORE | O22: 51.3 | P22: 10.4 | Q22: 2025-03-14
A23: LP-0122 | B23: Ledgport | C23: covered | D23: A | E23: 36 | F23: Medium | G23: COVERED | H23: 13 | I23: Water, 50A Power | J23: OCCUPIED | K23: MA-2024-0122 | L23: WL-01974 | M23: Paula Arroyo | N23: OTTER SOUND | O23: 48.2 | P23: 10.4 | Q23: 2024-10-09
A24: LP-0123 | B24: Ledgport | C24: covered | D24: A | E24: 32 | F24: Medium | G24: COVERED | H24: 12 | I24: Water, 30A/50A Power | J24: OCCUPIED | K24: MA-2024-0123 | L24: WL-03479 | M24: Brittney Daugherty | N24: SALISH GLIDE | O24: 25.3 | P24: 10.4 | Q24: 2026-03-15
A25: LP-0124 | B25: Ledgport | C25: covered | D25: A | E25: 28 | F25: Small | G25: COVERED | H25: 10 | I25: Water, 30A/50A Power | J25: OCCUPIED | K25: MA-2024-0124 | L25: WL-02080 | M25: Audrey Le | N25: GRAY MIST | O25: 38.8 | P25: 10.4 | Q25: 2025-01-23
... A31: LP-0206 | B31: Ledgport | C31: covered | D31: B | E31: 24 | F31: Small | G31: COVERED | H31: 9 | I31: Water, 30A/50A Power | J31: OCCUPIED | K31: MA-2024-0206 | L31: WL-03079 | M31: Crystal Glover | N31: TIDE STAR | O31: 41.4 | P31: 10.4 | Q31: 2026-01-29
A32: LP-0207 | B32: Ledgport | C32: covered | D32: B | E32: 40 | F32: Medium | G32: COVERED | H32: 14 | I32: Water, 50A Power | J32: VACANT | P32: 10.4 | Q32: 2025-09-26
A33: LP-0208 | B33: Ledgport | C33: covered | D33: B | E33: 32 | F33: Medium | G33: COVERED | H33: 12 | I33: Water, 30A/50A Power | J33: OCCUPIED | K33: MA-2024-0208 | L33: WL-02432 | M33: James Olson | N33: SALISH SONG | O33: 35.9 | P33: 10.4 | Q33: 2026-02-09
A34: LP-0209 | B34: Ledgport | C34: covered | D34: B | E34: 32 | F34: Medium | G34: COVERED | H34: 12 | I34: Water, 30A/50A Power | J34: OCCUPIED | K34: MA-2024-0209 | L34: WL-01517 | M34: Manuel Abbott | N34: ANCHOR MIST | O34: 19.8 | P34: 10.4 | Q34: 2025-12-25
A35: LP-0210 | B35: Ledgport | C35: covered | D35: B | E35: 40 | F35: Medium | G35: COVERED | H35: 14 | I35: Water, 50A Power | J35: OCCUPIED | K35: MA-2024-0210 | L35: WL-02178 | M35: Thomas Stone | N35: COHO SHORE | O35: 24.8 | P35: 10.4 | Q35: 2026-01-07
A36: LP-0211 | B36: Ledgport | C36: covered | D36: B | E36: 24 | F36: Small | G36: COVERED | H36: 9 | I36: Water, 30A/50A Power | J36: VACANT | P36: 10.4 | Q36: 2025-11-12
A37: LP-0212 | B37: Ledgport | C37: covered | D37: B | E37: 24 | F37: Small | G37: COVERED | H37: 9 | I37: Water, 30A/50A Power | J37: OCCUPIED | K37: MA-2024-0212 | L37: WL-03348 | M37: Sandra Jackson | N37: HERON RUNNER | O37: 57.4 | P37: 10.4 | Q37: 2026-03-30
A38: LP-0213 | B38: Ledgport | C38: covered | D38: B | E38: 40 | F38: Medium | G38: COVERED | H38: 14 | I38: Water, 50A Power | J38: OCCUPIED | K38: MA-2024-0213 | L38: WL-02388 | M38: Gregory Brady | N38: DRIFT SOUND | O38: 49.7 | P38: 10.4 | Q38: 2025-08-16
A39: LP-0214 | B39: Ledgport | C39: covered | D39: B | E39: 28 | F39: Small | G39: COVERED | H39: 10 | I39: Water, 30A/50A Power | J39: OCCUPIED | K39: MA-2024-0214 | L39: WL-01816 | M39: Jeanne Bennett | N39: BRANT WIND | O39: 31 | P39: 10.4 | Q39: 2025-04-09
A40: LP-0215 | B40: Ledgport | C40: covered | D40: B | E40: 28 | F40: Small | G40: COVERED | H40: 10 | I40: Water, 30A/50A Power | J40: OCCUPIED | K40: MA-2024-0215 | L40: WL-01337 | M40: Anna Wright | N40: WIDGEON LIGHT | O40: 26.3 | P40: 10.4 | Q40: 2025-01-13
A41: LP-0216 | B41: Ledgport | C41: covered | D41: B | E41: 32 | F41: Medium | G41: COVERED | H41: 12 | I41: Water, 30A/50A Power | J41: OCCUPIED | K41: MA-2024-0216 | L41: WL-01428 | M41: Audrey Taylor | N41: SCOTER CREST | O41: 57 | P41: 10.4 | Q41: 2025-04-15
A42: LP-0217 | B42: Ledgport | C42: covered | D42: B | E42: 40 | F42: Medium | G42: COVERED | H42: 14 | I42: Water, 50A Power | J42: OCCUPIED | K42: MA-2024-0217 | L42: WL-01497 | M42: Aaron Ellis | N42: SANDERLING STAR | O42: 58.7 | P42: 10.4 | Q42: 2025-04-30
A43: LP-0218 | B43: Ledgport | C43: covered | D43: B | E43: 24 | F43: Small | G43: COVERED | H43: 9 | I43: Water, 30A/50A Power | J43: OCCUPIED | K43: MA-2024-0218 | L43: WL-01177 | M43: Sydney Moore | N43: SCOTER STAR | O43: 41.6 | P43: 10.4 | Q43: 2024-12-31
A44: LP-0219 | B44: Ledgport | C44: covered | D44: B | E44: 28 | F44: Small | G44: COVERED | H44: 10 | I44: Water, 30A/50A Power | J44: OCCUPIED | K44: MA-2024-0219 | L44: WL-01324 | M44: Bradley Baker | N44: PINTAIL QUEEN | O44: 46.9 | P44: 10.4 | Q44: 2026-03-09
A45: LP-0220 | B45: Ledgport | C45: covered | D45: B | E45: 28 | F45: Small | G45: COVERED | H45: 10 | I45: Water, 30A/50A Power | J45: OCCUPIED | K45: MA-2024-0220 | L45: WL-02659 | M45: Loretta Murillo | N45: SALISH SONG | O45: 45.1 | P45: 10.4 | Q45: 2026-05-20
...

Sheet Offer Events
A1: offer_id | B1: offer_date | C1: applicant_id | D1: rank_at_offer | E1: slip_id | F1: basin | G1: slip_size_ft | H1: covered | I1: rate_class | J1: monthly_rate | K1: offer_seq | L1: outcome | M1: response_due_date | N1: response_date | O1: days_to_respond | P1: skip_reason_code | Q1: agreement_id | R1: notes
A2: OFR-2022-0001 | B2: 44582 | C2: WL-02136 | D2: 1136 | E2: GW-0701 | F2: Gullwing | G2: 80 | H2: OPEN | I2: NON_COMM_MONTHLY | J2: 7.55 | K2: 1 | L2: SKIPPED | M2: 44596 | P2: vessel-fit
A3: OFR-2022-0002 | B3: 44569 | C3: WL-02400 | D3: 1400 | E3: VB-0907 | F3: Vessbank | G3: 28 | H3: COVERED | I3: NON_COMM_MONTHLY | J3: 10.4 | K3: 1 | L3: ACCEPTED | M3: 44579 | N3: 44581 | O3: 12 | Q3: MA-2022-0907
A4: OFR-2022-0003 | B4: 44575 | C4: WL-02494 | D4: 1494 | E4: GW-0710 | F4: Gullwing | G4: 36 | H4: OPEN | I4: NON_COMM_MONTHLY | J4: 7.55 | K4: 1 | L4: DECLINED_RETAINER | M4: 44589 | N4: 44588 | O4: 13
A5: OFR-2022-0004 | B5: 44584 | C5: WL-01104 | D5: 104 | E5: LP-0414 | F5: Ledgport | G5: 40 | H5: COVERED | I5: NON_COMM_MONTHLY | J5: 10.4 | K5: 1 | L5: EXPIRED | M5: 44594 | N5: 44588 | O5: 4
A6: OFR-2022-0005 | B6: 44577 | C6: WL-02683 | D6: 1683 | E6: LP-0804 | F6: Ledgport | G6: 32 | H6: COVERED | I6: NON_COMM_MONTHLY | J6: 10.4 | K6: 1 | L6: ACCEPTED | M6: 44587 | N6: 44587 | O6: 10 | Q6: MA-2022-0804
A7: OFR-2022-0006 | B7: 44570 | C7: WL-03173 | D7: 2173 | E7: SB-0812 | F7: Salmonberry | G7: 32 | H7: OPEN | I7: NON_COMM_MONTHLY | J7: 7.55 | K7: 2 | L7: PENDING | M7: 44584
A8: OFR-2022-0007 | B8: 44562 | C8: WL-01369 | D8: 369 | E8: EW-0818 | F8: Eastwey | G8: 32 | H8: OPEN | I8: NON_COMM_MONTHLY | J8: 7.55 | K8: 2 | L8: EXPIRED | M8: 44576 | N8: 44569 | O8: 7
A9: OFR-2022-0008 | B9: 44563 | C9: WL-02883 | D9: 1883 | E9: SB-0209 | F9: Salmonberry | G9: 24 | H9: OPEN | I9: NON_COMM_MONTHLY | J9: 7.55 | K9: 1 | L9: EXPIRED | M9: 44577 | N9: 44577 | O9: 14
A10: OFR-2022-0009 | B10: 44581 | C10: WL-02049 | D10: 1049 | E10: LP-0707 | F10: Ledgport | G10: 28 | H10: COVERED | I10: NON_COMM_MONTHLY | J10: 10.4 | K10: 1 | L10: DECLINED_RETAINER | M10: 44591 | N10: 44591 | O10: 10
A11: OFR-2022-0010 | B11: 44582 | C11: WL-01004 | D11: 4 | E11: GW-0411 | F11: Gullwing | G11: 32 | H11: OPEN | I11: NON_COMM_MONTHLY | J11: 7.55 | K11: 1 | L11: SKIPPED | M11: 44596 | P11: not-current
A12: OFR-2022-0011 | B12: 44571 | C12: WL-03553 | D12: 2553 | E12: VB-0820 | F12: Vessbank | G12: 36 | H12: COVERED | I12: NON_COMM_MONTHLY | J12: 10.4 | K12: 1 | L12: ACCEPTED | M12: 44581 | N12: 44584 | O12: 13 | Q12: MA-2022-0820
A13: OFR-2022-0012 | B13: 44568 | C13: WL-03449 | D13: 2449 | E13: LP-0313 | F13: Ledgport | G13: 32 | H13: COVERED | I13: NON_COMM_MONTHLY | J13: 10.4 | K13: 1 | L13: DECLINED_RETAINER | M13: 44578 | N13: 44581 | O13: 13
A14: OFR-2022-0013 | B14: 44585 | C14: WL-03735 | D14: 2735 | E14: LP-0612 | F14: Ledgport | G14: 32 | H14: COVERED | I14: NON_COMM_MONTHLY | J14: 10.4 | K14: 2 | L14: ACCEPTED | M14: 44595 | N14: 44595 | O14: 10 | Q14: MA-2022-0612
A15: OFR-2022-0014 | B15: 44568 | C15: WL-03826 | D15: 2826 | E15: LP-0216 | F15: Ledgport | G15: 32 | H15: COVERED | I15: NON_COMM_MONTHLY | J15: 10.4 | K15: 1 | L15: DECLINED_RETAINER | M15: 44578 | N15: 44573 | O15: 5
A16: OFR-2022-0015 | B16: 44574 | C16: WL-01817 | D16: 817 | E16: SB-0307 | F16: Salmonberry | G16: 32 | H16: OPEN | I16: NON_COMM_MONTHLY | J16: 7.55 | K16: 1 | L16: DECLINED_RETAINER | M16: 44588 | N16: 44578 | O16: 4
A17: OFR-2022-0016 | B17: 44577 | C17: WL-01468 | D17: 468 | E17: LP-1003 | F17: Ledgport | G17: 28 | H17: COVERED | I17: NON_COMM_MONTHLY | J17: 10.4 | K17: 1 | L17: ACCEPTED | M17: 44587 | N17: 44581 | O17: 4 | Q17: MA-2022-1003
A18: OFR-2022-0017 | B18: 44576 | C18: WL-02851 | D18: 1851 | E18: SB-0315 | F18: Salmonberry | G18: 24 | H18: OPEN | I18: NON_COMM_MONTHLY | J18: 7.55 | K18: 1 | L18: DECLINED | M18: 44590 | N18: 44588 | O18: 12
A19: OFR-2022-0018 | B19: 44575 | C19: WL-01364 | D19: 364 | E19: GW-0811 | F19: Gullwing | G19: 45 | H19: OPEN | I19: NON_COMM_MONTHLY | J19: 7.55 | K19: 1 | L19: SKIPPED | M19: 44589 | P19: declined-prior-offer
A20: OFR-2022-0019 | B20: 44578 | C20: WL-01700 | D20: 700 | E20: LP-1019 | F20: Ledgport | G20: 32 | H20: COVERED | I20: NON_COMM_MONTHLY | J20: 10.4 | K20: 1 | L20: SKIPPED | M20: 44588 | P20: vessel-fit
A21: OFR-2022-0020 | B21: 44573 | C21: WL-01605 | D21: 605 | E21: LP-0111 | F21: Ledgport | G21: 40 | H21: COVERED | I21: NON_COMM_MONTHLY | J21: 10.4 | K21: 1 | L21: DECLINED | M21: 44583 | N21: 44586 | O21: 13
A22: OFR-2022-0021 | B22: 44579 | C22: WL-03516 | D22: 2516 | E22: GW-0419 | F22: Gullwing | G22: 32 | H22: OPEN | I22: NON_COMM_MONTHLY | J22: 7.55 | K22: 1 | L22: EXPIRED | M22: 44593 | N22: 44592 | O22: 13
A23: OFR-2022-0022 | B23: 44564 | C23: WL-01553 | D23: 553 | E23: EW-0408 | F23: Eastwey | G23: 28 | H23: OPEN | I23: NON_COMM_MONTHLY | J23: 7.55 | K23: 1 | L23: DECLINED | M23: 44578 | N23: 44578 | O23: 14
A24: OFR-2022-0023 | B24: 44585 | C24: WL-01399 | D24: 399 | E24: LP-0320 | F24: Ledgport | G24: 24 | H24: COVERED | I24: NON_COMM_MONTHLY | J24: 10.4 | K24: 1 | L24: SKIPPED | M24: 44595 | P24: preference-mismatch
A25: OFR-2022-0024 | B25: 44603 | C25: WL-03158 | D25: 2158 | E25: EW-0911 | F25: Eastwey | G25: 60 | H25: OPEN | I25: NON_COMM_MONTHLY | J25: 7.55 | K25: 1 | L25: ACCEPTED | M25: 44617 | N25: 44617 | O25: 14 | Q25: MA-2022-0911
A26: OFR-2022-0025 | B26: 44614 | C26: WL-03852 | D26: 2852 | E26: EW-0313 | F26: Eastwey | G26: 50 | H26: OPEN | I26: NON_COMM_MONTHLY | J26: 7.55 | K26: 2 | L26: SKIPPED | M26: 44628 | P26: declined-prior-offer
A27: OFR-2022-0026 | B27: 44605 | C27: WL-03346 | D27: 2346 | E27: GW-0406 | F27: Gullwing | G27: 28 | H27: OPEN | I27: NON_COMM_MONTHLY | J27: 7.55 | K27: 1 | L27: SKIPPED | M27: 44619 | P27: vessel-fit
A28: OFR-2022-0027 | B28: 44611 | C28: WL-02299 | D28: 1299 | E28: GW-0918 | F28: Gullwing | G28: 50 | H28: OPEN | I28: NON_COMM_MONTHLY | J28: 7.55 | K28: 2 | L28: DECLINED_RETAINER | M28: 44625 | N28: 44621 | O28: 10
A29: OFR-2022-0028 | B29: 44600 | C29: WL-02722 | D29: 1722 | E29: GW-0813 | F29: Gullwing | G29: 28 | H29: OPEN | I29: NON_COMM_MONTHLY | J29: 7.55 | K29: 2 | L29: ACCEPTED | M29: 44614 | N29: 44617 | O29: 17 | Q29: MA-2022-0813
A30: OFR-2022-0029 | B30: 44604 | C30: WL-02580 | D30: 1580 | E30: VB-1017 | F30: Vessbank | G30: 24 | H30: COVERED | I30: NON_COMM_MONTHLY | J30: 10.4 | K30: 1 | L30: EXPIRED | M30: 44614 | N30: 44616 | O30: 12
A31: OFR-2022-0030 | B31: 44600 | C31: WL-01051 | D31: 51 | E31: SB-0224 | F31: Salmonberry | G31: 32 | H31: OPEN | I31: NON_COMM_MONTHLY | J31: 7.55 | K31: 2 | L31: ACCEPTED | M31: 44614 | N31: 44617 | O31: 17 | Q31: MA-2022-0224
A32: OFR-2022-0031 | B32: 44596 | C32: WL-03579 | D32: 2579 | E32: GW-1012 | F32: Gullwing | G32: 80 | H32: OPEN | I32: NON_COMM_MONTHLY | J32: 7.55 | K32: 1 | L32: SKIPPED | M32: 44610 | P32: vessel-fit
A33: OFR-2022-0032 | B33: 44619 | C33: WL-01600 | D33: 600 | E33: EW-0317 | F33: Eastwey | G33: 36 | H33: OPEN | I33: NON_COMM_MONTHLY | J33: 7.55 | K33: 1 | L33: DECLINED | M33: 44633 | N33: 44621 | O33: 2
A34: OFR-2022-0033 | B34: 44609 | C34: WL-02224 | D34: 1224 | E34: LP-0121 | F34: Ledgport | G34: 32 | H34: COVERED | I34: NON_COMM_MONTHLY | J34: 10.4 | K34: 1 | L34: SKIPPED | M34: 44619 | P34: preference-mismatch
A35: OFR-2022-0034 | B35: 44604 | C35: WL-01971 | D35: 971 | E35: GW-0213 | F35: Gullwing | G35: 28 | H35: OPEN | I35: NON_COMM_MONTHLY | J35: 7.55 | K35: 2 | L35: DECLINED | M35: 44618 | N35: 44613 | O35: 9
A36: OFR-2022-0035 | B36: 44620 | C36: WL-02063 | D36: 1063 | E36: VB-0220 | F36: Vessbank | G36: 28 | H36: COVERED | I36: NON_COMM_MONTHLY | J36: 10.4 | K36: 2 | L36: SKIPPED | M36: 44630 | P36: declined-prior-offer
A37: OFR-2022-0036 | B37: 44595 | C37: WL-01307 | D37: 307 | E37: GW-0511 | F37: Gullwing | G37: 70 | H37: OPEN | I37: NON_COMM_MONTHLY | J37: 7.55 | K37: 1 | L37: EXPIRED | M37: 44609 | N37: 44604 | O37: 9
A38: OFR-2022-0037 | B38: 44640 | C38: WL-01140 | D38: 140 | E38: SB-0510 | F38: Salmonberry | G38: 32 | H38: OPEN | I38: NON_COMM_MONTHLY | J38: 7.55 | K38: 1 | L38: SKIPPED | M38: 44654 | P38: preference-mismatch
A39: OFR-2022-0038 | B39: 44625 | C39: WL-03416 | D39: 2416 | E39: SB-0319 | F39: Salmonberry | G39: 32 | H39: OPEN | I39: NON_COMM_MONTHLY | J39: 7.55 | K39: 1 | L39: ACCEPTED | M39: 44639 | N39: 44636 | O39: 11 | Q39: MA-2022-0319
A40: OFR-2022-0039 | B40: 44634 | C40: WL-01929 | D40: 929 | E40: EW-0119 | F40: Eastwey | G40: 32 | H40: OPEN | I40: NON_COMM_MONTHLY | J40: 7.55 | K40: 1 | L40: SKIPPED | M40: 44648 | P40: not-current
...

Sheet Skip Events
A1: skip_id | B1: offer_id | C1: skip_date | D1: applicant_id | E1: rank_at_offer | F1: slip_id | G1: basin | H1: slip_size_ft | I1: reason_code | J1: justification_category | K1: documentation_attached | L1: documentation_type | M1: reviewed_by | N1: review_date | O1: disposition | P1: notes
A2: SKP-2022-0001 | B2: OFR-2022-0001 | C2: 44582 | D2: WL-02136 | E2: 1136 | F2: GW-0701 | G2: Gullwing | H2: 80 | I2: vessel-fit | J2: SLIP_SIZE_MISMATCH | K2: Y | L2: INSURANCE_DECL | M2: MT | N2: 44584 | O2: SUSTAINED
A3: SKP-2022-0002 | B3: OFR-2022-0010 | C3: 44582 | D3: WL-01004 | E3: 4 | F3: GW-0411 | G3: Gullwing | H3: 32 | I3: not-current | J3: INSURANCE_LAPSE | K3: Y | L3: WRITTEN_STATEMENT | M3: EK | N3: 44587 | O3: SUSTAINED
A4: SKP-2022-0003 | B4: OFR-2022-0018 | C4: 44575 | D4: WL-01364 | E4: 364 | F4: GW-0811 | G4: Gullwing | H4: 45 | I4: declined-prior-offer | J4: OTHER | K4: Y | L4: INSURANCE_DECL | M4: MT | N4: 44580 | O4: SUSTAINED
A5: SKP-2022-0004 | B5: OFR-2022-0019 | C5: 44578 | D5: WL-01700 | E5: 700 | F5: LP-1019 | G5: Ledgport | H5: 32 | I5: vessel-fit | J5: SLIP_SIZE_MISMATCH | K5: Y | L5: REPAIR_ESTIMATE | M5: NO | N5: 44578 | O5: SUSTAINED
A6: SKP-2022-0005 | B6: OFR-2022-0023 | C6: 44585 | D6: WL-01399 | E6: 399 | F6: LP-0320 | G6: Ledgport | H6: 24 | I6: preference-mismatch | J6: LOCATION_PREF | K6: Y | L6: REPAIR_ESTIMATE | M6: RD | N6: 44587 | O6: SUSTAINED
A7: SKP-2022-0006 | B7: OFR-2022-0025 | C7: 44614 | D7: WL-03852 | E7: 2852 | F7: EW-0313 | G7: Eastwey | H7: 50 | I7: declined-prior-offer | J7: OTHER | K7: Y | L7: WRITTEN_STATEMENT | M7: PC | N7: 44615 | O7: SUSTAINED
A8: SKP-2022-0007 | B8: OFR-2022-0026 | C8: 44605 | D8: WL-03346 | E8: 2346 | F8: GW-0406 | G8: Gullwing | H8: 28 | I8: vessel-fit | J8: SLIP_SIZE_MISMATCH | K8: Y | L8: OTHER_SUPPORT | M8: PC | N8: 44607 | O8: SUSTAINED
A9: SKP-2022-0008 | B9: OFR-2022-0031 | C9: 44596 | D9: WL-03579 | E9: 2579 | F9: GW-1012 | G9: Gullwing | H9: 80 | I9: vessel-fit | J9: SLIP_SIZE_MISMATCH | K9: Y | L9: REPAIR_ESTIMATE | M9: PC | N9: 44600 | O9: SUSTAINED
A10: SKP-2022-0009 | B10: OFR-2022-0033 | C10: 44609 | D10: WL-02224 | E10: 1224 | F10: LP-0121 | G10: Ledgport | H10: 32 | I10: preference-mismatch | J10: LOCATION_PREF | K10: Y | L10: OTHER_SUPPORT | M10: TY | N10: 44610 | O10: SUSTAINED
A11: SKP-2022-0010 | B11: OFR-2022-0035 | C11: 44620 | D11: WL-02063 | E11: 1063 | F11: VB-0220 | G11: Vessbank | H11: 28 | I11: declined-prior-offer | J11: OTHER | K11: Y | L11: INSURANCE_DECL | M11: BH | N11: 44621 | O11: SUSTAINED
A12: SKP-2022-0011 | B12: OFR-2022-0037 | C12: 44640 | D12: WL-01140 | E12: 140 | F12: SB-0510 | G12: Salmonberry | H12: 32 | I12: preference-mismatch | J12: LOCATION_PREF | K12: Y | L12: REPAIR_ESTIMATE | M12: PC | N12: 44643 | O12: SUSTAINED
A13: SKP-2022-0012 | B13: OFR-2022-0039 | C13: 44634 | D13: WL-01929 | E13: 929 | F13: EW-0119 | G13: Eastwey | H13: 32 | I13: not-current | J13: INSURANCE_LAPSE | K13: Y | L13: OTHER_SUPPORT | M13: DR | N13: 44637 | O13: SUSTAINED
... A407: SKP-2026-0406 | B407: OFR-2026-1479 | C407: 46238 | D407: WL-01517 | E407: 517 | F407: SB-0623 | G407: Salmonberry | H407: 28 | I407: vessel-fit | J407: SLIP_SIZE_MISMATCH | K407: Y | L407: INSURANCE_DECL | M407: TY | N407: 46243 | O407: SUSTAINED
A408: SKP-2022-0407 | B408: OFR-2022-1487 | C408: 44818 | D408: WL-02211 | E408: 1211 | F408: GW-0417 | G408: Gullwing | H408: 32 | I408: not-current | J408: INSURANCE_LAPSE | K408: N | M408: BH | N408: 44820 | O408: SUSTAINED | P408: Cover sheet only - supporting record not attached
A409: SKP-2023-0408 | B409: OFR-2023-1487 | C409: 45048 | D409: WL-02618 | E409: 1618 | F409: GW-0610 | G409: Gullwing | H409: 32 | I409: vessel-fit | J409: SLIP_SIZE_MISMATCH | K409: N | M409: BH | N409: 45050 | O409: SUSTAINED | P409: Cover sheet only - supporting record not attached
A410: SKP-2024-0409 | B410: OFR-2024-1487 | C410: 45342 | D410: WL-03044 | E410: 2044 | F410: VB-0904 | G410: Vessbank | H410: 28 | I410: preference-mismatch | J410: LOCATION_PREF | K410: N | M410: PC | N410: 45344 | O410: SUSTAINED | P410: Cover sheet only - supporting record not attached
A411: SKP-2024-0410 | B411: OFR-2024-1487 | C411: 45601 | D411: WL-03390 | E411: 2390 | F411: SB-0120 | G411: Salmonberry | H411: 40 | I411: declined-prior-offer | J411: OTHER | K411: N | M411: GF | N411: 45603 | O411: SUSTAINED | P411: Cover sheet only - supporting record not attached
A412: SKP-2024-0411 | B412: OFR-2024-1487 | C412: 45370 | D412: WL-02877 | E412: 1877 | F412: GW-1012 | G412: Gullwing | H412: 80 | I412: vessel-fit | J412: SLIP_SIZE_MISMATCH | K412: Y | L412: REPAIR_ESTIMATE | M412: BH | N412: 45372 | O412: SUSTAINED
A413: SKP-2025-0412 | B413: OFR-2025-1487 | C413: 45909 | D413: WL-03102 | E413: 2102 | F413: LP-0806 | G413: Ledgport | H413: 36 | I413: preference-mismatch | J413: LOCATION_PREF | K413: Y | L413: OTHER_SUPPORT | M413: DR | N413: 45911 | O413: SUSTAINED

Sheet Skip PDF Index
A1: Skip Justification PDF Index
A2: Extracted from the six supplied PDFs and reconciled by formula to both event registers.
A3: A same-event PDF must also identify the registered slip and contain a supporting record. A cover sheet is not support under Standing Order 15-3 ss.3.2-3.3.
A5: source_file | B5: applicant_id | C5: applicant | D5: date_worked | E5: slip_in_pdf | F5: reason_code | G5: pages | H5: content_status | I5: same applicant/date/reason skips | J5: exact skip matches | K5: exact offer matches | L5: registered slip(s) | M5: reconciliation | N5: source_note
A6: WL-02211_skip_justification.pdf | B6: WL-02211 | C6: Ruth E. Mallory | D6: 44818 | E6: GW-0417 | F6: not-current | G6: 1 | H6: COVER ONLY | I6: =COUNTIFS('Skip Events'!$D$2:$D$413,B6,'Skip Events'!$C$2:$C$413,D6,'Skip Events'!$I$2:$I$413,F6) -> 1 | J6: =COUNTIFS('Skip Events'!$D$2:$D$413,B6,'Skip Events'!$C$2:$C$413,D6,'Skip Events'!$F$2:$F$413,E6,'Skip Events'!$I$2:$I$413,F6) -> 1 | K6: =COUNTIFS('Offer Events'!$C$2:$C$1487,B6,'Offer Events'!$B$2:$B$1487,D6,'Offer Events'!$E$2:$E$1487,E6,'Offer Events'!$L$2:$L$1487,"SKIPPED",'Offer Events'!$P$2:$P$1487,F6) -> 0 | L6: GW-0417 | M6: =IF(I6=0,"No skip event",IF(J6=0,"PDF slip differs from skip register",IF(H6<>"SUPPORTING RECORD","Cover only",IF(K6=0,"No matching offer event","Reconciled")))) -> Cover only | N6: Page 1 says supporting record not attached.
A7: WL-02618_skip_justification.pdf | B7: WL-02618 | C7: Gary Tomlinson | D7: 45048 | E7: EW-0414 | F7: vessel-fit | G7: 1 | H7: COVER ONLY | I7: =COUNTIFS('Skip Events'!$D$2:$D$413,B7,'Skip Events'!$C$2:$C$413,D7,'Skip Events'!$I$2:$I$413,F7) -> 1 | J7: =COUNTIFS('Skip Events'!$D$2:$D$413,B7,'Skip Events'!$C$2:$C$413,D7,'Skip Events'!$F$2:$F$413,E7,'Skip Events'!$I$2:$I$413,F7) -> 0 | K7: =COUNTIFS('Offer Events'!$C$2:$C$1487,B7,'Offer Events'!$B$2:$B$1487,D7,'Offer Events'!$E$2:$E$1487,E7,'Offer Events'!$L$2:$L$1487,"SKIPPED",'Offer Events'!$P$2:$P$1487,F7) -> 0 | L7: GW-0610 | M7: =IF(I7=0,"No skip event",IF(J7=0,"PDF slip differs from skip register",IF(H7<>"SUPPORTING RECORD","Cover only",IF(K7=0,"No matching offer event","Reconciled")))) -> PDF slip differs from skip register | N7: Page 1 says supporting record not attached.
A8: WL-02877_skip_justification.pdf | B8: WL-02877 | C8: Sandra Milovich | D8: 45370 | E8: GW-0702 | F8: vessel-fit | G8: 3 | H8: SUPPORTING RECORD | I8: =COUNTIFS('Skip Events'!$D$2:$D$413,B8,'Skip Events'!$C$2:$C$413,D8,'Skip Events'!$I$2:$I$413,F8) -> 1 | J8: =COUNTIFS('Skip Events'!$D$2:$D$413,B8,'Skip Events'!$C$2:$C$413,D8,'Skip Events'!$F$2:$F$413,E8,'Skip Events'!$I$2:$I$413,F8) -> 0 | K8: =COUNTIFS('Offer Events'!$C$2:$C$1487,B8,'Offer Events'!$B$2:$B$1487,D8,'Offer Events'!$E$2:$E$1487,E8,'Offer Events'!$L$2:$L$1487,"SKIPPED",'Offer Events'!$P$2:$P$1487,F8) -> 0 | L8: GW-1012 | M8: =IF(I8=0,"No skip event",IF(J8=0,"PDF slip differs from skip register",IF(H8<>"SUPPORTING RECORD","Cover only",IF(K8=0,"No matching offer event","Reconciled")))) -> PDF slip differs from skip register | N8: Pages 2-3 contain particulars and correspondence.
A9: WL-03044_skip_justification.pdf | B9: WL-03044 | C9: Iris B. Quan | D9: 45342 | E9: EW-0603 | F9: preference-mismatch | G9: 1 | H9: COVER ONLY | I9: =COUNTIFS('Skip Events'!$D$2:$D$413,B9,'Skip Events'!$C$2:$C$413,D9,'Skip Events'!$I$2:$I$413,F9) -> 1 | J9: =COUNTIFS('Skip Events'!$D$2:$D$413,B9,'Skip Events'!$C$2:$C$413,D9,'Skip Events'!$F$2:$F$413,E9,'Skip Events'!$I$2:$I$413,F9) -> 0 | K9: =COUNTIFS('Offer Events'!$C$2:$C$1487,B9,'Offer Events'!$B$2:$B$1487,D9,'Offer Events'!$E$2:$E$1487,E9,'Offer Events'!$L$2:$L$1487,"SKIPPED",'Offer Events'!$P$2:$P$1487,F9) -> 0 | L9: VB-0904 | M9: =IF(I9=0,"No skip event",IF(J9=0,"PDF slip differs from skip register",IF(H9<>"SUPPORTING RECORD","Cover only",IF(K9=0,"No matching offer event","Reconciled")))) -> PDF slip differs from skip register | N9: Page 1 says supporting record not attached.
A10: WL-03102_skip_justification.pdf | B10: WL-03102 | C10: Dennis K. Farlow | D10: 45909 | E10: EW-0620 | F10: preference-mismatch | G10: 3 | H10: SUPPORTING RECORD | I10: =COUNTIFS('Skip Events'!$D$2:$D$413,B10,'Skip Events'!$C$2:$C$413,D10,'Skip Events'!$I$2:$I$413,F10) -> 1 | J10: =COUNTIFS('Skip Events'!$D$2:$D$413,B10,'Skip Events'!$C$2:$C$413,D10,'Skip Events'!$F$2:$F$413,E10,'Skip Events'!$I$2:$I$413,F10) -> 0 | K10: =COUNTIFS('Offer Events'!$C$2:$C$1487,B10,'Offer Events'!$B$2:$B$1487,D10,'Offer Events'!$E$2:$E$1487,E10,'Offer Events'!$L$2:$L$1487,"SKIPPED",'Offer Events'!$P$2:$P$1487,F10) -> 0 | L10: LP-0806 | M10: =IF(I10=0,"No skip event",IF(J10=0,"PDF slip differs from skip register",IF(H10<>"SUPPORTING RECORD","Cover only",IF(K10=0,"No matching offer event","Reconciled")))) -> PDF slip differs from skip register | N10: Pages 2-3 contain preference extract and correspondence.
A11: WL-03390_skip_justification.pdf | B11: WL-03390 | C11: Phillip Ard | D11: 45601 | E11: VB-0144 | F11: declined-prior-offer | G11: 1 | H11: COVER ONLY | I11: =COUNTIFS('Skip Events'!$D$2:$D$413,B11,'Skip Events'!$C$2:$C$413,D11,'Skip Events'!$I$2:$I$413,F11) -> 1 | J11: =COUNTIFS('Skip Events'!$D$2:$D$413,B11,'Skip Events'!$C$2:$C$413,D11,'Skip Events'!$F$2:$F$413,E11,'Skip Events'!$I$2:$I$413,F11) -> 0 | K11: =COUNTIFS('Offer Events'!$C$2:$C$1487,B11,'Offer Events'!$B$2:$B$1487,D11,'Offer Events'!$E$2:$E$1487,E11,'Offer Events'!$L$2:$L$1487,"SKIPPED",'Offer Events'!$P$2:$P$1487,F11) -> 0 | L11: SB-0120 | M11: =IF(I11=0,"No skip event",IF(J11=0,"PDF slip differs from skip register",IF(H11<>"SUPPORTING RECORD","Cover only",IF(K11=0,"No matching offer event","Reconciled")))) -> PDF slip differs from skip register | N11: Page 1 says supporting record not attached.

Sheet Skip Audit
A1: Skip Audit | 2023-01-01 to 2026-07-31
A2: Formula test: exact supporting PDF + exact offer reconciliation + review_date on or before skip_date.
A3: The skip register's documentation_attached flag is displayed but does not satisfy the user's physical-file test. Priority 1 means no valid supporting record; Priority 2 means valid support exists but review was late.
A5: skip_id | B5: offer_id | C5: skip_date | D5: applicant_id | E5: applicant_name | F5: rank | G5: slip_id | H5: basin | I5: reason_code | J5: register_doc_flag | K5: reviewed_by | L5: review_date | M5: same-event PDF count | N5: exact-slip PDF count | O5: supported exact PDF count | P5: exact offer count | Q5: review timely | R5: contemporaneous proof | S5: reconciliation | T5: issue | U5: priority
A6: SKP-2023-0095 | B6: OFR-2023-0323 | C6: 44934 | D6: WL-03099 | E6: =IFERROR(VLOOKUP(D6,'Applicant Lookup'!$A$2:$F$2911,2,FALSE()),"Not found") -> Ryan Robertson | F6: 2099 | G6: LP-0317 | H6: Ledgport | I6: vessel-fit | J6: Y | K6: EK | L6: 44936 | M6: =COUNTIFS('Skip PDF Index'!$B$6:$B$11,D6,'Skip PDF Index'!$D$6:$D$11,C6,'Skip PDF Index'!$F$6:$F$11,I6) -> 0 | N6: =COUNTIFS('Skip PDF Index'!$B$6:$B$11,D6,'Skip PDF Index'!$D$6:$D$11,C6,'Skip PDF Index'!$E$6:$E$11,G6,'Skip PDF Index'!$F$6:$F$11,I6) -> 0 | O6: =COUNTIFS('Skip PDF Index'!$B$6:$B$11,D6,'Skip PDF Index'!$D$6:$D$11,C6,'Skip PDF Index'!$E$6:$E$11,G6,'Skip PDF Index'!$F$6:$F$11,I6,'Skip PDF Index'!$H$6:$H$11,"SUPPORTING RECORD") -> 0 | P6: =COUNTIFS('Offer Events'!$A$2:$A$1487,B6,'Offer Events'!$B$2:$B$1487,C6,'Offer Events'!$C$2:$C$1487,D6,'Offer Events'!$E$2:$E$1487,G6,'Offer Events'!$L$2:$L$1487,"SKIPPED",'Offer Events'!$P$2:$P$1487,I6) -> 1 | Q6: =IF(L6<=C6,"Y","N") -> N | R6: =IF(AND(O6>0,P6>0,Q6="Y"),"Y","N") -> N | S6: =IF(P6=0,"Offer register missing/mismatch",IF(N6=0,IF(M6>0,"PDF slip mismatch","No matching PDF"),IF(O6=0,"PDF lacks supporting record","Reconciled"))) -> No matching PDF | T6: =IF(R6="Y","Compliant",S6&IF(Q6="N","; review after skip","")) -> No matching PDF; review after skip | U6: =IF(R6="Y","",IF(AND(O6>0,P6>0,Q6="N"),"Priority 2","Priority 1")) -> Priority 1
A7: SKP-2023-0096 | B7: OFR-2023-0324 | C7: 44934 | D7: WL-02685 | E7: =IFERROR(VLOOKUP(D7,'Applicant Lookup'!$A$2:$F$2911,2,FALSE()),"Not found") -> Stephanie Hill | F7: 1685 | G7: LP-0906 | H7: Ledgport | I7: vessel-fit | J7: Y | K7: MT | L7: 44937 | M7: =COUNTIFS('Skip PDF Index'!$B$6:$B$11,D7,'Skip PDF Index'!$D$6:$D$11,C7,'Skip PDF Index'!$F$6:$F$11,I7) -> 0 | N7: =COUNTIFS('Skip PDF Index'!$B$6:$B$11,D7,'Skip PDF Index'!$D$6:$D$11,C7,'Skip PDF Index'!$E$6:$E$11,G7,'Skip PDF Index'!$F$6:$F$11,I7) -> 0 | O7: =COUNTIFS('Skip PDF Index'!$B$6:$B$11,D7,'Skip PDF Index'!$D$6:$D$11,C7,'Skip PDF Index'!$E$6:$E$11,G7,'Skip PDF Index'!$F$6:$F$11,I7,'Skip PDF Index'!$H$6:$H$11,"SUPPORTING RECORD") -> 0 | P7: =COUNTIFS('Offer Events'!$A$2:$A$1487,B7,'Offer Events'!$B$2:$B$1487,C7,'Offer Events'!$C$2:$C$1487,D7,'Offer Events'!$E$2:$E$1487,G7,'Offer Events'!$L$2:$L$1487,"SKIPPED",'Offer Events'!$P$2:$P$1487,I7) -> 1 | Q7: =IF(L7<=C7,"Y","N") -> N | R7: =IF(AND(O7>0,P7>0,Q7="Y"),"Y","N") -> N | S7: =IF(P7=0,"Offer register missing/mismatch",IF(N7=0,IF(M7>0,"PDF slip mismatch","No matching PDF"),IF(O7=0,"PDF lacks supporting record","Reconciled"))) -> No matching PDF | T7: =IF(R7="Y","Compliant",S7&IF(Q7="N","; review after skip","")) -> No matching PDF; review after skip | U7: =IF(R7="Y","",IF(AND(O7>0,P7>0,Q7="N"),"Priority 2","Priority 1")) -> Priority 1
A8: SKP-2023-0097 | B8: OFR-2023-0326 | C8: 44952 | D8: WL-01298 | E8: =IFERROR(VLOOKUP(D8,'Applicant Lookup'!$A$2:$F$2911,2,FALSE()),"Not found") -> Jason Boyd | F8: 298 | G8: GW-0708 | H8: Gullwing | I8: vessel-fit | J8: Y | K8: EK | L8: 44955 | M8: =COUNTIFS('Skip PDF Index'!$B$6:$B$11,D8,'Skip PDF Index'!$D$6:$D$11,C8,'Skip PDF Index'!$F$6:$F$11,I8) -> 0 | N8: =COUNTIFS('Skip PDF Index'!$B$6:$B$11,D8,'Skip PDF Index'!$D$6:$D$11,C8,'Skip PDF Index'!$E$6:$E$11,G8,'Skip PDF Index'!$F$6:$F$11,I8) -> 0 | O8: =COUNTIFS('Skip PDF Index'!$B$6:$B$11,D8,'Skip PDF Index'!$D$6:$D$11,C8,'Skip PDF Index'!$E$6:$E$11,G8,'Skip PDF Index'!$F$6:$F$11,I8,'Skip PDF Index'!$H$6:$H$11,"SUPPORTING RECORD") -> 0 | P8: =COUNTIFS('Offer Events'!$A$2:$A$1487,B8,'Offer Events'!$B$2:$B$1487,C8,'Offer Events'!$C$2:$C$1487,D8,'Offer Events'!$E$2:$E$1487,G8,'Offer Events'!$L$2:$L$1487,"SKIPPED",'Offer Events'!$P$2:$P$1487,I8) -> 1 | Q8: =IF(L8<=C8,"Y","N") -> N | R8: =IF(AND(O8>0,P8>0,Q8="Y"),"Y","N") -> N | S8: =IF(P8=0,"Offer register missing/mismatch",IF(N8=0,IF(M8>0,"PDF slip mismatch","No matching PDF"),IF(O8=0,"PDF lacks supporting record","Reconciled"))) -> No matching PDF | T8: =IF(R8="Y","Compliant",S8&IF(Q8="N","; review after skip","")) -> No matching PDF; review after skip | U8: =IF(R8="Y","",IF(AND(O8>0,P8>0,Q8="N"),"Priority 2","Priority 1")) -> Priority 1
A9: SKP-2023-0098 | B9: OFR-2023-0334 | C9: 44934 | D9: WL-01959 | E9: =IFERROR(VLOOKUP(D9,'Applicant Lookup'!$A$2:$F$2911,2,FALSE()),"Not found") -> Jonathan Moore | F9: 959 | G9: VB-1023 | H9: Vessbank | I9: not-current | J9: Y | K9: BH | L9: 44937 | M9: =COUNTIFS('Skip PDF Index'!$B$6:$B$11,D9,'Skip PDF Index'!$D$6:$D$11,C9,'Skip PDF Index'!$F$6:$F$11,I9) -> 0 | N9: =COUNTIFS('Skip PDF Index'!$B$6:$B$11,D9,'Skip PDF Index'!$D$6:$D$11,C9,'Skip PDF Index'!$E$6:$E$11,G9,'Skip PDF Index'!$F$6:$F$11,I9) -> 0 | O9: =COUNTIFS('Skip PDF Index'!$B$6:$B$11,D9,'Skip PDF Index'!$D$6:$D$11,C9,'Skip PDF Index'!$E$6:$E$11,G9,'Skip PDF Index'!$F$6:$F$11,I9,'Skip PDF Index'!$H$6:$H$11,"SUPPORTING RECORD") -> 0 | P9: =COUNTIFS('Offer Events'!$A$2:$A$1487,B9,'Offer Events'!$B$2:$B$1487,C9,'Offer Events'!$C$2:$C$1487,D9,'Offer Events'!$E$2:$E$1487,G9,'Offer Events'!$L$2:$L$1487,"SKIPPED",'Offer Events'!$P$2:$P$1487,I9) -> 1 | Q9: =IF(L9<=C9,"Y","N") -> N | R9: =IF(AND(O9>0,P9>0,Q9="Y"),"Y","N") -> N | S9: =IF(P9=0,"Offer register missing/mismatch",IF(N9=0,IF(M9>0,"PDF slip mismatch","No matching PDF"),IF(O9=0,"PDF lacks supporting record","Reconciled"))) -> No matching PDF | T9: =IF(R9="Y","Compliant",S9&IF(Q9="N","; review after skip","")) -> No matching PDF; review after skip | U9: =IF(R9="Y","",IF(AND(O9>0,P9>0,Q9="N"),"Priority 2","Priority 1")) -> Priority 1
A10: SKP-2023-0099 | B10: OFR-2023-0338 | C10: 44936 | D10: WL-01695 | E10: =IFERROR(VLOOKUP(D10,'Applicant Lookup'!$A$2:$F$2911,2,FALSE()),"Not found") -> Antonio Leach | F10: 695 | G10: EW-0203 | H10: Eastwey | I10: vessel-fit | J10: N | K10: GF | L10: 44939 | M10: =COUNTIFS('Skip PDF Index'!$B$6:$B$11,D10,'Skip PDF Index'!$D$6:$D$11,C10,'Skip PDF Index'!$F$6:$F$11,I10) -> 0 | N10: =COUNTIFS('Skip PDF Index'!$B$6:$B$11,D10,'Skip PDF Index'!$D$6:$D$11,C10,'Skip PDF Index'!$E$6:$E$11,G10,'Skip PDF Index'!$F$6:$F$11,I10) -> 0 | O10: =COUNTIFS('Skip PDF Index'!$B$6:$B$11,D10,'Skip PDF Index'!$D$6:$D$11,C10,'Skip PDF Index'!$E$6:$E$11,G10,'Skip PDF Index'!$F$6:$F$11,I10,'Skip PDF Index'!$H$6:$H$11,"SUPPORTING RECORD") -> 0 | P10: =COUNTIFS('Offer Events'!$A$2:$A$1487,B10,'Offer Events'!$B$2:$B$1487,C10,'Offer Events'!$C$2:$C$1487,D10,'Offer Events'!$E$2:$E$1487,G10,'Offer Events'!$L$2:$L$1487,"SKIPPED",'Offer Events'!$P$2:$P$1487,I10) -> 1 | Q10: =IF(L10<=C10,"Y","N") -> N | R10: =IF(AND(O10>0,P10>0,Q10="Y"),"Y","N") -> N | S10: =IF(P10=0,"Offer register missing/mismatch",IF(N10=0,IF(M10>0,"PDF slip mismatch","No matching PDF"),IF(O10=0,"PDF lacks supporting record","Reconciled"))) -> No matching PDF | T10: =IF(R10="Y","Compliant",S10&IF(Q10="N","; review after skip","")) -> No matching PDF; review after skip | U10: =IF(R10="Y","",IF(AND(O10>0,P10>0,Q10="N"),"Priority 2","Priority 1")) -> Priority 1
A11: SKP-2023-0100 | B11: OFR-2023-0343 | C11: 44975 | D11: WL-02565 | E11: =IFERROR(VLOOKUP(D11,'Applicant Lookup'!$A$2:$F$2911,2,FALSE()),"Not found") -> Christina Smith | F11: 1565 | G11: GW-0116 | H11: Gullwing | I11: vessel-fit | J11: Y | K11: PC | L11: 44980 | M11: =COUNTIFS('Skip PDF Index'!$B$6:$B$11,D11,'Skip PDF Index'!$D$6:$D$11,C11,'Skip PDF Index'!$F$6:$F$11,I11) -> 0 | N11: =COUNTIFS('Skip PDF Index'!$B$6:$B$11,D11,'Skip PDF Index'!$D$6:$D$11,C11,'Skip PDF Index'!$E$6:$E$11,G11,'Skip PDF Index'!$F$6:$F$11,I11) -> 0 | O11: =COUNTIFS('Skip PDF Index'!$B$6:$B$11,D11,'Skip PDF Index'!$D$6:$D$11,C11,'Skip PDF Index'!$E$6:$E$11,G11,'Skip PDF Index'!$F$6:$F$11,I11,'Skip PDF Index'!$H$6:$H$11,"SUPPORTING RECORD") -> 0 | P11: =COUNTIFS('Offer Events'!$A$2:$A$1487,B11,'Offer Events'!$B$2:$B$1487,C11,'Offer Events'!$C$2:$C$1487,D11,'Offer Events'!$E$2:$E$1487,G11,'Offer Events'!$L$2:$L$1487,"SKIPPED",'Offer Events'!$P$2:$P$1487,I11) -> 1 | Q11: =IF(L11<=C11,"Y","N") -> N | R11: =IF(AND(O11>0,P11>0,Q11="Y"),"Y","N") -> N | S11: =IF(P11=0,"Offer register missing/mismatch",IF(N11=0,IF(M11>0,"PDF slip mismatch","No matching PDF"),IF(O11=0,"PDF lacks supporting record","Reconciled"))) -> No matching PDF | T11: =IF(R11="Y","Compliant",S11&IF(Q11="N","; review after skip","")) -> No matching PDF; review after skip | U11: =IF(R11="Y","",IF(AND(O11>0,P11>0,Q11="N"),"Priority 2","Priority 1")) -> Priority 1
A12: SKP-2023-0101 | B12: OFR-2023-0345 | C12: 44976 | D12: WL-02664 | E12: =IFERROR(VLOOKUP(D12,'Applicant Lookup'!$A$2:$F$2911,2,FALSE()),"Not found") -> Mark Smith | F12: 1664 | G12: GW-0220 | H12: Gullwing | I12: preference-mismatch | J12: Y | K12: TY | L12: 44976 | M12: =COUNTIFS('Skip PDF Index'!$B$6:$B$11,D12,'Skip PDF Index'!$D$6:$D$11,C12,'Skip PDF Index'!$F$6:$F$11,I12) -> 0 | N12: =COUNTIFS('Skip PDF Index'!$B$6:$B$11,D12,'Skip PDF Index'!$D$6:$D$11,C12,'Skip PDF Index'!$E$6:$E$11,G12,'Skip PDF Index'!$F$6:$F$11,I12) -> 0 | O12: =COUNTIFS('Skip PDF Index'!$B$6:$B$11,D12,'Skip PDF Index'!$D$6:$D$11,C12,'Skip PDF Index'!$E$6:$E$11,G12,'Skip PDF Index'!$F$6:$F$11,I12,'Skip PDF Index'!$H$6:$H$11,"SUPPORTING RECORD") -> 0 | P12: =COUNTIFS('Offer Events'!$A$2:$A$1487,B12,'Offer Events'!$B$2:$B$1487,C12,'Offer Events'!$C$2:$C$1487,D12,'Offer Events'!$E$2:$E$1487,G12,'Offer Events'!$L$2:$L$1487,"SKIPPED",'Offer Events'!$P$2:$P$1487,I12) -> 1 | Q12: =IF(L12<=C12,"Y","N") -> Y | R12: =IF(AND(O12>0,P12>0,Q12="Y"),"Y","N") -> N | S12: =IF(P12=0,"Offer register missing/mismatch",IF(N12=0,IF(M12>0,"PDF slip mismatch","No matching PDF"),IF(O12=0,"PDF lacks supporting record","Reconciled"))) -> No matching PDF | T12: =IF(R12="Y","Compliant",S12&IF(Q12="N","; review after skip","")) -> No matching PDF | U12: =IF(R12="Y","",IF(AND(O12>0,P12>0,Q12="N"),"Priority 2","Priority 1")) -> Priority 1
A13: SKP-2023-0102 | B13: OFR-2023-0346 | C13: 44967 | D13: WL-03582 | E13: =IFERROR(VLOOKUP(D13,'Applicant Lookup'!$A$2:$F$2911,2,FALSE()),"Not found") -> Melissa Jones | F13: 2582 | G13: GW-0615 | H13: Gullwing | I13: not-current | J13: Y | K13: TY | L13: 44971 | M13: =COUNTIFS('Skip PDF Index'!$B$6:$B$11,D13,'Skip PDF Index'!$D$6:$D$11,C13,'Skip PDF Index'!$F$6:$F$11,I13) -> 0 | N13: =COUNTIFS('Skip PDF Index'!$B$6:$B$11,D13,'Skip PDF Index'!$D$6:$D$11,C13,'Skip PDF Index'!$E$6:$E$11,G13,'Skip PDF Index'!$F$6:$F$11,I13) -> 0 | O13: =COUNTIFS('Skip PDF Index'!$B$6:$B$11,D13,'Skip PDF Index'!$D$6:$D$11,C13,'Skip PDF Index'!$E$6:$E$11,G13,'Skip PDF Index'!$F$6:$F$11,I13,'Skip PDF Index'!$H$6:$H$11,"SUPPORTING RECORD") -> 0 | P13: =COUNTIFS('Offer Events'!$A$2:$A$1487,B13,'Offer Events'!$B$2:$B$1487,C13,'Offer Events'!$C$2:$C$1487,D13,'Offer Events'!$E$2:$E$1487,G13,'Offer Events'!$L$2:$L$1487,"SKIPPED",'Offer Events'!$P$2:$P$1487,I13) -> 1 | Q13: =IF(L13<=C13,"Y","N") -> N | R13: =IF(AND(O13>0,P13>0,Q13="Y"),"Y","N") -> N | S13: =IF(P13=0,"Offer register missing/mismatch",IF(N13=0,IF(M13>0,"PDF slip mismatch","No matching PDF"),IF(O13=0,"PDF lacks supporting record","Reconciled"))) -> No matching PDF | T13: =IF(R13="Y","Compliant",S13&IF(Q13="N","; review after skip","")) -> No matching PDF; review after skip | U13: =IF(R13="Y","",IF(AND(O13>0,P13>0,Q13="N"),"Priority 2","Priority 1")) -> Priority 1
A14: SKP-2023-0103 | B14: OFR-2023-0350 | C14: 44974 | D14: WL-02918 | E14: =IFERROR(VLOOKUP(D14,'Applicant Lookup'!$A$2:$F$2911,2,FALSE()),"Not found") -> Kara Aguilar | F14: 1918 | G14: LP-1116 | H14: Ledgport | I14: declined-prior-offer | J14: Y | K14: RD | L14: 44978 | M14: =COUNTIFS('Skip PDF Index'!$B$6:$B$11,D14,'Skip PDF Index'!$D$6:$D$11,C14,'Skip PDF Index'!$F$6:$F$11,I14) -> 0 | N14: =COUNTIFS('Skip PDF Index'!$B$6:$B$11,D14,'Skip PDF Index'!$D$6:$D$11,C14,'Skip PDF Index'!$E$6:$E$11,G14,'Skip PDF Index'!$F$6:$F$11,I14) -> 0 | O14: =COUNTIFS('Skip PDF Index'!$B$6:$B$11,D14,'Skip PDF Index'!$D$6:$D$11,C14,'Skip PDF Index'!$E$6:$E$11,G14,'Skip PDF Index'!$F$6:$F$11,I14,'Skip PDF Index'!$H$6:$H$11,"SUPPORTING RECORD") -> 0 | P14: =COUNTIFS('Offer Events'!$A$2:$A$1487,B14,'Offer Events'!$B$2:$B$1487,C14,'Offer Events'!$C$2:$C$1487,D14,'Offer Events'!$E$2:$E$1487,G14,'Offer Events'!$L$2:$L$1487,"SKIPPED",'Offer Events'!$P$2:$P$1487,I14) -> 1 | Q14: =IF(L14<=C14,"Y","N") -> N | R14: =IF(AND(O14>0,P14>0,Q14="Y"),"Y","N") -> N | S14: =IF(P14=0,"Offer register missing/mismatch",IF(N14=0,IF(M14>0,"PDF slip mismatch","No matching PDF"),IF(O14=0,"PDF lacks supporting record","Reconciled"))) -> No matching PDF | T14: =IF(R14="Y","Compliant",S14&IF(Q14="N","; review after skip","")) -> No matching PDF; review after skip | U14: =IF(R14="Y","",IF(AND(O14>0,P14>0,Q14="N"),"Priority 2","Priority 1")) -> Priority 1
A15: SKP-2023-0104 | B15: OFR-2023-0360 | C15: 45000 | D15: WL-03523 | E15: =IFERROR(VLOOKUP(D15,'Applicant Lookup'!$A$2:$F$2911,2,FALSE()),"Not found") -> Darlene Glover | F15: 2523 | G15: SB-0210 | H15: Salmonberry | I15: vessel-fit | J15: N | K15: NO | L15: 45003 | M15: =COUNTIFS('Skip PDF Index'!$B$6:$B$11,D15,'Skip PDF Index'!$D$6:$D$11,C15,'Skip PDF Index'!$F$6:$F$11,I15) -> 0 | N15: =COUNTIFS('Skip PDF Index'!$B$6:$B$11,D15,'Skip PDF Index'!$D$6:$D$11,C15,'Skip PDF Index'!$E$6:$E$11,G15,'Skip PDF Index'!$F$6:$F$11,I15) -> 0 | O15: =COUNTIFS('Skip PDF Index'!$B$6:$B$11,D15,'Skip PDF Index'!$D$6:$D$11,C15,'Skip PDF Index'!$E$6:$E$11,G15,'Skip PDF Index'!$F$6:$F$11,I15,'Skip PDF Index'!$H$6:$H$11,"SUPPORTING RECORD") -> 0 | P15: =COUNTIFS('Offer Events'!$A$2:$A$1487,B15,'Offer Events'!$B$2:$B$1487,C15,'Offer Events'!$C$2:$C$1487,D15,'Offer Events'!$E$2:$E$1487,G15,'Offer Events'!$L$2:$L$1487,"SKIPPED",'Offer Events'!$P$2:$P$1487,I15) -> 1 | Q15: =IF(L15<=C15,"Y","N") -> N | R15: =IF(AND(O15>0,P15>0,Q15="Y"),"Y","N") -> N | S15: =IF(P15=0,"Offer register missing/mismatch",IF(N15=0,IF(M15>0,"PDF slip mismatch","No matching PDF"),IF(O15=0,"PDF lacks supporting record","Reconciled"))) -> No matching PDF | T15: =IF(R15="Y","Compliant",S15&IF(Q15="N","; review after skip","")) -> No matching PDF; review after skip | U15: =IF(R15="Y","",IF(AND(O15>0,P15>0,Q15="N"),"Priority 2","Priority 1")) -> Priority 1
A16: SKP-2023-0105 | B16: OFR-2023-0361 | C16: 44991 | D16: WL-02366 | E16: =IFERROR(VLOOKUP(D16,'Applicant Lookup'!$A$2:$F$2911,2,FALSE()),"Not found") -> Megan Hoffman | F16: 1366 | G16: LP-1116 | H16: Ledgport | I16: vessel-fit | J16: Y | K16: DR | L16: 44995 | M16: =COUNTIFS('Skip PDF Index'!$B$6:$B$11,D16,'Skip PDF Index'!$D$6:$D$11,C16,'Skip PDF Index'!$F$6:$F$11,I16) -> 0 | N16: =COUNTIFS('Skip PDF Index'!$B$6:$B$11,D16,'Skip PDF Index'!$D$6:$D$11,C16,'Skip PDF Index'!$E$6:$E$11,G16,'Skip PDF Index'!$F$6:$F$11,I16) -> 0 | O16: =COUNTIFS('Skip PDF Index'!$B$6:$B$11,D16,'Skip PDF Index'!$D$6:$D$11,C16,'Skip PDF Index'!$E$6:$E$11,G16,'Skip PDF Index'!$F$6:$F$11,I16,'Skip PDF Index'!$H$6:$H$11,"SUPPORTING RECORD") -> 0 | P16: =COUNTIFS('Offer Events'!$A$2:$A$1487,B16,'Offer Events'!$B$2:$B$1487,C16,'Offer Events'!$C$2:$C$1487,D16,'Offer Events'!$E$2:$E$1487,G16,'Offer Events'!$L$2:$L$1487,"SKIPPED",'Offer Events'!$P$2:$P$1487,I16) -> 1 | Q16: =IF(L16<=C16,"Y","N") -> N | R16: =IF(AND(O16>0,P16>0,Q16="Y"),"Y","N") -> N | S16: =IF(P16=0,"Offer register missing/mismatch",IF(N16=0,IF(M16>0,"PDF slip mismatch","No matching PDF"),IF(O16=0,"PDF lacks supporting record","Reconciled"))) -> No matching PDF | T16: =IF(R16="Y","Compliant",S16&IF(Q16="N","; review after skip","")) -> No matching PDF; review after skip | U16: =IF(R16="Y","",IF(AND(O16>0,P16>0,Q16="N"),"Priority 2","Priority 1")) -> Priority 1
A17: SKP-2023-0106 | B17: OFR-2023-0364 | C17: 45012 | D17: WL-01388 | E17: =IFERROR(VLOOKUP(D17,'Applicant Lookup'!$A$2:$F$2911,2,FALSE()),"Not found") -> Sharon Young | F17: 388 | G17: SB-0617 | H17: Salmonberry | I17: vessel-fit | J17: Y | K17: GF | L17: 45015 | M17: =COUNTIFS('Skip PDF Index'!$B$6:$B$11,D17,'Skip PDF Index'!$D$6:$D$11,C17,'Skip PDF Index'!$F$6:$F$11,I17) -> 0 | N17: =COUNTIFS('Skip PDF Index'!$B$6:$B$11,D17,'Skip PDF Index'!$D$6:$D$11,C17,'Skip PDF Index'!$E$6:$E$11,G17,'Skip PDF Index'!$F$6:$F$11,I17) -> 0 | O17: =COUNTIFS('Skip PDF Index'!$B$6:$B$11,D17,'Skip PDF Index'!$D$6:$D$11,C17,'Skip PDF Index'!$E$6:$E$11,G17,'Skip PDF Index'!$F$6:$F$11,I17,'Skip PDF Index'!$H$6:$H$11,"SUPPORTING RECORD") -> 0 | P17: =COUNTIFS('Offer Events'!$A$2:$A$1487,B17,'Offer Events'!$B$2:$B$1487,C17,'Offer Events'!$C$2:$C$1487,D17,'Offer Events'!$E$2:$E$1487,G17,'Offer Events'!$L$2:$L$1487,"SKIPPED",'Offer Events'!$P$2:$P$1487,I17) -> 1 | Q17: =IF(L17<=C17,"Y","N") -> N | R17: =IF(AND(O17>0,P17>0,Q17="Y"),"Y","N") -> N | S17: =IF(P17=0,"Offer register missing/mismatch",IF(N17=0,IF(M17>0,"PDF slip mismatch","No matching PDF"),IF(O17=0,"PDF lacks supporting record","Reconciled"))) -> No matching PDF | T17: =IF(R17="Y","Compliant",S17&IF(Q17="N","; review after skip","")) -> No matching PDF; review after skip | U17: =IF(R17="Y","",IF(AND(O17>0,P17>0,Q17="N"),"Priority 2","Priority 1")) -> Priority 1
... A314: SKP-2025-0412 | B314: OFR-2025-1487 | C314: 45909 | D314: WL-03102 | E314: =IFERROR(VLOOKUP(D314,'Applicant Lookup'!$A$2:$F$2911,2,FALSE()),"Not found") -> Dennis Farlow | F314: 2102 | G314: LP-0806 | H314: Ledgport | I314: preference-mismatch | J314: Y | K314: DR | L314: 45911 | M314: =COUNTIFS('Skip PDF Index'!$B$6:$B$11,D314,'Skip PDF Index'!$D$6:$D$11,C314,'Skip PDF Index'!$F$6:$F$11,I314) -> 1 | N314: =COUNTIFS('Skip PDF Index'!$B$6:$B$11,D314,'Skip PDF Index'!$D$6:$D$11,C314,'Skip PDF Index'!$E$6:$E$11,G314,'Skip PDF Index'!$F$6:$F$11,I314) -> 0 | O314: =COUNTIFS('Skip PDF Index'!$B$6:$B$11,D314,'Skip PDF Index'!$D$6:$D$11,C314,'Skip PDF Index'!$E$6:$E$11,G314,'Skip PDF Index'!$F$6:$F$11,I314,'Skip PDF Index'!$H$6:$H$11,"SUPPORTING RECORD") -> 0 | P314: =COUNTIFS('Offer Events'!$A$2:$A$1487,B314,'Offer Events'!$B$2:$B$1487,C314,'Offer Events'!$C$2:$C$1487,D314,'Offer Events'!$E$2:$E$1487,G314,'Offer Events'!$L$2:$L$1487,"SKIPPED",'Offer Events'!$P$2:$P$1487,I314) -> 0 | Q314: =IF(L314<=C314,"Y","N") -> N | R314: =IF(AND(O314>0,P314>0,Q314="Y"),"Y","N") -> N | S314: =IF(P314=0,"Offer register missing/mismatch",IF(N314=0,IF(M314>0,"PDF slip mismatch","No matching PDF"),IF(O314=0,"PDF lacks supporting record","Reconciled"))) -> Offer register missing/mismatch | T314: =IF(R314="Y","Compliant",S314&IF(Q314="N","; review after skip","")) -> Offer register missing/mismatch; review after skip | U314: =IF(R314="Y","",IF(AND(O314>0,P314>0,Q314="N"),"Priority 2","Priority 1")) -> Priority 1

Sheet Certificate Check
